[2025-03-26T01:13:48.682+0000] {taskinstance.py:1159} INFO - Dependencies all met for dep_context=non-requeueable deps ti=<TaskInstance: job_data_stream.job_data_stream manual__2025-03-26T01:13:45.198203+00:00 [queued]>
[2025-03-26T01:13:48.692+0000] {taskinstance.py:1159} INFO - Dependencies all met for dep_context=requeueable deps ti=<TaskInstance: job_data_stream.job_data_stream manual__2025-03-26T01:13:45.198203+00:00 [queued]>
[2025-03-26T01:13:48.693+0000] {taskinstance.py:1361} INFO - Starting attempt 1 of 1
[2025-03-26T01:13:48.854+0000] {taskinstance.py:1382} INFO - Executing <Task(PythonOperator): job_data_stream> on 2025-03-26 01:13:45.198203+00:00
[2025-03-26T01:13:48.874+0000] {standard_task_runner.py:57} INFO - Started process 388 to run task
[2025-03-26T01:13:48.887+0000] {standard_task_runner.py:84} INFO - Running: ['***', 'tasks', 'run', 'job_data_stream', 'job_data_stream', 'manual__2025-03-26T01:13:45.198203+00:00', '--job-id', '58', '--raw', '--subdir', 'DAGS_FOLDER/data_stream.py', '--cfg-path', '/tmp/tmptd4a8yo2']
[2025-03-26T01:13:48.890+0000] {standard_task_runner.py:85} INFO - Job 58: Subtask job_data_stream
[2025-03-26T01:13:49.383+0000] {task_command.py:415} INFO - Running <TaskInstance: job_data_stream.job_data_stream manual__2025-03-26T01:13:45.198203+00:00 [running]> on host c0041b6c44f7
[2025-03-26T01:13:50.331+0000] {taskinstance.py:1660} INFO - Exporting env vars: AIRFLOW_CTX_DAG_OWNER='dii' AIRFLOW_CTX_DAG_ID='job_data_stream' AIRFLOW_CTX_TASK_ID='job_data_stream' AIRFLOW_CTX_EXECUTION_DATE='2025-03-26T01:13:45.198203+00:00' AIRFLOW_CTX_TRY_NUMBER='1' AIRFLOW_CTX_DAG_RUN_ID='manual__2025-03-26T01:13:45.198203+00:00'
[2025-03-26T01:13:50.352+0000] {conn.py:384} INFO - <BrokerConnection client_id=kafka-python-producer-1, node_id=bootstrap-0 host=broker:29092 <connecting> [IPv4 ('172.18.0.2', 29092)]>: connecting to broker:29092 [('172.18.0.2', 29092) IPv4]
[2025-03-26T01:13:50.355+0000] {conn.py:1219} INFO - Probing node bootstrap-0 broker version
[2025-03-26T01:13:50.360+0000] {conn.py:414} INFO - <BrokerConnection client_id=kafka-python-producer-1, node_id=bootstrap-0 host=broker:29092 <connecting> [IPv4 ('172.18.0.2', 29092)]>: Connection complete.
[2025-03-26T01:13:50.481+0000] {conn.py:1282} INFO - Broker version identified as 2.6.0
[2025-03-26T01:13:50.481+0000] {conn.py:1283} INFO - Set configuration api_version=(2, 6, 0) to skip auto check_version requests on startup
[2025-03-26T01:14:09.655+0000] {logging_mixin.py:151} INFO - Số công việc tìm thấy trên trang 401:70
[2025-03-26T01:16:05.559+0000] {logging_mixin.py:151} INFO - Số công việc tìm thấy trên trang 402:70
[2025-03-26T01:18:00.830+0000] {logging_mixin.py:151} INFO - Số công việc tìm thấy trên trang 403:70
[2025-03-26T01:18:50.565+0000] {conn.py:384} INFO - <BrokerConnection client_id=kafka-python-producer-1, node_id=1 host=broker:29092 <connecting> [IPv4 ('172.18.0.2', 29092)]>: connecting to broker:29092 [('172.18.0.2', 29092) IPv4]
[2025-03-26T01:18:50.567+0000] {conn.py:414} INFO - <BrokerConnection client_id=kafka-python-producer-1, node_id=1 host=broker:29092 <connecting> [IPv4 ('172.18.0.2', 29092)]>: Connection complete.
[2025-03-26T01:18:50.570+0000] {conn.py:928} INFO - <BrokerConnection client_id=kafka-python-producer-1, node_id=bootstrap-0 host=broker:29092 <connected> [IPv4 ('172.18.0.2', 29092)]>: Closing connection. 
[2025-03-26T01:19:55.002+0000] {logging_mixin.py:151} INFO - Số công việc tìm thấy trên trang 404:70
[2025-03-26T01:21:47.781+0000] {logging_mixin.py:151} INFO - Số công việc tìm thấy trên trang 405:70
[2025-03-26T01:23:42.389+0000] {logging_mixin.py:151} INFO - Số công việc tìm thấy trên trang 406:70
[2025-03-26T01:25:36.283+0000] {logging_mixin.py:151} INFO - Số công việc tìm thấy trên trang 407:70
[2025-03-26T01:27:33.441+0000] {logging_mixin.py:151} INFO - Số công việc tìm thấy trên trang 408:70
[2025-03-26T01:29:30.503+0000] {logging_mixin.py:151} INFO - Số công việc tìm thấy trên trang 409:70
[2025-03-26T01:31:25.612+0000] {logging_mixin.py:151} INFO - Số công việc tìm thấy trên trang 410:70
[2025-03-26T01:33:20.668+0000] {logging_mixin.py:151} INFO - Số công việc tìm thấy trên trang 411:70
[2025-03-26T01:35:16.855+0000] {logging_mixin.py:151} INFO - Số công việc tìm thấy trên trang 412:70
[2025-03-26T01:37:14.653+0000] {logging_mixin.py:151} INFO - Số công việc tìm thấy trên trang 413:70
[2025-03-26T01:39:08.281+0000] {logging_mixin.py:151} INFO - Số công việc tìm thấy trên trang 414:70
[2025-03-26T01:41:03.262+0000] {logging_mixin.py:151} INFO - Số công việc tìm thấy trên trang 415:70
[2025-03-26T01:42:56.913+0000] {logging_mixin.py:151} INFO - Số công việc tìm thấy trên trang 416:70
[2025-03-26T01:44:51.915+0000] {logging_mixin.py:151} INFO - Số công việc tìm thấy trên trang 417:70
[2025-03-26T01:46:48.074+0000] {logging_mixin.py:151} INFO - Số công việc tìm thấy trên trang 418:70
[2025-03-26T01:48:43.768+0000] {logging_mixin.py:151} INFO - Số công việc tìm thấy trên trang 419:70
[2025-03-26T01:50:37.903+0000] {logging_mixin.py:151} INFO - Số công việc tìm thấy trên trang 420:70
[2025-03-26T01:52:33.690+0000] {logging_mixin.py:151} INFO - Số công việc tìm thấy trên trang 421:70
[2025-03-26T01:54:31.049+0000] {logging_mixin.py:151} INFO - Số công việc tìm thấy trên trang 422:70
[2025-03-26T01:56:24.594+0000] {logging_mixin.py:151} INFO - Số công việc tìm thấy trên trang 423:70
[2025-03-26T01:57:08.489+0000] {local_task_job_runner.py:115} ERROR - Received SIGTERM. Terminating subprocesses
[2025-03-26T01:57:08.493+0000] {process_utils.py:131} INFO - Sending 15 to group 388. PIDs of all processes in the group: [390, 396, 400, 401, 407, 410, 432, 582, 443, 491, 545, 555, 1956, 1992, 2001, 2013, 431, 388]
[2025-03-26T01:57:08.498+0000] {process_utils.py:86} INFO - Sending the signal 15 to group 388
[2025-03-26T01:57:08.505+0000] {taskinstance.py:1632} ERROR - Received SIGTERM. Terminating subprocesses.
[2025-03-26T01:57:08.508+0000] {logging_mixin.py:151} INFO - Lỗi khi lấy dữ liệu: Task received SIGTERM signal
[2025-03-26T01:57:08.513+0000] {connectionpool.py:823} WARNING - Retrying (Retry(total=2, connect=None, read=None, redirect=None, status=None)) after connection broken by 'NewConnectionError('<urllib3.connection.HTTPConnection object at 0x7f560dd6fe50>: Failed to establish a new connection: [Errno 111] Connection refused')': /session/ceda48d9fcb6d771447fe0f56bc46039/actions
[2025-03-26T01:57:08.524+0000] {connectionpool.py:823} WARNING - Retrying (Retry(total=1, connect=None, read=None, redirect=None, status=None)) after connection broken by 'NewConnectionError('<urllib3.connection.HTTPConnection object at 0x7f560dd6ff70>: Failed to establish a new connection: [Errno 111] Connection refused')': /session/ceda48d9fcb6d771447fe0f56bc46039/actions
[2025-03-26T01:57:08.533+0000] {connectionpool.py:823} WARNING - Retrying (Retry(total=0, connect=None, read=None, redirect=None, status=None)) after connection broken by 'NewConnectionError('<urllib3.connection.HTTPConnection object at 0x7f560dd84190>: Failed to establish a new connection: [Errno 111] Connection refused')': /session/ceda48d9fcb6d771447fe0f56bc46039/actions
[2025-03-26T01:57:08.536+0000] {logging_mixin.py:151} INFO - Lỗi khi lấy dữ liệu: HTTPConnectionPool(host='localhost', port=50821): Max retries exceeded with url: /session/ceda48d9fcb6d771447fe0f56bc46039/actions (Caused by NewConnectionError('<urllib3.connection.HTTPConnection object at 0x7f560dd84370>: Failed to establish a new connection: [Errno 111] Connection refused'))
[2025-03-26T01:57:08.550+0000] {connectionpool.py:823} WARNING - Retrying (Retry(total=2, connect=None, read=None, redirect=None, status=None)) after connection broken by 'NewConnectionError('<urllib3.connection.HTTPConnection object at 0x7f560dd845e0>: Failed to establish a new connection: [Errno 111] Connection refused')': /session/ceda48d9fcb6d771447fe0f56bc46039/actions
[2025-03-26T01:57:08.556+0000] {connectionpool.py:823} WARNING - Retrying (Retry(total=1, connect=None, read=None, redirect=None, status=None)) after connection broken by 'NewConnectionError('<urllib3.connection.HTTPConnection object at 0x7f560dd847c0>: Failed to establish a new connection: [Errno 111] Connection refused')': /session/ceda48d9fcb6d771447fe0f56bc46039/actions
[2025-03-26T01:57:08.557+0000] {connectionpool.py:823} WARNING - Retrying (Retry(total=0, connect=None, read=None, redirect=None, status=None)) after connection broken by 'NewConnectionError('<urllib3.connection.HTTPConnection object at 0x7f560dd84940>: Failed to establish a new connection: [Errno 111] Connection refused')': /session/ceda48d9fcb6d771447fe0f56bc46039/actions
[2025-03-26T01:57:08.559+0000] {logging_mixin.py:151} INFO - Lỗi khi lấy dữ liệu: HTTPConnectionPool(host='localhost', port=50821): Max retries exceeded with url: /session/ceda48d9fcb6d771447fe0f56bc46039/actions (Caused by NewConnectionError('<urllib3.connection.HTTPConnection object at 0x7f560dd84a90>: Failed to establish a new connection: [Errno 111] Connection refused'))
[2025-03-26T01:57:08.561+0000] {connectionpool.py:823} WARNING - Retrying (Retry(total=2, connect=None, read=None, redirect=None, status=None)) after connection broken by 'NewConnectionError('<urllib3.connection.HTTPConnection object at 0x7f560dd84ee0>: Failed to establish a new connection: [Errno 111] Connection refused')': /session/ceda48d9fcb6d771447fe0f56bc46039/actions
[2025-03-26T01:57:08.562+0000] {connectionpool.py:823} WARNING - Retrying (Retry(total=1, connect=None, read=None, redirect=None, status=None)) after connection broken by 'NewConnectionError('<urllib3.connection.HTTPConnection object at 0x7f560ddcf400>: Failed to establish a new connection: [Errno 111] Connection refused')': /session/ceda48d9fcb6d771447fe0f56bc46039/actions
[2025-03-26T01:57:08.565+0000] {connectionpool.py:823} WARNING - Retrying (Retry(total=0, connect=None, read=None, redirect=None, status=None)) after connection broken by 'NewConnectionError('<urllib3.connection.HTTPConnection object at 0x7f560dd846a0>: Failed to establish a new connection: [Errno 111] Connection refused')': /session/ceda48d9fcb6d771447fe0f56bc46039/actions
[2025-03-26T01:57:08.567+0000] {logging_mixin.py:151} INFO - Lỗi khi lấy dữ liệu: HTTPConnectionPool(host='localhost', port=50821): Max retries exceeded with url: /session/ceda48d9fcb6d771447fe0f56bc46039/actions (Caused by NewConnectionError('<urllib3.connection.HTTPConnection object at 0x7f560dd84ac0>: Failed to establish a new connection: [Errno 111] Connection refused'))
[2025-03-26T01:57:08.569+0000] {connectionpool.py:823} WARNING - Retrying (Retry(total=2, connect=None, read=None, redirect=None, status=None)) after connection broken by 'NewConnectionError('<urllib3.connection.HTTPConnection object at 0x7f560dd84580>: Failed to establish a new connection: [Errno 111] Connection refused')': /session/ceda48d9fcb6d771447fe0f56bc46039/actions
[2025-03-26T01:57:08.570+0000] {connectionpool.py:823} WARNING - Retrying (Retry(total=1, connect=None, read=None, redirect=None, status=None)) after connection broken by 'NewConnectionError('<urllib3.connection.HTTPConnection object at 0x7f560dd84460>: Failed to establish a new connection: [Errno 111] Connection refused')': /session/ceda48d9fcb6d771447fe0f56bc46039/actions
[2025-03-26T01:57:08.572+0000] {connectionpool.py:823} WARNING - Retrying (Retry(total=0, connect=None, read=None, redirect=None, status=None)) after connection broken by 'NewConnectionError('<urllib3.connection.HTTPConnection object at 0x7f560dd843d0>: Failed to establish a new connection: [Errno 111] Connection refused')': /session/ceda48d9fcb6d771447fe0f56bc46039/actions
[2025-03-26T01:57:08.573+0000] {logging_mixin.py:151} INFO - Lỗi khi lấy dữ liệu: HTTPConnectionPool(host='localhost', port=50821): Max retries exceeded with url: /session/ceda48d9fcb6d771447fe0f56bc46039/actions (Caused by NewConnectionError('<urllib3.connection.HTTPConnection object at 0x7f560dd6fd00>: Failed to establish a new connection: [Errno 111] Connection refused'))
[2025-03-26T01:57:08.576+0000] {connectionpool.py:823} WARNING - Retrying (Retry(total=2, connect=None, read=None, redirect=None, status=None)) after connection broken by 'NewConnectionError('<urllib3.connection.HTTPConnection object at 0x7f560dd1e6a0>: Failed to establish a new connection: [Errno 111] Connection refused')': /session/ceda48d9fcb6d771447fe0f56bc46039/actions
[2025-03-26T01:57:08.578+0000] {connectionpool.py:823} WARNING - Retrying (Retry(total=1, connect=None, read=None, redirect=None, status=None)) after connection broken by 'NewConnectionError('<urllib3.connection.HTTPConnection object at 0x7f560dd1e400>: Failed to establish a new connection: [Errno 111] Connection refused')': /session/ceda48d9fcb6d771447fe0f56bc46039/actions
[2025-03-26T01:57:08.574+0000] {process_utils.py:79} INFO - Process psutil.Process(pid=2001, status='terminated', started='01:56:13') (2001) terminated with exit code None
[2025-03-26T01:57:08.580+0000] {connectionpool.py:823} WARNING - Retrying (Retry(total=0, connect=None, read=None, redirect=None, status=None)) after connection broken by 'NewConnectionError('<urllib3.connection.HTTPConnection object at 0x7f560dd55280>: Failed to establish a new connection: [Errno 111] Connection refused')': /session/ceda48d9fcb6d771447fe0f56bc46039/actions
[2025-03-26T01:57:08.581+0000] {process_utils.py:79} INFO - Process psutil.Process(pid=443, status='terminated', started='01:13:50') (443) terminated with exit code None
[2025-03-26T01:57:08.583+0000] {logging_mixin.py:151} INFO - Lỗi khi lấy dữ liệu: HTTPConnectionPool(host='localhost', port=50821): Max retries exceeded with url: /session/ceda48d9fcb6d771447fe0f56bc46039/actions (Caused by NewConnectionError('<urllib3.connection.HTTPConnection object at 0x7f560dd55880>: Failed to establish a new connection: [Errno 111] Connection refused'))
[2025-03-26T01:57:08.587+0000] {connectionpool.py:823} WARNING - Retrying (Retry(total=2, connect=None, read=None, redirect=None, status=None)) after connection broken by 'NewConnectionError('<urllib3.connection.HTTPConnection object at 0x7f560dcb4dc0>: Failed to establish a new connection: [Errno 111] Connection refused')': /session/ceda48d9fcb6d771447fe0f56bc46039/actions
[2025-03-26T01:57:08.589+0000] {connectionpool.py:823} WARNING - Retrying (Retry(total=1, connect=None, read=None, redirect=None, status=None)) after connection broken by 'NewConnectionError('<urllib3.connection.HTTPConnection object at 0x7f560dcb4eb0>: Failed to establish a new connection: [Errno 111] Connection refused')': /session/ceda48d9fcb6d771447fe0f56bc46039/actions
[2025-03-26T01:57:08.590+0000] {connectionpool.py:823} WARNING - Retrying (Retry(total=0, connect=None, read=None, redirect=None, status=None)) after connection broken by 'NewConnectionError('<urllib3.connection.HTTPConnection object at 0x7f560dc460a0>: Failed to establish a new connection: [Errno 111] Connection refused')': /session/ceda48d9fcb6d771447fe0f56bc46039/actions
[2025-03-26T01:57:08.592+0000] {logging_mixin.py:151} INFO - Lỗi khi lấy dữ liệu: HTTPConnectionPool(host='localhost', port=50821): Max retries exceeded with url: /session/ceda48d9fcb6d771447fe0f56bc46039/actions (Caused by NewConnectionError('<urllib3.connection.HTTPConnection object at 0x7f560dc461c0>: Failed to establish a new connection: [Errno 111] Connection refused'))
[2025-03-26T01:57:08.595+0000] {connectionpool.py:823} WARNING - Retrying (Retry(total=2, connect=None, read=None, redirect=None, status=None)) after connection broken by 'NewConnectionError('<urllib3.connection.HTTPConnection object at 0x7f560dc46610>: Failed to establish a new connection: [Errno 111] Connection refused')': /session/ceda48d9fcb6d771447fe0f56bc46039/actions
[2025-03-26T01:57:08.599+0000] {connectionpool.py:823} WARNING - Retrying (Retry(total=1, connect=None, read=None, redirect=None, status=None)) after connection broken by 'NewConnectionError('<urllib3.connection.HTTPConnection object at 0x7f560dcb4e80>: Failed to establish a new connection: [Errno 111] Connection refused')': /session/ceda48d9fcb6d771447fe0f56bc46039/actions
[2025-03-26T01:57:08.602+0000] {connectionpool.py:823} WARNING - Retrying (Retry(total=0, connect=None, read=None, redirect=None, status=None)) after connection broken by 'NewConnectionError('<urllib3.connection.HTTPConnection object at 0x7f560dcb4dc0>: Failed to establish a new connection: [Errno 111] Connection refused')': /session/ceda48d9fcb6d771447fe0f56bc46039/actions
[2025-03-26T01:57:08.605+0000] {logging_mixin.py:151} INFO - Lỗi khi lấy dữ liệu: HTTPConnectionPool(host='localhost', port=50821): Max retries exceeded with url: /session/ceda48d9fcb6d771447fe0f56bc46039/actions (Caused by NewConnectionError('<urllib3.connection.HTTPConnection object at 0x7f560dcb4ca0>: Failed to establish a new connection: [Errno 111] Connection refused'))
[2025-03-26T01:57:08.610+0000] {connectionpool.py:823} WARNING - Retrying (Retry(total=2, connect=None, read=None, redirect=None, status=None)) after connection broken by 'NewConnectionError('<urllib3.connection.HTTPConnection object at 0x7f560dda2700>: Failed to establish a new connection: [Errno 111] Connection refused')': /session/ceda48d9fcb6d771447fe0f56bc46039/actions
[2025-03-26T01:57:08.610+0000] {process_utils.py:79} INFO - Process psutil.Process(pid=400, status='terminated', started='01:13:50') (400) terminated with exit code None
[2025-03-26T01:57:08.612+0000] {connectionpool.py:823} WARNING - Retrying (Retry(total=1, connect=None, read=None, redirect=None, status=None)) after connection broken by 'NewConnectionError('<urllib3.connection.HTTPConnection object at 0x7f560dd1e8b0>: Failed to establish a new connection: [Errno 111] Connection refused')': /session/ceda48d9fcb6d771447fe0f56bc46039/actions
[2025-03-26T01:57:08.613+0000] {process_utils.py:79} INFO - Process psutil.Process(pid=1956, status='terminated', started='01:54:20') (1956) terminated with exit code None
[2025-03-26T01:57:08.614+0000] {connectionpool.py:823} WARNING - Retrying (Retry(total=0, connect=None, read=None, redirect=None, status=None)) after connection broken by 'NewConnectionError('<urllib3.connection.HTTPConnection object at 0x7f560dd1e5e0>: Failed to establish a new connection: [Errno 111] Connection refused')': /session/ceda48d9fcb6d771447fe0f56bc46039/actions
[2025-03-26T01:57:08.616+0000] {logging_mixin.py:151} INFO - Lỗi khi lấy dữ liệu: HTTPConnectionPool(host='localhost', port=50821): Max retries exceeded with url: /session/ceda48d9fcb6d771447fe0f56bc46039/actions (Caused by NewConnectionError('<urllib3.connection.HTTPConnection object at 0x7f560dd6f670>: Failed to establish a new connection: [Errno 111] Connection refused'))
[2025-03-26T01:57:08.618+0000] {connectionpool.py:823} WARNING - Retrying (Retry(total=2, connect=None, read=None, redirect=None, status=None)) after connection broken by 'NewConnectionError('<urllib3.connection.HTTPConnection object at 0x7f560dd84550>: Failed to establish a new connection: [Errno 111] Connection refused')': /session/ceda48d9fcb6d771447fe0f56bc46039/actions
[2025-03-26T01:57:08.620+0000] {connectionpool.py:823} WARNING - Retrying (Retry(total=1, connect=None, read=None, redirect=None, status=None)) after connection broken by 'NewConnectionError('<urllib3.connection.HTTPConnection object at 0x7f560dd843d0>: Failed to establish a new connection: [Errno 111] Connection refused')': /session/ceda48d9fcb6d771447fe0f56bc46039/actions
[2025-03-26T01:57:08.621+0000] {connectionpool.py:823} WARNING - Retrying (Retry(total=0, connect=None, read=None, redirect=None, status=None)) after connection broken by 'NewConnectionError('<urllib3.connection.HTTPConnection object at 0x7f560dd842b0>: Failed to establish a new connection: [Errno 111] Connection refused')': /session/ceda48d9fcb6d771447fe0f56bc46039/actions
[2025-03-26T01:57:08.623+0000] {logging_mixin.py:151} INFO - Lỗi khi lấy dữ liệu: HTTPConnectionPool(host='localhost', port=50821): Max retries exceeded with url: /session/ceda48d9fcb6d771447fe0f56bc46039/actions (Caused by NewConnectionError('<urllib3.connection.HTTPConnection object at 0x7f560dd84af0>: Failed to establish a new connection: [Errno 111] Connection refused'))
[2025-03-26T01:57:08.626+0000] {connectionpool.py:823} WARNING - Retrying (Retry(total=2, connect=None, read=None, redirect=None, status=None)) after connection broken by 'NewConnectionError('<urllib3.connection.HTTPConnection object at 0x7f560dd84850>: Failed to establish a new connection: [Errno 111] Connection refused')': /session/ceda48d9fcb6d771447fe0f56bc46039/actions
[2025-03-26T01:57:08.627+0000] {connectionpool.py:823} WARNING - Retrying (Retry(total=1, connect=None, read=None, redirect=None, status=None)) after connection broken by 'NewConnectionError('<urllib3.connection.HTTPConnection object at 0x7f560dc460d0>: Failed to establish a new connection: [Errno 111] Connection refused')': /session/ceda48d9fcb6d771447fe0f56bc46039/actions
[2025-03-26T01:57:08.630+0000] {connectionpool.py:823} WARNING - Retrying (Retry(total=0, connect=None, read=None, redirect=None, status=None)) after connection broken by 'NewConnectionError('<urllib3.connection.HTTPConnection object at 0x7f560dc460a0>: Failed to establish a new connection: [Errno 111] Connection refused')': /session/ceda48d9fcb6d771447fe0f56bc46039/actions
[2025-03-26T01:57:08.633+0000] {logging_mixin.py:151} INFO - Lỗi khi lấy dữ liệu: HTTPConnectionPool(host='localhost', port=50821): Max retries exceeded with url: /session/ceda48d9fcb6d771447fe0f56bc46039/actions (Caused by NewConnectionError('<urllib3.connection.HTTPConnection object at 0x7f560dc46790>: Failed to establish a new connection: [Errno 111] Connection refused'))
[2025-03-26T01:57:08.636+0000] {connectionpool.py:823} WARNING - Retrying (Retry(total=2, connect=None, read=None, redirect=None, status=None)) after connection broken by 'NewConnectionError('<urllib3.connection.HTTPConnection object at 0x7f560dc46be0>: Failed to establish a new connection: [Errno 111] Connection refused')': /session/ceda48d9fcb6d771447fe0f56bc46039/actions
[2025-03-26T01:57:08.638+0000] {connectionpool.py:823} WARNING - Retrying (Retry(total=1, connect=None, read=None, redirect=None, status=None)) after connection broken by 'NewConnectionError('<urllib3.connection.HTTPConnection object at 0x7f560dd84730>: Failed to establish a new connection: [Errno 111] Connection refused')': /session/ceda48d9fcb6d771447fe0f56bc46039/actions
[2025-03-26T01:57:08.640+0000] {connectionpool.py:823} WARNING - Retrying (Retry(total=0, connect=None, read=None, redirect=None, status=None)) after connection broken by 'NewConnectionError('<urllib3.connection.HTTPConnection object at 0x7f560dd84790>: Failed to establish a new connection: [Errno 111] Connection refused')': /session/ceda48d9fcb6d771447fe0f56bc46039/actions
[2025-03-26T01:57:08.642+0000] {logging_mixin.py:151} INFO - Lỗi khi lấy dữ liệu: HTTPConnectionPool(host='localhost', port=50821): Max retries exceeded with url: /session/ceda48d9fcb6d771447fe0f56bc46039/actions (Caused by NewConnectionError('<urllib3.connection.HTTPConnection object at 0x7f560dd849d0>: Failed to establish a new connection: [Errno 111] Connection refused'))
[2025-03-26T01:57:08.646+0000] {connectionpool.py:823} WARNING - Retrying (Retry(total=2, connect=None, read=None, redirect=None, status=None)) after connection broken by 'NewConnectionError('<urllib3.connection.HTTPConnection object at 0x7f560dd84100>: Failed to establish a new connection: [Errno 111] Connection refused')': /session/ceda48d9fcb6d771447fe0f56bc46039/actions
[2025-03-26T01:57:08.649+0000] {connectionpool.py:823} WARNING - Retrying (Retry(total=1, connect=None, read=None, redirect=None, status=None)) after connection broken by 'NewConnectionError('<urllib3.connection.HTTPConnection object at 0x7f560dd845b0>: Failed to establish a new connection: [Errno 111] Connection refused')': /session/ceda48d9fcb6d771447fe0f56bc46039/actions
[2025-03-26T01:57:08.652+0000] {connectionpool.py:823} WARNING - Retrying (Retry(total=0, connect=None, read=None, redirect=None, status=None)) after connection broken by 'NewConnectionError('<urllib3.connection.HTTPConnection object at 0x7f560dd6fd30>: Failed to establish a new connection: [Errno 111] Connection refused')': /session/ceda48d9fcb6d771447fe0f56bc46039/actions
[2025-03-26T01:57:08.655+0000] {logging_mixin.py:151} INFO - Lỗi khi lấy dữ liệu: HTTPConnectionPool(host='localhost', port=50821): Max retries exceeded with url: /session/ceda48d9fcb6d771447fe0f56bc46039/actions (Caused by NewConnectionError('<urllib3.connection.HTTPConnection object at 0x7f560dd6fdf0>: Failed to establish a new connection: [Errno 111] Connection refused'))
[2025-03-26T01:57:08.657+0000] {connectionpool.py:823} WARNING - Retrying (Retry(total=2, connect=None, read=None, redirect=None, status=None)) after connection broken by 'NewConnectionError('<urllib3.connection.HTTPConnection object at 0x7f560dda2ca0>: Failed to establish a new connection: [Errno 111] Connection refused')': /session/ceda48d9fcb6d771447fe0f56bc46039/actions
[2025-03-26T01:57:08.660+0000] {connectionpool.py:823} WARNING - Retrying (Retry(total=1, connect=None, read=None, redirect=None, status=None)) after connection broken by 'NewConnectionError('<urllib3.connection.HTTPConnection object at 0x7f560dd55190>: Failed to establish a new connection: [Errno 111] Connection refused')': /session/ceda48d9fcb6d771447fe0f56bc46039/actions
[2025-03-26T01:57:08.661+0000] {connectionpool.py:823} WARNING - Retrying (Retry(total=0, connect=None, read=None, redirect=None, status=None)) after connection broken by 'NewConnectionError('<urllib3.connection.HTTPConnection object at 0x7f560dd55280>: Failed to establish a new connection: [Errno 111] Connection refused')': /session/ceda48d9fcb6d771447fe0f56bc46039/actions
[2025-03-26T01:57:08.664+0000] {logging_mixin.py:151} INFO - Lỗi khi lấy dữ liệu: HTTPConnectionPool(host='localhost', port=50821): Max retries exceeded with url: /session/ceda48d9fcb6d771447fe0f56bc46039/actions (Caused by NewConnectionError('<urllib3.connection.HTTPConnection object at 0x7f560dd55040>: Failed to establish a new connection: [Errno 111] Connection refused'))
[2025-03-26T01:57:08.666+0000] {connectionpool.py:823} WARNING - Retrying (Retry(total=2, connect=None, read=None, redirect=None, status=None)) after connection broken by 'NewConnectionError('<urllib3.connection.HTTPConnection object at 0x7f560dcb4fa0>: Failed to establish a new connection: [Errno 111] Connection refused')': /session/ceda48d9fcb6d771447fe0f56bc46039/actions
[2025-03-26T01:57:08.668+0000] {connectionpool.py:823} WARNING - Retrying (Retry(total=1, connect=None, read=None, redirect=None, status=None)) after connection broken by 'NewConnectionError('<urllib3.connection.HTTPConnection object at 0x7f560dc46190>: Failed to establish a new connection: [Errno 111] Connection refused')': /session/ceda48d9fcb6d771447fe0f56bc46039/actions
[2025-03-26T01:57:08.671+0000] {connectionpool.py:823} WARNING - Retrying (Retry(total=0, connect=None, read=None, redirect=None, status=None)) after connection broken by 'NewConnectionError('<urllib3.connection.HTTPConnection object at 0x7f560dc46730>: Failed to establish a new connection: [Errno 111] Connection refused')': /session/ceda48d9fcb6d771447fe0f56bc46039/actions
[2025-03-26T01:57:08.672+0000] {logging_mixin.py:151} INFO - Lỗi khi lấy dữ liệu: HTTPConnectionPool(host='localhost', port=50821): Max retries exceeded with url: /session/ceda48d9fcb6d771447fe0f56bc46039/actions (Caused by NewConnectionError('<urllib3.connection.HTTPConnection object at 0x7f560dc46100>: Failed to establish a new connection: [Errno 111] Connection refused'))
[2025-03-26T01:57:08.677+0000] {connectionpool.py:823} WARNING - Retrying (Retry(total=2, connect=None, read=None, redirect=None, status=None)) after connection broken by 'NewConnectionError('<urllib3.connection.HTTPConnection object at 0x7f560dc46310>: Failed to establish a new connection: [Errno 111] Connection refused')': /session/ceda48d9fcb6d771447fe0f56bc46039/actions
[2025-03-26T01:57:08.680+0000] {connectionpool.py:823} WARNING - Retrying (Retry(total=1, connect=None, read=None, redirect=None, status=None)) after connection broken by 'NewConnectionError('<urllib3.connection.HTTPConnection object at 0x7f560dcb4df0>: Failed to establish a new connection: [Errno 111] Connection refused')': /session/ceda48d9fcb6d771447fe0f56bc46039/actions
[2025-03-26T01:57:08.684+0000] {connectionpool.py:823} WARNING - Retrying (Retry(total=0, connect=None, read=None, redirect=None, status=None)) after connection broken by 'NewConnectionError('<urllib3.connection.HTTPConnection object at 0x7f560dcb4f70>: Failed to establish a new connection: [Errno 111] Connection refused')': /session/ceda48d9fcb6d771447fe0f56bc46039/actions
[2025-03-26T01:57:08.686+0000] {logging_mixin.py:151} INFO - Lỗi khi lấy dữ liệu: HTTPConnectionPool(host='localhost', port=50821): Max retries exceeded with url: /session/ceda48d9fcb6d771447fe0f56bc46039/actions (Caused by NewConnectionError('<urllib3.connection.HTTPConnection object at 0x7f560dcb4c70>: Failed to establish a new connection: [Errno 111] Connection refused'))
[2025-03-26T01:57:08.688+0000] {connectionpool.py:823} WARNING - Retrying (Retry(total=2, connect=None, read=None, redirect=None, status=None)) after connection broken by 'NewConnectionError('<urllib3.connection.HTTPConnection object at 0x7f560dd55310>: Failed to establish a new connection: [Errno 111] Connection refused')': /session/ceda48d9fcb6d771447fe0f56bc46039/actions
[2025-03-26T01:57:08.692+0000] {connectionpool.py:823} WARNING - Retrying (Retry(total=1, connect=None, read=None, redirect=None, status=None)) after connection broken by 'NewConnectionError('<urllib3.connection.HTTPConnection object at 0x7f560dd1e580>: Failed to establish a new connection: [Errno 111] Connection refused')': /session/ceda48d9fcb6d771447fe0f56bc46039/actions
[2025-03-26T01:57:08.695+0000] {connectionpool.py:823} WARNING - Retrying (Retry(total=0, connect=None, read=None, redirect=None, status=None)) after connection broken by 'NewConnectionError('<urllib3.connection.HTTPConnection object at 0x7f560dd1e790>: Failed to establish a new connection: [Errno 111] Connection refused')': /session/ceda48d9fcb6d771447fe0f56bc46039/actions
[2025-03-26T01:57:08.697+0000] {logging_mixin.py:151} INFO - Lỗi khi lấy dữ liệu: HTTPConnectionPool(host='localhost', port=50821): Max retries exceeded with url: /session/ceda48d9fcb6d771447fe0f56bc46039/actions (Caused by NewConnectionError('<urllib3.connection.HTTPConnection object at 0x7f560dd6fd90>: Failed to establish a new connection: [Errno 111] Connection refused'))
[2025-03-26T01:57:08.700+0000] {connectionpool.py:823} WARNING - Retrying (Retry(total=2, connect=None, read=None, redirect=None, status=None)) after connection broken by 'NewConnectionError('<urllib3.connection.HTTPConnection object at 0x7f560dd846d0>: Failed to establish a new connection: [Errno 111] Connection refused')': /session/ceda48d9fcb6d771447fe0f56bc46039/actions
[2025-03-26T01:57:08.701+0000] {connectionpool.py:823} WARNING - Retrying (Retry(total=1, connect=None, read=None, redirect=None, status=None)) after connection broken by 'NewConnectionError('<urllib3.connection.HTTPConnection object at 0x7f560dd84250>: Failed to establish a new connection: [Errno 111] Connection refused')': /session/ceda48d9fcb6d771447fe0f56bc46039/actions
[2025-03-26T01:57:08.703+0000] {connectionpool.py:823} WARNING - Retrying (Retry(total=0, connect=None, read=None, redirect=None, status=None)) after connection broken by 'NewConnectionError('<urllib3.connection.HTTPConnection object at 0x7f560dd843d0>: Failed to establish a new connection: [Errno 111] Connection refused')': /session/ceda48d9fcb6d771447fe0f56bc46039/actions
[2025-03-26T01:57:08.706+0000] {logging_mixin.py:151} INFO - Lỗi khi lấy dữ liệu: HTTPConnectionPool(host='localhost', port=50821): Max retries exceeded with url: /session/ceda48d9fcb6d771447fe0f56bc46039/actions (Caused by NewConnectionError('<urllib3.connection.HTTPConnection object at 0x7f560dd843a0>: Failed to establish a new connection: [Errno 111] Connection refused'))
[2025-03-26T01:57:08.709+0000] {connectionpool.py:823} WARNING - Retrying (Retry(total=2, connect=None, read=None, redirect=None, status=None)) after connection broken by 'NewConnectionError('<urllib3.connection.HTTPConnection object at 0x7f560dd846a0>: Failed to establish a new connection: [Errno 111] Connection refused')': /session/ceda48d9fcb6d771447fe0f56bc46039/actions
[2025-03-26T01:57:08.710+0000] {process_utils.py:79} INFO - Process psutil.Process(pid=401, status='terminated', started='01:13:50') (401) terminated with exit code None
[2025-03-26T01:57:08.711+0000] {connectionpool.py:823} WARNING - Retrying (Retry(total=1, connect=None, read=None, redirect=None, status=None)) after connection broken by 'NewConnectionError('<urllib3.connection.HTTPConnection object at 0x7f560dc462b0>: Failed to establish a new connection: [Errno 111] Connection refused')': /session/ceda48d9fcb6d771447fe0f56bc46039/actions
[2025-03-26T01:57:08.711+0000] {process_utils.py:79} INFO - Process psutil.Process(pid=407, status='terminated', started='01:13:50') (407) terminated with exit code None
[2025-03-26T01:57:08.713+0000] {process_utils.py:79} INFO - Process psutil.Process(pid=396, status='terminated', started='01:13:50') (396) terminated with exit code None
[2025-03-26T01:57:08.713+0000] {process_utils.py:79} INFO - Process psutil.Process(pid=431, status='terminated', started='01:13:50') (431) terminated with exit code None
[2025-03-26T01:57:08.714+0000] {connectionpool.py:823} WARNING - Retrying (Retry(total=0, connect=None, read=None, redirect=None, status=None)) after connection broken by 'NewConnectionError('<urllib3.connection.HTTPConnection object at 0x7f560dc465e0>: Failed to establish a new connection: [Errno 111] Connection refused')': /session/ceda48d9fcb6d771447fe0f56bc46039/actions
[2025-03-26T01:57:08.715+0000] {process_utils.py:79} INFO - Process psutil.Process(pid=491, status='terminated', started='01:13:50') (491) terminated with exit code None
[2025-03-26T01:57:08.716+0000] {logging_mixin.py:151} INFO - Lỗi khi lấy dữ liệu: HTTPConnectionPool(host='localhost', port=50821): Max retries exceeded with url: /session/ceda48d9fcb6d771447fe0f56bc46039/actions (Caused by NewConnectionError('<urllib3.connection.HTTPConnection object at 0x7f560dc46790>: Failed to establish a new connection: [Errno 111] Connection refused'))
[2025-03-26T01:57:08.717+0000] {process_utils.py:79} INFO - Process psutil.Process(pid=410, status='terminated', started='01:13:50') (410) terminated with exit code None
[2025-03-26T01:57:08.719+0000] {connectionpool.py:823} WARNING - Retrying (Retry(total=2, connect=None, read=None, redirect=None, status=None)) after connection broken by 'NewConnectionError('<urllib3.connection.HTTPConnection object at 0x7f560dc46b80>: Failed to establish a new connection: [Errno 111] Connection refused')': /session/ceda48d9fcb6d771447fe0f56bc46039/actions
[2025-03-26T01:57:08.721+0000] {process_utils.py:79} INFO - Process psutil.Process(pid=432, status='terminated', started='01:13:50') (432) terminated with exit code None
[2025-03-26T01:57:08.723+0000] {connectionpool.py:823} WARNING - Retrying (Retry(total=1, connect=None, read=None, redirect=None, status=None)) after connection broken by 'NewConnectionError('<urllib3.connection.HTTPConnection object at 0x7f560dd84850>: Failed to establish a new connection: [Errno 111] Connection refused')': /session/ceda48d9fcb6d771447fe0f56bc46039/actions
[2025-03-26T01:57:08.727+0000] {process_utils.py:79} INFO - Process psutil.Process(pid=555, status='terminated', started='01:13:59') (555) terminated with exit code None
[2025-03-26T01:57:08.728+0000] {connectionpool.py:823} WARNING - Retrying (Retry(total=0, connect=None, read=None, redirect=None, status=None)) after connection broken by 'NewConnectionError('<urllib3.connection.HTTPConnection object at 0x7f560dd841f0>: Failed to establish a new connection: [Errno 111] Connection refused')': /session/ceda48d9fcb6d771447fe0f56bc46039/actions
[2025-03-26T01:57:08.728+0000] {process_utils.py:79} INFO - Process psutil.Process(pid=545, status='terminated', started='01:13:59') (545) terminated with exit code None
[2025-03-26T01:57:08.731+0000] {logging_mixin.py:151} INFO - Lỗi khi lấy dữ liệu: HTTPConnectionPool(host='localhost', port=50821): Max retries exceeded with url: /session/ceda48d9fcb6d771447fe0f56bc46039/actions (Caused by NewConnectionError('<urllib3.connection.HTTPConnection object at 0x7f560dd84a30>: Failed to establish a new connection: [Errno 111] Connection refused'))
[2025-03-26T01:57:08.732+0000] {process_utils.py:79} INFO - Process psutil.Process(pid=2013, status='terminated', started='01:56:13') (2013) terminated with exit code None
[2025-03-26T01:57:08.734+0000] {connectionpool.py:823} WARNING - Retrying (Retry(total=2, connect=None, read=None, redirect=None, status=None)) after connection broken by 'NewConnectionError('<urllib3.connection.HTTPConnection object at 0x7f560dd844c0>: Failed to establish a new connection: [Errno 111] Connection refused')': /session/ceda48d9fcb6d771447fe0f56bc46039/actions
[2025-03-26T01:57:08.737+0000] {process_utils.py:79} INFO - Process psutil.Process(pid=1992, status='terminated', started='01:56:13') (1992) terminated with exit code None
[2025-03-26T01:57:08.738+0000] {connectionpool.py:823} WARNING - Retrying (Retry(total=1, connect=None, read=None, redirect=None, status=None)) after connection broken by 'NewConnectionError('<urllib3.connection.HTTPConnection object at 0x7f560dd84100>: Failed to establish a new connection: [Errno 111] Connection refused')': /session/ceda48d9fcb6d771447fe0f56bc46039/actions
[2025-03-26T01:57:08.740+0000] {connectionpool.py:823} WARNING - Retrying (Retry(total=0, connect=None, read=None, redirect=None, status=None)) after connection broken by 'NewConnectionError('<urllib3.connection.HTTPConnection object at 0x7f560dd6fd00>: Failed to establish a new connection: [Errno 111] Connection refused')': /session/ceda48d9fcb6d771447fe0f56bc46039/actions
[2025-03-26T01:57:08.742+0000] {logging_mixin.py:151} INFO - Lỗi khi lấy dữ liệu: HTTPConnectionPool(host='localhost', port=50821): Max retries exceeded with url: /session/ceda48d9fcb6d771447fe0f56bc46039/actions (Caused by NewConnectionError('<urllib3.connection.HTTPConnection object at 0x7f560dd6ff70>: Failed to establish a new connection: [Errno 111] Connection refused'))
[2025-03-26T01:57:08.744+0000] {connectionpool.py:823} WARNING - Retrying (Retry(total=2, connect=None, read=None, redirect=None, status=None)) after connection broken by 'NewConnectionError('<urllib3.connection.HTTPConnection object at 0x7f560dd1e880>: Failed to establish a new connection: [Errno 111] Connection refused')': /session/ceda48d9fcb6d771447fe0f56bc46039/actions
[2025-03-26T01:57:08.746+0000] {connectionpool.py:823} WARNING - Retrying (Retry(total=1, connect=None, read=None, redirect=None, status=None)) after connection broken by 'NewConnectionError('<urllib3.connection.HTTPConnection object at 0x7f560dd55130>: Failed to establish a new connection: [Errno 111] Connection refused')': /session/ceda48d9fcb6d771447fe0f56bc46039/actions
[2025-03-26T01:57:08.747+0000] {connectionpool.py:823} WARNING - Retrying (Retry(total=0, connect=None, read=None, redirect=None, status=None)) after connection broken by 'NewConnectionError('<urllib3.connection.HTTPConnection object at 0x7f560dd55940>: Failed to establish a new connection: [Errno 111] Connection refused')': /session/ceda48d9fcb6d771447fe0f56bc46039/actions
[2025-03-26T01:57:08.749+0000] {logging_mixin.py:151} INFO - Lỗi khi lấy dữ liệu: HTTPConnectionPool(host='localhost', port=50821): Max retries exceeded with url: /session/ceda48d9fcb6d771447fe0f56bc46039/actions (Caused by NewConnectionError('<urllib3.connection.HTTPConnection object at 0x7f560dd55250>: Failed to establish a new connection: [Errno 111] Connection refused'))
[2025-03-26T01:57:08.751+0000] {connectionpool.py:823} WARNING - Retrying (Retry(total=2, connect=None, read=None, redirect=None, status=None)) after connection broken by 'NewConnectionError('<urllib3.connection.HTTPConnection object at 0x7f560dcb4eb0>: Failed to establish a new connection: [Errno 111] Connection refused')': /session/ceda48d9fcb6d771447fe0f56bc46039/actions
[2025-03-26T01:57:08.754+0000] {connectionpool.py:823} WARNING - Retrying (Retry(total=1, connect=None, read=None, redirect=None, status=None)) after connection broken by 'NewConnectionError('<urllib3.connection.HTTPConnection object at 0x7f560dc46d60>: Failed to establish a new connection: [Errno 111] Connection refused')': /session/ceda48d9fcb6d771447fe0f56bc46039/actions
[2025-03-26T01:57:08.756+0000] {connectionpool.py:823} WARNING - Retrying (Retry(total=0, connect=None, read=None, redirect=None, status=None)) after connection broken by 'NewConnectionError('<urllib3.connection.HTTPConnection object at 0x7f560dc46ee0>: Failed to establish a new connection: [Errno 111] Connection refused')': /session/ceda48d9fcb6d771447fe0f56bc46039/actions
[2025-03-26T01:57:08.757+0000] {logging_mixin.py:151} INFO - Lỗi khi lấy dữ liệu: HTTPConnectionPool(host='localhost', port=50821): Max retries exceeded with url: /session/ceda48d9fcb6d771447fe0f56bc46039/actions (Caused by NewConnectionError('<urllib3.connection.HTTPConnection object at 0x7f560dc461f0>: Failed to establish a new connection: [Errno 111] Connection refused'))
[2025-03-26T01:57:08.759+0000] {connectionpool.py:823} WARNING - Retrying (Retry(total=2, connect=None, read=None, redirect=None, status=None)) after connection broken by 'NewConnectionError('<urllib3.connection.HTTPConnection object at 0x7f560dbd40a0>: Failed to establish a new connection: [Errno 111] Connection refused')': /session/ceda48d9fcb6d771447fe0f56bc46039/actions
[2025-03-26T01:57:08.760+0000] {connectionpool.py:823} WARNING - Retrying (Retry(total=1, connect=None, read=None, redirect=None, status=None)) after connection broken by 'NewConnectionError('<urllib3.connection.HTTPConnection object at 0x7f560dc46e50>: Failed to establish a new connection: [Errno 111] Connection refused')': /session/ceda48d9fcb6d771447fe0f56bc46039/actions
[2025-03-26T01:57:08.762+0000] {connectionpool.py:823} WARNING - Retrying (Retry(total=0, connect=None, read=None, redirect=None, status=None)) after connection broken by 'NewConnectionError('<urllib3.connection.HTTPConnection object at 0x7f560dc460d0>: Failed to establish a new connection: [Errno 111] Connection refused')': /session/ceda48d9fcb6d771447fe0f56bc46039/actions
[2025-03-26T01:57:08.763+0000] {logging_mixin.py:151} INFO - Lỗi khi lấy dữ liệu: HTTPConnectionPool(host='localhost', port=50821): Max retries exceeded with url: /session/ceda48d9fcb6d771447fe0f56bc46039/actions (Caused by NewConnectionError('<urllib3.connection.HTTPConnection object at 0x7f560dc46e80>: Failed to establish a new connection: [Errno 111] Connection refused'))
[2025-03-26T01:57:08.765+0000] {connectionpool.py:823} WARNING - Retrying (Retry(total=2, connect=None, read=None, redirect=None, status=None)) after connection broken by 'NewConnectionError('<urllib3.connection.HTTPConnection object at 0x7f560dcb4f70>: Failed to establish a new connection: [Errno 111] Connection refused')': /session/ceda48d9fcb6d771447fe0f56bc46039/actions
[2025-03-26T01:57:08.767+0000] {connectionpool.py:823} WARNING - Retrying (Retry(total=1, connect=None, read=None, redirect=None, status=None)) after connection broken by 'NewConnectionError('<urllib3.connection.HTTPConnection object at 0x7f560dd55220>: Failed to establish a new connection: [Errno 111] Connection refused')': /session/ceda48d9fcb6d771447fe0f56bc46039/actions
[2025-03-26T01:57:08.769+0000] {connectionpool.py:823} WARNING - Retrying (Retry(total=0, connect=None, read=None, redirect=None, status=None)) after connection broken by 'NewConnectionError('<urllib3.connection.HTTPConnection object at 0x7f560dd55250>: Failed to establish a new connection: [Errno 111] Connection refused')': /session/ceda48d9fcb6d771447fe0f56bc46039/actions
[2025-03-26T01:57:08.771+0000] {logging_mixin.py:151} INFO - Lỗi khi lấy dữ liệu: HTTPConnectionPool(host='localhost', port=50821): Max retries exceeded with url: /session/ceda48d9fcb6d771447fe0f56bc46039/actions (Caused by NewConnectionError('<urllib3.connection.HTTPConnection object at 0x7f560dd55160>: Failed to establish a new connection: [Errno 111] Connection refused'))
[2025-03-26T01:57:08.773+0000] {connectionpool.py:823} WARNING - Retrying (Retry(total=2, connect=None, read=None, redirect=None, status=None)) after connection broken by 'NewConnectionError('<urllib3.connection.HTTPConnection object at 0x7f560dd1e790>: Failed to establish a new connection: [Errno 111] Connection refused')': /session/ceda48d9fcb6d771447fe0f56bc46039/actions
[2025-03-26T01:57:08.774+0000] {connectionpool.py:823} WARNING - Retrying (Retry(total=1, connect=None, read=None, redirect=None, status=None)) after connection broken by 'NewConnectionError('<urllib3.connection.HTTPConnection object at 0x7f560dd6fe20>: Failed to establish a new connection: [Errno 111] Connection refused')': /session/ceda48d9fcb6d771447fe0f56bc46039/actions
[2025-03-26T01:57:08.776+0000] {connectionpool.py:823} WARNING - Retrying (Retry(total=0, connect=None, read=None, redirect=None, status=None)) after connection broken by 'NewConnectionError('<urllib3.connection.HTTPConnection object at 0x7f560dd6fd00>: Failed to establish a new connection: [Errno 111] Connection refused')': /session/ceda48d9fcb6d771447fe0f56bc46039/actions
[2025-03-26T01:57:08.777+0000] {logging_mixin.py:151} INFO - Lỗi khi lấy dữ liệu: HTTPConnectionPool(host='localhost', port=50821): Max retries exceeded with url: /session/ceda48d9fcb6d771447fe0f56bc46039/actions (Caused by NewConnectionError('<urllib3.connection.HTTPConnection object at 0x7f560dd84370>: Failed to establish a new connection: [Errno 111] Connection refused'))
[2025-03-26T01:57:08.779+0000] {connectionpool.py:823} WARNING - Retrying (Retry(total=2, connect=None, read=None, redirect=None, status=None)) after connection broken by 'NewConnectionError('<urllib3.connection.HTTPConnection object at 0x7f560dd84190>: Failed to establish a new connection: [Errno 111] Connection refused')': /session/ceda48d9fcb6d771447fe0f56bc46039/actions
[2025-03-26T01:57:08.780+0000] {connectionpool.py:823} WARNING - Retrying (Retry(total=1, connect=None, read=None, redirect=None, status=None)) after connection broken by 'NewConnectionError('<urllib3.connection.HTTPConnection object at 0x7f560dd847f0>: Failed to establish a new connection: [Errno 111] Connection refused')': /session/ceda48d9fcb6d771447fe0f56bc46039/actions
[2025-03-26T01:57:08.781+0000] {connectionpool.py:823} WARNING - Retrying (Retry(total=0, connect=None, read=None, redirect=None, status=None)) after connection broken by 'NewConnectionError('<urllib3.connection.HTTPConnection object at 0x7f560dd849d0>: Failed to establish a new connection: [Errno 111] Connection refused')': /session/ceda48d9fcb6d771447fe0f56bc46039/actions
[2025-03-26T01:57:08.782+0000] {logging_mixin.py:151} INFO - Lỗi khi lấy dữ liệu: HTTPConnectionPool(host='localhost', port=50821): Max retries exceeded with url: /session/ceda48d9fcb6d771447fe0f56bc46039/actions (Caused by NewConnectionError('<urllib3.connection.HTTPConnection object at 0x7f560dd84490>: Failed to establish a new connection: [Errno 111] Connection refused'))
[2025-03-26T01:57:08.785+0000] {connectionpool.py:823} WARNING - Retrying (Retry(total=2, connect=None, read=None, redirect=None, status=None)) after connection broken by 'NewConnectionError('<urllib3.connection.HTTPConnection object at 0x7f560dbd4520>: Failed to establish a new connection: [Errno 111] Connection refused')': /session/ceda48d9fcb6d771447fe0f56bc46039/actions
[2025-03-26T01:57:08.787+0000] {connectionpool.py:823} WARNING - Retrying (Retry(total=1, connect=None, read=None, redirect=None, status=None)) after connection broken by 'NewConnectionError('<urllib3.connection.HTTPConnection object at 0x7f560dd84760>: Failed to establish a new connection: [Errno 111] Connection refused')': /session/ceda48d9fcb6d771447fe0f56bc46039/actions
[2025-03-26T01:57:08.788+0000] {connectionpool.py:823} WARNING - Retrying (Retry(total=0, connect=None, read=None, redirect=None, status=None)) after connection broken by 'NewConnectionError('<urllib3.connection.HTTPConnection object at 0x7f560dd84b20>: Failed to establish a new connection: [Errno 111] Connection refused')': /session/ceda48d9fcb6d771447fe0f56bc46039/actions
[2025-03-26T01:57:08.790+0000] {logging_mixin.py:151} INFO - Lỗi khi lấy dữ liệu: HTTPConnectionPool(host='localhost', port=50821): Max retries exceeded with url: /session/ceda48d9fcb6d771447fe0f56bc46039/actions (Caused by NewConnectionError('<urllib3.connection.HTTPConnection object at 0x7f560dd849d0>: Failed to establish a new connection: [Errno 111] Connection refused'))
[2025-03-26T01:57:08.792+0000] {connectionpool.py:823} WARNING - Retrying (Retry(total=2, connect=None, read=None, redirect=None, status=None)) after connection broken by 'NewConnectionError('<urllib3.connection.HTTPConnection object at 0x7f560dd84580>: Failed to establish a new connection: [Errno 111] Connection refused')': /session/ceda48d9fcb6d771447fe0f56bc46039/actions
[2025-03-26T01:57:08.793+0000] {connectionpool.py:823} WARNING - Retrying (Retry(total=1, connect=None, read=None, redirect=None, status=None)) after connection broken by 'NewConnectionError('<urllib3.connection.HTTPConnection object at 0x7f560dd846d0>: Failed to establish a new connection: [Errno 111] Connection refused')': /session/ceda48d9fcb6d771447fe0f56bc46039/actions
[2025-03-26T01:57:08.795+0000] {connectionpool.py:823} WARNING - Retrying (Retry(total=0, connect=None, read=None, redirect=None, status=None)) after connection broken by 'NewConnectionError('<urllib3.connection.HTTPConnection object at 0x7f560dd6ff10>: Failed to establish a new connection: [Errno 111] Connection refused')': /session/ceda48d9fcb6d771447fe0f56bc46039/actions
[2025-03-26T01:57:08.796+0000] {logging_mixin.py:151} INFO - Lỗi khi lấy dữ liệu: HTTPConnectionPool(host='localhost', port=50821): Max retries exceeded with url: /session/ceda48d9fcb6d771447fe0f56bc46039/actions (Caused by NewConnectionError('<urllib3.connection.HTTPConnection object at 0x7f560dd6fe20>: Failed to establish a new connection: [Errno 111] Connection refused'))
[2025-03-26T01:57:08.797+0000] {process_utils.py:79} INFO - Process psutil.Process(pid=582, status='terminated', started='01:14:01') (582) terminated with exit code None
[2025-03-26T01:57:08.798+0000] {connectionpool.py:823} WARNING - Retrying (Retry(total=2, connect=None, read=None, redirect=None, status=None)) after connection broken by 'NewConnectionError('<urllib3.connection.HTTPConnection object at 0x7f560dd1e2e0>: Failed to establish a new connection: [Errno 111] Connection refused')': /session/ceda48d9fcb6d771447fe0f56bc46039/actions
[2025-03-26T01:57:08.800+0000] {connectionpool.py:823} WARNING - Retrying (Retry(total=1, connect=None, read=None, redirect=None, status=None)) after connection broken by 'NewConnectionError('<urllib3.connection.HTTPConnection object at 0x7f560dd552e0>: Failed to establish a new connection: [Errno 111] Connection refused')': /session/ceda48d9fcb6d771447fe0f56bc46039/actions
[2025-03-26T01:57:08.802+0000] {connectionpool.py:823} WARNING - Retrying (Retry(total=0, connect=None, read=None, redirect=None, status=None)) after connection broken by 'NewConnectionError('<urllib3.connection.HTTPConnection object at 0x7f560dd550d0>: Failed to establish a new connection: [Errno 111] Connection refused')': /session/ceda48d9fcb6d771447fe0f56bc46039/actions
[2025-03-26T01:57:08.804+0000] {logging_mixin.py:151} INFO - Lỗi khi lấy dữ liệu: HTTPConnectionPool(host='localhost', port=50821): Max retries exceeded with url: /session/ceda48d9fcb6d771447fe0f56bc46039/actions (Caused by NewConnectionError('<urllib3.connection.HTTPConnection object at 0x7f560dd55220>: Failed to establish a new connection: [Errno 111] Connection refused'))
[2025-03-26T01:57:08.807+0000] {connectionpool.py:823} WARNING - Retrying (Retry(total=2, connect=None, read=None, redirect=None, status=None)) after connection broken by 'NewConnectionError('<urllib3.connection.HTTPConnection object at 0x7f560dc465e0>: Failed to establish a new connection: [Errno 111] Connection refused')': /session/ceda48d9fcb6d771447fe0f56bc46039/actions
[2025-03-26T01:57:08.809+0000] {connectionpool.py:823} WARNING - Retrying (Retry(total=1, connect=None, read=None, redirect=None, status=None)) after connection broken by 'NewConnectionError('<urllib3.connection.HTTPConnection object at 0x7f560dc46df0>: Failed to establish a new connection: [Errno 111] Connection refused')': /session/ceda48d9fcb6d771447fe0f56bc46039/actions
[2025-03-26T01:57:08.811+0000] {connectionpool.py:823} WARNING - Retrying (Retry(total=0, connect=None, read=None, redirect=None, status=None)) after connection broken by 'NewConnectionError('<urllib3.connection.HTTPConnection object at 0x7f560dc46ca0>: Failed to establish a new connection: [Errno 111] Connection refused')': /session/ceda48d9fcb6d771447fe0f56bc46039/actions
[2025-03-26T01:57:08.812+0000] {logging_mixin.py:151} INFO - Lỗi khi lấy dữ liệu: HTTPConnectionPool(host='localhost', port=50821): Max retries exceeded with url: /session/ceda48d9fcb6d771447fe0f56bc46039/actions (Caused by NewConnectionError('<urllib3.connection.HTTPConnection object at 0x7f560dc46e50>: Failed to establish a new connection: [Errno 111] Connection refused'))
[2025-03-26T01:57:08.815+0000] {connectionpool.py:823} WARNING - Retrying (Retry(total=2, connect=None, read=None, redirect=None, status=None)) after connection broken by 'NewConnectionError('<urllib3.connection.HTTPConnection object at 0x7f560dbd49a0>: Failed to establish a new connection: [Errno 111] Connection refused')': /session/ceda48d9fcb6d771447fe0f56bc46039/actions
[2025-03-26T01:57:08.817+0000] {connectionpool.py:823} WARNING - Retrying (Retry(total=1, connect=None, read=None, redirect=None, status=None)) after connection broken by 'NewConnectionError('<urllib3.connection.HTTPConnection object at 0x7f560dc46e80>: Failed to establish a new connection: [Errno 111] Connection refused')': /session/ceda48d9fcb6d771447fe0f56bc46039/actions
[2025-03-26T01:57:08.819+0000] {connectionpool.py:823} WARNING - Retrying (Retry(total=0, connect=None, read=None, redirect=None, status=None)) after connection broken by 'NewConnectionError('<urllib3.connection.HTTPConnection object at 0x7f560dc46190>: Failed to establish a new connection: [Errno 111] Connection refused')': /session/ceda48d9fcb6d771447fe0f56bc46039/actions
[2025-03-26T01:57:08.821+0000] {logging_mixin.py:151} INFO - Lỗi khi lấy dữ liệu: HTTPConnectionPool(host='localhost', port=50821): Max retries exceeded with url: /session/ceda48d9fcb6d771447fe0f56bc46039/actions (Caused by NewConnectionError('<urllib3.connection.HTTPConnection object at 0x7f560dc46dc0>: Failed to establish a new connection: [Errno 111] Connection refused'))
[2025-03-26T01:57:08.823+0000] {connectionpool.py:823} WARNING - Retrying (Retry(total=2, connect=None, read=None, redirect=None, status=None)) after connection broken by 'NewConnectionError('<urllib3.connection.HTTPConnection object at 0x7f560dcb4eb0>: Failed to establish a new connection: [Errno 111] Connection refused')': /session/ceda48d9fcb6d771447fe0f56bc46039/actions
[2025-03-26T01:57:08.824+0000] {connectionpool.py:823} WARNING - Retrying (Retry(total=1, connect=None, read=None, redirect=None, status=None)) after connection broken by 'NewConnectionError('<urllib3.connection.HTTPConnection object at 0x7f560dd55160>: Failed to establish a new connection: [Errno 111] Connection refused')': /session/ceda48d9fcb6d771447fe0f56bc46039/actions
[2025-03-26T01:57:08.826+0000] {connectionpool.py:823} WARNING - Retrying (Retry(total=0, connect=None, read=None, redirect=None, status=None)) after connection broken by 'NewConnectionError('<urllib3.connection.HTTPConnection object at 0x7f560dd556d0>: Failed to establish a new connection: [Errno 111] Connection refused')': /session/ceda48d9fcb6d771447fe0f56bc46039/actions
[2025-03-26T01:57:08.828+0000] {logging_mixin.py:151} INFO - Lỗi khi lấy dữ liệu: HTTPConnectionPool(host='localhost', port=50821): Max retries exceeded with url: /session/ceda48d9fcb6d771447fe0f56bc46039/actions (Caused by NewConnectionError('<urllib3.connection.HTTPConnection object at 0x7f560dd55250>: Failed to establish a new connection: [Errno 111] Connection refused'))
[2025-03-26T01:57:08.830+0000] {connectionpool.py:823} WARNING - Retrying (Retry(total=2, connect=None, read=None, redirect=None, status=None)) after connection broken by 'NewConnectionError('<urllib3.connection.HTTPConnection object at 0x7f560dd1e790>: Failed to establish a new connection: [Errno 111] Connection refused')': /session/ceda48d9fcb6d771447fe0f56bc46039/actions
[2025-03-26T01:57:08.832+0000] {connectionpool.py:823} WARNING - Retrying (Retry(total=1, connect=None, read=None, redirect=None, status=None)) after connection broken by 'NewConnectionError('<urllib3.connection.HTTPConnection object at 0x7f560dd6fd00>: Failed to establish a new connection: [Errno 111] Connection refused')': /session/ceda48d9fcb6d771447fe0f56bc46039/actions
[2025-03-26T01:57:08.834+0000] {connectionpool.py:823} WARNING - Retrying (Retry(total=0, connect=None, read=None, redirect=None, status=None)) after connection broken by 'NewConnectionError('<urllib3.connection.HTTPConnection object at 0x7f560dd6ff70>: Failed to establish a new connection: [Errno 111] Connection refused')': /session/ceda48d9fcb6d771447fe0f56bc46039/actions
[2025-03-26T01:57:08.836+0000] {logging_mixin.py:151} INFO - Lỗi khi lấy dữ liệu: HTTPConnectionPool(host='localhost', port=50821): Max retries exceeded with url: /session/ceda48d9fcb6d771447fe0f56bc46039/actions (Caused by NewConnectionError('<urllib3.connection.HTTPConnection object at 0x7f560dd84940>: Failed to establish a new connection: [Errno 111] Connection refused'))
[2025-03-26T01:57:08.838+0000] {connectionpool.py:823} WARNING - Retrying (Retry(total=2, connect=None, read=None, redirect=None, status=None)) after connection broken by 'NewConnectionError('<urllib3.connection.HTTPConnection object at 0x7f560dd84eb0>: Failed to establish a new connection: [Errno 111] Connection refused')': /session/ceda48d9fcb6d771447fe0f56bc46039/actions
[2025-03-26T01:57:08.840+0000] {connectionpool.py:823} WARNING - Retrying (Retry(total=1, connect=None, read=None, redirect=None, status=None)) after connection broken by 'NewConnectionError('<urllib3.connection.HTTPConnection object at 0x7f560dd84970>: Failed to establish a new connection: [Errno 111] Connection refused')': /session/ceda48d9fcb6d771447fe0f56bc46039/actions
[2025-03-26T01:57:08.841+0000] {connectionpool.py:823} WARNING - Retrying (Retry(total=0, connect=None, read=None, redirect=None, status=None)) after connection broken by 'NewConnectionError('<urllib3.connection.HTTPConnection object at 0x7f560dd846a0>: Failed to establish a new connection: [Errno 111] Connection refused')': /session/ceda48d9fcb6d771447fe0f56bc46039/actions
[2025-03-26T01:57:08.843+0000] {logging_mixin.py:151} INFO - Lỗi khi lấy dữ liệu: HTTPConnectionPool(host='localhost', port=50821): Max retries exceeded with url: /session/ceda48d9fcb6d771447fe0f56bc46039/actions (Caused by NewConnectionError('<urllib3.connection.HTTPConnection object at 0x7f560dd84790>: Failed to establish a new connection: [Errno 111] Connection refused'))
[2025-03-26T01:57:08.845+0000] {connectionpool.py:823} WARNING - Retrying (Retry(total=2, connect=None, read=None, redirect=None, status=None)) after connection broken by 'NewConnectionError('<urllib3.connection.HTTPConnection object at 0x7f560dbd4e20>: Failed to establish a new connection: [Errno 111] Connection refused')': /session/ceda48d9fcb6d771447fe0f56bc46039/actions
[2025-03-26T01:57:08.847+0000] {connectionpool.py:823} WARNING - Retrying (Retry(total=1, connect=None, read=None, redirect=None, status=None)) after connection broken by 'NewConnectionError('<urllib3.connection.HTTPConnection object at 0x7f560dd84580>: Failed to establish a new connection: [Errno 111] Connection refused')': /session/ceda48d9fcb6d771447fe0f56bc46039/actions
[2025-03-26T01:57:08.849+0000] {connectionpool.py:823} WARNING - Retrying (Retry(total=0, connect=None, read=None, redirect=None, status=None)) after connection broken by 'NewConnectionError('<urllib3.connection.HTTPConnection object at 0x7f560dd84a00>: Failed to establish a new connection: [Errno 111] Connection refused')': /session/ceda48d9fcb6d771447fe0f56bc46039/actions
[2025-03-26T01:57:08.851+0000] {logging_mixin.py:151} INFO - Lỗi khi lấy dữ liệu: HTTPConnectionPool(host='localhost', port=50821): Max retries exceeded with url: /session/ceda48d9fcb6d771447fe0f56bc46039/actions (Caused by NewConnectionError('<urllib3.connection.HTTPConnection object at 0x7f560dd84490>: Failed to establish a new connection: [Errno 111] Connection refused'))
[2025-03-26T01:57:08.854+0000] {connectionpool.py:823} WARNING - Retrying (Retry(total=2, connect=None, read=None, redirect=None, status=None)) after connection broken by 'NewConnectionError('<urllib3.connection.HTTPConnection object at 0x7f560dd84550>: Failed to establish a new connection: [Errno 111] Connection refused')': /session/ceda48d9fcb6d771447fe0f56bc46039/actions
[2025-03-26T01:57:08.856+0000] {connectionpool.py:823} WARNING - Retrying (Retry(total=1, connect=None, read=None, redirect=None, status=None)) after connection broken by 'NewConnectionError('<urllib3.connection.HTTPConnection object at 0x7f560dd84940>: Failed to establish a new connection: [Errno 111] Connection refused')': /session/ceda48d9fcb6d771447fe0f56bc46039/actions
[2025-03-26T01:57:08.858+0000] {connectionpool.py:823} WARNING - Retrying (Retry(total=0, connect=None, read=None, redirect=None, status=None)) after connection broken by 'NewConnectionError('<urllib3.connection.HTTPConnection object at 0x7f560dd6fe50>: Failed to establish a new connection: [Errno 111] Connection refused')': /session/ceda48d9fcb6d771447fe0f56bc46039/actions
[2025-03-26T01:57:08.859+0000] {logging_mixin.py:151} INFO - Lỗi khi lấy dữ liệu: HTTPConnectionPool(host='localhost', port=50821): Max retries exceeded with url: /session/ceda48d9fcb6d771447fe0f56bc46039/actions (Caused by NewConnectionError('<urllib3.connection.HTTPConnection object at 0x7f560dd6fee0>: Failed to establish a new connection: [Errno 111] Connection refused'))
[2025-03-26T01:57:08.861+0000] {connectionpool.py:823} WARNING - Retrying (Retry(total=2, connect=None, read=None, redirect=None, status=None)) after connection broken by 'NewConnectionError('<urllib3.connection.HTTPConnection object at 0x7f560dda2700>: Failed to establish a new connection: [Errno 111] Connection refused')': /session/ceda48d9fcb6d771447fe0f56bc46039/actions
[2025-03-26T01:57:08.863+0000] {connectionpool.py:823} WARNING - Retrying (Retry(total=1, connect=None, read=None, redirect=None, status=None)) after connection broken by 'NewConnectionError('<urllib3.connection.HTTPConnection object at 0x7f560dd550d0>: Failed to establish a new connection: [Errno 111] Connection refused')': /session/ceda48d9fcb6d771447fe0f56bc46039/actions
[2025-03-26T01:57:08.864+0000] {connectionpool.py:823} WARNING - Retrying (Retry(total=0, connect=None, read=None, redirect=None, status=None)) after connection broken by 'NewConnectionError('<urllib3.connection.HTTPConnection object at 0x7f560dd556d0>: Failed to establish a new connection: [Errno 111] Connection refused')': /session/ceda48d9fcb6d771447fe0f56bc46039/actions
[2025-03-26T01:57:08.866+0000] {logging_mixin.py:151} INFO - Lỗi khi lấy dữ liệu: HTTPConnectionPool(host='localhost', port=50821): Max retries exceeded with url: /session/ceda48d9fcb6d771447fe0f56bc46039/actions (Caused by NewConnectionError('<urllib3.connection.HTTPConnection object at 0x7f560dd55070>: Failed to establish a new connection: [Errno 111] Connection refused'))
[2025-03-26T01:57:08.868+0000] {connectionpool.py:823} WARNING - Retrying (Retry(total=2, connect=None, read=None, redirect=None, status=None)) after connection broken by 'NewConnectionError('<urllib3.connection.HTTPConnection object at 0x7f560dc460a0>: Failed to establish a new connection: [Errno 111] Connection refused')': /session/ceda48d9fcb6d771447fe0f56bc46039/actions
[2025-03-26T01:57:08.869+0000] {connectionpool.py:823} WARNING - Retrying (Retry(total=1, connect=None, read=None, redirect=None, status=None)) after connection broken by 'NewConnectionError('<urllib3.connection.HTTPConnection object at 0x7f560dc46f40>: Failed to establish a new connection: [Errno 111] Connection refused')': /session/ceda48d9fcb6d771447fe0f56bc46039/actions
[2025-03-26T01:57:08.872+0000] {connectionpool.py:823} WARNING - Retrying (Retry(total=0, connect=None, read=None, redirect=None, status=None)) after connection broken by 'NewConnectionError('<urllib3.connection.HTTPConnection object at 0x7f560dc46190>: Failed to establish a new connection: [Errno 111] Connection refused')': /session/ceda48d9fcb6d771447fe0f56bc46039/actions
[2025-03-26T01:57:08.875+0000] {logging_mixin.py:151} INFO - Lỗi khi lấy dữ liệu: HTTPConnectionPool(host='localhost', port=50821): Max retries exceeded with url: /session/ceda48d9fcb6d771447fe0f56bc46039/actions (Caused by NewConnectionError('<urllib3.connection.HTTPConnection object at 0x7f560dbd4df0>: Failed to establish a new connection: [Errno 111] Connection refused'))
[2025-03-26T01:57:08.878+0000] {connectionpool.py:823} WARNING - Retrying (Retry(total=2, connect=None, read=None, redirect=None, status=None)) after connection broken by 'NewConnectionError('<urllib3.connection.HTTPConnection object at 0x7f560dbd72e0>: Failed to establish a new connection: [Errno 111] Connection refused')': /session/ceda48d9fcb6d771447fe0f56bc46039/actions
[2025-03-26T01:57:08.880+0000] {connectionpool.py:823} WARNING - Retrying (Retry(total=1, connect=None, read=None, redirect=None, status=None)) after connection broken by 'NewConnectionError('<urllib3.connection.HTTPConnection object at 0x7f560dbd4970>: Failed to establish a new connection: [Errno 111] Connection refused')': /session/ceda48d9fcb6d771447fe0f56bc46039/actions
[2025-03-26T01:57:08.882+0000] {connectionpool.py:823} WARNING - Retrying (Retry(total=0, connect=None, read=None, redirect=None, status=None)) after connection broken by 'NewConnectionError('<urllib3.connection.HTTPConnection object at 0x7f560dc460d0>: Failed to establish a new connection: [Errno 111] Connection refused')': /session/ceda48d9fcb6d771447fe0f56bc46039/actions
[2025-03-26T01:57:08.884+0000] {logging_mixin.py:151} INFO - Lỗi khi lấy dữ liệu: HTTPConnectionPool(host='localhost', port=50821): Max retries exceeded with url: /session/ceda48d9fcb6d771447fe0f56bc46039/actions (Caused by NewConnectionError('<urllib3.connection.HTTPConnection object at 0x7f560dc461f0>: Failed to establish a new connection: [Errno 111] Connection refused'))
[2025-03-26T01:57:08.886+0000] {connectionpool.py:823} WARNING - Retrying (Retry(total=2, connect=None, read=None, redirect=None, status=None)) after connection broken by 'NewConnectionError('<urllib3.connection.HTTPConnection object at 0x7f560dc46e20>: Failed to establish a new connection: [Errno 111] Connection refused')': /session/ceda48d9fcb6d771447fe0f56bc46039/url
[2025-03-26T01:57:08.888+0000] {connectionpool.py:823} WARNING - Retrying (Retry(total=1, connect=None, read=None, redirect=None, status=None)) after connection broken by 'NewConnectionError('<urllib3.connection.HTTPConnection object at 0x7f560dcb4d60>: Failed to establish a new connection: [Errno 111] Connection refused')': /session/ceda48d9fcb6d771447fe0f56bc46039/url
[2025-03-26T01:57:08.890+0000] {connectionpool.py:823} WARNING - Retrying (Retry(total=0, connect=None, read=None, redirect=None, status=None)) after connection broken by 'NewConnectionError('<urllib3.connection.HTTPConnection object at 0x7f560dcb4d30>: Failed to establish a new connection: [Errno 111] Connection refused')': /session/ceda48d9fcb6d771447fe0f56bc46039/url
[2025-03-26T01:57:08.893+0000] {data_stream.py:39} ERROR - An error occurred: HTTPConnectionPool(host='localhost', port=50821): Max retries exceeded with url: /session/ceda48d9fcb6d771447fe0f56bc46039/url (Caused by NewConnectionError('<urllib3.connection.HTTPConnection object at 0x7f560dd55100>: Failed to establish a new connection: [Errno 111] Connection refused'))
[2025-03-26T01:57:08.893+0000] {python.py:194} INFO - Done. Returned value was: None
[2025-03-26T01:57:08.920+0000] {taskinstance.py:1400} INFO - Marking task as SUCCESS. dag_id=job_data_stream, task_id=job_data_stream, execution_date=20250326T011345, start_date=20250326T011348, end_date=20250326T015708
[2025-03-26T01:57:08.954+0000] {process_utils.py:79} INFO - Process psutil.Process(pid=390, status='terminated', started='01:13:50') (390) terminated with exit code None
[2025-03-26T01:57:08.955+0000] {process_utils.py:79} INFO - Process psutil.Process(pid=388, status='terminated', exitcode=0, started='01:13:48') (388) terminated with exit code 0
[2025-03-26T01:57:08.956+0000] {local_task_job_runner.py:228} INFO - Task exited with return code 143
[2025-03-26T01:57:08.986+0000] {taskinstance.py:2784} INFO - 0 downstream tasks scheduled from follow-on schedule check
