[2025-03-10T12:44:16.631+0000] {taskinstance.py:1159} INFO - Dependencies all met for dep_context=non-requeueable deps ti=<TaskInstance: stream_data.stream_data manual__2025-03-10T12:44:15.125960+00:00 [queued]>
[2025-03-10T12:44:16.642+0000] {taskinstance.py:1159} INFO - Dependencies all met for dep_context=requeueable deps ti=<TaskInstance: stream_data.stream_data manual__2025-03-10T12:44:15.125960+00:00 [queued]>
[2025-03-10T12:44:16.642+0000] {taskinstance.py:1361} INFO - Starting attempt 1 of 1
[2025-03-10T12:44:16.659+0000] {taskinstance.py:1382} INFO - Executing <Task(PythonOperator): stream_data> on 2025-03-10 12:44:15.125960+00:00
[2025-03-10T12:44:16.664+0000] {standard_task_runner.py:57} INFO - Started process 52 to run task
[2025-03-10T12:44:16.669+0000] {standard_task_runner.py:84} INFO - Running: ['***', 'tasks', 'run', 'stream_data', 'stream_data', 'manual__2025-03-10T12:44:15.125960+00:00', '--job-id', '64', '--raw', '--subdir', 'DAGS_FOLDER/data_stream.py', '--cfg-path', '/tmp/tmppyiw5exu']
[2025-03-10T12:44:16.671+0000] {standard_task_runner.py:85} INFO - Job 64: Subtask stream_data
[2025-03-10T12:44:16.735+0000] {task_command.py:415} INFO - Running <TaskInstance: stream_data.stream_data manual__2025-03-10T12:44:15.125960+00:00 [running]> on host 0431913abdf0
[2025-03-10T12:44:16.834+0000] {taskinstance.py:1660} INFO - Exporting env vars: AIRFLOW_CTX_DAG_OWNER='dii' AIRFLOW_CTX_DAG_ID='stream_data' AIRFLOW_CTX_TASK_ID='stream_data' AIRFLOW_CTX_EXECUTION_DATE='2025-03-10T12:44:15.125960+00:00' AIRFLOW_CTX_TRY_NUMBER='1' AIRFLOW_CTX_DAG_RUN_ID='manual__2025-03-10T12:44:15.125960+00:00'
[2025-03-10T12:44:16.899+0000] {conn.py:1542} WARNING - DNS lookup failed for broker:29092, exception was [Errno -2] Name or service not known. Is your advertised.listeners (called advertised.host.name before Kafka 9) correct and resolvable?
[2025-03-10T12:44:16.899+0000] {conn.py:315} ERROR - DNS lookup failed for broker:29092 (0)
[2025-03-10T12:44:16.900+0000] {conn.py:1219} INFO - Probing node bootstrap-0 broker version
[2025-03-10T12:44:16.916+0000] {conn.py:1542} WARNING - DNS lookup failed for broker:29092, exception was [Errno -2] Name or service not known. Is your advertised.listeners (called advertised.host.name before Kafka 9) correct and resolvable?
[2025-03-10T12:44:16.918+0000] {conn.py:315} ERROR - DNS lookup failed for broker:29092 (0)
[2025-03-10T12:44:16.930+0000] {conn.py:1542} WARNING - DNS lookup failed for broker:29092, exception was [Errno -2] Name or service not known. Is your advertised.listeners (called advertised.host.name before Kafka 9) correct and resolvable?
[2025-03-10T12:44:16.931+0000] {conn.py:315} ERROR - DNS lookup failed for broker:29092 (0)
[2025-03-10T12:44:16.932+0000] {conn.py:1219} INFO - Probing node bootstrap-0 broker version
[2025-03-10T12:44:16.945+0000] {conn.py:1542} WARNING - DNS lookup failed for broker:29092, exception was [Errno -2] Name or service not known. Is your advertised.listeners (called advertised.host.name before Kafka 9) correct and resolvable?
[2025-03-10T12:44:16.946+0000] {conn.py:315} ERROR - DNS lookup failed for broker:29092 (0)
[2025-03-10T12:44:16.947+0000] {taskinstance.py:1943} ERROR - Task failed with exception
Traceback (most recent call last):
  File "/home/airflow/.local/lib/python3.8/site-packages/airflow/operators/python.py", line 192, in execute
    return_value = self.execute_callable()
  File "/home/airflow/.local/lib/python3.8/site-packages/airflow/operators/python.py", line 209, in execute_callable
    return self.python_callable(*self.op_args, **self.op_kwargs)
  File "/opt/airflow/dags/data_stream.py", line 31, in stream_data
    producer = KafkaProducer(bootstrap_servers=['broker:29092'])
  File "/home/airflow/.local/lib/python3.8/site-packages/kafka/producer/kafka.py", line 383, in __init__
    client = self.config['kafka_client'](
  File "/home/airflow/.local/lib/python3.8/site-packages/kafka/client_async.py", line 241, in __init__
    self.config['api_version'] = self.check_version(timeout=check_timeout)
  File "/home/airflow/.local/lib/python3.8/site-packages/kafka/client_async.py", line 918, in check_version
    raise Errors.NoBrokersAvailable()
kafka.errors.NoBrokersAvailable: NoBrokersAvailable
[2025-03-10T12:44:16.964+0000] {taskinstance.py:1400} INFO - Marking task as FAILED. dag_id=stream_data, task_id=stream_data, execution_date=20250310T124415, start_date=20250310T124416, end_date=20250310T124416
[2025-03-10T12:44:16.977+0000] {standard_task_runner.py:104} ERROR - Failed to execute job 64 for task stream_data (NoBrokersAvailable; 52)
[2025-03-10T12:44:17.011+0000] {local_task_job_runner.py:228} INFO - Task exited with return code 1
[2025-03-10T12:44:17.037+0000] {taskinstance.py:2784} INFO - 0 downstream tasks scheduled from follow-on schedule check
