[2025-02-27T11:54:29.265+0000] {taskinstance.py:1159} INFO - Dependencies all met for dep_context=non-requeueable deps ti=<TaskInstance: stream_data.stream_data_from_api manual__2025-02-27T11:54:27.063153+00:00 [queued]>
[2025-02-27T11:54:29.305+0000] {taskinstance.py:1159} INFO - Dependencies all met for dep_context=requeueable deps ti=<TaskInstance: stream_data.stream_data_from_api manual__2025-02-27T11:54:27.063153+00:00 [queued]>
[2025-02-27T11:54:29.307+0000] {taskinstance.py:1361} INFO - Starting attempt 1 of 1
[2025-02-27T11:54:29.335+0000] {taskinstance.py:1382} INFO - Executing <Task(PythonOperator): stream_data_from_api> on 2025-02-27 11:54:27.063153+00:00
[2025-02-27T11:54:29.344+0000] {standard_task_runner.py:57} INFO - Started process 52 to run task
[2025-02-27T11:54:29.353+0000] {standard_task_runner.py:84} INFO - Running: ['***', 'tasks', 'run', 'stream_data', 'stream_data_from_api', 'manual__2025-02-27T11:54:27.063153+00:00', '--job-id', '12', '--raw', '--subdir', 'DAGS_FOLDER/data_stream.py', '--cfg-path', '/tmp/tmpg_s3osr5']
[2025-02-27T11:54:29.357+0000] {standard_task_runner.py:85} INFO - Job 12: Subtask stream_data_from_api
[2025-02-27T11:54:29.418+0000] {warnings.py:109} WARNING - /home/***/.local/lib/python3.8/site-packages/***/settings.py:195: DeprecationWarning: The sql_alchemy_conn option in [core] has been moved to the sql_alchemy_conn option in [database] - the old setting has been used, but please update your config.
  SQL_ALCHEMY_CONN = conf.get("database", "SQL_ALCHEMY_CONN")

[2025-02-27T11:54:29.537+0000] {task_command.py:415} INFO - Running <TaskInstance: stream_data.stream_data_from_api manual__2025-02-27T11:54:27.063153+00:00 [running]> on host e100a4eec7b3
[2025-02-27T11:54:29.868+0000] {taskinstance.py:1660} INFO - Exporting env vars: AIRFLOW_CTX_DAG_OWNER='dii' AIRFLOW_CTX_DAG_ID='stream_data' AIRFLOW_CTX_TASK_ID='stream_data_from_api' AIRFLOW_CTX_EXECUTION_DATE='2025-02-27T11:54:27.063153+00:00' AIRFLOW_CTX_TRY_NUMBER='1' AIRFLOW_CTX_DAG_RUN_ID='manual__2025-02-27T11:54:27.063153+00:00'
[2025-02-27T11:54:29.912+0000] {conn.py:1542} WARNING - DNS lookup failed for broker:29092, exception was [Errno -2] Name or service not known. Is your advertised.listeners (called advertised.host.name before Kafka 9) correct and resolvable?
[2025-02-27T11:54:29.913+0000] {conn.py:315} ERROR - DNS lookup failed for broker:29092 (0)
[2025-02-27T11:54:29.914+0000] {conn.py:1219} INFO - Probing node bootstrap-0 broker version
[2025-02-27T11:54:29.928+0000] {conn.py:1542} WARNING - DNS lookup failed for broker:29092, exception was [Errno -2] Name or service not known. Is your advertised.listeners (called advertised.host.name before Kafka 9) correct and resolvable?
[2025-02-27T11:54:29.929+0000] {conn.py:315} ERROR - DNS lookup failed for broker:29092 (0)
[2025-02-27T11:54:29.944+0000] {conn.py:1542} WARNING - DNS lookup failed for broker:29092, exception was [Errno -2] Name or service not known. Is your advertised.listeners (called advertised.host.name before Kafka 9) correct and resolvable?
[2025-02-27T11:54:29.945+0000] {conn.py:315} ERROR - DNS lookup failed for broker:29092 (0)
[2025-02-27T11:54:29.945+0000] {conn.py:1219} INFO - Probing node bootstrap-0 broker version
[2025-02-27T11:54:29.962+0000] {conn.py:1542} WARNING - DNS lookup failed for broker:29092, exception was [Errno -2] Name or service not known. Is your advertised.listeners (called advertised.host.name before Kafka 9) correct and resolvable?
[2025-02-27T11:54:29.963+0000] {conn.py:315} ERROR - DNS lookup failed for broker:29092 (0)
[2025-02-27T11:54:29.964+0000] {taskinstance.py:1943} ERROR - Task failed with exception
Traceback (most recent call last):
  File "/home/airflow/.local/lib/python3.8/site-packages/airflow/operators/python.py", line 192, in execute
    return_value = self.execute_callable()
  File "/home/airflow/.local/lib/python3.8/site-packages/airflow/operators/python.py", line 209, in execute_callable
    return self.python_callable(*self.op_args, **self.op_kwargs)
  File "/opt/airflow/dags/data_stream.py", line 21, in stream_data
    producer = KafkaProducer(bootstrap_servers=['broker:29092'], max_block_ms=5000)
  File "/home/airflow/.local/lib/python3.8/site-packages/kafka/producer/kafka.py", line 383, in __init__
    client = self.config['kafka_client'](
  File "/home/airflow/.local/lib/python3.8/site-packages/kafka/client_async.py", line 241, in __init__
    self.config['api_version'] = self.check_version(timeout=check_timeout)
  File "/home/airflow/.local/lib/python3.8/site-packages/kafka/client_async.py", line 918, in check_version
    raise Errors.NoBrokersAvailable()
kafka.errors.NoBrokersAvailable: NoBrokersAvailable
[2025-02-27T11:54:29.989+0000] {taskinstance.py:1400} INFO - Marking task as FAILED. dag_id=stream_data, task_id=stream_data_from_api, execution_date=20250227T115427, start_date=20250227T115429, end_date=20250227T115429
[2025-02-27T11:54:30.011+0000] {standard_task_runner.py:104} ERROR - Failed to execute job 12 for task stream_data_from_api (NoBrokersAvailable; 52)
[2025-02-27T11:54:30.029+0000] {local_task_job_runner.py:228} INFO - Task exited with return code 1
[2025-02-27T11:54:30.052+0000] {taskinstance.py:2784} INFO - 0 downstream tasks scheduled from follow-on schedule check
