[2025-03-26T01:11:15.241+0000] {taskinstance.py:1159} INFO - Dependencies all met for dep_context=non-requeueable deps ti=<TaskInstance: job_data_stream.job_data_stream scheduled__2025-03-25T00:00:00+00:00 [queued]>
[2025-03-26T01:11:15.251+0000] {taskinstance.py:1159} INFO - Dependencies all met for dep_context=requeueable deps ti=<TaskInstance: job_data_stream.job_data_stream scheduled__2025-03-25T00:00:00+00:00 [queued]>
[2025-03-26T01:11:15.252+0000] {taskinstance.py:1361} INFO - Starting attempt 1 of 1
[2025-03-26T01:11:15.264+0000] {taskinstance.py:1382} INFO - Executing <Task(PythonOperator): job_data_stream> on 2025-03-25 00:00:00+00:00
[2025-03-26T01:11:15.269+0000] {standard_task_runner.py:57} INFO - Started process 52 to run task
[2025-03-26T01:11:15.274+0000] {standard_task_runner.py:84} INFO - Running: ['***', 'tasks', 'run', 'job_data_stream', 'job_data_stream', 'scheduled__2025-03-25T00:00:00+00:00', '--job-id', '57', '--raw', '--subdir', 'DAGS_FOLDER/data_stream.py', '--cfg-path', '/tmp/tmp4xza1kai']
[2025-03-26T01:11:15.276+0000] {standard_task_runner.py:85} INFO - Job 57: Subtask job_data_stream
[2025-03-26T01:11:15.347+0000] {task_command.py:415} INFO - Running <TaskInstance: job_data_stream.job_data_stream scheduled__2025-03-25T00:00:00+00:00 [running]> on host c0041b6c44f7
[2025-03-26T01:11:15.450+0000] {taskinstance.py:1660} INFO - Exporting env vars: AIRFLOW_CTX_DAG_OWNER='dii' AIRFLOW_CTX_DAG_ID='job_data_stream' AIRFLOW_CTX_TASK_ID='job_data_stream' AIRFLOW_CTX_EXECUTION_DATE='2025-03-25T00:00:00+00:00' AIRFLOW_CTX_TRY_NUMBER='1' AIRFLOW_CTX_DAG_RUN_ID='scheduled__2025-03-25T00:00:00+00:00'
[2025-03-26T01:11:15.456+0000] {conn.py:384} INFO - <BrokerConnection client_id=kafka-python-producer-1, node_id=bootstrap-0 host=broker:29092 <connecting> [IPv4 ('172.18.0.2', 29092)]>: connecting to broker:29092 [('172.18.0.2', 29092) IPv4]
[2025-03-26T01:11:15.457+0000] {conn.py:1219} INFO - Probing node bootstrap-0 broker version
[2025-03-26T01:11:15.459+0000] {conn.py:414} INFO - <BrokerConnection client_id=kafka-python-producer-1, node_id=bootstrap-0 host=broker:29092 <connecting> [IPv4 ('172.18.0.2', 29092)]>: Connection complete.
[2025-03-26T01:11:15.583+0000] {conn.py:1282} INFO - Broker version identified as 2.6.0
[2025-03-26T01:11:15.583+0000] {conn.py:1283} INFO - Set configuration api_version=(2, 6, 0) to skip auto check_version requests on startup
[2025-03-26T01:11:29.464+0000] {logging_mixin.py:151} INFO - Số công việc tìm thấy trên trang 401:70
[2025-03-26T01:13:23.140+0000] {logging_mixin.py:151} INFO - Số công việc tìm thấy trên trang 402:70
[2025-03-26T01:13:43.333+0000] {local_task_job_runner.py:294} WARNING - State of this instance has been externally set to failed. Terminating instance.
[2025-03-26T01:13:43.339+0000] {process_utils.py:131} INFO - Sending 15 to group 52. PIDs of all processes in the group: [54, 60, 64, 65, 74, 75, 97, 181, 121, 146, 211, 220, 318, 335, 344, 352, 96, 52]
[2025-03-26T01:13:43.340+0000] {process_utils.py:86} INFO - Sending the signal 15 to group 52
[2025-03-26T01:13:43.357+0000] {taskinstance.py:1632} ERROR - Received SIGTERM. Terminating subprocesses.
[2025-03-26T01:13:43.358+0000] {logging_mixin.py:151} INFO - Lỗi khi lấy dữ liệu: Task received SIGTERM signal
[2025-03-26T01:13:43.361+0000] {connectionpool.py:823} WARNING - Retrying (Retry(total=2, connect=None, read=None, redirect=None, status=None)) after connection broken by 'NewConnectionError('<urllib3.connection.HTTPConnection object at 0x7f560ddbb160>: Failed to establish a new connection: [Errno 111] Connection refused')': /session/a833db34a5f9e805150e1d501248a6a9/actions
[2025-03-26T01:13:43.367+0000] {connectionpool.py:823} WARNING - Retrying (Retry(total=1, connect=None, read=None, redirect=None, status=None)) after connection broken by 'NewConnectionError('<urllib3.connection.HTTPConnection object at 0x7f560ddbb7c0>: Failed to establish a new connection: [Errno 111] Connection refused')': /session/a833db34a5f9e805150e1d501248a6a9/actions
[2025-03-26T01:13:43.368+0000] {connectionpool.py:823} WARNING - Retrying (Retry(total=0, connect=None, read=None, redirect=None, status=None)) after connection broken by 'NewConnectionError('<urllib3.connection.HTTPConnection object at 0x7f560ddbb8b0>: Failed to establish a new connection: [Errno 111] Connection refused')': /session/a833db34a5f9e805150e1d501248a6a9/actions
[2025-03-26T01:13:43.370+0000] {logging_mixin.py:151} INFO - Lỗi khi lấy dữ liệu: HTTPConnectionPool(host='localhost', port=37583): Max retries exceeded with url: /session/a833db34a5f9e805150e1d501248a6a9/actions (Caused by NewConnectionError('<urllib3.connection.HTTPConnection object at 0x7f560ddbba00>: Failed to establish a new connection: [Errno 111] Connection refused'))
[2025-03-26T01:13:43.371+0000] {connectionpool.py:823} WARNING - Retrying (Retry(total=2, connect=None, read=None, redirect=None, status=None)) after connection broken by 'NewConnectionError('<urllib3.connection.HTTPConnection object at 0x7f560ddbbe50>: Failed to establish a new connection: [Errno 111] Connection refused')': /session/a833db34a5f9e805150e1d501248a6a9/actions
[2025-03-26T01:13:43.373+0000] {connectionpool.py:823} WARNING - Retrying (Retry(total=1, connect=None, read=None, redirect=None, status=None)) after connection broken by 'NewConnectionError('<urllib3.connection.HTTPConnection object at 0x7f560ddbbf40>: Failed to establish a new connection: [Errno 111] Connection refused')': /session/a833db34a5f9e805150e1d501248a6a9/actions
[2025-03-26T01:13:43.374+0000] {connectionpool.py:823} WARNING - Retrying (Retry(total=0, connect=None, read=None, redirect=None, status=None)) after connection broken by 'NewConnectionError('<urllib3.connection.HTTPConnection object at 0x7f560dd55070>: Failed to establish a new connection: [Errno 111] Connection refused')': /session/a833db34a5f9e805150e1d501248a6a9/actions
[2025-03-26T01:13:43.375+0000] {logging_mixin.py:151} INFO - Lỗi khi lấy dữ liệu: HTTPConnectionPool(host='localhost', port=37583): Max retries exceeded with url: /session/a833db34a5f9e805150e1d501248a6a9/actions (Caused by NewConnectionError('<urllib3.connection.HTTPConnection object at 0x7f560dd551c0>: Failed to establish a new connection: [Errno 111] Connection refused'))
[2025-03-26T01:13:43.376+0000] {connectionpool.py:823} WARNING - Retrying (Retry(total=2, connect=None, read=None, redirect=None, status=None)) after connection broken by 'NewConnectionError('<urllib3.connection.HTTPConnection object at 0x7f560dd55610>: Failed to establish a new connection: [Errno 111] Connection refused')': /session/a833db34a5f9e805150e1d501248a6a9/actions
[2025-03-26T01:13:43.377+0000] {connectionpool.py:823} WARNING - Retrying (Retry(total=1, connect=None, read=None, redirect=None, status=None)) after connection broken by 'NewConnectionError('<urllib3.connection.HTTPConnection object at 0x7f560dd55700>: Failed to establish a new connection: [Errno 111] Connection refused')': /session/a833db34a5f9e805150e1d501248a6a9/actions
[2025-03-26T01:13:43.378+0000] {connectionpool.py:823} WARNING - Retrying (Retry(total=0, connect=None, read=None, redirect=None, status=None)) after connection broken by 'NewConnectionError('<urllib3.connection.HTTPConnection object at 0x7f560ddbbca0>: Failed to establish a new connection: [Errno 111] Connection refused')': /session/a833db34a5f9e805150e1d501248a6a9/actions
[2025-03-26T01:13:43.379+0000] {logging_mixin.py:151} INFO - Lỗi khi lấy dữ liệu: HTTPConnectionPool(host='localhost', port=37583): Max retries exceeded with url: /session/a833db34a5f9e805150e1d501248a6a9/actions (Caused by NewConnectionError('<urllib3.connection.HTTPConnection object at 0x7f560ddbbf40>: Failed to establish a new connection: [Errno 111] Connection refused'))
[2025-03-26T01:13:43.381+0000] {connectionpool.py:823} WARNING - Retrying (Retry(total=2, connect=None, read=None, redirect=None, status=None)) after connection broken by 'NewConnectionError('<urllib3.connection.HTTPConnection object at 0x7f560ddbb610>: Failed to establish a new connection: [Errno 111] Connection refused')': /session/a833db34a5f9e805150e1d501248a6a9/actions
[2025-03-26T01:13:43.382+0000] {connectionpool.py:823} WARNING - Retrying (Retry(total=1, connect=None, read=None, redirect=None, status=None)) after connection broken by 'NewConnectionError('<urllib3.connection.HTTPConnection object at 0x7f560ddbb970>: Failed to establish a new connection: [Errno 111] Connection refused')': /session/a833db34a5f9e805150e1d501248a6a9/actions
[2025-03-26T01:13:43.383+0000] {connectionpool.py:823} WARNING - Retrying (Retry(total=0, connect=None, read=None, redirect=None, status=None)) after connection broken by 'NewConnectionError('<urllib3.connection.HTTPConnection object at 0x7f560ddbba60>: Failed to establish a new connection: [Errno 111] Connection refused')': /session/a833db34a5f9e805150e1d501248a6a9/actions
[2025-03-26T01:13:43.385+0000] {logging_mixin.py:151} INFO - Lỗi khi lấy dữ liệu: HTTPConnectionPool(host='localhost', port=37583): Max retries exceeded with url: /session/a833db34a5f9e805150e1d501248a6a9/actions (Caused by NewConnectionError('<urllib3.connection.HTTPConnection object at 0x7f560ddbb250>: Failed to establish a new connection: [Errno 111] Connection refused'))
[2025-03-26T01:13:43.387+0000] {connectionpool.py:823} WARNING - Retrying (Retry(total=2, connect=None, read=None, redirect=None, status=None)) after connection broken by 'NewConnectionError('<urllib3.connection.HTTPConnection object at 0x7f560dd551f0>: Failed to establish a new connection: [Errno 111] Connection refused')': /session/a833db34a5f9e805150e1d501248a6a9/actions
[2025-03-26T01:13:43.388+0000] {connectionpool.py:823} WARNING - Retrying (Retry(total=1, connect=None, read=None, redirect=None, status=None)) after connection broken by 'NewConnectionError('<urllib3.connection.HTTPConnection object at 0x7f560dd55160>: Failed to establish a new connection: [Errno 111] Connection refused')': /session/a833db34a5f9e805150e1d501248a6a9/actions
[2025-03-26T01:13:43.389+0000] {connectionpool.py:823} WARNING - Retrying (Retry(total=0, connect=None, read=None, redirect=None, status=None)) after connection broken by 'NewConnectionError('<urllib3.connection.HTTPConnection object at 0x7f560dd55850>: Failed to establish a new connection: [Errno 111] Connection refused')': /session/a833db34a5f9e805150e1d501248a6a9/actions
[2025-03-26T01:13:43.390+0000] {logging_mixin.py:151} INFO - Lỗi khi lấy dữ liệu: HTTPConnectionPool(host='localhost', port=37583): Max retries exceeded with url: /session/a833db34a5f9e805150e1d501248a6a9/actions (Caused by NewConnectionError('<urllib3.connection.HTTPConnection object at 0x7f560dd559d0>: Failed to establish a new connection: [Errno 111] Connection refused'))
[2025-03-26T01:13:43.391+0000] {connectionpool.py:823} WARNING - Retrying (Retry(total=2, connect=None, read=None, redirect=None, status=None)) after connection broken by 'NewConnectionError('<urllib3.connection.HTTPConnection object at 0x7f560dd70a00>: Failed to establish a new connection: [Errno 111] Connection refused')': /session/a833db34a5f9e805150e1d501248a6a9/actions
[2025-03-26T01:13:43.392+0000] {connectionpool.py:823} WARNING - Retrying (Retry(total=1, connect=None, read=None, redirect=None, status=None)) after connection broken by 'NewConnectionError('<urllib3.connection.HTTPConnection object at 0x7f560dd70af0>: Failed to establish a new connection: [Errno 111] Connection refused')': /session/a833db34a5f9e805150e1d501248a6a9/actions
[2025-03-26T01:13:43.392+0000] {connectionpool.py:823} WARNING - Retrying (Retry(total=0, connect=None, read=None, redirect=None, status=None)) after connection broken by 'NewConnectionError('<urllib3.connection.HTTPConnection object at 0x7f560dd70c70>: Failed to establish a new connection: [Errno 111] Connection refused')': /session/a833db34a5f9e805150e1d501248a6a9/actions
[2025-03-26T01:13:43.393+0000] {logging_mixin.py:151} INFO - Lỗi khi lấy dữ liệu: HTTPConnectionPool(host='localhost', port=37583): Max retries exceeded with url: /session/a833db34a5f9e805150e1d501248a6a9/actions (Caused by NewConnectionError('<urllib3.connection.HTTPConnection object at 0x7f560dd70dc0>: Failed to establish a new connection: [Errno 111] Connection refused'))
[2025-03-26T01:13:43.395+0000] {connectionpool.py:823} WARNING - Retrying (Retry(total=2, connect=None, read=None, redirect=None, status=None)) after connection broken by 'NewConnectionError('<urllib3.connection.HTTPConnection object at 0x7f560dd17250>: Failed to establish a new connection: [Errno 111] Connection refused')': /session/a833db34a5f9e805150e1d501248a6a9/actions
[2025-03-26T01:13:43.396+0000] {connectionpool.py:823} WARNING - Retrying (Retry(total=1, connect=None, read=None, redirect=None, status=None)) after connection broken by 'NewConnectionError('<urllib3.connection.HTTPConnection object at 0x7f560dd70ac0>: Failed to establish a new connection: [Errno 111] Connection refused')': /session/a833db34a5f9e805150e1d501248a6a9/actions
[2025-03-26T01:13:43.397+0000] {connectionpool.py:823} WARNING - Retrying (Retry(total=0, connect=None, read=None, redirect=None, status=None)) after connection broken by 'NewConnectionError('<urllib3.connection.HTTPConnection object at 0x7f560dd70e50>: Failed to establish a new connection: [Errno 111] Connection refused')': /session/a833db34a5f9e805150e1d501248a6a9/actions
[2025-03-26T01:13:43.398+0000] {logging_mixin.py:151} INFO - Lỗi khi lấy dữ liệu: HTTPConnectionPool(host='localhost', port=37583): Max retries exceeded with url: /session/a833db34a5f9e805150e1d501248a6a9/actions (Caused by NewConnectionError('<urllib3.connection.HTTPConnection object at 0x7f560dd70be0>: Failed to establish a new connection: [Errno 111] Connection refused'))
[2025-03-26T01:13:43.399+0000] {connectionpool.py:823} WARNING - Retrying (Retry(total=2, connect=None, read=None, redirect=None, status=None)) after connection broken by 'NewConnectionError('<urllib3.connection.HTTPConnection object at 0x7f560dd55c10>: Failed to establish a new connection: [Errno 111] Connection refused')': /session/a833db34a5f9e805150e1d501248a6a9/actions
[2025-03-26T01:13:43.400+0000] {connectionpool.py:823} WARNING - Retrying (Retry(total=1, connect=None, read=None, redirect=None, status=None)) after connection broken by 'NewConnectionError('<urllib3.connection.HTTPConnection object at 0x7f560dd55100>: Failed to establish a new connection: [Errno 111] Connection refused')': /session/a833db34a5f9e805150e1d501248a6a9/actions
[2025-03-26T01:13:43.401+0000] {connectionpool.py:823} WARNING - Retrying (Retry(total=0, connect=None, read=None, redirect=None, status=None)) after connection broken by 'NewConnectionError('<urllib3.connection.HTTPConnection object at 0x7f560dd559a0>: Failed to establish a new connection: [Errno 111] Connection refused')': /session/a833db34a5f9e805150e1d501248a6a9/actions
[2025-03-26T01:13:43.402+0000] {logging_mixin.py:151} INFO - Lỗi khi lấy dữ liệu: HTTPConnectionPool(host='localhost', port=37583): Max retries exceeded with url: /session/a833db34a5f9e805150e1d501248a6a9/actions (Caused by NewConnectionError('<urllib3.connection.HTTPConnection object at 0x7f560dd55160>: Failed to establish a new connection: [Errno 111] Connection refused'))
[2025-03-26T01:13:43.404+0000] {connectionpool.py:823} WARNING - Retrying (Retry(total=2, connect=None, read=None, redirect=None, status=None)) after connection broken by 'NewConnectionError('<urllib3.connection.HTTPConnection object at 0x7f560ddbb550>: Failed to establish a new connection: [Errno 111] Connection refused')': /session/a833db34a5f9e805150e1d501248a6a9/actions
[2025-03-26T01:13:43.405+0000] {connectionpool.py:823} WARNING - Retrying (Retry(total=1, connect=None, read=None, redirect=None, status=None)) after connection broken by 'NewConnectionError('<urllib3.connection.HTTPConnection object at 0x7f560ddbbb20>: Failed to establish a new connection: [Errno 111] Connection refused')': /session/a833db34a5f9e805150e1d501248a6a9/actions
[2025-03-26T01:13:43.406+0000] {connectionpool.py:823} WARNING - Retrying (Retry(total=0, connect=None, read=None, redirect=None, status=None)) after connection broken by 'NewConnectionError('<urllib3.connection.HTTPConnection object at 0x7f560ddbb160>: Failed to establish a new connection: [Errno 111] Connection refused')': /session/a833db34a5f9e805150e1d501248a6a9/actions
[2025-03-26T01:13:43.407+0000] {logging_mixin.py:151} INFO - Lỗi khi lấy dữ liệu: HTTPConnectionPool(host='localhost', port=37583): Max retries exceeded with url: /session/a833db34a5f9e805150e1d501248a6a9/actions (Caused by NewConnectionError('<urllib3.connection.HTTPConnection object at 0x7f560ddbb790>: Failed to establish a new connection: [Errno 111] Connection refused'))
[2025-03-26T01:13:43.408+0000] {connectionpool.py:823} WARNING - Retrying (Retry(total=2, connect=None, read=None, redirect=None, status=None)) after connection broken by 'NewConnectionError('<urllib3.connection.HTTPConnection object at 0x7f560ddbbd00>: Failed to establish a new connection: [Errno 111] Connection refused')': /session/a833db34a5f9e805150e1d501248a6a9/actions
[2025-03-26T01:13:43.409+0000] {connectionpool.py:823} WARNING - Retrying (Retry(total=1, connect=None, read=None, redirect=None, status=None)) after connection broken by 'NewConnectionError('<urllib3.connection.HTTPConnection object at 0x7f560ddbbfd0>: Failed to establish a new connection: [Errno 111] Connection refused')': /session/a833db34a5f9e805150e1d501248a6a9/actions
[2025-03-26T01:13:43.410+0000] {connectionpool.py:823} WARNING - Retrying (Retry(total=0, connect=None, read=None, redirect=None, status=None)) after connection broken by 'NewConnectionError('<urllib3.connection.HTTPConnection object at 0x7f560ddbbeb0>: Failed to establish a new connection: [Errno 111] Connection refused')': /session/a833db34a5f9e805150e1d501248a6a9/actions
[2025-03-26T01:13:43.411+0000] {logging_mixin.py:151} INFO - Lỗi khi lấy dữ liệu: HTTPConnectionPool(host='localhost', port=37583): Max retries exceeded with url: /session/a833db34a5f9e805150e1d501248a6a9/actions (Caused by NewConnectionError('<urllib3.connection.HTTPConnection object at 0x7f560dd173d0>: Failed to establish a new connection: [Errno 111] Connection refused'))
[2025-03-26T01:13:43.412+0000] {connectionpool.py:823} WARNING - Retrying (Retry(total=2, connect=None, read=None, redirect=None, status=None)) after connection broken by 'NewConnectionError('<urllib3.connection.HTTPConnection object at 0x7f560dd17820>: Failed to establish a new connection: [Errno 111] Connection refused')': /session/a833db34a5f9e805150e1d501248a6a9/actions
[2025-03-26T01:13:43.412+0000] {connectionpool.py:823} WARNING - Retrying (Retry(total=1, connect=None, read=None, redirect=None, status=None)) after connection broken by 'NewConnectionError('<urllib3.connection.HTTPConnection object at 0x7f560ddbb610>: Failed to establish a new connection: [Errno 111] Connection refused')': /session/a833db34a5f9e805150e1d501248a6a9/actions
[2025-03-26T01:13:43.413+0000] {connectionpool.py:823} WARNING - Retrying (Retry(total=0, connect=None, read=None, redirect=None, status=None)) after connection broken by 'NewConnectionError('<urllib3.connection.HTTPConnection object at 0x7f560ddbb4c0>: Failed to establish a new connection: [Errno 111] Connection refused')': /session/a833db34a5f9e805150e1d501248a6a9/actions
[2025-03-26T01:13:43.414+0000] {logging_mixin.py:151} INFO - Lỗi khi lấy dữ liệu: HTTPConnectionPool(host='localhost', port=37583): Max retries exceeded with url: /session/a833db34a5f9e805150e1d501248a6a9/actions (Caused by NewConnectionError('<urllib3.connection.HTTPConnection object at 0x7f560ddbbfa0>: Failed to establish a new connection: [Errno 111] Connection refused'))
[2025-03-26T01:13:43.415+0000] {connectionpool.py:823} WARNING - Retrying (Retry(total=2, connect=None, read=None, redirect=None, status=None)) after connection broken by 'NewConnectionError('<urllib3.connection.HTTPConnection object at 0x7f560ddbb340>: Failed to establish a new connection: [Errno 111] Connection refused')': /session/a833db34a5f9e805150e1d501248a6a9/actions
[2025-03-26T01:13:43.416+0000] {connectionpool.py:823} WARNING - Retrying (Retry(total=1, connect=None, read=None, redirect=None, status=None)) after connection broken by 'NewConnectionError('<urllib3.connection.HTTPConnection object at 0x7f560ddbb910>: Failed to establish a new connection: [Errno 111] Connection refused')': /session/a833db34a5f9e805150e1d501248a6a9/actions
[2025-03-26T01:13:43.418+0000] {connectionpool.py:823} WARNING - Retrying (Retry(total=0, connect=None, read=None, redirect=None, status=None)) after connection broken by 'NewConnectionError('<urllib3.connection.HTTPConnection object at 0x7f560ddbba00>: Failed to establish a new connection: [Errno 111] Connection refused')': /session/a833db34a5f9e805150e1d501248a6a9/actions
[2025-03-26T01:13:43.419+0000] {logging_mixin.py:151} INFO - Lỗi khi lấy dữ liệu: HTTPConnectionPool(host='localhost', port=37583): Max retries exceeded with url: /session/a833db34a5f9e805150e1d501248a6a9/actions (Caused by NewConnectionError('<urllib3.connection.HTTPConnection object at 0x7f560ddbb3a0>: Failed to establish a new connection: [Errno 111] Connection refused'))
[2025-03-26T01:13:43.421+0000] {connectionpool.py:823} WARNING - Retrying (Retry(total=2, connect=None, read=None, redirect=None, status=None)) after connection broken by 'NewConnectionError('<urllib3.connection.HTTPConnection object at 0x7f560dd551f0>: Failed to establish a new connection: [Errno 111] Connection refused')': /session/a833db34a5f9e805150e1d501248a6a9/actions
[2025-03-26T01:13:43.422+0000] {connectionpool.py:823} WARNING - Retrying (Retry(total=1, connect=None, read=None, redirect=None, status=None)) after connection broken by 'NewConnectionError('<urllib3.connection.HTTPConnection object at 0x7f560dd559a0>: Failed to establish a new connection: [Errno 111] Connection refused')': /session/a833db34a5f9e805150e1d501248a6a9/actions
[2025-03-26T01:13:43.423+0000] {connectionpool.py:823} WARNING - Retrying (Retry(total=0, connect=None, read=None, redirect=None, status=None)) after connection broken by 'NewConnectionError('<urllib3.connection.HTTPConnection object at 0x7f560dd55880>: Failed to establish a new connection: [Errno 111] Connection refused')': /session/a833db34a5f9e805150e1d501248a6a9/actions
[2025-03-26T01:13:43.424+0000] {logging_mixin.py:151} INFO - Lỗi khi lấy dữ liệu: HTTPConnectionPool(host='localhost', port=37583): Max retries exceeded with url: /session/a833db34a5f9e805150e1d501248a6a9/actions (Caused by NewConnectionError('<urllib3.connection.HTTPConnection object at 0x7f560dd55b80>: Failed to establish a new connection: [Errno 111] Connection refused'))
[2025-03-26T01:13:43.425+0000] {connectionpool.py:823} WARNING - Retrying (Retry(total=2, connect=None, read=None, redirect=None, status=None)) after connection broken by 'NewConnectionError('<urllib3.connection.HTTPConnection object at 0x7f560dd70ee0>: Failed to establish a new connection: [Errno 111] Connection refused')': /session/a833db34a5f9e805150e1d501248a6a9/actions
[2025-03-26T01:13:43.426+0000] {connectionpool.py:823} WARNING - Retrying (Retry(total=1, connect=None, read=None, redirect=None, status=None)) after connection broken by 'NewConnectionError('<urllib3.connection.HTTPConnection object at 0x7f560dd70e20>: Failed to establish a new connection: [Errno 111] Connection refused')': /session/a833db34a5f9e805150e1d501248a6a9/actions
[2025-03-26T01:13:43.427+0000] {connectionpool.py:823} WARNING - Retrying (Retry(total=0, connect=None, read=None, redirect=None, status=None)) after connection broken by 'NewConnectionError('<urllib3.connection.HTTPConnection object at 0x7f560dd70cd0>: Failed to establish a new connection: [Errno 111] Connection refused')': /session/a833db34a5f9e805150e1d501248a6a9/actions
[2025-03-26T01:13:43.429+0000] {logging_mixin.py:151} INFO - Lỗi khi lấy dữ liệu: HTTPConnectionPool(host='localhost', port=37583): Max retries exceeded with url: /session/a833db34a5f9e805150e1d501248a6a9/actions (Caused by NewConnectionError('<urllib3.connection.HTTPConnection object at 0x7f560dd177f0>: Failed to establish a new connection: [Errno 111] Connection refused'))
[2025-03-26T01:13:43.431+0000] {connectionpool.py:823} WARNING - Retrying (Retry(total=2, connect=None, read=None, redirect=None, status=None)) after connection broken by 'NewConnectionError('<urllib3.connection.HTTPConnection object at 0x7f560dd17220>: Failed to establish a new connection: [Errno 111] Connection refused')': /session/a833db34a5f9e805150e1d501248a6a9/actions
[2025-03-26T01:13:43.432+0000] {connectionpool.py:823} WARNING - Retrying (Retry(total=1, connect=None, read=None, redirect=None, status=None)) after connection broken by 'NewConnectionError('<urllib3.connection.HTTPConnection object at 0x7f560dd70a30>: Failed to establish a new connection: [Errno 111] Connection refused')': /session/a833db34a5f9e805150e1d501248a6a9/actions
[2025-03-26T01:13:43.434+0000] {connectionpool.py:823} WARNING - Retrying (Retry(total=0, connect=None, read=None, redirect=None, status=None)) after connection broken by 'NewConnectionError('<urllib3.connection.HTTPConnection object at 0x7f560dd70d30>: Failed to establish a new connection: [Errno 111] Connection refused')': /session/a833db34a5f9e805150e1d501248a6a9/actions
[2025-03-26T01:13:43.435+0000] {logging_mixin.py:151} INFO - Lỗi khi lấy dữ liệu: HTTPConnectionPool(host='localhost', port=37583): Max retries exceeded with url: /session/a833db34a5f9e805150e1d501248a6a9/actions (Caused by NewConnectionError('<urllib3.connection.HTTPConnection object at 0x7f560dd70e20>: Failed to establish a new connection: [Errno 111] Connection refused'))
[2025-03-26T01:13:43.436+0000] {connectionpool.py:823} WARNING - Retrying (Retry(total=2, connect=None, read=None, redirect=None, status=None)) after connection broken by 'NewConnectionError('<urllib3.connection.HTTPConnection object at 0x7f560dd55070>: Failed to establish a new connection: [Errno 111] Connection refused')': /session/a833db34a5f9e805150e1d501248a6a9/actions
[2025-03-26T01:13:43.437+0000] {connectionpool.py:823} WARNING - Retrying (Retry(total=1, connect=None, read=None, redirect=None, status=None)) after connection broken by 'NewConnectionError('<urllib3.connection.HTTPConnection object at 0x7f560dd55a90>: Failed to establish a new connection: [Errno 111] Connection refused')': /session/a833db34a5f9e805150e1d501248a6a9/actions
[2025-03-26T01:13:43.438+0000] {connectionpool.py:823} WARNING - Retrying (Retry(total=0, connect=None, read=None, redirect=None, status=None)) after connection broken by 'NewConnectionError('<urllib3.connection.HTTPConnection object at 0x7f560dd55880>: Failed to establish a new connection: [Errno 111] Connection refused')': /session/a833db34a5f9e805150e1d501248a6a9/actions
[2025-03-26T01:13:43.439+0000] {logging_mixin.py:151} INFO - Lỗi khi lấy dữ liệu: HTTPConnectionPool(host='localhost', port=37583): Max retries exceeded with url: /session/a833db34a5f9e805150e1d501248a6a9/actions (Caused by NewConnectionError('<urllib3.connection.HTTPConnection object at 0x7f560dd55ac0>: Failed to establish a new connection: [Errno 111] Connection refused'))
[2025-03-26T01:13:43.441+0000] {connectionpool.py:823} WARNING - Retrying (Retry(total=2, connect=None, read=None, redirect=None, status=None)) after connection broken by 'NewConnectionError('<urllib3.connection.HTTPConnection object at 0x7f560ddbb8e0>: Failed to establish a new connection: [Errno 111] Connection refused')': /session/a833db34a5f9e805150e1d501248a6a9/actions
[2025-03-26T01:13:43.442+0000] {connectionpool.py:823} WARNING - Retrying (Retry(total=1, connect=None, read=None, redirect=None, status=None)) after connection broken by 'NewConnectionError('<urllib3.connection.HTTPConnection object at 0x7f560ddbba60>: Failed to establish a new connection: [Errno 111] Connection refused')': /session/a833db34a5f9e805150e1d501248a6a9/actions
[2025-03-26T01:13:43.443+0000] {connectionpool.py:823} WARNING - Retrying (Retry(total=0, connect=None, read=None, redirect=None, status=None)) after connection broken by 'NewConnectionError('<urllib3.connection.HTTPConnection object at 0x7f560ddbb880>: Failed to establish a new connection: [Errno 111] Connection refused')': /session/a833db34a5f9e805150e1d501248a6a9/actions
[2025-03-26T01:13:43.444+0000] {logging_mixin.py:151} INFO - Lỗi khi lấy dữ liệu: HTTPConnectionPool(host='localhost', port=37583): Max retries exceeded with url: /session/a833db34a5f9e805150e1d501248a6a9/actions (Caused by NewConnectionError('<urllib3.connection.HTTPConnection object at 0x7f560ddbb9a0>: Failed to establish a new connection: [Errno 111] Connection refused'))
[2025-03-26T01:13:43.446+0000] {connectionpool.py:823} WARNING - Retrying (Retry(total=2, connect=None, read=None, redirect=None, status=None)) after connection broken by 'NewConnectionError('<urllib3.connection.HTTPConnection object at 0x7f560ddbbc40>: Failed to establish a new connection: [Errno 111] Connection refused')': /session/a833db34a5f9e805150e1d501248a6a9/actions
[2025-03-26T01:13:43.447+0000] {connectionpool.py:823} WARNING - Retrying (Retry(total=1, connect=None, read=None, redirect=None, status=None)) after connection broken by 'NewConnectionError('<urllib3.connection.HTTPConnection object at 0x7f560ddbbfd0>: Failed to establish a new connection: [Errno 111] Connection refused')': /session/a833db34a5f9e805150e1d501248a6a9/actions
[2025-03-26T01:13:43.447+0000] {connectionpool.py:823} WARNING - Retrying (Retry(total=0, connect=None, read=None, redirect=None, status=None)) after connection broken by 'NewConnectionError('<urllib3.connection.HTTPConnection object at 0x7f560ddbb4c0>: Failed to establish a new connection: [Errno 111] Connection refused')': /session/a833db34a5f9e805150e1d501248a6a9/actions
[2025-03-26T01:13:43.448+0000] {logging_mixin.py:151} INFO - Lỗi khi lấy dữ liệu: HTTPConnectionPool(host='localhost', port=37583): Max retries exceeded with url: /session/a833db34a5f9e805150e1d501248a6a9/actions (Caused by NewConnectionError('<urllib3.connection.HTTPConnection object at 0x7f560ddbbf10>: Failed to establish a new connection: [Errno 111] Connection refused'))
[2025-03-26T01:13:43.449+0000] {connectionpool.py:823} WARNING - Retrying (Retry(total=2, connect=None, read=None, redirect=None, status=None)) after connection broken by 'NewConnectionError('<urllib3.connection.HTTPConnection object at 0x7f560dd17850>: Failed to establish a new connection: [Errno 111] Connection refused')': /session/a833db34a5f9e805150e1d501248a6a9/actions
[2025-03-26T01:13:43.451+0000] {connectionpool.py:823} WARNING - Retrying (Retry(total=1, connect=None, read=None, redirect=None, status=None)) after connection broken by 'NewConnectionError('<urllib3.connection.HTTPConnection object at 0x7f560ddbbcd0>: Failed to establish a new connection: [Errno 111] Connection refused')': /session/a833db34a5f9e805150e1d501248a6a9/actions
[2025-03-26T01:13:43.452+0000] {connectionpool.py:823} WARNING - Retrying (Retry(total=0, connect=None, read=None, redirect=None, status=None)) after connection broken by 'NewConnectionError('<urllib3.connection.HTTPConnection object at 0x7f560ddbbb50>: Failed to establish a new connection: [Errno 111] Connection refused')': /session/a833db34a5f9e805150e1d501248a6a9/actions
[2025-03-26T01:13:43.453+0000] {logging_mixin.py:151} INFO - Lỗi khi lấy dữ liệu: HTTPConnectionPool(host='localhost', port=37583): Max retries exceeded with url: /session/a833db34a5f9e805150e1d501248a6a9/actions (Caused by NewConnectionError('<urllib3.connection.HTTPConnection object at 0x7f560ddbbca0>: Failed to establish a new connection: [Errno 111] Connection refused'))
[2025-03-26T01:13:43.454+0000] {connectionpool.py:823} WARNING - Retrying (Retry(total=2, connect=None, read=None, redirect=None, status=None)) after connection broken by 'NewConnectionError('<urllib3.connection.HTTPConnection object at 0x7f560ddbb670>: Failed to establish a new connection: [Errno 111] Connection refused')': /session/a833db34a5f9e805150e1d501248a6a9/actions
[2025-03-26T01:13:43.455+0000] {connectionpool.py:823} WARNING - Retrying (Retry(total=1, connect=None, read=None, redirect=None, status=None)) after connection broken by 'NewConnectionError('<urllib3.connection.HTTPConnection object at 0x7f560ddbb400>: Failed to establish a new connection: [Errno 111] Connection refused')': /session/a833db34a5f9e805150e1d501248a6a9/actions
[2025-03-26T01:13:43.456+0000] {connectionpool.py:823} WARNING - Retrying (Retry(total=0, connect=None, read=None, redirect=None, status=None)) after connection broken by 'NewConnectionError('<urllib3.connection.HTTPConnection object at 0x7f560ddbb550>: Failed to establish a new connection: [Errno 111] Connection refused')': /session/a833db34a5f9e805150e1d501248a6a9/actions
[2025-03-26T01:13:43.457+0000] {logging_mixin.py:151} INFO - Lỗi khi lấy dữ liệu: HTTPConnectionPool(host='localhost', port=37583): Max retries exceeded with url: /session/a833db34a5f9e805150e1d501248a6a9/actions (Caused by NewConnectionError('<urllib3.connection.HTTPConnection object at 0x7f560ddbb5e0>: Failed to establish a new connection: [Errno 111] Connection refused'))
[2025-03-26T01:13:43.457+0000] {process_utils.py:79} INFO - Process psutil.Process(pid=146, status='terminated', started='01:11:16') (146) terminated with exit code None
[2025-03-26T01:13:43.458+0000] {connectionpool.py:823} WARNING - Retrying (Retry(total=2, connect=None, read=None, redirect=None, status=None)) after connection broken by 'NewConnectionError('<urllib3.connection.HTTPConnection object at 0x7f560dd559d0>: Failed to establish a new connection: [Errno 111] Connection refused')': /session/a833db34a5f9e805150e1d501248a6a9/actions
[2025-03-26T01:13:43.459+0000] {connectionpool.py:823} WARNING - Retrying (Retry(total=1, connect=None, read=None, redirect=None, status=None)) after connection broken by 'NewConnectionError('<urllib3.connection.HTTPConnection object at 0x7f560dd55ca0>: Failed to establish a new connection: [Errno 111] Connection refused')': /session/a833db34a5f9e805150e1d501248a6a9/actions
[2025-03-26T01:13:43.459+0000] {connectionpool.py:823} WARNING - Retrying (Retry(total=0, connect=None, read=None, redirect=None, status=None)) after connection broken by 'NewConnectionError('<urllib3.connection.HTTPConnection object at 0x7f560dd559a0>: Failed to establish a new connection: [Errno 111] Connection refused')': /session/a833db34a5f9e805150e1d501248a6a9/actions
[2025-03-26T01:13:43.460+0000] {logging_mixin.py:151} INFO - Lỗi khi lấy dữ liệu: HTTPConnectionPool(host='localhost', port=37583): Max retries exceeded with url: /session/a833db34a5f9e805150e1d501248a6a9/actions (Caused by NewConnectionError('<urllib3.connection.HTTPConnection object at 0x7f560dd55d30>: Failed to establish a new connection: [Errno 111] Connection refused'))
[2025-03-26T01:13:43.462+0000] {connectionpool.py:823} WARNING - Retrying (Retry(total=2, connect=None, read=None, redirect=None, status=None)) after connection broken by 'NewConnectionError('<urllib3.connection.HTTPConnection object at 0x7f560dd70940>: Failed to establish a new connection: [Errno 111] Connection refused')': /session/a833db34a5f9e805150e1d501248a6a9/actions
[2025-03-26T01:13:43.463+0000] {connectionpool.py:823} WARNING - Retrying (Retry(total=1, connect=None, read=None, redirect=None, status=None)) after connection broken by 'NewConnectionError('<urllib3.connection.HTTPConnection object at 0x7f560dd70d60>: Failed to establish a new connection: [Errno 111] Connection refused')': /session/a833db34a5f9e805150e1d501248a6a9/actions
[2025-03-26T01:13:43.464+0000] {connectionpool.py:823} WARNING - Retrying (Retry(total=0, connect=None, read=None, redirect=None, status=None)) after connection broken by 'NewConnectionError('<urllib3.connection.HTTPConnection object at 0x7f560dd70d30>: Failed to establish a new connection: [Errno 111] Connection refused')': /session/a833db34a5f9e805150e1d501248a6a9/actions
[2025-03-26T01:13:43.465+0000] {logging_mixin.py:151} INFO - Lỗi khi lấy dữ liệu: HTTPConnectionPool(host='localhost', port=37583): Max retries exceeded with url: /session/a833db34a5f9e805150e1d501248a6a9/actions (Caused by NewConnectionError('<urllib3.connection.HTTPConnection object at 0x7f560dd177c0>: Failed to establish a new connection: [Errno 111] Connection refused'))
[2025-03-26T01:13:43.465+0000] {connectionpool.py:823} WARNING - Retrying (Retry(total=2, connect=None, read=None, redirect=None, status=None)) after connection broken by 'NewConnectionError('<urllib3.connection.HTTPConnection object at 0x7f560dd17ca0>: Failed to establish a new connection: [Errno 111] Connection refused')': /session/a833db34a5f9e805150e1d501248a6a9/actions
[2025-03-26T01:13:43.467+0000] {connectionpool.py:823} WARNING - Retrying (Retry(total=1, connect=None, read=None, redirect=None, status=None)) after connection broken by 'NewConnectionError('<urllib3.connection.HTTPConnection object at 0x7f560dd70ac0>: Failed to establish a new connection: [Errno 111] Connection refused')': /session/a833db34a5f9e805150e1d501248a6a9/actions
[2025-03-26T01:13:43.468+0000] {connectionpool.py:823} WARNING - Retrying (Retry(total=0, connect=None, read=None, redirect=None, status=None)) after connection broken by 'NewConnectionError('<urllib3.connection.HTTPConnection object at 0x7f560dd70a30>: Failed to establish a new connection: [Errno 111] Connection refused')': /session/a833db34a5f9e805150e1d501248a6a9/actions
[2025-03-26T01:13:43.470+0000] {logging_mixin.py:151} INFO - Lỗi khi lấy dữ liệu: HTTPConnectionPool(host='localhost', port=37583): Max retries exceeded with url: /session/a833db34a5f9e805150e1d501248a6a9/actions (Caused by NewConnectionError('<urllib3.connection.HTTPConnection object at 0x7f560dd70a60>: Failed to establish a new connection: [Errno 111] Connection refused'))
[2025-03-26T01:13:43.471+0000] {connectionpool.py:823} WARNING - Retrying (Retry(total=2, connect=None, read=None, redirect=None, status=None)) after connection broken by 'NewConnectionError('<urllib3.connection.HTTPConnection object at 0x7f560ddbb310>: Failed to establish a new connection: [Errno 111] Connection refused')': /session/a833db34a5f9e805150e1d501248a6a9/actions
[2025-03-26T01:13:43.472+0000] {connectionpool.py:823} WARNING - Retrying (Retry(total=1, connect=None, read=None, redirect=None, status=None)) after connection broken by 'NewConnectionError('<urllib3.connection.HTTPConnection object at 0x7f560ddbbe50>: Failed to establish a new connection: [Errno 111] Connection refused')': /session/a833db34a5f9e805150e1d501248a6a9/actions
[2025-03-26T01:13:43.473+0000] {connectionpool.py:823} WARNING - Retrying (Retry(total=0, connect=None, read=None, redirect=None, status=None)) after connection broken by 'NewConnectionError('<urllib3.connection.HTTPConnection object at 0x7f560ddbb3a0>: Failed to establish a new connection: [Errno 111] Connection refused')': /session/a833db34a5f9e805150e1d501248a6a9/actions
[2025-03-26T01:13:43.473+0000] {logging_mixin.py:151} INFO - Lỗi khi lấy dữ liệu: HTTPConnectionPool(host='localhost', port=37583): Max retries exceeded with url: /session/a833db34a5f9e805150e1d501248a6a9/actions (Caused by NewConnectionError('<urllib3.connection.HTTPConnection object at 0x7f560ddbb550>: Failed to establish a new connection: [Errno 111] Connection refused'))
[2025-03-26T01:13:43.474+0000] {connectionpool.py:823} WARNING - Retrying (Retry(total=2, connect=None, read=None, redirect=None, status=None)) after connection broken by 'NewConnectionError('<urllib3.connection.HTTPConnection object at 0x7f560ddbb580>: Failed to establish a new connection: [Errno 111] Connection refused')': /session/a833db34a5f9e805150e1d501248a6a9/actions
[2025-03-26T01:13:43.475+0000] {connectionpool.py:823} WARNING - Retrying (Retry(total=1, connect=None, read=None, redirect=None, status=None)) after connection broken by 'NewConnectionError('<urllib3.connection.HTTPConnection object at 0x7f560ddbbc10>: Failed to establish a new connection: [Errno 111] Connection refused')': /session/a833db34a5f9e805150e1d501248a6a9/actions
[2025-03-26T01:13:43.476+0000] {connectionpool.py:823} WARNING - Retrying (Retry(total=0, connect=None, read=None, redirect=None, status=None)) after connection broken by 'NewConnectionError('<urllib3.connection.HTTPConnection object at 0x7f560ddbbfd0>: Failed to establish a new connection: [Errno 111] Connection refused')': /session/a833db34a5f9e805150e1d501248a6a9/actions
[2025-03-26T01:13:43.476+0000] {logging_mixin.py:151} INFO - Lỗi khi lấy dữ liệu: HTTPConnectionPool(host='localhost', port=37583): Max retries exceeded with url: /session/a833db34a5f9e805150e1d501248a6a9/actions (Caused by NewConnectionError('<urllib3.connection.HTTPConnection object at 0x7f560ddbbeb0>: Failed to establish a new connection: [Errno 111] Connection refused'))
[2025-03-26T01:13:43.477+0000] {connectionpool.py:823} WARNING - Retrying (Retry(total=2, connect=None, read=None, redirect=None, status=None)) after connection broken by 'NewConnectionError('<urllib3.connection.HTTPConnection object at 0x7f560dd55af0>: Failed to establish a new connection: [Errno 111] Connection refused')': /session/a833db34a5f9e805150e1d501248a6a9/actions
[2025-03-26T01:13:43.478+0000] {connectionpool.py:823} WARNING - Retrying (Retry(total=1, connect=None, read=None, redirect=None, status=None)) after connection broken by 'NewConnectionError('<urllib3.connection.HTTPConnection object at 0x7f560dd55ac0>: Failed to establish a new connection: [Errno 111] Connection refused')': /session/a833db34a5f9e805150e1d501248a6a9/actions
[2025-03-26T01:13:43.479+0000] {connectionpool.py:823} WARNING - Retrying (Retry(total=0, connect=None, read=None, redirect=None, status=None)) after connection broken by 'NewConnectionError('<urllib3.connection.HTTPConnection object at 0x7f560dd55850>: Failed to establish a new connection: [Errno 111] Connection refused')': /session/a833db34a5f9e805150e1d501248a6a9/actions
[2025-03-26T01:13:43.479+0000] {logging_mixin.py:151} INFO - Lỗi khi lấy dữ liệu: HTTPConnectionPool(host='localhost', port=37583): Max retries exceeded with url: /session/a833db34a5f9e805150e1d501248a6a9/actions (Caused by NewConnectionError('<urllib3.connection.HTTPConnection object at 0x7f560dd550a0>: Failed to establish a new connection: [Errno 111] Connection refused'))
[2025-03-26T01:13:43.480+0000] {connectionpool.py:823} WARNING - Retrying (Retry(total=2, connect=None, read=None, redirect=None, status=None)) after connection broken by 'NewConnectionError('<urllib3.connection.HTTPConnection object at 0x7f560dd55430>: Failed to establish a new connection: [Errno 111] Connection refused')': /session/a833db34a5f9e805150e1d501248a6a9/actions
[2025-03-26T01:13:43.481+0000] {connectionpool.py:823} WARNING - Retrying (Retry(total=1, connect=None, read=None, redirect=None, status=None)) after connection broken by 'NewConnectionError('<urllib3.connection.HTTPConnection object at 0x7f560dd553d0>: Failed to establish a new connection: [Errno 111] Connection refused')': /session/a833db34a5f9e805150e1d501248a6a9/actions
[2025-03-26T01:13:43.482+0000] {connectionpool.py:823} WARNING - Retrying (Retry(total=0, connect=None, read=None, redirect=None, status=None)) after connection broken by 'NewConnectionError('<urllib3.connection.HTTPConnection object at 0x7f560dd559a0>: Failed to establish a new connection: [Errno 111] Connection refused')': /session/a833db34a5f9e805150e1d501248a6a9/actions
[2025-03-26T01:13:43.483+0000] {logging_mixin.py:151} INFO - Lỗi khi lấy dữ liệu: HTTPConnectionPool(host='localhost', port=37583): Max retries exceeded with url: /session/a833db34a5f9e805150e1d501248a6a9/actions (Caused by NewConnectionError('<urllib3.connection.HTTPConnection object at 0x7f560dd55940>: Failed to establish a new connection: [Errno 111] Connection refused'))
[2025-03-26T01:13:43.484+0000] {connectionpool.py:823} WARNING - Retrying (Retry(total=2, connect=None, read=None, redirect=None, status=None)) after connection broken by 'NewConnectionError('<urllib3.connection.HTTPConnection object at 0x7f560dd552b0>: Failed to establish a new connection: [Errno 111] Connection refused')': /session/a833db34a5f9e805150e1d501248a6a9/actions
[2025-03-26T01:13:43.485+0000] {connectionpool.py:823} WARNING - Retrying (Retry(total=1, connect=None, read=None, redirect=None, status=None)) after connection broken by 'NewConnectionError('<urllib3.connection.HTTPConnection object at 0x7f560dd55a60>: Failed to establish a new connection: [Errno 111] Connection refused')': /session/a833db34a5f9e805150e1d501248a6a9/actions
[2025-03-26T01:13:43.486+0000] {connectionpool.py:823} WARNING - Retrying (Retry(total=0, connect=None, read=None, redirect=None, status=None)) after connection broken by 'NewConnectionError('<urllib3.connection.HTTPConnection object at 0x7f560ddbb730>: Failed to establish a new connection: [Errno 111] Connection refused')': /session/a833db34a5f9e805150e1d501248a6a9/actions
[2025-03-26T01:13:43.487+0000] {logging_mixin.py:151} INFO - Lỗi khi lấy dữ liệu: HTTPConnectionPool(host='localhost', port=37583): Max retries exceeded with url: /session/a833db34a5f9e805150e1d501248a6a9/actions (Caused by NewConnectionError('<urllib3.connection.HTTPConnection object at 0x7f560ddbbcd0>: Failed to establish a new connection: [Errno 111] Connection refused'))
[2025-03-26T01:13:43.489+0000] {connectionpool.py:823} WARNING - Retrying (Retry(total=2, connect=None, read=None, redirect=None, status=None)) after connection broken by 'NewConnectionError('<urllib3.connection.HTTPConnection object at 0x7f560ddbb640>: Failed to establish a new connection: [Errno 111] Connection refused')': /session/a833db34a5f9e805150e1d501248a6a9/actions
[2025-03-26T01:13:43.489+0000] {connectionpool.py:823} WARNING - Retrying (Retry(total=1, connect=None, read=None, redirect=None, status=None)) after connection broken by 'NewConnectionError('<urllib3.connection.HTTPConnection object at 0x7f560ddbb460>: Failed to establish a new connection: [Errno 111] Connection refused')': /session/a833db34a5f9e805150e1d501248a6a9/actions
[2025-03-26T01:13:43.490+0000] {connectionpool.py:823} WARNING - Retrying (Retry(total=0, connect=None, read=None, redirect=None, status=None)) after connection broken by 'NewConnectionError('<urllib3.connection.HTTPConnection object at 0x7f560ddbb400>: Failed to establish a new connection: [Errno 111] Connection refused')': /session/a833db34a5f9e805150e1d501248a6a9/actions
[2025-03-26T01:13:43.491+0000] {logging_mixin.py:151} INFO - Lỗi khi lấy dữ liệu: HTTPConnectionPool(host='localhost', port=37583): Max retries exceeded with url: /session/a833db34a5f9e805150e1d501248a6a9/actions (Caused by NewConnectionError('<urllib3.connection.HTTPConnection object at 0x7f560ddbb6a0>: Failed to establish a new connection: [Errno 111] Connection refused'))
[2025-03-26T01:13:43.491+0000] {connectionpool.py:823} WARNING - Retrying (Retry(total=2, connect=None, read=None, redirect=None, status=None)) after connection broken by 'NewConnectionError('<urllib3.connection.HTTPConnection object at 0x7f560dd70af0>: Failed to establish a new connection: [Errno 111] Connection refused')': /session/a833db34a5f9e805150e1d501248a6a9/actions
[2025-03-26T01:13:43.492+0000] {connectionpool.py:823} WARNING - Retrying (Retry(total=1, connect=None, read=None, redirect=None, status=None)) after connection broken by 'NewConnectionError('<urllib3.connection.HTTPConnection object at 0x7f560dd70be0>: Failed to establish a new connection: [Errno 111] Connection refused')': /session/a833db34a5f9e805150e1d501248a6a9/actions
[2025-03-26T01:13:43.493+0000] {connectionpool.py:823} WARNING - Retrying (Retry(total=0, connect=None, read=None, redirect=None, status=None)) after connection broken by 'NewConnectionError('<urllib3.connection.HTTPConnection object at 0x7f560dd70cd0>: Failed to establish a new connection: [Errno 111] Connection refused')': /session/a833db34a5f9e805150e1d501248a6a9/actions
[2025-03-26T01:13:43.493+0000] {logging_mixin.py:151} INFO - Lỗi khi lấy dữ liệu: HTTPConnectionPool(host='localhost', port=37583): Max retries exceeded with url: /session/a833db34a5f9e805150e1d501248a6a9/actions (Caused by NewConnectionError('<urllib3.connection.HTTPConnection object at 0x7f560dd70d00>: Failed to establish a new connection: [Errno 111] Connection refused'))
[2025-03-26T01:13:43.494+0000] {connectionpool.py:823} WARNING - Retrying (Retry(total=2, connect=None, read=None, redirect=None, status=None)) after connection broken by 'NewConnectionError('<urllib3.connection.HTTPConnection object at 0x7f560dd178b0>: Failed to establish a new connection: [Errno 111] Connection refused')': /session/a833db34a5f9e805150e1d501248a6a9/actions
[2025-03-26T01:13:43.495+0000] {connectionpool.py:823} WARNING - Retrying (Retry(total=1, connect=None, read=None, redirect=None, status=None)) after connection broken by 'NewConnectionError('<urllib3.connection.HTTPConnection object at 0x7f560dd17580>: Failed to establish a new connection: [Errno 111] Connection refused')': /session/a833db34a5f9e805150e1d501248a6a9/actions
[2025-03-26T01:13:43.496+0000] {connectionpool.py:823} WARNING - Retrying (Retry(total=0, connect=None, read=None, redirect=None, status=None)) after connection broken by 'NewConnectionError('<urllib3.connection.HTTPConnection object at 0x7f560dd70ca0>: Failed to establish a new connection: [Errno 111] Connection refused')': /session/a833db34a5f9e805150e1d501248a6a9/actions
[2025-03-26T01:13:43.496+0000] {logging_mixin.py:151} INFO - Lỗi khi lấy dữ liệu: HTTPConnectionPool(host='localhost', port=37583): Max retries exceeded with url: /session/a833db34a5f9e805150e1d501248a6a9/actions (Caused by NewConnectionError('<urllib3.connection.HTTPConnection object at 0x7f560dd70d00>: Failed to establish a new connection: [Errno 111] Connection refused'))
[2025-03-26T01:13:43.497+0000] {connectionpool.py:823} WARNING - Retrying (Retry(total=2, connect=None, read=None, redirect=None, status=None)) after connection broken by 'NewConnectionError('<urllib3.connection.HTTPConnection object at 0x7f560ddbb880>: Failed to establish a new connection: [Errno 111] Connection refused')': /session/a833db34a5f9e805150e1d501248a6a9/actions
[2025-03-26T01:13:43.498+0000] {connectionpool.py:823} WARNING - Retrying (Retry(total=1, connect=None, read=None, redirect=None, status=None)) after connection broken by 'NewConnectionError('<urllib3.connection.HTTPConnection object at 0x7f560ddbbd60>: Failed to establish a new connection: [Errno 111] Connection refused')': /session/a833db34a5f9e805150e1d501248a6a9/actions
[2025-03-26T01:13:43.499+0000] {connectionpool.py:823} WARNING - Retrying (Retry(total=0, connect=None, read=None, redirect=None, status=None)) after connection broken by 'NewConnectionError('<urllib3.connection.HTTPConnection object at 0x7f560ddbbca0>: Failed to establish a new connection: [Errno 111] Connection refused')': /session/a833db34a5f9e805150e1d501248a6a9/actions
[2025-03-26T01:13:43.499+0000] {logging_mixin.py:151} INFO - Lỗi khi lấy dữ liệu: HTTPConnectionPool(host='localhost', port=37583): Max retries exceeded with url: /session/a833db34a5f9e805150e1d501248a6a9/actions (Caused by NewConnectionError('<urllib3.connection.HTTPConnection object at 0x7f560ddbb3a0>: Failed to establish a new connection: [Errno 111] Connection refused'))
[2025-03-26T01:13:43.501+0000] {connectionpool.py:823} WARNING - Retrying (Retry(total=2, connect=None, read=None, redirect=None, status=None)) after connection broken by 'NewConnectionError('<urllib3.connection.HTTPConnection object at 0x7f560ddbb790>: Failed to establish a new connection: [Errno 111] Connection refused')': /session/a833db34a5f9e805150e1d501248a6a9/actions
[2025-03-26T01:13:43.502+0000] {connectionpool.py:823} WARNING - Retrying (Retry(total=1, connect=None, read=None, redirect=None, status=None)) after connection broken by 'NewConnectionError('<urllib3.connection.HTTPConnection object at 0x7f560ddbbfd0>: Failed to establish a new connection: [Errno 111] Connection refused')': /session/a833db34a5f9e805150e1d501248a6a9/actions
[2025-03-26T01:13:43.503+0000] {connectionpool.py:823} WARNING - Retrying (Retry(total=0, connect=None, read=None, redirect=None, status=None)) after connection broken by 'NewConnectionError('<urllib3.connection.HTTPConnection object at 0x7f560ddbbfa0>: Failed to establish a new connection: [Errno 111] Connection refused')': /session/a833db34a5f9e805150e1d501248a6a9/actions
[2025-03-26T01:13:43.504+0000] {logging_mixin.py:151} INFO - Lỗi khi lấy dữ liệu: HTTPConnectionPool(host='localhost', port=37583): Max retries exceeded with url: /session/a833db34a5f9e805150e1d501248a6a9/actions (Caused by NewConnectionError('<urllib3.connection.HTTPConnection object at 0x7f560ddbb730>: Failed to establish a new connection: [Errno 111] Connection refused'))
[2025-03-26T01:13:43.506+0000] {connectionpool.py:823} WARNING - Retrying (Retry(total=2, connect=None, read=None, redirect=None, status=None)) after connection broken by 'NewConnectionError('<urllib3.connection.HTTPConnection object at 0x7f560dd55100>: Failed to establish a new connection: [Errno 111] Connection refused')': /session/a833db34a5f9e805150e1d501248a6a9/actions
[2025-03-26T01:13:43.554+0000] {process_utils.py:79} INFO - Process psutil.Process(pid=318, status='terminated', started='01:13:12') (318) terminated with exit code None
[2025-03-26T01:13:43.572+0000] {process_utils.py:79} INFO - Process psutil.Process(pid=352, status='terminated', started='01:13:12') (352) terminated with exit code None
[2025-03-26T01:13:43.573+0000] {connectionpool.py:823} WARNING - Retrying (Retry(total=1, connect=None, read=None, redirect=None, status=None)) after connection broken by 'NewConnectionError('<urllib3.connection.HTTPConnection object at 0x7f560dd55ac0>: Failed to establish a new connection: [Errno 111] Connection refused')': /session/a833db34a5f9e805150e1d501248a6a9/actions
[2025-03-26T01:13:43.574+0000] {connectionpool.py:823} WARNING - Retrying (Retry(total=0, connect=None, read=None, redirect=None, status=None)) after connection broken by 'NewConnectionError('<urllib3.connection.HTTPConnection object at 0x7f560dd55190>: Failed to establish a new connection: [Errno 111] Connection refused')': /session/a833db34a5f9e805150e1d501248a6a9/actions
[2025-03-26T01:13:43.575+0000] {logging_mixin.py:151} INFO - Lỗi khi lấy dữ liệu: HTTPConnectionPool(host='localhost', port=37583): Max retries exceeded with url: /session/a833db34a5f9e805150e1d501248a6a9/actions (Caused by NewConnectionError('<urllib3.connection.HTTPConnection object at 0x7f560dd559a0>: Failed to establish a new connection: [Errno 111] Connection refused'))
[2025-03-26T01:13:43.774+0000] {connectionpool.py:823} WARNING - Retrying (Retry(total=2, connect=None, read=None, redirect=None, status=None)) after connection broken by 'NewConnectionError('<urllib3.connection.HTTPConnection object at 0x7f560dd17130>: Failed to establish a new connection: [Errno 111] Connection refused')': /session/a833db34a5f9e805150e1d501248a6a9/actions
[2025-03-26T01:13:43.793+0000] {connectionpool.py:823} WARNING - Retrying (Retry(total=1, connect=None, read=None, redirect=None, status=None)) after connection broken by 'NewConnectionError('<urllib3.connection.HTTPConnection object at 0x7f560dd17040>: Failed to establish a new connection: [Errno 111] Connection refused')': /session/a833db34a5f9e805150e1d501248a6a9/actions
[2025-03-26T01:13:43.796+0000] {connectionpool.py:823} WARNING - Retrying (Retry(total=0, connect=None, read=None, redirect=None, status=None)) after connection broken by 'NewConnectionError('<urllib3.connection.HTTPConnection object at 0x7f560dd55c40>: Failed to establish a new connection: [Errno 111] Connection refused')': /session/a833db34a5f9e805150e1d501248a6a9/actions
[2025-03-26T01:13:43.782+0000] {process_utils.py:79} INFO - Process psutil.Process(pid=220, status='terminated', started='01:11:19') (220) terminated with exit code None
[2025-03-26T01:13:43.797+0000] {process_utils.py:79} INFO - Process psutil.Process(pid=335, status='terminated', started='01:13:12') (335) terminated with exit code None
[2025-03-26T01:13:43.797+0000] {logging_mixin.py:151} INFO - Lỗi khi lấy dữ liệu: HTTPConnectionPool(host='localhost', port=37583): Max retries exceeded with url: /session/a833db34a5f9e805150e1d501248a6a9/actions (Caused by NewConnectionError('<urllib3.connection.HTTPConnection object at 0x7f560dd550a0>: Failed to establish a new connection: [Errno 111] Connection refused'))
[2025-03-26T01:13:43.798+0000] {process_utils.py:79} INFO - Process psutil.Process(pid=211, status='terminated', started='01:11:19') (211) terminated with exit code None
[2025-03-26T01:13:43.799+0000] {process_utils.py:79} INFO - Process psutil.Process(pid=344, status='terminated', started='01:13:12') (344) terminated with exit code None
[2025-03-26T01:13:43.799+0000] {connectionpool.py:823} WARNING - Retrying (Retry(total=2, connect=None, read=None, redirect=None, status=None)) after connection broken by 'NewConnectionError('<urllib3.connection.HTTPConnection object at 0x7f560dd552b0>: Failed to establish a new connection: [Errno 111] Connection refused')': /session/a833db34a5f9e805150e1d501248a6a9/actions
[2025-03-26T01:13:43.800+0000] {process_utils.py:79} INFO - Process psutil.Process(pid=121, status='terminated', started='01:11:15') (121) terminated with exit code None
[2025-03-26T01:13:43.801+0000] {connectionpool.py:823} WARNING - Retrying (Retry(total=1, connect=None, read=None, redirect=None, status=None)) after connection broken by 'NewConnectionError('<urllib3.connection.HTTPConnection object at 0x7f560ddbbee0>: Failed to establish a new connection: [Errno 111] Connection refused')': /session/a833db34a5f9e805150e1d501248a6a9/actions
[2025-03-26T01:13:43.803+0000] {connectionpool.py:823} WARNING - Retrying (Retry(total=0, connect=None, read=None, redirect=None, status=None)) after connection broken by 'NewConnectionError('<urllib3.connection.HTTPConnection object at 0x7f560ddbbc10>: Failed to establish a new connection: [Errno 111] Connection refused')': /session/a833db34a5f9e805150e1d501248a6a9/actions
[2025-03-26T01:13:43.804+0000] {logging_mixin.py:151} INFO - Lỗi khi lấy dữ liệu: HTTPConnectionPool(host='localhost', port=37583): Max retries exceeded with url: /session/a833db34a5f9e805150e1d501248a6a9/actions (Caused by NewConnectionError('<urllib3.connection.HTTPConnection object at 0x7f560ddbb730>: Failed to establish a new connection: [Errno 111] Connection refused'))
[2025-03-26T01:13:43.805+0000] {connectionpool.py:823} WARNING - Retrying (Retry(total=2, connect=None, read=None, redirect=None, status=None)) after connection broken by 'NewConnectionError('<urllib3.connection.HTTPConnection object at 0x7f560ddbbf40>: Failed to establish a new connection: [Errno 111] Connection refused')': /session/a833db34a5f9e805150e1d501248a6a9/actions
[2025-03-26T01:13:43.806+0000] {connectionpool.py:823} WARNING - Retrying (Retry(total=1, connect=None, read=None, redirect=None, status=None)) after connection broken by 'NewConnectionError('<urllib3.connection.HTTPConnection object at 0x7f560ddbb640>: Failed to establish a new connection: [Errno 111] Connection refused')': /session/a833db34a5f9e805150e1d501248a6a9/actions
[2025-03-26T01:13:43.807+0000] {connectionpool.py:823} WARNING - Retrying (Retry(total=0, connect=None, read=None, redirect=None, status=None)) after connection broken by 'NewConnectionError('<urllib3.connection.HTTPConnection object at 0x7f560ddbb7f0>: Failed to establish a new connection: [Errno 111] Connection refused')': /session/a833db34a5f9e805150e1d501248a6a9/actions
[2025-03-26T01:13:43.807+0000] {logging_mixin.py:151} INFO - Lỗi khi lấy dữ liệu: HTTPConnectionPool(host='localhost', port=37583): Max retries exceeded with url: /session/a833db34a5f9e805150e1d501248a6a9/actions (Caused by NewConnectionError('<urllib3.connection.HTTPConnection object at 0x7f560ddbbca0>: Failed to establish a new connection: [Errno 111] Connection refused'))
[2025-03-26T01:13:43.808+0000] {connectionpool.py:823} WARNING - Retrying (Retry(total=2, connect=None, read=None, redirect=None, status=None)) after connection broken by 'NewConnectionError('<urllib3.connection.HTTPConnection object at 0x7f560dd70df0>: Failed to establish a new connection: [Errno 111] Connection refused')': /session/a833db34a5f9e805150e1d501248a6a9/actions
[2025-03-26T01:13:43.809+0000] {connectionpool.py:823} WARNING - Retrying (Retry(total=1, connect=None, read=None, redirect=None, status=None)) after connection broken by 'NewConnectionError('<urllib3.connection.HTTPConnection object at 0x7f560dd70b20>: Failed to establish a new connection: [Errno 111] Connection refused')': /session/a833db34a5f9e805150e1d501248a6a9/actions
[2025-03-26T01:13:43.810+0000] {connectionpool.py:823} WARNING - Retrying (Retry(total=0, connect=None, read=None, redirect=None, status=None)) after connection broken by 'NewConnectionError('<urllib3.connection.HTTPConnection object at 0x7f560dd70c10>: Failed to establish a new connection: [Errno 111] Connection refused')': /session/a833db34a5f9e805150e1d501248a6a9/actions
[2025-03-26T01:13:43.810+0000] {logging_mixin.py:151} INFO - Lỗi khi lấy dữ liệu: HTTPConnectionPool(host='localhost', port=37583): Max retries exceeded with url: /session/a833db34a5f9e805150e1d501248a6a9/actions (Caused by NewConnectionError('<urllib3.connection.HTTPConnection object at 0x7f560dd17100>: Failed to establish a new connection: [Errno 111] Connection refused'))
[2025-03-26T01:13:43.811+0000] {connectionpool.py:823} WARNING - Retrying (Retry(total=2, connect=None, read=None, redirect=None, status=None)) after connection broken by 'NewConnectionError('<urllib3.connection.HTTPConnection object at 0x7f560dd1e2e0>: Failed to establish a new connection: [Errno 111] Connection refused')': /session/a833db34a5f9e805150e1d501248a6a9/actions
[2025-03-26T01:13:43.812+0000] {connectionpool.py:823} WARNING - Retrying (Retry(total=1, connect=None, read=None, redirect=None, status=None)) after connection broken by 'NewConnectionError('<urllib3.connection.HTTPConnection object at 0x7f560dd1e3d0>: Failed to establish a new connection: [Errno 111] Connection refused')': /session/a833db34a5f9e805150e1d501248a6a9/actions
[2025-03-26T01:13:43.813+0000] {connectionpool.py:823} WARNING - Retrying (Retry(total=0, connect=None, read=None, redirect=None, status=None)) after connection broken by 'NewConnectionError('<urllib3.connection.HTTPConnection object at 0x7f560dd70fa0>: Failed to establish a new connection: [Errno 111] Connection refused')': /session/a833db34a5f9e805150e1d501248a6a9/actions
[2025-03-26T01:13:43.813+0000] {logging_mixin.py:151} INFO - Lỗi khi lấy dữ liệu: HTTPConnectionPool(host='localhost', port=37583): Max retries exceeded with url: /session/a833db34a5f9e805150e1d501248a6a9/actions (Caused by NewConnectionError('<urllib3.connection.HTTPConnection object at 0x7f560dd70f40>: Failed to establish a new connection: [Errno 111] Connection refused'))
[2025-03-26T01:13:43.814+0000] {connectionpool.py:823} WARNING - Retrying (Retry(total=2, connect=None, read=None, redirect=None, status=None)) after connection broken by 'NewConnectionError('<urllib3.connection.HTTPConnection object at 0x7f560dd70cd0>: Failed to establish a new connection: [Errno 111] Connection refused')': /session/a833db34a5f9e805150e1d501248a6a9/actions
[2025-03-26T01:13:43.815+0000] {connectionpool.py:823} WARNING - Retrying (Retry(total=1, connect=None, read=None, redirect=None, status=None)) after connection broken by 'NewConnectionError('<urllib3.connection.HTTPConnection object at 0x7f560ddbb8e0>: Failed to establish a new connection: [Errno 111] Connection refused')': /session/a833db34a5f9e805150e1d501248a6a9/actions
[2025-03-26T01:13:43.816+0000] {connectionpool.py:823} WARNING - Retrying (Retry(total=0, connect=None, read=None, redirect=None, status=None)) after connection broken by 'NewConnectionError('<urllib3.connection.HTTPConnection object at 0x7f560ddbb820>: Failed to establish a new connection: [Errno 111] Connection refused')': /session/a833db34a5f9e805150e1d501248a6a9/actions
[2025-03-26T01:13:43.816+0000] {logging_mixin.py:151} INFO - Lỗi khi lấy dữ liệu: HTTPConnectionPool(host='localhost', port=37583): Max retries exceeded with url: /session/a833db34a5f9e805150e1d501248a6a9/actions (Caused by NewConnectionError('<urllib3.connection.HTTPConnection object at 0x7f560ddbbd60>: Failed to establish a new connection: [Errno 111] Connection refused'))
[2025-03-26T01:13:43.817+0000] {connectionpool.py:823} WARNING - Retrying (Retry(total=2, connect=None, read=None, redirect=None, status=None)) after connection broken by 'NewConnectionError('<urllib3.connection.HTTPConnection object at 0x7f560ddbb670>: Failed to establish a new connection: [Errno 111] Connection refused')': /session/a833db34a5f9e805150e1d501248a6a9/actions
[2025-03-26T01:13:43.818+0000] {connectionpool.py:823} WARNING - Retrying (Retry(total=1, connect=None, read=None, redirect=None, status=None)) after connection broken by 'NewConnectionError('<urllib3.connection.HTTPConnection object at 0x7f560ddbb160>: Failed to establish a new connection: [Errno 111] Connection refused')': /session/a833db34a5f9e805150e1d501248a6a9/actions
[2025-03-26T01:13:43.819+0000] {connectionpool.py:823} WARNING - Retrying (Retry(total=0, connect=None, read=None, redirect=None, status=None)) after connection broken by 'NewConnectionError('<urllib3.connection.HTTPConnection object at 0x7f560ddbbf70>: Failed to establish a new connection: [Errno 111] Connection refused')': /session/a833db34a5f9e805150e1d501248a6a9/actions
[2025-03-26T01:13:43.820+0000] {logging_mixin.py:151} INFO - Lỗi khi lấy dữ liệu: HTTPConnectionPool(host='localhost', port=37583): Max retries exceeded with url: /session/a833db34a5f9e805150e1d501248a6a9/actions (Caused by NewConnectionError('<urllib3.connection.HTTPConnection object at 0x7f560ddbbdc0>: Failed to establish a new connection: [Errno 111] Connection refused'))
[2025-03-26T01:13:43.821+0000] {connectionpool.py:823} WARNING - Retrying (Retry(total=2, connect=None, read=None, redirect=None, status=None)) after connection broken by 'NewConnectionError('<urllib3.connection.HTTPConnection object at 0x7f560dd55220>: Failed to establish a new connection: [Errno 111] Connection refused')': /session/a833db34a5f9e805150e1d501248a6a9/actions
[2025-03-26T01:13:43.821+0000] {connectionpool.py:823} WARNING - Retrying (Retry(total=1, connect=None, read=None, redirect=None, status=None)) after connection broken by 'NewConnectionError('<urllib3.connection.HTTPConnection object at 0x7f560dd55c10>: Failed to establish a new connection: [Errno 111] Connection refused')': /session/a833db34a5f9e805150e1d501248a6a9/actions
[2025-03-26T01:13:43.822+0000] {connectionpool.py:823} WARNING - Retrying (Retry(total=0, connect=None, read=None, redirect=None, status=None)) after connection broken by 'NewConnectionError('<urllib3.connection.HTTPConnection object at 0x7f560dd55a30>: Failed to establish a new connection: [Errno 111] Connection refused')': /session/a833db34a5f9e805150e1d501248a6a9/actions
[2025-03-26T01:13:43.822+0000] {logging_mixin.py:151} INFO - Lỗi khi lấy dữ liệu: HTTPConnectionPool(host='localhost', port=37583): Max retries exceeded with url: /session/a833db34a5f9e805150e1d501248a6a9/actions (Caused by NewConnectionError('<urllib3.connection.HTTPConnection object at 0x7f560dd559a0>: Failed to establish a new connection: [Errno 111] Connection refused'))
[2025-03-26T01:13:43.823+0000] {connectionpool.py:823} WARNING - Retrying (Retry(total=2, connect=None, read=None, redirect=None, status=None)) after connection broken by 'NewConnectionError('<urllib3.connection.HTTPConnection object at 0x7f560dd1e8b0>: Failed to establish a new connection: [Errno 111] Connection refused')': /session/a833db34a5f9e805150e1d501248a6a9/actions
[2025-03-26T01:13:43.824+0000] {connectionpool.py:823} WARNING - Retrying (Retry(total=1, connect=None, read=None, redirect=None, status=None)) after connection broken by 'NewConnectionError('<urllib3.connection.HTTPConnection object at 0x7f560dd55c70>: Failed to establish a new connection: [Errno 111] Connection refused')': /session/a833db34a5f9e805150e1d501248a6a9/actions
[2025-03-26T01:13:43.824+0000] {connectionpool.py:823} WARNING - Retrying (Retry(total=0, connect=None, read=None, redirect=None, status=None)) after connection broken by 'NewConnectionError('<urllib3.connection.HTTPConnection object at 0x7f560dd559a0>: Failed to establish a new connection: [Errno 111] Connection refused')': /session/a833db34a5f9e805150e1d501248a6a9/actions
[2025-03-26T01:13:43.825+0000] {logging_mixin.py:151} INFO - Lỗi khi lấy dữ liệu: HTTPConnectionPool(host='localhost', port=37583): Max retries exceeded with url: /session/a833db34a5f9e805150e1d501248a6a9/actions (Caused by NewConnectionError('<urllib3.connection.HTTPConnection object at 0x7f560dd55b20>: Failed to establish a new connection: [Errno 111] Connection refused'))
[2025-03-26T01:13:43.826+0000] {connectionpool.py:823} WARNING - Retrying (Retry(total=2, connect=None, read=None, redirect=None, status=None)) after connection broken by 'NewConnectionError('<urllib3.connection.HTTPConnection object at 0x7f560ddbb4c0>: Failed to establish a new connection: [Errno 111] Connection refused')': /session/a833db34a5f9e805150e1d501248a6a9/actions
[2025-03-26T01:13:43.827+0000] {connectionpool.py:823} WARNING - Retrying (Retry(total=1, connect=None, read=None, redirect=None, status=None)) after connection broken by 'NewConnectionError('<urllib3.connection.HTTPConnection object at 0x7f560ddbb250>: Failed to establish a new connection: [Errno 111] Connection refused')': /session/a833db34a5f9e805150e1d501248a6a9/actions
[2025-03-26T01:13:43.828+0000] {connectionpool.py:823} WARNING - Retrying (Retry(total=0, connect=None, read=None, redirect=None, status=None)) after connection broken by 'NewConnectionError('<urllib3.connection.HTTPConnection object at 0x7f560ddbbdc0>: Failed to establish a new connection: [Errno 111] Connection refused')': /session/a833db34a5f9e805150e1d501248a6a9/actions
[2025-03-26T01:13:43.828+0000] {logging_mixin.py:151} INFO - Lỗi khi lấy dữ liệu: HTTPConnectionPool(host='localhost', port=37583): Max retries exceeded with url: /session/a833db34a5f9e805150e1d501248a6a9/actions (Caused by NewConnectionError('<urllib3.connection.HTTPConnection object at 0x7f560ddbbd00>: Failed to establish a new connection: [Errno 111] Connection refused'))
[2025-03-26T01:13:43.829+0000] {connectionpool.py:823} WARNING - Retrying (Retry(total=2, connect=None, read=None, redirect=None, status=None)) after connection broken by 'NewConnectionError('<urllib3.connection.HTTPConnection object at 0x7f560ddbb640>: Failed to establish a new connection: [Errno 111] Connection refused')': /session/a833db34a5f9e805150e1d501248a6a9/actions
[2025-03-26T01:13:43.830+0000] {connectionpool.py:823} WARNING - Retrying (Retry(total=1, connect=None, read=None, redirect=None, status=None)) after connection broken by 'NewConnectionError('<urllib3.connection.HTTPConnection object at 0x7f560ddbb340>: Failed to establish a new connection: [Errno 111] Connection refused')': /session/a833db34a5f9e805150e1d501248a6a9/actions
[2025-03-26T01:13:43.831+0000] {connectionpool.py:823} WARNING - Retrying (Retry(total=0, connect=None, read=None, redirect=None, status=None)) after connection broken by 'NewConnectionError('<urllib3.connection.HTTPConnection object at 0x7f560ddbb820>: Failed to establish a new connection: [Errno 111] Connection refused')': /session/a833db34a5f9e805150e1d501248a6a9/actions
[2025-03-26T01:13:43.832+0000] {logging_mixin.py:151} INFO - Lỗi khi lấy dữ liệu: HTTPConnectionPool(host='localhost', port=37583): Max retries exceeded with url: /session/a833db34a5f9e805150e1d501248a6a9/actions (Caused by NewConnectionError('<urllib3.connection.HTTPConnection object at 0x7f560ddbb880>: Failed to establish a new connection: [Errno 111] Connection refused'))
[2025-03-26T01:13:43.835+0000] {connectionpool.py:823} WARNING - Retrying (Retry(total=2, connect=None, read=None, redirect=None, status=None)) after connection broken by 'NewConnectionError('<urllib3.connection.HTTPConnection object at 0x7f560dd70be0>: Failed to establish a new connection: [Errno 111] Connection refused')': /session/a833db34a5f9e805150e1d501248a6a9/actions
[2025-03-26T01:13:43.836+0000] {connectionpool.py:823} WARNING - Retrying (Retry(total=1, connect=None, read=None, redirect=None, status=None)) after connection broken by 'NewConnectionError('<urllib3.connection.HTTPConnection object at 0x7f560dd70f40>: Failed to establish a new connection: [Errno 111] Connection refused')': /session/a833db34a5f9e805150e1d501248a6a9/actions
[2025-03-26T01:13:43.836+0000] {connectionpool.py:823} WARNING - Retrying (Retry(total=0, connect=None, read=None, redirect=None, status=None)) after connection broken by 'NewConnectionError('<urllib3.connection.HTTPConnection object at 0x7f560dd17fd0>: Failed to establish a new connection: [Errno 111] Connection refused')': /session/a833db34a5f9e805150e1d501248a6a9/actions
[2025-03-26T01:13:43.837+0000] {logging_mixin.py:151} INFO - Lỗi khi lấy dữ liệu: HTTPConnectionPool(host='localhost', port=37583): Max retries exceeded with url: /session/a833db34a5f9e805150e1d501248a6a9/actions (Caused by NewConnectionError('<urllib3.connection.HTTPConnection object at 0x7f560dd1ea30>: Failed to establish a new connection: [Errno 111] Connection refused'))
[2025-03-26T01:13:43.839+0000] {connectionpool.py:823} WARNING - Retrying (Retry(total=2, connect=None, read=None, redirect=None, status=None)) after connection broken by 'NewConnectionError('<urllib3.connection.HTTPConnection object at 0x7f560dd1ed30>: Failed to establish a new connection: [Errno 111] Connection refused')': /session/a833db34a5f9e805150e1d501248a6a9/actions
[2025-03-26T01:13:43.841+0000] {connectionpool.py:823} WARNING - Retrying (Retry(total=1, connect=None, read=None, redirect=None, status=None)) after connection broken by 'NewConnectionError('<urllib3.connection.HTTPConnection object at 0x7f560dd17f10>: Failed to establish a new connection: [Errno 111] Connection refused')': /session/a833db34a5f9e805150e1d501248a6a9/actions
[2025-03-26T01:13:43.843+0000] {connectionpool.py:823} WARNING - Retrying (Retry(total=0, connect=None, read=None, redirect=None, status=None)) after connection broken by 'NewConnectionError('<urllib3.connection.HTTPConnection object at 0x7f560dd70ee0>: Failed to establish a new connection: [Errno 111] Connection refused')': /session/a833db34a5f9e805150e1d501248a6a9/actions
[2025-03-26T01:13:43.856+0000] {process_utils.py:79} INFO - Process psutil.Process(pid=96, status='terminated', started='01:11:15') (96) terminated with exit code None
[2025-03-26T01:13:43.913+0000] {logging_mixin.py:151} INFO - Lỗi khi lấy dữ liệu: HTTPConnectionPool(host='localhost', port=37583): Max retries exceeded with url: /session/a833db34a5f9e805150e1d501248a6a9/actions (Caused by NewConnectionError('<urllib3.connection.HTTPConnection object at 0x7f560dd70a60>: Failed to establish a new connection: [Errno 111] Connection refused'))
[2025-03-26T01:13:43.920+0000] {connectionpool.py:823} WARNING - Retrying (Retry(total=2, connect=None, read=None, redirect=None, status=None)) after connection broken by 'NewConnectionError('<urllib3.connection.HTTPConnection object at 0x7f560ddbb790>: Failed to establish a new connection: [Errno 111] Connection refused')': /session/a833db34a5f9e805150e1d501248a6a9/actions
[2025-03-26T01:13:43.925+0000] {connectionpool.py:823} WARNING - Retrying (Retry(total=1, connect=None, read=None, redirect=None, status=None)) after connection broken by 'NewConnectionError('<urllib3.connection.HTTPConnection object at 0x7f560ddbb520>: Failed to establish a new connection: [Errno 111] Connection refused')': /session/a833db34a5f9e805150e1d501248a6a9/actions
[2025-03-26T01:13:43.929+0000] {connectionpool.py:823} WARNING - Retrying (Retry(total=0, connect=None, read=None, redirect=None, status=None)) after connection broken by 'NewConnectionError('<urllib3.connection.HTTPConnection object at 0x7f560ddbbfd0>: Failed to establish a new connection: [Errno 111] Connection refused')': /session/a833db34a5f9e805150e1d501248a6a9/actions
[2025-03-26T01:13:43.934+0000] {logging_mixin.py:151} INFO - Lỗi khi lấy dữ liệu: HTTPConnectionPool(host='localhost', port=37583): Max retries exceeded with url: /session/a833db34a5f9e805150e1d501248a6a9/actions (Caused by NewConnectionError('<urllib3.connection.HTTPConnection object at 0x7f560ddbb310>: Failed to establish a new connection: [Errno 111] Connection refused'))
[2025-03-26T01:13:43.940+0000] {connectionpool.py:823} WARNING - Retrying (Retry(total=2, connect=None, read=None, redirect=None, status=None)) after connection broken by 'NewConnectionError('<urllib3.connection.HTTPConnection object at 0x7f560ddbbf70>: Failed to establish a new connection: [Errno 111] Connection refused')': /session/a833db34a5f9e805150e1d501248a6a9/actions
[2025-03-26T01:13:43.944+0000] {connectionpool.py:823} WARNING - Retrying (Retry(total=1, connect=None, read=None, redirect=None, status=None)) after connection broken by 'NewConnectionError('<urllib3.connection.HTTPConnection object at 0x7f560ddbbb80>: Failed to establish a new connection: [Errno 111] Connection refused')': /session/a833db34a5f9e805150e1d501248a6a9/actions
[2025-03-26T01:13:43.949+0000] {connectionpool.py:823} WARNING - Retrying (Retry(total=0, connect=None, read=None, redirect=None, status=None)) after connection broken by 'NewConnectionError('<urllib3.connection.HTTPConnection object at 0x7f560ddbbc10>: Failed to establish a new connection: [Errno 111] Connection refused')': /session/a833db34a5f9e805150e1d501248a6a9/actions
[2025-03-26T01:13:43.954+0000] {logging_mixin.py:151} INFO - Lỗi khi lấy dữ liệu: HTTPConnectionPool(host='localhost', port=37583): Max retries exceeded with url: /session/a833db34a5f9e805150e1d501248a6a9/actions (Caused by NewConnectionError('<urllib3.connection.HTTPConnection object at 0x7f560dd55bb0>: Failed to establish a new connection: [Errno 111] Connection refused'))
[2025-03-26T01:13:43.961+0000] {connectionpool.py:823} WARNING - Retrying (Retry(total=2, connect=None, read=None, redirect=None, status=None)) after connection broken by 'NewConnectionError('<urllib3.connection.HTTPConnection object at 0x7f560dd55eb0>: Failed to establish a new connection: [Errno 111] Connection refused')': /session/a833db34a5f9e805150e1d501248a6a9/actions
[2025-03-26T01:13:43.966+0000] {connectionpool.py:823} WARNING - Retrying (Retry(total=1, connect=None, read=None, redirect=None, status=None)) after connection broken by 'NewConnectionError('<urllib3.connection.HTTPConnection object at 0x7f560dd559d0>: Failed to establish a new connection: [Errno 111] Connection refused')': /session/a833db34a5f9e805150e1d501248a6a9/actions
[2025-03-26T01:13:43.971+0000] {connectionpool.py:823} WARNING - Retrying (Retry(total=0, connect=None, read=None, redirect=None, status=None)) after connection broken by 'NewConnectionError('<urllib3.connection.HTTPConnection object at 0x7f560dd55af0>: Failed to establish a new connection: [Errno 111] Connection refused')': /session/a833db34a5f9e805150e1d501248a6a9/actions
[2025-03-26T01:13:43.977+0000] {logging_mixin.py:151} INFO - Lỗi khi lấy dữ liệu: HTTPConnectionPool(host='localhost', port=37583): Max retries exceeded with url: /session/a833db34a5f9e805150e1d501248a6a9/actions (Caused by NewConnectionError('<urllib3.connection.HTTPConnection object at 0x7f560dd1ea60>: Failed to establish a new connection: [Errno 111] Connection refused'))
[2025-03-26T01:13:43.983+0000] {connectionpool.py:823} WARNING - Retrying (Retry(total=2, connect=None, read=None, redirect=None, status=None)) after connection broken by 'NewConnectionError('<urllib3.connection.HTTPConnection object at 0x7f560dd361f0>: Failed to establish a new connection: [Errno 111] Connection refused')': /session/a833db34a5f9e805150e1d501248a6a9/actions
[2025-03-26T01:13:43.987+0000] {connectionpool.py:823} WARNING - Retrying (Retry(total=1, connect=None, read=None, redirect=None, status=None)) after connection broken by 'NewConnectionError('<urllib3.connection.HTTPConnection object at 0x7f560dd1ee80>: Failed to establish a new connection: [Errno 111] Connection refused')': /session/a833db34a5f9e805150e1d501248a6a9/actions
[2025-03-26T01:13:43.992+0000] {connectionpool.py:823} WARNING - Retrying (Retry(total=0, connect=None, read=None, redirect=None, status=None)) after connection broken by 'NewConnectionError('<urllib3.connection.HTTPConnection object at 0x7f560dd55850>: Failed to establish a new connection: [Errno 111] Connection refused')': /session/a833db34a5f9e805150e1d501248a6a9/actions
[2025-03-26T01:13:43.996+0000] {logging_mixin.py:151} INFO - Lỗi khi lấy dữ liệu: HTTPConnectionPool(host='localhost', port=37583): Max retries exceeded with url: /session/a833db34a5f9e805150e1d501248a6a9/actions (Caused by NewConnectionError('<urllib3.connection.HTTPConnection object at 0x7f560dd558b0>: Failed to establish a new connection: [Errno 111] Connection refused'))
[2025-03-26T01:13:44.003+0000] {connectionpool.py:823} WARNING - Retrying (Retry(total=2, connect=None, read=None, redirect=None, status=None)) after connection broken by 'NewConnectionError('<urllib3.connection.HTTPConnection object at 0x7f560dd55040>: Failed to establish a new connection: [Errno 111] Connection refused')': /session/a833db34a5f9e805150e1d501248a6a9/actions
[2025-03-26T01:13:44.008+0000] {connectionpool.py:823} WARNING - Retrying (Retry(total=1, connect=None, read=None, redirect=None, status=None)) after connection broken by 'NewConnectionError('<urllib3.connection.HTTPConnection object at 0x7f560dd551c0>: Failed to establish a new connection: [Errno 111] Connection refused')': /session/a833db34a5f9e805150e1d501248a6a9/actions
[2025-03-26T01:13:44.013+0000] {connectionpool.py:823} WARNING - Retrying (Retry(total=0, connect=None, read=None, redirect=None, status=None)) after connection broken by 'NewConnectionError('<urllib3.connection.HTTPConnection object at 0x7f560ddbb730>: Failed to establish a new connection: [Errno 111] Connection refused')': /session/a833db34a5f9e805150e1d501248a6a9/actions
[2025-03-26T01:13:44.016+0000] {logging_mixin.py:151} INFO - Lỗi khi lấy dữ liệu: HTTPConnectionPool(host='localhost', port=37583): Max retries exceeded with url: /session/a833db34a5f9e805150e1d501248a6a9/actions (Caused by NewConnectionError('<urllib3.connection.HTTPConnection object at 0x7f560ddbbc10>: Failed to establish a new connection: [Errno 111] Connection refused'))
[2025-03-26T01:13:44.022+0000] {connectionpool.py:823} WARNING - Retrying (Retry(total=2, connect=None, read=None, redirect=None, status=None)) after connection broken by 'NewConnectionError('<urllib3.connection.HTTPConnection object at 0x7f560ddbb400>: Failed to establish a new connection: [Errno 111] Connection refused')': /session/a833db34a5f9e805150e1d501248a6a9/actions
[2025-03-26T01:13:44.027+0000] {connectionpool.py:823} WARNING - Retrying (Retry(total=1, connect=None, read=None, redirect=None, status=None)) after connection broken by 'NewConnectionError('<urllib3.connection.HTTPConnection object at 0x7f560ddbb7f0>: Failed to establish a new connection: [Errno 111] Connection refused')': /session/a833db34a5f9e805150e1d501248a6a9/actions
[2025-03-26T01:13:44.030+0000] {connectionpool.py:823} WARNING - Retrying (Retry(total=0, connect=None, read=None, redirect=None, status=None)) after connection broken by 'NewConnectionError('<urllib3.connection.HTTPConnection object at 0x7f560ddbb310>: Failed to establish a new connection: [Errno 111] Connection refused')': /session/a833db34a5f9e805150e1d501248a6a9/actions
[2025-03-26T01:13:44.035+0000] {logging_mixin.py:151} INFO - Lỗi khi lấy dữ liệu: HTTPConnectionPool(host='localhost', port=37583): Max retries exceeded with url: /session/a833db34a5f9e805150e1d501248a6a9/actions (Caused by NewConnectionError('<urllib3.connection.HTTPConnection object at 0x7f560ddbbd90>: Failed to establish a new connection: [Errno 111] Connection refused'))
[2025-03-26T01:13:44.043+0000] {connectionpool.py:823} WARNING - Retrying (Retry(total=2, connect=None, read=None, redirect=None, status=None)) after connection broken by 'NewConnectionError('<urllib3.connection.HTTPConnection object at 0x7f560dd70df0>: Failed to establish a new connection: [Errno 111] Connection refused')': /session/a833db34a5f9e805150e1d501248a6a9/actions
[2025-03-26T01:13:44.112+0000] {connectionpool.py:823} WARNING - Retrying (Retry(total=1, connect=None, read=None, redirect=None, status=None)) after connection broken by 'NewConnectionError('<urllib3.connection.HTTPConnection object at 0x7f560dd70d30>: Failed to establish a new connection: [Errno 111] Connection refused')': /session/a833db34a5f9e805150e1d501248a6a9/actions
[2025-03-26T01:13:44.117+0000] {connectionpool.py:823} WARNING - Retrying (Retry(total=0, connect=None, read=None, redirect=None, status=None)) after connection broken by 'NewConnectionError('<urllib3.connection.HTTPConnection object at 0x7f560dd70fa0>: Failed to establish a new connection: [Errno 111] Connection refused')': /session/a833db34a5f9e805150e1d501248a6a9/actions
[2025-03-26T01:13:44.122+0000] {logging_mixin.py:151} INFO - Lỗi khi lấy dữ liệu: HTTPConnectionPool(host='localhost', port=37583): Max retries exceeded with url: /session/a833db34a5f9e805150e1d501248a6a9/actions (Caused by NewConnectionError('<urllib3.connection.HTTPConnection object at 0x7f560dd17340>: Failed to establish a new connection: [Errno 111] Connection refused'))
[2025-03-26T01:13:44.128+0000] {connectionpool.py:823} WARNING - Retrying (Retry(total=2, connect=None, read=None, redirect=None, status=None)) after connection broken by 'NewConnectionError('<urllib3.connection.HTTPConnection object at 0x7f560dd366a0>: Failed to establish a new connection: [Errno 111] Connection refused')': /session/a833db34a5f9e805150e1d501248a6a9/actions
[2025-03-26T01:13:44.132+0000] {connectionpool.py:823} WARNING - Retrying (Retry(total=1, connect=None, read=None, redirect=None, status=None)) after connection broken by 'NewConnectionError('<urllib3.connection.HTTPConnection object at 0x7f560dd17100>: Failed to establish a new connection: [Errno 111] Connection refused')': /session/a833db34a5f9e805150e1d501248a6a9/actions
[2025-03-26T01:13:44.137+0000] {connectionpool.py:823} WARNING - Retrying (Retry(total=0, connect=None, read=None, redirect=None, status=None)) after connection broken by 'NewConnectionError('<urllib3.connection.HTTPConnection object at 0x7f560dd70a60>: Failed to establish a new connection: [Errno 111] Connection refused')': /session/a833db34a5f9e805150e1d501248a6a9/actions
[2025-03-26T01:13:44.143+0000] {logging_mixin.py:151} INFO - Lỗi khi lấy dữ liệu: HTTPConnectionPool(host='localhost', port=37583): Max retries exceeded with url: /session/a833db34a5f9e805150e1d501248a6a9/actions (Caused by NewConnectionError('<urllib3.connection.HTTPConnection object at 0x7f560dd70be0>: Failed to establish a new connection: [Errno 111] Connection refused'))
[2025-03-26T01:13:44.149+0000] {connectionpool.py:823} WARNING - Retrying (Retry(total=2, connect=None, read=None, redirect=None, status=None)) after connection broken by 'NewConnectionError('<urllib3.connection.HTTPConnection object at 0x7f560ddbbd30>: Failed to establish a new connection: [Errno 111] Connection refused')': /session/a833db34a5f9e805150e1d501248a6a9/actions
[2025-03-26T01:13:44.154+0000] {connectionpool.py:823} WARNING - Retrying (Retry(total=1, connect=None, read=None, redirect=None, status=None)) after connection broken by 'NewConnectionError('<urllib3.connection.HTTPConnection object at 0x7f560ddbbe20>: Failed to establish a new connection: [Errno 111] Connection refused')': /session/a833db34a5f9e805150e1d501248a6a9/actions
[2025-03-26T01:13:44.159+0000] {connectionpool.py:823} WARNING - Retrying (Retry(total=0, connect=None, read=None, redirect=None, status=None)) after connection broken by 'NewConnectionError('<urllib3.connection.HTTPConnection object at 0x7f560ddbb8e0>: Failed to establish a new connection: [Errno 111] Connection refused')': /session/a833db34a5f9e805150e1d501248a6a9/actions
[2025-03-26T01:13:44.163+0000] {logging_mixin.py:151} INFO - Lỗi khi lấy dữ liệu: HTTPConnectionPool(host='localhost', port=37583): Max retries exceeded with url: /session/a833db34a5f9e805150e1d501248a6a9/actions (Caused by NewConnectionError('<urllib3.connection.HTTPConnection object at 0x7f560ddbb520>: Failed to establish a new connection: [Errno 111] Connection refused'))
[2025-03-26T01:13:44.168+0000] {connectionpool.py:823} WARNING - Retrying (Retry(total=2, connect=None, read=None, redirect=None, status=None)) after connection broken by 'NewConnectionError('<urllib3.connection.HTTPConnection object at 0x7f560ddbb400>: Failed to establish a new connection: [Errno 111] Connection refused')': /session/a833db34a5f9e805150e1d501248a6a9/url
[2025-03-26T01:13:44.172+0000] {connectionpool.py:823} WARNING - Retrying (Retry(total=1, connect=None, read=None, redirect=None, status=None)) after connection broken by 'NewConnectionError('<urllib3.connection.HTTPConnection object at 0x7f560ddbbdc0>: Failed to establish a new connection: [Errno 111] Connection refused')': /session/a833db34a5f9e805150e1d501248a6a9/url
[2025-03-26T01:13:44.178+0000] {connectionpool.py:823} WARNING - Retrying (Retry(total=0, connect=None, read=None, redirect=None, status=None)) after connection broken by 'NewConnectionError('<urllib3.connection.HTTPConnection object at 0x7f560ddbb610>: Failed to establish a new connection: [Errno 111] Connection refused')': /session/a833db34a5f9e805150e1d501248a6a9/url
[2025-03-26T01:13:44.182+0000] {data_stream.py:39} ERROR - An error occurred: HTTPConnectionPool(host='localhost', port=37583): Max retries exceeded with url: /session/a833db34a5f9e805150e1d501248a6a9/url (Caused by NewConnectionError('<urllib3.connection.HTTPConnection object at 0x7f560ddbb940>: Failed to establish a new connection: [Errno 111] Connection refused'))
[2025-03-26T01:13:44.183+0000] {python.py:194} INFO - Done. Returned value was: None
[2025-03-26T01:13:44.279+0000] {taskinstance.py:1400} INFO - Marking task as SUCCESS. dag_id=job_data_stream, task_id=job_data_stream, execution_date=20250325T000000, start_date=20250326T011115, end_date=20250326T011344
[2025-03-26T01:13:44.304+0000] {process_utils.py:79} INFO - Process psutil.Process(pid=60, status='terminated', started='01:11:15') (60) terminated with exit code None
[2025-03-26T01:13:44.365+0000] {process_utils.py:79} INFO - Process psutil.Process(pid=52, status='terminated', exitcode=0, started='01:11:14') (52) terminated with exit code 0
[2025-03-26T01:13:44.365+0000] {process_utils.py:79} INFO - Process psutil.Process(pid=74, status='terminated', started='01:11:15') (74) terminated with exit code None
[2025-03-26T01:13:44.366+0000] {process_utils.py:79} INFO - Process psutil.Process(pid=75, status='terminated', started='01:11:15') (75) terminated with exit code None
[2025-03-26T01:13:44.367+0000] {process_utils.py:79} INFO - Process psutil.Process(pid=54, status='terminated', started='01:11:15') (54) terminated with exit code None
[2025-03-26T01:13:44.368+0000] {process_utils.py:79} INFO - Process psutil.Process(pid=181, status='terminated', started='01:11:19') (181) terminated with exit code None
[2025-03-26T01:13:44.369+0000] {process_utils.py:79} INFO - Process psutil.Process(pid=64, status='terminated', started='01:11:15') (64) terminated with exit code None
[2025-03-26T01:13:44.370+0000] {process_utils.py:79} INFO - Process psutil.Process(pid=97, status='terminated', started='01:11:15') (97) terminated with exit code None
[2025-03-26T01:13:44.370+0000] {process_utils.py:79} INFO - Process psutil.Process(pid=65, status='terminated', started='01:11:15') (65) terminated with exit code None
