[2025-03-25T05:55:22.946+0000] {taskinstance.py:1159} INFO - Dependencies all met for dep_context=non-requeueable deps ti=<TaskInstance: job_data_stream.job_data_stream manual__2025-03-25T05:55:21.352419+00:00 [queued]>
[2025-03-25T05:55:22.960+0000] {taskinstance.py:1159} INFO - Dependencies all met for dep_context=requeueable deps ti=<TaskInstance: job_data_stream.job_data_stream manual__2025-03-25T05:55:21.352419+00:00 [queued]>
[2025-03-25T05:55:22.960+0000] {taskinstance.py:1361} INFO - Starting attempt 1 of 1
[2025-03-25T05:55:22.982+0000] {taskinstance.py:1382} INFO - Executing <Task(PythonOperator): job_data_stream> on 2025-03-25 05:55:21.352419+00:00
[2025-03-25T05:55:22.987+0000] {standard_task_runner.py:57} INFO - Started process 51 to run task
[2025-03-25T05:55:22.996+0000] {standard_task_runner.py:84} INFO - Running: ['***', 'tasks', 'run', 'job_data_stream', 'job_data_stream', 'manual__2025-03-25T05:55:21.352419+00:00', '--job-id', '52', '--raw', '--subdir', 'DAGS_FOLDER/data_stream.py', '--cfg-path', '/tmp/tmpteu8zpat']
[2025-03-25T05:55:22.999+0000] {standard_task_runner.py:85} INFO - Job 52: Subtask job_data_stream
[2025-03-25T05:55:23.117+0000] {task_command.py:415} INFO - Running <TaskInstance: job_data_stream.job_data_stream manual__2025-03-25T05:55:21.352419+00:00 [running]> on host c0041b6c44f7
[2025-03-25T05:55:23.253+0000] {taskinstance.py:1660} INFO - Exporting env vars: AIRFLOW_CTX_DAG_OWNER='dii' AIRFLOW_CTX_DAG_ID='job_data_stream' AIRFLOW_CTX_TASK_ID='job_data_stream' AIRFLOW_CTX_EXECUTION_DATE='2025-03-25T05:55:21.352419+00:00' AIRFLOW_CTX_TRY_NUMBER='1' AIRFLOW_CTX_DAG_RUN_ID='manual__2025-03-25T05:55:21.352419+00:00'
[2025-03-25T05:55:23.260+0000] {conn.py:384} INFO - <BrokerConnection client_id=kafka-python-producer-1, node_id=bootstrap-0 host=broker:29092 <connecting> [IPv4 ('172.18.0.2', 29092)]>: connecting to broker:29092 [('172.18.0.2', 29092) IPv4]
[2025-03-25T05:55:23.261+0000] {conn.py:1219} INFO - Probing node bootstrap-0 broker version
[2025-03-25T05:55:23.263+0000] {conn.py:414} INFO - <BrokerConnection client_id=kafka-python-producer-1, node_id=bootstrap-0 host=broker:29092 <connecting> [IPv4 ('172.18.0.2', 29092)]>: Connection complete.
[2025-03-25T05:55:23.376+0000] {conn.py:1282} INFO - Broker version identified as 2.6.0
[2025-03-25T05:55:23.377+0000] {conn.py:1283} INFO - Set configuration api_version=(2, 6, 0) to skip auto check_version requests on startup
[2025-03-25T05:55:37.484+0000] {logging_mixin.py:151} INFO - Số công việc tìm thấy trên trang 301:70
[2025-03-25T05:56:12.201+0000] {local_task_job_runner.py:115} ERROR - Received SIGTERM. Terminating subprocesses
[2025-03-25T05:56:12.216+0000] {process_utils.py:131} INFO - Sending 15 to group 51. PIDs of all processes in the group: [53, 59, 64, 65, 74, 75, 97, 183, 113, 148, 157, 173, 197, 219, 232, 96, 51]
[2025-03-25T05:56:12.218+0000] {process_utils.py:86} INFO - Sending the signal 15 to group 51
[2025-03-25T05:56:12.221+0000] {taskinstance.py:1632} ERROR - Received SIGTERM. Terminating subprocesses.
[2025-03-25T05:56:12.225+0000] {logging_mixin.py:151} INFO - Lỗi khi lấy dữ liệu: Task received SIGTERM signal
[2025-03-25T05:56:12.257+0000] {logging_mixin.py:151} INFO - Lỗi khi lấy dữ liệu: ('Connection aborted.', ConnectionResetError(104, 'Connection reset by peer'))
[2025-03-25T05:56:12.264+0000] {connectionpool.py:823} WARNING - Retrying (Retry(total=2, connect=None, read=None, redirect=None, status=None)) after connection broken by 'NewConnectionError('<urllib3.connection.HTTPConnection object at 0x7fc01d1e7910>: Failed to establish a new connection: [Errno 111] Connection refused')': /session/af7ef39ab9b0dcf418be7597fa32b139/actions
[2025-03-25T05:56:12.262+0000] {process_utils.py:79} INFO - Process psutil.Process(pid=113, status='terminated', started='05:55:24') (113) terminated with exit code None
[2025-03-25T05:56:12.272+0000] {connectionpool.py:823} WARNING - Retrying (Retry(total=1, connect=None, read=None, redirect=None, status=None)) after connection broken by 'NewConnectionError('<urllib3.connection.HTTPConnection object at 0x7fc01d1e7a00>: Failed to establish a new connection: [Errno 111] Connection refused')': /session/af7ef39ab9b0dcf418be7597fa32b139/actions
[2025-03-25T05:56:12.275+0000] {connectionpool.py:823} WARNING - Retrying (Retry(total=0, connect=None, read=None, redirect=None, status=None)) after connection broken by 'NewConnectionError('<urllib3.connection.HTTPConnection object at 0x7fc01d1e7b80>: Failed to establish a new connection: [Errno 111] Connection refused')': /session/af7ef39ab9b0dcf418be7597fa32b139/actions
[2025-03-25T05:56:12.280+0000] {logging_mixin.py:151} INFO - Lỗi khi lấy dữ liệu: HTTPConnectionPool(host='localhost', port=59811): Max retries exceeded with url: /session/af7ef39ab9b0dcf418be7597fa32b139/actions (Caused by NewConnectionError('<urllib3.connection.HTTPConnection object at 0x7fc01d1e7cd0>: Failed to establish a new connection: [Errno 111] Connection refused'))
[2025-03-25T05:56:12.294+0000] {connectionpool.py:823} WARNING - Retrying (Retry(total=2, connect=None, read=None, redirect=None, status=None)) after connection broken by 'NewConnectionError('<urllib3.connection.HTTPConnection object at 0x7fc01d201160>: Failed to establish a new connection: [Errno 111] Connection refused')': /session/af7ef39ab9b0dcf418be7597fa32b139/actions
[2025-03-25T05:56:12.301+0000] {connectionpool.py:823} WARNING - Retrying (Retry(total=1, connect=None, read=None, redirect=None, status=None)) after connection broken by 'NewConnectionError('<urllib3.connection.HTTPConnection object at 0x7fc01d201250>: Failed to establish a new connection: [Errno 111] Connection refused')': /session/af7ef39ab9b0dcf418be7597fa32b139/actions
[2025-03-25T05:56:12.303+0000] {connectionpool.py:823} WARNING - Retrying (Retry(total=0, connect=None, read=None, redirect=None, status=None)) after connection broken by 'NewConnectionError('<urllib3.connection.HTTPConnection object at 0x7fc01d2013d0>: Failed to establish a new connection: [Errno 111] Connection refused')': /session/af7ef39ab9b0dcf418be7597fa32b139/actions
[2025-03-25T05:56:12.306+0000] {logging_mixin.py:151} INFO - Lỗi khi lấy dữ liệu: HTTPConnectionPool(host='localhost', port=59811): Max retries exceeded with url: /session/af7ef39ab9b0dcf418be7597fa32b139/actions (Caused by NewConnectionError('<urllib3.connection.HTTPConnection object at 0x7fc01d201520>: Failed to establish a new connection: [Errno 111] Connection refused'))
[2025-03-25T05:56:12.320+0000] {connectionpool.py:823} WARNING - Retrying (Retry(total=2, connect=None, read=None, redirect=None, status=None)) after connection broken by 'NewConnectionError('<urllib3.connection.HTTPConnection object at 0x7fc01d201970>: Failed to establish a new connection: [Errno 111] Connection refused')': /session/af7ef39ab9b0dcf418be7597fa32b139/actions
[2025-03-25T05:56:12.324+0000] {connectionpool.py:823} WARNING - Retrying (Retry(total=1, connect=None, read=None, redirect=None, status=None)) after connection broken by 'NewConnectionError('<urllib3.connection.HTTPConnection object at 0x7fc01d1e7f70>: Failed to establish a new connection: [Errno 111] Connection refused')': /session/af7ef39ab9b0dcf418be7597fa32b139/actions
[2025-03-25T05:56:12.338+0000] {process_utils.py:79} INFO - Process psutil.Process(pid=157, status='terminated', started='05:55:25') (157) terminated with exit code None
[2025-03-25T05:56:12.337+0000] {connectionpool.py:823} WARNING - Retrying (Retry(total=0, connect=None, read=None, redirect=None, status=None)) after connection broken by 'NewConnectionError('<urllib3.connection.HTTPConnection object at 0x7fc01d1e7fd0>: Failed to establish a new connection: [Errno 111] Connection refused')': /session/af7ef39ab9b0dcf418be7597fa32b139/actions
[2025-03-25T05:56:12.351+0000] {logging_mixin.py:151} INFO - Lỗi khi lấy dữ liệu: HTTPConnectionPool(host='localhost', port=59811): Max retries exceeded with url: /session/af7ef39ab9b0dcf418be7597fa32b139/actions (Caused by NewConnectionError('<urllib3.connection.HTTPConnection object at 0x7fc01d1e7940>: Failed to establish a new connection: [Errno 111] Connection refused'))
[2025-03-25T05:56:12.356+0000] {connectionpool.py:823} WARNING - Retrying (Retry(total=2, connect=None, read=None, redirect=None, status=None)) after connection broken by 'NewConnectionError('<urllib3.connection.HTTPConnection object at 0x7fc01d1e79a0>: Failed to establish a new connection: [Errno 111] Connection refused')': /session/af7ef39ab9b0dcf418be7597fa32b139/actions
[2025-03-25T05:56:12.358+0000] {connectionpool.py:823} WARNING - Retrying (Retry(total=1, connect=None, read=None, redirect=None, status=None)) after connection broken by 'NewConnectionError('<urllib3.connection.HTTPConnection object at 0x7fc01d1e7850>: Failed to establish a new connection: [Errno 111] Connection refused')': /session/af7ef39ab9b0dcf418be7597fa32b139/actions
[2025-03-25T05:56:12.360+0000] {connectionpool.py:823} WARNING - Retrying (Retry(total=0, connect=None, read=None, redirect=None, status=None)) after connection broken by 'NewConnectionError('<urllib3.connection.HTTPConnection object at 0x7fc01d1e7310>: Failed to establish a new connection: [Errno 111] Connection refused')': /session/af7ef39ab9b0dcf418be7597fa32b139/actions
[2025-03-25T05:56:12.363+0000] {logging_mixin.py:151} INFO - Lỗi khi lấy dữ liệu: HTTPConnectionPool(host='localhost', port=59811): Max retries exceeded with url: /session/af7ef39ab9b0dcf418be7597fa32b139/actions (Caused by NewConnectionError('<urllib3.connection.HTTPConnection object at 0x7fc01d1e7730>: Failed to establish a new connection: [Errno 111] Connection refused'))
[2025-03-25T05:56:12.365+0000] {connectionpool.py:823} WARNING - Retrying (Retry(total=2, connect=None, read=None, redirect=None, status=None)) after connection broken by 'NewConnectionError('<urllib3.connection.HTTPConnection object at 0x7fc01d2012e0>: Failed to establish a new connection: [Errno 111] Connection refused')': /session/af7ef39ab9b0dcf418be7597fa32b139/actions
[2025-03-25T05:56:12.367+0000] {connectionpool.py:823} WARNING - Retrying (Retry(total=1, connect=None, read=None, redirect=None, status=None)) after connection broken by 'NewConnectionError('<urllib3.connection.HTTPConnection object at 0x7fc01d201610>: Failed to establish a new connection: [Errno 111] Connection refused')': /session/af7ef39ab9b0dcf418be7597fa32b139/actions
[2025-03-25T05:56:12.369+0000] {connectionpool.py:823} WARNING - Retrying (Retry(total=0, connect=None, read=None, redirect=None, status=None)) after connection broken by 'NewConnectionError('<urllib3.connection.HTTPConnection object at 0x7fc01d2013a0>: Failed to establish a new connection: [Errno 111] Connection refused')': /session/af7ef39ab9b0dcf418be7597fa32b139/actions
[2025-03-25T05:56:12.372+0000] {logging_mixin.py:151} INFO - Lỗi khi lấy dữ liệu: HTTPConnectionPool(host='localhost', port=59811): Max retries exceeded with url: /session/af7ef39ab9b0dcf418be7597fa32b139/actions (Caused by NewConnectionError('<urllib3.connection.HTTPConnection object at 0x7fc01d201160>: Failed to establish a new connection: [Errno 111] Connection refused'))
[2025-03-25T05:56:12.375+0000] {connectionpool.py:823} WARNING - Retrying (Retry(total=2, connect=None, read=None, redirect=None, status=None)) after connection broken by 'NewConnectionError('<urllib3.connection.HTTPConnection object at 0x7fc01d201d00>: Failed to establish a new connection: [Errno 111] Connection refused')': /session/af7ef39ab9b0dcf418be7597fa32b139/actions
[2025-03-25T05:56:12.378+0000] {connectionpool.py:823} WARNING - Retrying (Retry(total=1, connect=None, read=None, redirect=None, status=None)) after connection broken by 'NewConnectionError('<urllib3.connection.HTTPConnection object at 0x7fc01d201df0>: Failed to establish a new connection: [Errno 111] Connection refused')': /session/af7ef39ab9b0dcf418be7597fa32b139/actions
[2025-03-25T05:56:12.380+0000] {connectionpool.py:823} WARNING - Retrying (Retry(total=0, connect=None, read=None, redirect=None, status=None)) after connection broken by 'NewConnectionError('<urllib3.connection.HTTPConnection object at 0x7fc01d201f70>: Failed to establish a new connection: [Errno 111] Connection refused')': /session/af7ef39ab9b0dcf418be7597fa32b139/actions
[2025-03-25T05:56:12.383+0000] {logging_mixin.py:151} INFO - Lỗi khi lấy dữ liệu: HTTPConnectionPool(host='localhost', port=59811): Max retries exceeded with url: /session/af7ef39ab9b0dcf418be7597fa32b139/actions (Caused by NewConnectionError('<urllib3.connection.HTTPConnection object at 0x7fc01d198130>: Failed to establish a new connection: [Errno 111] Connection refused'))
[2025-03-25T05:56:12.385+0000] {connectionpool.py:823} WARNING - Retrying (Retry(total=2, connect=None, read=None, redirect=None, status=None)) after connection broken by 'NewConnectionError('<urllib3.connection.HTTPConnection object at 0x7fc01d201250>: Failed to establish a new connection: [Errno 111] Connection refused')': /session/af7ef39ab9b0dcf418be7597fa32b139/actions
[2025-03-25T05:56:12.386+0000] {connectionpool.py:823} WARNING - Retrying (Retry(total=1, connect=None, read=None, redirect=None, status=None)) after connection broken by 'NewConnectionError('<urllib3.connection.HTTPConnection object at 0x7fc01d201520>: Failed to establish a new connection: [Errno 111] Connection refused')': /session/af7ef39ab9b0dcf418be7597fa32b139/actions
[2025-03-25T05:56:12.388+0000] {connectionpool.py:823} WARNING - Retrying (Retry(total=0, connect=None, read=None, redirect=None, status=None)) after connection broken by 'NewConnectionError('<urllib3.connection.HTTPConnection object at 0x7fc01d1e7430>: Failed to establish a new connection: [Errno 111] Connection refused')': /session/af7ef39ab9b0dcf418be7597fa32b139/actions
[2025-03-25T05:56:12.389+0000] {logging_mixin.py:151} INFO - Lỗi khi lấy dữ liệu: HTTPConnectionPool(host='localhost', port=59811): Max retries exceeded with url: /session/af7ef39ab9b0dcf418be7597fa32b139/actions (Caused by NewConnectionError('<urllib3.connection.HTTPConnection object at 0x7fc01d1e76a0>: Failed to establish a new connection: [Errno 111] Connection refused'))
[2025-03-25T05:56:12.391+0000] {connectionpool.py:823} WARNING - Retrying (Retry(total=2, connect=None, read=None, redirect=None, status=None)) after connection broken by 'NewConnectionError('<urllib3.connection.HTTPConnection object at 0x7fc01d1e77c0>: Failed to establish a new connection: [Errno 111] Connection refused')': /session/af7ef39ab9b0dcf418be7597fa32b139/actions
[2025-03-25T05:56:12.393+0000] {connectionpool.py:823} WARNING - Retrying (Retry(total=1, connect=None, read=None, redirect=None, status=None)) after connection broken by 'NewConnectionError('<urllib3.connection.HTTPConnection object at 0x7fc01d1e77f0>: Failed to establish a new connection: [Errno 111] Connection refused')': /session/af7ef39ab9b0dcf418be7597fa32b139/actions
[2025-03-25T05:56:12.395+0000] {connectionpool.py:823} WARNING - Retrying (Retry(total=0, connect=None, read=None, redirect=None, status=None)) after connection broken by 'NewConnectionError('<urllib3.connection.HTTPConnection object at 0x7fc01d1e7c10>: Failed to establish a new connection: [Errno 111] Connection refused')': /session/af7ef39ab9b0dcf418be7597fa32b139/actions
[2025-03-25T05:56:12.398+0000] {logging_mixin.py:151} INFO - Lỗi khi lấy dữ liệu: HTTPConnectionPool(host='localhost', port=59811): Max retries exceeded with url: /session/af7ef39ab9b0dcf418be7597fa32b139/actions (Caused by NewConnectionError('<urllib3.connection.HTTPConnection object at 0x7fc01d1e7af0>: Failed to establish a new connection: [Errno 111] Connection refused'))
[2025-03-25T05:56:12.400+0000] {connectionpool.py:823} WARNING - Retrying (Retry(total=2, connect=None, read=None, redirect=None, status=None)) after connection broken by 'NewConnectionError('<urllib3.connection.HTTPConnection object at 0x7fc01d1981f0>: Failed to establish a new connection: [Errno 111] Connection refused')': /session/af7ef39ab9b0dcf418be7597fa32b139/actions
[2025-03-25T05:56:12.401+0000] {process_utils.py:79} INFO - Process psutil.Process(pid=64, status='terminated', started='05:55:23') (64) terminated with exit code None
[2025-03-25T05:56:12.402+0000] {connectionpool.py:823} WARNING - Retrying (Retry(total=1, connect=None, read=None, redirect=None, status=None)) after connection broken by 'NewConnectionError('<urllib3.connection.HTTPConnection object at 0x7fc01d198280>: Failed to establish a new connection: [Errno 111] Connection refused')': /session/af7ef39ab9b0dcf418be7597fa32b139/actions
[2025-03-25T05:56:12.403+0000] {process_utils.py:79} INFO - Process psutil.Process(pid=75, status='terminated', started='05:55:23') (75) terminated with exit code None
[2025-03-25T05:56:12.404+0000] {connectionpool.py:823} WARNING - Retrying (Retry(total=0, connect=None, read=None, redirect=None, status=None)) after connection broken by 'NewConnectionError('<urllib3.connection.HTTPConnection object at 0x7fc01d198430>: Failed to establish a new connection: [Errno 111] Connection refused')': /session/af7ef39ab9b0dcf418be7597fa32b139/actions
[2025-03-25T05:56:12.405+0000] {process_utils.py:79} INFO - Process psutil.Process(pid=59, status='terminated', started='05:55:23') (59) terminated with exit code None
[2025-03-25T05:56:12.406+0000] {logging_mixin.py:151} INFO - Lỗi khi lấy dữ liệu: HTTPConnectionPool(host='localhost', port=59811): Max retries exceeded with url: /session/af7ef39ab9b0dcf418be7597fa32b139/actions (Caused by NewConnectionError('<urllib3.connection.HTTPConnection object at 0x7fc01d198580>: Failed to establish a new connection: [Errno 111] Connection refused'))
[2025-03-25T05:56:12.406+0000] {process_utils.py:79} INFO - Process psutil.Process(pid=97, status='terminated', started='05:55:24') (97) terminated with exit code None
[2025-03-25T05:56:12.408+0000] {connectionpool.py:823} WARNING - Retrying (Retry(total=2, connect=None, read=None, redirect=None, status=None)) after connection broken by 'NewConnectionError('<urllib3.connection.HTTPConnection object at 0x7fc01d1989d0>: Failed to establish a new connection: [Errno 111] Connection refused')': /session/af7ef39ab9b0dcf418be7597fa32b139/actions
[2025-03-25T05:56:12.409+0000] {process_utils.py:79} INFO - Process psutil.Process(pid=183, status='terminated', started='05:55:27') (183) terminated with exit code None
[2025-03-25T05:56:12.412+0000] {connectionpool.py:823} WARNING - Retrying (Retry(total=1, connect=None, read=None, redirect=None, status=None)) after connection broken by 'NewConnectionError('<urllib3.connection.HTTPConnection object at 0x7fc01d198ac0>: Failed to establish a new connection: [Errno 111] Connection refused')': /session/af7ef39ab9b0dcf418be7597fa32b139/actions
[2025-03-25T05:56:12.413+0000] {process_utils.py:79} INFO - Process psutil.Process(pid=197, status='terminated', started='05:55:27') (197) terminated with exit code None
[2025-03-25T05:56:12.415+0000] {process_utils.py:79} INFO - Process psutil.Process(pid=173, status='terminated', started='05:55:27') (173) terminated with exit code None
[2025-03-25T05:56:12.415+0000] {connectionpool.py:823} WARNING - Retrying (Retry(total=0, connect=None, read=None, redirect=None, status=None)) after connection broken by 'NewConnectionError('<urllib3.connection.HTTPConnection object at 0x7fc01d198c40>: Failed to establish a new connection: [Errno 111] Connection refused')': /session/af7ef39ab9b0dcf418be7597fa32b139/actions
[2025-03-25T05:56:12.416+0000] {process_utils.py:79} INFO - Process psutil.Process(pid=232, status='terminated', started='05:55:30') (232) terminated with exit code None
[2025-03-25T05:56:12.417+0000] {logging_mixin.py:151} INFO - Lỗi khi lấy dữ liệu: HTTPConnectionPool(host='localhost', port=59811): Max retries exceeded with url: /session/af7ef39ab9b0dcf418be7597fa32b139/actions (Caused by NewConnectionError('<urllib3.connection.HTTPConnection object at 0x7fc01d1e7e20>: Failed to establish a new connection: [Errno 111] Connection refused'))
[2025-03-25T05:56:12.417+0000] {process_utils.py:79} INFO - Process psutil.Process(pid=148, status='terminated', started='05:55:24') (148) terminated with exit code None
[2025-03-25T05:56:12.418+0000] {process_utils.py:79} INFO - Process psutil.Process(pid=96, status='terminated', started='05:55:24') (96) terminated with exit code None
[2025-03-25T05:56:12.418+0000] {process_utils.py:79} INFO - Process psutil.Process(pid=219, status='terminated', started='05:55:30') (219) terminated with exit code None
[2025-03-25T05:56:12.419+0000] {connectionpool.py:823} WARNING - Retrying (Retry(total=2, connect=None, read=None, redirect=None, status=None)) after connection broken by 'NewConnectionError('<urllib3.connection.HTTPConnection object at 0x7fc01d1e7ac0>: Failed to establish a new connection: [Errno 111] Connection refused')': /session/af7ef39ab9b0dcf418be7597fa32b139/actions
[2025-03-25T05:56:12.419+0000] {process_utils.py:79} INFO - Process psutil.Process(pid=74, status='terminated', started='05:55:23') (74) terminated with exit code None
[2025-03-25T05:56:12.421+0000] {connectionpool.py:823} WARNING - Retrying (Retry(total=1, connect=None, read=None, redirect=None, status=None)) after connection broken by 'NewConnectionError('<urllib3.connection.HTTPConnection object at 0x7fc01d1e7cd0>: Failed to establish a new connection: [Errno 111] Connection refused')': /session/af7ef39ab9b0dcf418be7597fa32b139/actions
[2025-03-25T05:56:12.422+0000] {connectionpool.py:823} WARNING - Retrying (Retry(total=0, connect=None, read=None, redirect=None, status=None)) after connection broken by 'NewConnectionError('<urllib3.connection.HTTPConnection object at 0x7fc01d1e7970>: Failed to establish a new connection: [Errno 111] Connection refused')': /session/af7ef39ab9b0dcf418be7597fa32b139/actions
[2025-03-25T05:56:12.424+0000] {logging_mixin.py:151} INFO - Lỗi khi lấy dữ liệu: HTTPConnectionPool(host='localhost', port=59811): Max retries exceeded with url: /session/af7ef39ab9b0dcf418be7597fa32b139/actions (Caused by NewConnectionError('<urllib3.connection.HTTPConnection object at 0x7fc01d1e7dc0>: Failed to establish a new connection: [Errno 111] Connection refused'))
[2025-03-25T05:56:12.426+0000] {connectionpool.py:823} WARNING - Retrying (Retry(total=2, connect=None, read=None, redirect=None, status=None)) after connection broken by 'NewConnectionError('<urllib3.connection.HTTPConnection object at 0x7fc01d1e72e0>: Failed to establish a new connection: [Errno 111] Connection refused')': /session/af7ef39ab9b0dcf418be7597fa32b139/actions
[2025-03-25T05:56:12.428+0000] {connectionpool.py:823} WARNING - Retrying (Retry(total=1, connect=None, read=None, redirect=None, status=None)) after connection broken by 'NewConnectionError('<urllib3.connection.HTTPConnection object at 0x7fc01d201610>: Failed to establish a new connection: [Errno 111] Connection refused')': /session/af7ef39ab9b0dcf418be7597fa32b139/actions
[2025-03-25T05:56:12.430+0000] {connectionpool.py:823} WARNING - Retrying (Retry(total=0, connect=None, read=None, redirect=None, status=None)) after connection broken by 'NewConnectionError('<urllib3.connection.HTTPConnection object at 0x7fc01d201190>: Failed to establish a new connection: [Errno 111] Connection refused')': /session/af7ef39ab9b0dcf418be7597fa32b139/actions
[2025-03-25T05:56:12.432+0000] {logging_mixin.py:151} INFO - Lỗi khi lấy dữ liệu: HTTPConnectionPool(host='localhost', port=59811): Max retries exceeded with url: /session/af7ef39ab9b0dcf418be7597fa32b139/actions (Caused by NewConnectionError('<urllib3.connection.HTTPConnection object at 0x7fc01d201400>: Failed to establish a new connection: [Errno 111] Connection refused'))
[2025-03-25T05:56:12.434+0000] {connectionpool.py:823} WARNING - Retrying (Retry(total=2, connect=None, read=None, redirect=None, status=None)) after connection broken by 'NewConnectionError('<urllib3.connection.HTTPConnection object at 0x7fc01d1985b0>: Failed to establish a new connection: [Errno 111] Connection refused')': /session/af7ef39ab9b0dcf418be7597fa32b139/actions
[2025-03-25T05:56:12.436+0000] {connectionpool.py:823} WARNING - Retrying (Retry(total=1, connect=None, read=None, redirect=None, status=None)) after connection broken by 'NewConnectionError('<urllib3.connection.HTTPConnection object at 0x7fc01d198520>: Failed to establish a new connection: [Errno 111] Connection refused')': /session/af7ef39ab9b0dcf418be7597fa32b139/actions
[2025-03-25T05:56:12.439+0000] {connectionpool.py:823} WARNING - Retrying (Retry(total=0, connect=None, read=None, redirect=None, status=None)) after connection broken by 'NewConnectionError('<urllib3.connection.HTTPConnection object at 0x7fc01d198370>: Failed to establish a new connection: [Errno 111] Connection refused')': /session/af7ef39ab9b0dcf418be7597fa32b139/actions
[2025-03-25T05:56:12.442+0000] {logging_mixin.py:151} INFO - Lỗi khi lấy dữ liệu: HTTPConnectionPool(host='localhost', port=59811): Max retries exceeded with url: /session/af7ef39ab9b0dcf418be7597fa32b139/actions (Caused by NewConnectionError('<urllib3.connection.HTTPConnection object at 0x7fc01d198d60>: Failed to establish a new connection: [Errno 111] Connection refused'))
[2025-03-25T05:56:12.447+0000] {connectionpool.py:823} WARNING - Retrying (Retry(total=2, connect=None, read=None, redirect=None, status=None)) after connection broken by 'NewConnectionError('<urllib3.connection.HTTPConnection object at 0x7fc01d1aa220>: Failed to establish a new connection: [Errno 111] Connection refused')': /session/af7ef39ab9b0dcf418be7597fa32b139/actions
[2025-03-25T05:56:12.450+0000] {connectionpool.py:823} WARNING - Retrying (Retry(total=1, connect=None, read=None, redirect=None, status=None)) after connection broken by 'NewConnectionError('<urllib3.connection.HTTPConnection object at 0x7fc01d1aa310>: Failed to establish a new connection: [Errno 111] Connection refused')': /session/af7ef39ab9b0dcf418be7597fa32b139/actions
[2025-03-25T05:56:12.452+0000] {connectionpool.py:823} WARNING - Retrying (Retry(total=0, connect=None, read=None, redirect=None, status=None)) after connection broken by 'NewConnectionError('<urllib3.connection.HTTPConnection object at 0x7fc01d198550>: Failed to establish a new connection: [Errno 111] Connection refused')': /session/af7ef39ab9b0dcf418be7597fa32b139/actions
[2025-03-25T05:56:12.455+0000] {logging_mixin.py:151} INFO - Lỗi khi lấy dữ liệu: HTTPConnectionPool(host='localhost', port=59811): Max retries exceeded with url: /session/af7ef39ab9b0dcf418be7597fa32b139/actions (Caused by NewConnectionError('<urllib3.connection.HTTPConnection object at 0x7fc01d198e50>: Failed to establish a new connection: [Errno 111] Connection refused'))
[2025-03-25T05:56:12.458+0000] {connectionpool.py:823} WARNING - Retrying (Retry(total=2, connect=None, read=None, redirect=None, status=None)) after connection broken by 'NewConnectionError('<urllib3.connection.HTTPConnection object at 0x7fc01d198220>: Failed to establish a new connection: [Errno 111] Connection refused')': /session/af7ef39ab9b0dcf418be7597fa32b139/actions
[2025-03-25T05:56:12.462+0000] {connectionpool.py:823} WARNING - Retrying (Retry(total=1, connect=None, read=None, redirect=None, status=None)) after connection broken by 'NewConnectionError('<urllib3.connection.HTTPConnection object at 0x7fc01d201310>: Failed to establish a new connection: [Errno 111] Connection refused')': /session/af7ef39ab9b0dcf418be7597fa32b139/actions
[2025-03-25T05:56:12.465+0000] {connectionpool.py:823} WARNING - Retrying (Retry(total=0, connect=None, read=None, redirect=None, status=None)) after connection broken by 'NewConnectionError('<urllib3.connection.HTTPConnection object at 0x7fc01d201940>: Failed to establish a new connection: [Errno 111] Connection refused')': /session/af7ef39ab9b0dcf418be7597fa32b139/actions
[2025-03-25T05:56:12.468+0000] {logging_mixin.py:151} INFO - Lỗi khi lấy dữ liệu: HTTPConnectionPool(host='localhost', port=59811): Max retries exceeded with url: /session/af7ef39ab9b0dcf418be7597fa32b139/actions (Caused by NewConnectionError('<urllib3.connection.HTTPConnection object at 0x7fc01d201250>: Failed to establish a new connection: [Errno 111] Connection refused'))
[2025-03-25T05:56:12.471+0000] {connectionpool.py:823} WARNING - Retrying (Retry(total=2, connect=None, read=None, redirect=None, status=None)) after connection broken by 'NewConnectionError('<urllib3.connection.HTTPConnection object at 0x7fc01d1e7790>: Failed to establish a new connection: [Errno 111] Connection refused')': /session/af7ef39ab9b0dcf418be7597fa32b139/actions
[2025-03-25T05:56:12.473+0000] {connectionpool.py:823} WARNING - Retrying (Retry(total=1, connect=None, read=None, redirect=None, status=None)) after connection broken by 'NewConnectionError('<urllib3.connection.HTTPConnection object at 0x7fc01d1e76a0>: Failed to establish a new connection: [Errno 111] Connection refused')': /session/af7ef39ab9b0dcf418be7597fa32b139/actions
[2025-03-25T05:56:12.476+0000] {connectionpool.py:823} WARNING - Retrying (Retry(total=0, connect=None, read=None, redirect=None, status=None)) after connection broken by 'NewConnectionError('<urllib3.connection.HTTPConnection object at 0x7fc01d1e7280>: Failed to establish a new connection: [Errno 111] Connection refused')': /session/af7ef39ab9b0dcf418be7597fa32b139/actions
[2025-03-25T05:56:12.480+0000] {logging_mixin.py:151} INFO - Lỗi khi lấy dữ liệu: HTTPConnectionPool(host='localhost', port=59811): Max retries exceeded with url: /session/af7ef39ab9b0dcf418be7597fa32b139/actions (Caused by NewConnectionError('<urllib3.connection.HTTPConnection object at 0x7fc01d1e7550>: Failed to establish a new connection: [Errno 111] Connection refused'))
[2025-03-25T05:56:12.483+0000] {connectionpool.py:823} WARNING - Retrying (Retry(total=2, connect=None, read=None, redirect=None, status=None)) after connection broken by 'NewConnectionError('<urllib3.connection.HTTPConnection object at 0x7fc01d1e7940>: Failed to establish a new connection: [Errno 111] Connection refused')': /session/af7ef39ab9b0dcf418be7597fa32b139/actions
[2025-03-25T05:56:12.486+0000] {connectionpool.py:823} WARNING - Retrying (Retry(total=1, connect=None, read=None, redirect=None, status=None)) after connection broken by 'NewConnectionError('<urllib3.connection.HTTPConnection object at 0x7fc01d1e7190>: Failed to establish a new connection: [Errno 111] Connection refused')': /session/af7ef39ab9b0dcf418be7597fa32b139/actions
[2025-03-25T05:56:12.488+0000] {connectionpool.py:823} WARNING - Retrying (Retry(total=0, connect=None, read=None, redirect=None, status=None)) after connection broken by 'NewConnectionError('<urllib3.connection.HTTPConnection object at 0x7fc01d1e7340>: Failed to establish a new connection: [Errno 111] Connection refused')': /session/af7ef39ab9b0dcf418be7597fa32b139/actions
[2025-03-25T05:56:12.490+0000] {logging_mixin.py:151} INFO - Lỗi khi lấy dữ liệu: HTTPConnectionPool(host='localhost', port=59811): Max retries exceeded with url: /session/af7ef39ab9b0dcf418be7597fa32b139/actions (Caused by NewConnectionError('<urllib3.connection.HTTPConnection object at 0x7fc01d1aa4c0>: Failed to establish a new connection: [Errno 111] Connection refused'))
[2025-03-25T05:56:12.494+0000] {connectionpool.py:823} WARNING - Retrying (Retry(total=2, connect=None, read=None, redirect=None, status=None)) after connection broken by 'NewConnectionError('<urllib3.connection.HTTPConnection object at 0x7fc01d1aa940>: Failed to establish a new connection: [Errno 111] Connection refused')': /session/af7ef39ab9b0dcf418be7597fa32b139/actions
[2025-03-25T05:56:12.498+0000] {connectionpool.py:823} WARNING - Retrying (Retry(total=1, connect=None, read=None, redirect=None, status=None)) after connection broken by 'NewConnectionError('<urllib3.connection.HTTPConnection object at 0x7fc01d1aaa30>: Failed to establish a new connection: [Errno 111] Connection refused')': /session/af7ef39ab9b0dcf418be7597fa32b139/actions
[2025-03-25T05:56:12.501+0000] {connectionpool.py:823} WARNING - Retrying (Retry(total=0, connect=None, read=None, redirect=None, status=None)) after connection broken by 'NewConnectionError('<urllib3.connection.HTTPConnection object at 0x7fc01d1e7760>: Failed to establish a new connection: [Errno 111] Connection refused')': /session/af7ef39ab9b0dcf418be7597fa32b139/actions
[2025-03-25T05:56:12.503+0000] {logging_mixin.py:151} INFO - Lỗi khi lấy dữ liệu: HTTPConnectionPool(host='localhost', port=59811): Max retries exceeded with url: /session/af7ef39ab9b0dcf418be7597fa32b139/actions (Caused by NewConnectionError('<urllib3.connection.HTTPConnection object at 0x7fc01d1e7eb0>: Failed to establish a new connection: [Errno 111] Connection refused'))
[2025-03-25T05:56:12.507+0000] {connectionpool.py:823} WARNING - Retrying (Retry(total=2, connect=None, read=None, redirect=None, status=None)) after connection broken by 'NewConnectionError('<urllib3.connection.HTTPConnection object at 0x7fc01d1e7850>: Failed to establish a new connection: [Errno 111] Connection refused')': /session/af7ef39ab9b0dcf418be7597fa32b139/actions
[2025-03-25T05:56:12.509+0000] {connectionpool.py:823} WARNING - Retrying (Retry(total=1, connect=None, read=None, redirect=None, status=None)) after connection broken by 'NewConnectionError('<urllib3.connection.HTTPConnection object at 0x7fc01d1e72b0>: Failed to establish a new connection: [Errno 111] Connection refused')': /session/af7ef39ab9b0dcf418be7597fa32b139/actions
[2025-03-25T05:56:12.513+0000] {connectionpool.py:823} WARNING - Retrying (Retry(total=0, connect=None, read=None, redirect=None, status=None)) after connection broken by 'NewConnectionError('<urllib3.connection.HTTPConnection object at 0x7fc01d1e7c70>: Failed to establish a new connection: [Errno 111] Connection refused')': /session/af7ef39ab9b0dcf418be7597fa32b139/actions
[2025-03-25T05:56:12.514+0000] {logging_mixin.py:151} INFO - Lỗi khi lấy dữ liệu: HTTPConnectionPool(host='localhost', port=59811): Max retries exceeded with url: /session/af7ef39ab9b0dcf418be7597fa32b139/actions (Caused by NewConnectionError('<urllib3.connection.HTTPConnection object at 0x7fc01d1e7f70>: Failed to establish a new connection: [Errno 111] Connection refused'))
[2025-03-25T05:56:12.516+0000] {connectionpool.py:823} WARNING - Retrying (Retry(total=2, connect=None, read=None, redirect=None, status=None)) after connection broken by 'NewConnectionError('<urllib3.connection.HTTPConnection object at 0x7fc01d201610>: Failed to establish a new connection: [Errno 111] Connection refused')': /session/af7ef39ab9b0dcf418be7597fa32b139/actions
[2025-03-25T05:56:12.518+0000] {process_utils.py:79} INFO - Process psutil.Process(pid=65, status='terminated', started='05:55:23') (65) terminated with exit code None
[2025-03-25T05:56:12.518+0000] {connectionpool.py:823} WARNING - Retrying (Retry(total=1, connect=None, read=None, redirect=None, status=None)) after connection broken by 'NewConnectionError('<urllib3.connection.HTTPConnection object at 0x7fc01d2015b0>: Failed to establish a new connection: [Errno 111] Connection refused')': /session/af7ef39ab9b0dcf418be7597fa32b139/actions
[2025-03-25T05:56:12.520+0000] {connectionpool.py:823} WARNING - Retrying (Retry(total=0, connect=None, read=None, redirect=None, status=None)) after connection broken by 'NewConnectionError('<urllib3.connection.HTTPConnection object at 0x7fc01d201940>: Failed to establish a new connection: [Errno 111] Connection refused')': /session/af7ef39ab9b0dcf418be7597fa32b139/actions
[2025-03-25T05:56:12.522+0000] {logging_mixin.py:151} INFO - Lỗi khi lấy dữ liệu: HTTPConnectionPool(host='localhost', port=59811): Max retries exceeded with url: /session/af7ef39ab9b0dcf418be7597fa32b139/actions (Caused by NewConnectionError('<urllib3.connection.HTTPConnection object at 0x7fc01d2012b0>: Failed to establish a new connection: [Errno 111] Connection refused'))
[2025-03-25T05:56:12.526+0000] {connectionpool.py:823} WARNING - Retrying (Retry(total=2, connect=None, read=None, redirect=None, status=None)) after connection broken by 'NewConnectionError('<urllib3.connection.HTTPConnection object at 0x7fc01d198400>: Failed to establish a new connection: [Errno 111] Connection refused')': /session/af7ef39ab9b0dcf418be7597fa32b139/actions
[2025-03-25T05:56:12.529+0000] {connectionpool.py:823} WARNING - Retrying (Retry(total=1, connect=None, read=None, redirect=None, status=None)) after connection broken by 'NewConnectionError('<urllib3.connection.HTTPConnection object at 0x7fc01d198d60>: Failed to establish a new connection: [Errno 111] Connection refused')': /session/af7ef39ab9b0dcf418be7597fa32b139/actions
[2025-03-25T05:56:12.532+0000] {connectionpool.py:823} WARNING - Retrying (Retry(total=0, connect=None, read=None, redirect=None, status=None)) after connection broken by 'NewConnectionError('<urllib3.connection.HTTPConnection object at 0x7fc01d1aa910>: Failed to establish a new connection: [Errno 111] Connection refused')': /session/af7ef39ab9b0dcf418be7597fa32b139/actions
[2025-03-25T05:56:12.535+0000] {logging_mixin.py:151} INFO - Lỗi khi lấy dữ liệu: HTTPConnectionPool(host='localhost', port=59811): Max retries exceeded with url: /session/af7ef39ab9b0dcf418be7597fa32b139/actions (Caused by NewConnectionError('<urllib3.connection.HTTPConnection object at 0x7fc01d1aa4c0>: Failed to establish a new connection: [Errno 111] Connection refused'))
[2025-03-25T05:56:12.538+0000] {connectionpool.py:823} WARNING - Retrying (Retry(total=2, connect=None, read=None, redirect=None, status=None)) after connection broken by 'NewConnectionError('<urllib3.connection.HTTPConnection object at 0x7fc01d1aaf10>: Failed to establish a new connection: [Errno 111] Connection refused')': /session/af7ef39ab9b0dcf418be7597fa32b139/actions
[2025-03-25T05:56:12.543+0000] {connectionpool.py:823} WARNING - Retrying (Retry(total=1, connect=None, read=None, redirect=None, status=None)) after connection broken by 'NewConnectionError('<urllib3.connection.HTTPConnection object at 0x7fc01d234520>: Failed to establish a new connection: [Errno 111] Connection refused')': /session/af7ef39ab9b0dcf418be7597fa32b139/actions
[2025-03-25T05:56:12.547+0000] {connectionpool.py:823} WARNING - Retrying (Retry(total=0, connect=None, read=None, redirect=None, status=None)) after connection broken by 'NewConnectionError('<urllib3.connection.HTTPConnection object at 0x7fc01d1aa5e0>: Failed to establish a new connection: [Errno 111] Connection refused')': /session/af7ef39ab9b0dcf418be7597fa32b139/actions
[2025-03-25T05:56:12.550+0000] {logging_mixin.py:151} INFO - Lỗi khi lấy dữ liệu: HTTPConnectionPool(host='localhost', port=59811): Max retries exceeded with url: /session/af7ef39ab9b0dcf418be7597fa32b139/actions (Caused by NewConnectionError('<urllib3.connection.HTTPConnection object at 0x7fc01d1aa790>: Failed to establish a new connection: [Errno 111] Connection refused'))
[2025-03-25T05:56:12.553+0000] {connectionpool.py:823} WARNING - Retrying (Retry(total=2, connect=None, read=None, redirect=None, status=None)) after connection broken by 'NewConnectionError('<urllib3.connection.HTTPConnection object at 0x7fc01d1aa7c0>: Failed to establish a new connection: [Errno 111] Connection refused')': /session/af7ef39ab9b0dcf418be7597fa32b139/actions
[2025-03-25T05:56:12.555+0000] {connectionpool.py:823} WARNING - Retrying (Retry(total=1, connect=None, read=None, redirect=None, status=None)) after connection broken by 'NewConnectionError('<urllib3.connection.HTTPConnection object at 0x7fc01d1aa250>: Failed to establish a new connection: [Errno 111] Connection refused')': /session/af7ef39ab9b0dcf418be7597fa32b139/actions
[2025-03-25T05:56:12.557+0000] {connectionpool.py:823} WARNING - Retrying (Retry(total=0, connect=None, read=None, redirect=None, status=None)) after connection broken by 'NewConnectionError('<urllib3.connection.HTTPConnection object at 0x7fc01d1aa2b0>: Failed to establish a new connection: [Errno 111] Connection refused')': /session/af7ef39ab9b0dcf418be7597fa32b139/actions
[2025-03-25T05:56:12.562+0000] {logging_mixin.py:151} INFO - Lỗi khi lấy dữ liệu: HTTPConnectionPool(host='localhost', port=59811): Max retries exceeded with url: /session/af7ef39ab9b0dcf418be7597fa32b139/actions (Caused by NewConnectionError('<urllib3.connection.HTTPConnection object at 0x7fc01d1aa040>: Failed to establish a new connection: [Errno 111] Connection refused'))
[2025-03-25T05:56:12.566+0000] {connectionpool.py:823} WARNING - Retrying (Retry(total=2, connect=None, read=None, redirect=None, status=None)) after connection broken by 'NewConnectionError('<urllib3.connection.HTTPConnection object at 0x7fc01d198370>: Failed to establish a new connection: [Errno 111] Connection refused')': /session/af7ef39ab9b0dcf418be7597fa32b139/actions
[2025-03-25T05:56:12.567+0000] {connectionpool.py:823} WARNING - Retrying (Retry(total=1, connect=None, read=None, redirect=None, status=None)) after connection broken by 'NewConnectionError('<urllib3.connection.HTTPConnection object at 0x7fc01d198490>: Failed to establish a new connection: [Errno 111] Connection refused')': /session/af7ef39ab9b0dcf418be7597fa32b139/actions
[2025-03-25T05:56:12.569+0000] {connectionpool.py:823} WARNING - Retrying (Retry(total=0, connect=None, read=None, redirect=None, status=None)) after connection broken by 'NewConnectionError('<urllib3.connection.HTTPConnection object at 0x7fc01d198310>: Failed to establish a new connection: [Errno 111] Connection refused')': /session/af7ef39ab9b0dcf418be7597fa32b139/actions
[2025-03-25T05:56:12.571+0000] {logging_mixin.py:151} INFO - Lỗi khi lấy dữ liệu: HTTPConnectionPool(host='localhost', port=59811): Max retries exceeded with url: /session/af7ef39ab9b0dcf418be7597fa32b139/actions (Caused by NewConnectionError('<urllib3.connection.HTTPConnection object at 0x7fc01d198eb0>: Failed to establish a new connection: [Errno 111] Connection refused'))
[2025-03-25T05:56:12.573+0000] {connectionpool.py:823} WARNING - Retrying (Retry(total=2, connect=None, read=None, redirect=None, status=None)) after connection broken by 'NewConnectionError('<urllib3.connection.HTTPConnection object at 0x7fc01d198af0>: Failed to establish a new connection: [Errno 111] Connection refused')': /session/af7ef39ab9b0dcf418be7597fa32b139/actions
[2025-03-25T05:56:12.576+0000] {connectionpool.py:823} WARNING - Retrying (Retry(total=1, connect=None, read=None, redirect=None, status=None)) after connection broken by 'NewConnectionError('<urllib3.connection.HTTPConnection object at 0x7fc01d198910>: Failed to establish a new connection: [Errno 111] Connection refused')': /session/af7ef39ab9b0dcf418be7597fa32b139/actions
[2025-03-25T05:56:12.578+0000] {connectionpool.py:823} WARNING - Retrying (Retry(total=0, connect=None, read=None, redirect=None, status=None)) after connection broken by 'NewConnectionError('<urllib3.connection.HTTPConnection object at 0x7fc01d1987c0>: Failed to establish a new connection: [Errno 111] Connection refused')': /session/af7ef39ab9b0dcf418be7597fa32b139/actions
[2025-03-25T05:56:12.580+0000] {logging_mixin.py:151} INFO - Lỗi khi lấy dữ liệu: HTTPConnectionPool(host='localhost', port=59811): Max retries exceeded with url: /session/af7ef39ab9b0dcf418be7597fa32b139/actions (Caused by NewConnectionError('<urllib3.connection.HTTPConnection object at 0x7fc01d198130>: Failed to establish a new connection: [Errno 111] Connection refused'))
[2025-03-25T05:56:12.583+0000] {connectionpool.py:823} WARNING - Retrying (Retry(total=2, connect=None, read=None, redirect=None, status=None)) after connection broken by 'NewConnectionError('<urllib3.connection.HTTPConnection object at 0x7fc01d1e7310>: Failed to establish a new connection: [Errno 111] Connection refused')': /session/af7ef39ab9b0dcf418be7597fa32b139/actions
[2025-03-25T05:56:12.585+0000] {connectionpool.py:823} WARNING - Retrying (Retry(total=1, connect=None, read=None, redirect=None, status=None)) after connection broken by 'NewConnectionError('<urllib3.connection.HTTPConnection object at 0x7fc01d1e7f70>: Failed to establish a new connection: [Errno 111] Connection refused')': /session/af7ef39ab9b0dcf418be7597fa32b139/actions
[2025-03-25T05:56:12.587+0000] {connectionpool.py:823} WARNING - Retrying (Retry(total=0, connect=None, read=None, redirect=None, status=None)) after connection broken by 'NewConnectionError('<urllib3.connection.HTTPConnection object at 0x7fc01d1986d0>: Failed to establish a new connection: [Errno 111] Connection refused')': /session/af7ef39ab9b0dcf418be7597fa32b139/actions
[2025-03-25T05:56:12.590+0000] {logging_mixin.py:151} INFO - Lỗi khi lấy dữ liệu: HTTPConnectionPool(host='localhost', port=59811): Max retries exceeded with url: /session/af7ef39ab9b0dcf418be7597fa32b139/actions (Caused by NewConnectionError('<urllib3.connection.HTTPConnection object at 0x7fc01d198040>: Failed to establish a new connection: [Errno 111] Connection refused'))
[2025-03-25T05:56:12.595+0000] {connectionpool.py:823} WARNING - Retrying (Retry(total=2, connect=None, read=None, redirect=None, status=None)) after connection broken by 'NewConnectionError('<urllib3.connection.HTTPConnection object at 0x7fc01d198c10>: Failed to establish a new connection: [Errno 111] Connection refused')': /session/af7ef39ab9b0dcf418be7597fa32b139/actions
[2025-03-25T05:56:12.598+0000] {connectionpool.py:823} WARNING - Retrying (Retry(total=1, connect=None, read=None, redirect=None, status=None)) after connection broken by 'NewConnectionError('<urllib3.connection.HTTPConnection object at 0x7fc01d198ac0>: Failed to establish a new connection: [Errno 111] Connection refused')': /session/af7ef39ab9b0dcf418be7597fa32b139/actions
[2025-03-25T05:56:12.600+0000] {connectionpool.py:823} WARNING - Retrying (Retry(total=0, connect=None, read=None, redirect=None, status=None)) after connection broken by 'NewConnectionError('<urllib3.connection.HTTPConnection object at 0x7fc01d198610>: Failed to establish a new connection: [Errno 111] Connection refused')': /session/af7ef39ab9b0dcf418be7597fa32b139/actions
[2025-03-25T05:56:12.603+0000] {logging_mixin.py:151} INFO - Lỗi khi lấy dữ liệu: HTTPConnectionPool(host='localhost', port=59811): Max retries exceeded with url: /session/af7ef39ab9b0dcf418be7597fa32b139/actions (Caused by NewConnectionError('<urllib3.connection.HTTPConnection object at 0x7fc01d198e80>: Failed to establish a new connection: [Errno 111] Connection refused'))
[2025-03-25T05:56:12.606+0000] {connectionpool.py:823} WARNING - Retrying (Retry(total=2, connect=None, read=None, redirect=None, status=None)) after connection broken by 'NewConnectionError('<urllib3.connection.HTTPConnection object at 0x7fc01d198280>: Failed to establish a new connection: [Errno 111] Connection refused')': /session/af7ef39ab9b0dcf418be7597fa32b139/actions
[2025-03-25T05:56:12.608+0000] {connectionpool.py:823} WARNING - Retrying (Retry(total=1, connect=None, read=None, redirect=None, status=None)) after connection broken by 'NewConnectionError('<urllib3.connection.HTTPConnection object at 0x7fc01d1aa610>: Failed to establish a new connection: [Errno 111] Connection refused')': /session/af7ef39ab9b0dcf418be7597fa32b139/actions
[2025-03-25T05:56:12.611+0000] {connectionpool.py:823} WARNING - Retrying (Retry(total=0, connect=None, read=None, redirect=None, status=None)) after connection broken by 'NewConnectionError('<urllib3.connection.HTTPConnection object at 0x7fc01d1aa9a0>: Failed to establish a new connection: [Errno 111] Connection refused')': /session/af7ef39ab9b0dcf418be7597fa32b139/actions
[2025-03-25T05:56:12.613+0000] {logging_mixin.py:151} INFO - Lỗi khi lấy dữ liệu: HTTPConnectionPool(host='localhost', port=59811): Max retries exceeded with url: /session/af7ef39ab9b0dcf418be7597fa32b139/actions (Caused by NewConnectionError('<urllib3.connection.HTTPConnection object at 0x7fc01d1aa070>: Failed to establish a new connection: [Errno 111] Connection refused'))
[2025-03-25T05:56:12.615+0000] {connectionpool.py:823} WARNING - Retrying (Retry(total=2, connect=None, read=None, redirect=None, status=None)) after connection broken by 'NewConnectionError('<urllib3.connection.HTTPConnection object at 0x7fc01d1aa820>: Failed to establish a new connection: [Errno 111] Connection refused')': /session/af7ef39ab9b0dcf418be7597fa32b139/actions
[2025-03-25T05:56:12.617+0000] {connectionpool.py:823} WARNING - Retrying (Retry(total=1, connect=None, read=None, redirect=None, status=None)) after connection broken by 'NewConnectionError('<urllib3.connection.HTTPConnection object at 0x7fc01d1aaa30>: Failed to establish a new connection: [Errno 111] Connection refused')': /session/af7ef39ab9b0dcf418be7597fa32b139/actions
[2025-03-25T05:56:12.619+0000] {connectionpool.py:823} WARNING - Retrying (Retry(total=0, connect=None, read=None, redirect=None, status=None)) after connection broken by 'NewConnectionError('<urllib3.connection.HTTPConnection object at 0x7fc01d1aa490>: Failed to establish a new connection: [Errno 111] Connection refused')': /session/af7ef39ab9b0dcf418be7597fa32b139/actions
[2025-03-25T05:56:12.621+0000] {logging_mixin.py:151} INFO - Lỗi khi lấy dữ liệu: HTTPConnectionPool(host='localhost', port=59811): Max retries exceeded with url: /session/af7ef39ab9b0dcf418be7597fa32b139/actions (Caused by NewConnectionError('<urllib3.connection.HTTPConnection object at 0x7fc01d1aa5e0>: Failed to establish a new connection: [Errno 111] Connection refused'))
[2025-03-25T05:56:12.623+0000] {connectionpool.py:823} WARNING - Retrying (Retry(total=2, connect=None, read=None, redirect=None, status=None)) after connection broken by 'NewConnectionError('<urllib3.connection.HTTPConnection object at 0x7fc01d1e7880>: Failed to establish a new connection: [Errno 111] Connection refused')': /session/af7ef39ab9b0dcf418be7597fa32b139/actions
[2025-03-25T05:56:12.626+0000] {connectionpool.py:823} WARNING - Retrying (Retry(total=1, connect=None, read=None, redirect=None, status=None)) after connection broken by 'NewConnectionError('<urllib3.connection.HTTPConnection object at 0x7fc01d1e77f0>: Failed to establish a new connection: [Errno 111] Connection refused')': /session/af7ef39ab9b0dcf418be7597fa32b139/actions
[2025-03-25T05:56:12.629+0000] {connectionpool.py:823} WARNING - Retrying (Retry(total=0, connect=None, read=None, redirect=None, status=None)) after connection broken by 'NewConnectionError('<urllib3.connection.HTTPConnection object at 0x7fc01d1aa850>: Failed to establish a new connection: [Errno 111] Connection refused')': /session/af7ef39ab9b0dcf418be7597fa32b139/actions
[2025-03-25T05:56:12.630+0000] {logging_mixin.py:151} INFO - Lỗi khi lấy dữ liệu: HTTPConnectionPool(host='localhost', port=59811): Max retries exceeded with url: /session/af7ef39ab9b0dcf418be7597fa32b139/actions (Caused by NewConnectionError('<urllib3.connection.HTTPConnection object at 0x7fc01d1aa970>: Failed to establish a new connection: [Errno 111] Connection refused'))
[2025-03-25T05:56:12.632+0000] {connectionpool.py:823} WARNING - Retrying (Retry(total=2, connect=None, read=None, redirect=None, status=None)) after connection broken by 'NewConnectionError('<urllib3.connection.HTTPConnection object at 0x7fc01d1aaee0>: Failed to establish a new connection: [Errno 111] Connection refused')': /session/af7ef39ab9b0dcf418be7597fa32b139/actions
[2025-03-25T05:56:12.633+0000] {connectionpool.py:823} WARNING - Retrying (Retry(total=1, connect=None, read=None, redirect=None, status=None)) after connection broken by 'NewConnectionError('<urllib3.connection.HTTPConnection object at 0x7fc01d1aa2b0>: Failed to establish a new connection: [Errno 111] Connection refused')': /session/af7ef39ab9b0dcf418be7597fa32b139/actions
[2025-03-25T05:56:12.635+0000] {connectionpool.py:823} WARNING - Retrying (Retry(total=0, connect=None, read=None, redirect=None, status=None)) after connection broken by 'NewConnectionError('<urllib3.connection.HTTPConnection object at 0x7fc01d1aa310>: Failed to establish a new connection: [Errno 111] Connection refused')': /session/af7ef39ab9b0dcf418be7597fa32b139/actions
[2025-03-25T05:56:12.636+0000] {logging_mixin.py:151} INFO - Lỗi khi lấy dữ liệu: HTTPConnectionPool(host='localhost', port=59811): Max retries exceeded with url: /session/af7ef39ab9b0dcf418be7597fa32b139/actions (Caused by NewConnectionError('<urllib3.connection.HTTPConnection object at 0x7fc01d1aa9a0>: Failed to establish a new connection: [Errno 111] Connection refused'))
[2025-03-25T05:56:12.638+0000] {connectionpool.py:823} WARNING - Retrying (Retry(total=2, connect=None, read=None, redirect=None, status=None)) after connection broken by 'NewConnectionError('<urllib3.connection.HTTPConnection object at 0x7fc01d198370>: Failed to establish a new connection: [Errno 111] Connection refused')': /session/af7ef39ab9b0dcf418be7597fa32b139/actions
[2025-03-25T05:56:12.639+0000] {connectionpool.py:823} WARNING - Retrying (Retry(total=1, connect=None, read=None, redirect=None, status=None)) after connection broken by 'NewConnectionError('<urllib3.connection.HTTPConnection object at 0x7fc01d198dc0>: Failed to establish a new connection: [Errno 111] Connection refused')': /session/af7ef39ab9b0dcf418be7597fa32b139/actions
[2025-03-25T05:56:12.642+0000] {connectionpool.py:823} WARNING - Retrying (Retry(total=0, connect=None, read=None, redirect=None, status=None)) after connection broken by 'NewConnectionError('<urllib3.connection.HTTPConnection object at 0x7fc01d198970>: Failed to establish a new connection: [Errno 111] Connection refused')': /session/af7ef39ab9b0dcf418be7597fa32b139/actions
[2025-03-25T05:56:12.644+0000] {logging_mixin.py:151} INFO - Lỗi khi lấy dữ liệu: HTTPConnectionPool(host='localhost', port=59811): Max retries exceeded with url: /session/af7ef39ab9b0dcf418be7597fa32b139/actions (Caused by NewConnectionError('<urllib3.connection.HTTPConnection object at 0x7fc01d198fd0>: Failed to establish a new connection: [Errno 111] Connection refused'))
[2025-03-25T05:56:12.647+0000] {connectionpool.py:823} WARNING - Retrying (Retry(total=2, connect=None, read=None, redirect=None, status=None)) after connection broken by 'NewConnectionError('<urllib3.connection.HTTPConnection object at 0x7fc01d1988b0>: Failed to establish a new connection: [Errno 111] Connection refused')': /session/af7ef39ab9b0dcf418be7597fa32b139/actions
[2025-03-25T05:56:12.649+0000] {connectionpool.py:823} WARNING - Retrying (Retry(total=1, connect=None, read=None, redirect=None, status=None)) after connection broken by 'NewConnectionError('<urllib3.connection.HTTPConnection object at 0x7fc01d198790>: Failed to establish a new connection: [Errno 111] Connection refused')': /session/af7ef39ab9b0dcf418be7597fa32b139/actions
[2025-03-25T05:56:12.651+0000] {connectionpool.py:823} WARNING - Retrying (Retry(total=0, connect=None, read=None, redirect=None, status=None)) after connection broken by 'NewConnectionError('<urllib3.connection.HTTPConnection object at 0x7fc01d198760>: Failed to establish a new connection: [Errno 111] Connection refused')': /session/af7ef39ab9b0dcf418be7597fa32b139/actions
[2025-03-25T05:56:12.654+0000] {logging_mixin.py:151} INFO - Lỗi khi lấy dữ liệu: HTTPConnectionPool(host='localhost', port=59811): Max retries exceeded with url: /session/af7ef39ab9b0dcf418be7597fa32b139/actions (Caused by NewConnectionError('<urllib3.connection.HTTPConnection object at 0x7fc01d1986d0>: Failed to establish a new connection: [Errno 111] Connection refused'))
[2025-03-25T05:56:12.656+0000] {connectionpool.py:823} WARNING - Retrying (Retry(total=2, connect=None, read=None, redirect=None, status=None)) after connection broken by 'NewConnectionError('<urllib3.connection.HTTPConnection object at 0x7fc01d1e7a30>: Failed to establish a new connection: [Errno 111] Connection refused')': /session/af7ef39ab9b0dcf418be7597fa32b139/actions
[2025-03-25T05:56:12.659+0000] {connectionpool.py:823} WARNING - Retrying (Retry(total=1, connect=None, read=None, redirect=None, status=None)) after connection broken by 'NewConnectionError('<urllib3.connection.HTTPConnection object at 0x7fc01d1be0d0>: Failed to establish a new connection: [Errno 111] Connection refused')': /session/af7ef39ab9b0dcf418be7597fa32b139/actions
[2025-03-25T05:56:12.662+0000] {connectionpool.py:823} WARNING - Retrying (Retry(total=0, connect=None, read=None, redirect=None, status=None)) after connection broken by 'NewConnectionError('<urllib3.connection.HTTPConnection object at 0x7fc01d198f70>: Failed to establish a new connection: [Errno 111] Connection refused')': /session/af7ef39ab9b0dcf418be7597fa32b139/actions
[2025-03-25T05:56:12.664+0000] {logging_mixin.py:151} INFO - Lỗi khi lấy dữ liệu: HTTPConnectionPool(host='localhost', port=59811): Max retries exceeded with url: /session/af7ef39ab9b0dcf418be7597fa32b139/actions (Caused by NewConnectionError('<urllib3.connection.HTTPConnection object at 0x7fc01d1980d0>: Failed to establish a new connection: [Errno 111] Connection refused'))
[2025-03-25T05:56:12.668+0000] {connectionpool.py:823} WARNING - Retrying (Retry(total=2, connect=None, read=None, redirect=None, status=None)) after connection broken by 'NewConnectionError('<urllib3.connection.HTTPConnection object at 0x7fc01d198c40>: Failed to establish a new connection: [Errno 111] Connection refused')': /session/af7ef39ab9b0dcf418be7597fa32b139/actions
[2025-03-25T05:56:12.670+0000] {connectionpool.py:823} WARNING - Retrying (Retry(total=1, connect=None, read=None, redirect=None, status=None)) after connection broken by 'NewConnectionError('<urllib3.connection.HTTPConnection object at 0x7fc01d198730>: Failed to establish a new connection: [Errno 111] Connection refused')': /session/af7ef39ab9b0dcf418be7597fa32b139/actions
[2025-03-25T05:56:12.672+0000] {connectionpool.py:823} WARNING - Retrying (Retry(total=0, connect=None, read=None, redirect=None, status=None)) after connection broken by 'NewConnectionError('<urllib3.connection.HTTPConnection object at 0x7fc01d1985e0>: Failed to establish a new connection: [Errno 111] Connection refused')': /session/af7ef39ab9b0dcf418be7597fa32b139/actions
[2025-03-25T05:56:12.674+0000] {logging_mixin.py:151} INFO - Lỗi khi lấy dữ liệu: HTTPConnectionPool(host='localhost', port=59811): Max retries exceeded with url: /session/af7ef39ab9b0dcf418be7597fa32b139/actions (Caused by NewConnectionError('<urllib3.connection.HTTPConnection object at 0x7fc01d198fd0>: Failed to establish a new connection: [Errno 111] Connection refused'))
[2025-03-25T05:56:12.678+0000] {connectionpool.py:823} WARNING - Retrying (Retry(total=2, connect=None, read=None, redirect=None, status=None)) after connection broken by 'NewConnectionError('<urllib3.connection.HTTPConnection object at 0x7fc01d198280>: Failed to establish a new connection: [Errno 111] Connection refused')': /session/af7ef39ab9b0dcf418be7597fa32b139/actions
[2025-03-25T05:56:12.681+0000] {connectionpool.py:823} WARNING - Retrying (Retry(total=1, connect=None, read=None, redirect=None, status=None)) after connection broken by 'NewConnectionError('<urllib3.connection.HTTPConnection object at 0x7fc01d1aa400>: Failed to establish a new connection: [Errno 111] Connection refused')': /session/af7ef39ab9b0dcf418be7597fa32b139/actions
[2025-03-25T05:56:12.683+0000] {connectionpool.py:823} WARNING - Retrying (Retry(total=0, connect=None, read=None, redirect=None, status=None)) after connection broken by 'NewConnectionError('<urllib3.connection.HTTPConnection object at 0x7fc01d1aa760>: Failed to establish a new connection: [Errno 111] Connection refused')': /session/af7ef39ab9b0dcf418be7597fa32b139/actions
[2025-03-25T05:56:12.685+0000] {logging_mixin.py:151} INFO - Lỗi khi lấy dữ liệu: HTTPConnectionPool(host='localhost', port=59811): Max retries exceeded with url: /session/af7ef39ab9b0dcf418be7597fa32b139/actions (Caused by NewConnectionError('<urllib3.connection.HTTPConnection object at 0x7fc01d1aa190>: Failed to establish a new connection: [Errno 111] Connection refused'))
[2025-03-25T05:56:12.688+0000] {connectionpool.py:823} WARNING - Retrying (Retry(total=2, connect=None, read=None, redirect=None, status=None)) after connection broken by 'NewConnectionError('<urllib3.connection.HTTPConnection object at 0x7fc01d1aaaf0>: Failed to establish a new connection: [Errno 111] Connection refused')': /session/af7ef39ab9b0dcf418be7597fa32b139/actions
[2025-03-25T05:56:12.690+0000] {connectionpool.py:823} WARNING - Retrying (Retry(total=1, connect=None, read=None, redirect=None, status=None)) after connection broken by 'NewConnectionError('<urllib3.connection.HTTPConnection object at 0x7fc01d1aaa30>: Failed to establish a new connection: [Errno 111] Connection refused')': /session/af7ef39ab9b0dcf418be7597fa32b139/actions
[2025-03-25T05:56:12.693+0000] {connectionpool.py:823} WARNING - Retrying (Retry(total=0, connect=None, read=None, redirect=None, status=None)) after connection broken by 'NewConnectionError('<urllib3.connection.HTTPConnection object at 0x7fc01d1aa6a0>: Failed to establish a new connection: [Errno 111] Connection refused')': /session/af7ef39ab9b0dcf418be7597fa32b139/actions
[2025-03-25T05:56:12.696+0000] {logging_mixin.py:151} INFO - Lỗi khi lấy dữ liệu: HTTPConnectionPool(host='localhost', port=59811): Max retries exceeded with url: /session/af7ef39ab9b0dcf418be7597fa32b139/actions (Caused by NewConnectionError('<urllib3.connection.HTTPConnection object at 0x7fc01d1aa850>: Failed to establish a new connection: [Errno 111] Connection refused'))
[2025-03-25T05:56:12.698+0000] {connectionpool.py:823} WARNING - Retrying (Retry(total=2, connect=None, read=None, redirect=None, status=None)) after connection broken by 'NewConnectionError('<urllib3.connection.HTTPConnection object at 0x7fc01d1be5b0>: Failed to establish a new connection: [Errno 111] Connection refused')': /session/af7ef39ab9b0dcf418be7597fa32b139/actions
[2025-03-25T05:56:12.700+0000] {connectionpool.py:823} WARNING - Retrying (Retry(total=1, connect=None, read=None, redirect=None, status=None)) after connection broken by 'NewConnectionError('<urllib3.connection.HTTPConnection object at 0x7fc01d1be6a0>: Failed to establish a new connection: [Errno 111] Connection refused')': /session/af7ef39ab9b0dcf418be7597fa32b139/actions
[2025-03-25T05:56:12.702+0000] {connectionpool.py:823} WARNING - Retrying (Retry(total=0, connect=None, read=None, redirect=None, status=None)) after connection broken by 'NewConnectionError('<urllib3.connection.HTTPConnection object at 0x7fc01d1aa8b0>: Failed to establish a new connection: [Errno 111] Connection refused')': /session/af7ef39ab9b0dcf418be7597fa32b139/actions
[2025-03-25T05:56:12.703+0000] {logging_mixin.py:151} INFO - Lỗi khi lấy dữ liệu: HTTPConnectionPool(host='localhost', port=59811): Max retries exceeded with url: /session/af7ef39ab9b0dcf418be7597fa32b139/actions (Caused by NewConnectionError('<urllib3.connection.HTTPConnection object at 0x7fc01d1aa280>: Failed to establish a new connection: [Errno 111] Connection refused'))
[2025-03-25T05:56:12.705+0000] {connectionpool.py:823} WARNING - Retrying (Retry(total=2, connect=None, read=None, redirect=None, status=None)) after connection broken by 'NewConnectionError('<urllib3.connection.HTTPConnection object at 0x7fc01d1aa730>: Failed to establish a new connection: [Errno 111] Connection refused')': /session/af7ef39ab9b0dcf418be7597fa32b139/actions
[2025-03-25T05:56:12.707+0000] {connectionpool.py:823} WARNING - Retrying (Retry(total=1, connect=None, read=None, redirect=None, status=None)) after connection broken by 'NewConnectionError('<urllib3.connection.HTTPConnection object at 0x7fc01d1aa2b0>: Failed to establish a new connection: [Errno 111] Connection refused')': /session/af7ef39ab9b0dcf418be7597fa32b139/actions
[2025-03-25T05:56:12.709+0000] {connectionpool.py:823} WARNING - Retrying (Retry(total=0, connect=None, read=None, redirect=None, status=None)) after connection broken by 'NewConnectionError('<urllib3.connection.HTTPConnection object at 0x7fc01d1aa220>: Failed to establish a new connection: [Errno 111] Connection refused')': /session/af7ef39ab9b0dcf418be7597fa32b139/actions
[2025-03-25T05:56:12.713+0000] {logging_mixin.py:151} INFO - Lỗi khi lấy dữ liệu: HTTPConnectionPool(host='localhost', port=59811): Max retries exceeded with url: /session/af7ef39ab9b0dcf418be7597fa32b139/actions (Caused by NewConnectionError('<urllib3.connection.HTTPConnection object at 0x7fc01d1aa400>: Failed to establish a new connection: [Errno 111] Connection refused'))
[2025-03-25T05:56:12.716+0000] {connectionpool.py:823} WARNING - Retrying (Retry(total=2, connect=None, read=None, redirect=None, status=None)) after connection broken by 'NewConnectionError('<urllib3.connection.HTTPConnection object at 0x7fc01d1982e0>: Failed to establish a new connection: [Errno 111] Connection refused')': /session/af7ef39ab9b0dcf418be7597fa32b139/actions
[2025-03-25T05:56:12.719+0000] {connectionpool.py:823} WARNING - Retrying (Retry(total=1, connect=None, read=None, redirect=None, status=None)) after connection broken by 'NewConnectionError('<urllib3.connection.HTTPConnection object at 0x7fc01d198460>: Failed to establish a new connection: [Errno 111] Connection refused')': /session/af7ef39ab9b0dcf418be7597fa32b139/actions
[2025-03-25T05:56:12.720+0000] {connectionpool.py:823} WARNING - Retrying (Retry(total=0, connect=None, read=None, redirect=None, status=None)) after connection broken by 'NewConnectionError('<urllib3.connection.HTTPConnection object at 0x7fc01d198670>: Failed to establish a new connection: [Errno 111] Connection refused')': /session/af7ef39ab9b0dcf418be7597fa32b139/actions
[2025-03-25T05:56:12.722+0000] {logging_mixin.py:151} INFO - Lỗi khi lấy dữ liệu: HTTPConnectionPool(host='localhost', port=59811): Max retries exceeded with url: /session/af7ef39ab9b0dcf418be7597fa32b139/actions (Caused by NewConnectionError('<urllib3.connection.HTTPConnection object at 0x7fc01d198fd0>: Failed to establish a new connection: [Errno 111] Connection refused'))
[2025-03-25T05:56:12.724+0000] {connectionpool.py:823} WARNING - Retrying (Retry(total=2, connect=None, read=None, redirect=None, status=None)) after connection broken by 'NewConnectionError('<urllib3.connection.HTTPConnection object at 0x7fc01d1980a0>: Failed to establish a new connection: [Errno 111] Connection refused')': /session/af7ef39ab9b0dcf418be7597fa32b139/actions
[2025-03-25T05:56:12.726+0000] {connectionpool.py:823} WARNING - Retrying (Retry(total=1, connect=None, read=None, redirect=None, status=None)) after connection broken by 'NewConnectionError('<urllib3.connection.HTTPConnection object at 0x7fc01d1988b0>: Failed to establish a new connection: [Errno 111] Connection refused')': /session/af7ef39ab9b0dcf418be7597fa32b139/actions
[2025-03-25T05:56:12.727+0000] {connectionpool.py:823} WARNING - Retrying (Retry(total=0, connect=None, read=None, redirect=None, status=None)) after connection broken by 'NewConnectionError('<urllib3.connection.HTTPConnection object at 0x7fc01d1980d0>: Failed to establish a new connection: [Errno 111] Connection refused')': /session/af7ef39ab9b0dcf418be7597fa32b139/actions
[2025-03-25T05:56:12.731+0000] {logging_mixin.py:151} INFO - Lỗi khi lấy dữ liệu: HTTPConnectionPool(host='localhost', port=59811): Max retries exceeded with url: /session/af7ef39ab9b0dcf418be7597fa32b139/actions (Caused by NewConnectionError('<urllib3.connection.HTTPConnection object at 0x7fc01d1be880>: Failed to establish a new connection: [Errno 111] Connection refused'))
[2025-03-25T05:56:12.733+0000] {connectionpool.py:823} WARNING - Retrying (Retry(total=2, connect=None, read=None, redirect=None, status=None)) after connection broken by 'NewConnectionError('<urllib3.connection.HTTPConnection object at 0x7fc01d1beb80>: Failed to establish a new connection: [Errno 111] Connection refused')': /session/af7ef39ab9b0dcf418be7597fa32b139/actions
[2025-03-25T05:56:12.734+0000] {connectionpool.py:823} WARNING - Retrying (Retry(total=1, connect=None, read=None, redirect=None, status=None)) after connection broken by 'NewConnectionError('<urllib3.connection.HTTPConnection object at 0x7fc01d1bec70>: Failed to establish a new connection: [Errno 111] Connection refused')': /session/af7ef39ab9b0dcf418be7597fa32b139/actions
[2025-03-25T05:56:12.736+0000] {connectionpool.py:823} WARNING - Retrying (Retry(total=0, connect=None, read=None, redirect=None, status=None)) after connection broken by 'NewConnectionError('<urllib3.connection.HTTPConnection object at 0x7fc01d198550>: Failed to establish a new connection: [Errno 111] Connection refused')': /session/af7ef39ab9b0dcf418be7597fa32b139/actions
[2025-03-25T05:56:12.737+0000] {logging_mixin.py:151} INFO - Lỗi khi lấy dữ liệu: HTTPConnectionPool(host='localhost', port=59811): Max retries exceeded with url: /session/af7ef39ab9b0dcf418be7597fa32b139/actions (Caused by NewConnectionError('<urllib3.connection.HTTPConnection object at 0x7fc01d198f70>: Failed to establish a new connection: [Errno 111] Connection refused'))
[2025-03-25T05:56:12.738+0000] {connectionpool.py:823} WARNING - Retrying (Retry(total=2, connect=None, read=None, redirect=None, status=None)) after connection broken by 'NewConnectionError('<urllib3.connection.HTTPConnection object at 0x7fc01d1981f0>: Failed to establish a new connection: [Errno 111] Connection refused')': /session/af7ef39ab9b0dcf418be7597fa32b139/actions
[2025-03-25T05:56:12.740+0000] {connectionpool.py:823} WARNING - Retrying (Retry(total=1, connect=None, read=None, redirect=None, status=None)) after connection broken by 'NewConnectionError('<urllib3.connection.HTTPConnection object at 0x7fc01d198220>: Failed to establish a new connection: [Errno 111] Connection refused')': /session/af7ef39ab9b0dcf418be7597fa32b139/actions
[2025-03-25T05:56:12.742+0000] {connectionpool.py:823} WARNING - Retrying (Retry(total=0, connect=None, read=None, redirect=None, status=None)) after connection broken by 'NewConnectionError('<urllib3.connection.HTTPConnection object at 0x7fc01d198c70>: Failed to establish a new connection: [Errno 111] Connection refused')': /session/af7ef39ab9b0dcf418be7597fa32b139/actions
[2025-03-25T05:56:12.744+0000] {logging_mixin.py:151} INFO - Lỗi khi lấy dữ liệu: HTTPConnectionPool(host='localhost', port=59811): Max retries exceeded with url: /session/af7ef39ab9b0dcf418be7597fa32b139/actions (Caused by NewConnectionError('<urllib3.connection.HTTPConnection object at 0x7fc01d198670>: Failed to establish a new connection: [Errno 111] Connection refused'))
[2025-03-25T05:56:12.747+0000] {connectionpool.py:823} WARNING - Retrying (Retry(total=2, connect=None, read=None, redirect=None, status=None)) after connection broken by 'NewConnectionError('<urllib3.connection.HTTPConnection object at 0x7fc01d198dc0>: Failed to establish a new connection: [Errno 111] Connection refused')': /session/af7ef39ab9b0dcf418be7597fa32b139/url
[2025-03-25T05:56:12.749+0000] {connectionpool.py:823} WARNING - Retrying (Retry(total=1, connect=None, read=None, redirect=None, status=None)) after connection broken by 'NewConnectionError('<urllib3.connection.HTTPConnection object at 0x7fc01d198d90>: Failed to establish a new connection: [Errno 111] Connection refused')': /session/af7ef39ab9b0dcf418be7597fa32b139/url
[2025-03-25T05:56:12.751+0000] {connectionpool.py:823} WARNING - Retrying (Retry(total=0, connect=None, read=None, redirect=None, status=None)) after connection broken by 'NewConnectionError('<urllib3.connection.HTTPConnection object at 0x7fc01d1984f0>: Failed to establish a new connection: [Errno 111] Connection refused')': /session/af7ef39ab9b0dcf418be7597fa32b139/url
[2025-03-25T05:56:12.754+0000] {data_stream.py:39} ERROR - An error occurred: HTTPConnectionPool(host='localhost', port=59811): Max retries exceeded with url: /session/af7ef39ab9b0dcf418be7597fa32b139/url (Caused by NewConnectionError('<urllib3.connection.HTTPConnection object at 0x7fc01d198190>: Failed to establish a new connection: [Errno 111] Connection refused'))
[2025-03-25T05:56:12.755+0000] {python.py:194} INFO - Done. Returned value was: None
[2025-03-25T05:56:12.785+0000] {taskinstance.py:1400} INFO - Marking task as SUCCESS. dag_id=job_data_stream, task_id=job_data_stream, execution_date=20250325T055521, start_date=20250325T055522, end_date=20250325T055612
[2025-03-25T05:56:12.821+0000] {process_utils.py:79} INFO - Process psutil.Process(pid=53, status='terminated', started='05:55:23') (53) terminated with exit code None
[2025-03-25T05:56:12.821+0000] {process_utils.py:79} INFO - Process psutil.Process(pid=51, status='terminated', exitcode=0, started='05:55:22') (51) terminated with exit code 0
[2025-03-25T05:56:12.822+0000] {local_task_job_runner.py:228} INFO - Task exited with return code 143
[2025-03-25T05:56:12.851+0000] {taskinstance.py:2784} INFO - 0 downstream tasks scheduled from follow-on schedule check
