[2025-04-01T06:49:59.815+0000] {taskinstance.py:1159} INFO - Dependencies all met for dep_context=non-requeueable deps ti=<TaskInstance: job_data_stream.job_data_stream manual__2025-04-01T06:49:58.357412+00:00 [queued]>
[2025-04-01T06:49:59.825+0000] {taskinstance.py:1159} INFO - Dependencies all met for dep_context=requeueable deps ti=<TaskInstance: job_data_stream.job_data_stream manual__2025-04-01T06:49:58.357412+00:00 [queued]>
[2025-04-01T06:49:59.825+0000] {taskinstance.py:1361} INFO - Starting attempt 1 of 1
[2025-04-01T06:49:59.842+0000] {taskinstance.py:1382} INFO - Executing <Task(PythonOperator): job_data_stream> on 2025-04-01 06:49:58.357412+00:00
[2025-04-01T06:49:59.846+0000] {standard_task_runner.py:57} INFO - Started process 52 to run task
[2025-04-01T06:49:59.850+0000] {standard_task_runner.py:84} INFO - Running: ['***', 'tasks', 'run', 'job_data_stream', 'job_data_stream', 'manual__2025-04-01T06:49:58.357412+00:00', '--job-id', '63', '--raw', '--subdir', 'DAGS_FOLDER/data_stream.py', '--cfg-path', '/tmp/tmp5224vurq']
[2025-04-01T06:49:59.852+0000] {standard_task_runner.py:85} INFO - Job 63: Subtask job_data_stream
[2025-04-01T06:49:59.927+0000] {task_command.py:415} INFO - Running <TaskInstance: job_data_stream.job_data_stream manual__2025-04-01T06:49:58.357412+00:00 [running]> on host d37500fbf577
[2025-04-01T06:50:00.044+0000] {taskinstance.py:1660} INFO - Exporting env vars: AIRFLOW_CTX_DAG_OWNER='dii' AIRFLOW_CTX_DAG_ID='job_data_stream' AIRFLOW_CTX_TASK_ID='job_data_stream' AIRFLOW_CTX_EXECUTION_DATE='2025-04-01T06:49:58.357412+00:00' AIRFLOW_CTX_TRY_NUMBER='1' AIRFLOW_CTX_DAG_RUN_ID='manual__2025-04-01T06:49:58.357412+00:00'
[2025-04-01T06:50:00.049+0000] {conn.py:384} INFO - <BrokerConnection client_id=kafka-python-producer-1, node_id=bootstrap-0 host=broker:29092 <connecting> [IPv4 ('172.18.0.6', 29092)]>: connecting to broker:29092 [('172.18.0.6', 29092) IPv4]
[2025-04-01T06:50:00.050+0000] {conn.py:1219} INFO - Probing node bootstrap-0 broker version
[2025-04-01T06:50:00.052+0000] {conn.py:414} INFO - <BrokerConnection client_id=kafka-python-producer-1, node_id=bootstrap-0 host=broker:29092 <connecting> [IPv4 ('172.18.0.6', 29092)]>: Connection complete.
[2025-04-01T06:50:00.187+0000] {conn.py:1282} INFO - Broker version identified as 2.6.0
[2025-04-01T06:50:00.188+0000] {conn.py:1283} INFO - Set configuration api_version=(2, 6, 0) to skip auto check_version requests on startup
[2025-04-01T06:50:13.694+0000] {logging_mixin.py:151} INFO - Số công việc tìm thấy trên trang 401:70
[2025-04-01T06:50:33.847+0000] {local_task_job_runner.py:115} ERROR - Received SIGTERM. Terminating subprocesses
[2025-04-01T06:50:33.864+0000] {process_utils.py:131} INFO - Sending 15 to group 52. PIDs of all processes in the group: [54, 60, 65, 66, 75, 76, 98, 180, 122, 147, 156, 171, 194, 208, 219, 96, 52]
[2025-04-01T06:50:33.867+0000] {process_utils.py:86} INFO - Sending the signal 15 to group 52
[2025-04-01T06:50:33.870+0000] {taskinstance.py:1632} ERROR - Received SIGTERM. Terminating subprocesses.
[2025-04-01T06:50:33.891+0000] {logging_mixin.py:151} INFO - Lỗi khi lấy dữ liệu: Task received SIGTERM signal
[2025-04-01T06:50:33.913+0000] {process_utils.py:79} INFO - Process psutil.Process(pid=122, status='terminated', started='06:50:00') (122) terminated with exit code None
[2025-04-01T06:50:33.926+0000] {connectionpool.py:823} WARNING - Retrying (Retry(total=2, connect=None, read=None, redirect=None, status=None)) after connection broken by 'NewConnectionError('<urllib3.connection.HTTPConnection object at 0x7fd4e34301f0>: Failed to establish a new connection: [Errno 111] Connection refused')': /session/d803562141e0fe33d1b8b54dd081e0b9/actions
[2025-04-01T06:50:33.938+0000] {connectionpool.py:823} WARNING - Retrying (Retry(total=1, connect=None, read=None, redirect=None, status=None)) after connection broken by 'NewConnectionError('<urllib3.connection.HTTPConnection object at 0x7fd4e3430400>: Failed to establish a new connection: [Errno 111] Connection refused')': /session/d803562141e0fe33d1b8b54dd081e0b9/actions
[2025-04-01T06:50:33.947+0000] {connectionpool.py:823} WARNING - Retrying (Retry(total=0, connect=None, read=None, redirect=None, status=None)) after connection broken by 'NewConnectionError('<urllib3.connection.HTTPConnection object at 0x7fd4e34302e0>: Failed to establish a new connection: [Errno 111] Connection refused')': /session/d803562141e0fe33d1b8b54dd081e0b9/actions
[2025-04-01T06:50:33.952+0000] {logging_mixin.py:151} INFO - Lỗi khi lấy dữ liệu: HTTPConnectionPool(host='localhost', port=49435): Max retries exceeded with url: /session/d803562141e0fe33d1b8b54dd081e0b9/actions (Caused by NewConnectionError('<urllib3.connection.HTTPConnection object at 0x7fd4e3430760>: Failed to establish a new connection: [Errno 111] Connection refused'))
[2025-04-01T06:50:33.960+0000] {connectionpool.py:823} WARNING - Retrying (Retry(total=2, connect=None, read=None, redirect=None, status=None)) after connection broken by 'NewConnectionError('<urllib3.connection.HTTPConnection object at 0x7fd4e3430bb0>: Failed to establish a new connection: [Errno 111] Connection refused')': /session/d803562141e0fe33d1b8b54dd081e0b9/actions
[2025-04-01T06:50:33.963+0000] {connectionpool.py:823} WARNING - Retrying (Retry(total=1, connect=None, read=None, redirect=None, status=None)) after connection broken by 'NewConnectionError('<urllib3.connection.HTTPConnection object at 0x7fd4e3430ca0>: Failed to establish a new connection: [Errno 111] Connection refused')': /session/d803562141e0fe33d1b8b54dd081e0b9/actions
[2025-04-01T06:50:33.975+0000] {connectionpool.py:823} WARNING - Retrying (Retry(total=0, connect=None, read=None, redirect=None, status=None)) after connection broken by 'NewConnectionError('<urllib3.connection.HTTPConnection object at 0x7fd4e347d760>: Failed to establish a new connection: [Errno 111] Connection refused')': /session/d803562141e0fe33d1b8b54dd081e0b9/actions
[2025-04-01T06:50:33.978+0000] {logging_mixin.py:151} INFO - Lỗi khi lấy dữ liệu: HTTPConnectionPool(host='localhost', port=49435): Max retries exceeded with url: /session/d803562141e0fe33d1b8b54dd081e0b9/actions (Caused by NewConnectionError('<urllib3.connection.HTTPConnection object at 0x7fd4e34304f0>: Failed to establish a new connection: [Errno 111] Connection refused'))
[2025-04-01T06:50:33.986+0000] {connectionpool.py:823} WARNING - Retrying (Retry(total=2, connect=None, read=None, redirect=None, status=None)) after connection broken by 'NewConnectionError('<urllib3.connection.HTTPConnection object at 0x7fd4e34301f0>: Failed to establish a new connection: [Errno 111] Connection refused')': /session/d803562141e0fe33d1b8b54dd081e0b9/actions
[2025-04-01T06:50:33.991+0000] {connectionpool.py:823} WARNING - Retrying (Retry(total=1, connect=None, read=None, redirect=None, status=None)) after connection broken by 'NewConnectionError('<urllib3.connection.HTTPConnection object at 0x7fd4e34302b0>: Failed to establish a new connection: [Errno 111] Connection refused')': /session/d803562141e0fe33d1b8b54dd081e0b9/actions
[2025-04-01T06:50:33.997+0000] {connectionpool.py:823} WARNING - Retrying (Retry(total=0, connect=None, read=None, redirect=None, status=None)) after connection broken by 'NewConnectionError('<urllib3.connection.HTTPConnection object at 0x7fd4e34303a0>: Failed to establish a new connection: [Errno 111] Connection refused')': /session/d803562141e0fe33d1b8b54dd081e0b9/actions
[2025-04-01T06:50:33.994+0000] {process_utils.py:79} INFO - Process psutil.Process(pid=208, status='terminated', started='06:50:04') (208) terminated with exit code None
[2025-04-01T06:50:34.005+0000] {logging_mixin.py:151} INFO - Lỗi khi lấy dữ liệu: HTTPConnectionPool(host='localhost', port=49435): Max retries exceeded with url: /session/d803562141e0fe33d1b8b54dd081e0b9/actions (Caused by NewConnectionError('<urllib3.connection.HTTPConnection object at 0x7fd4e3430f70>: Failed to establish a new connection: [Errno 111] Connection refused'))
[2025-04-01T06:50:34.008+0000] {connectionpool.py:823} WARNING - Retrying (Retry(total=2, connect=None, read=None, redirect=None, status=None)) after connection broken by 'NewConnectionError('<urllib3.connection.HTTPConnection object at 0x7fd4e3448400>: Failed to establish a new connection: [Errno 111] Connection refused')': /session/d803562141e0fe33d1b8b54dd081e0b9/actions
[2025-04-01T06:50:34.013+0000] {connectionpool.py:823} WARNING - Retrying (Retry(total=1, connect=None, read=None, redirect=None, status=None)) after connection broken by 'NewConnectionError('<urllib3.connection.HTTPConnection object at 0x7fd4e34484f0>: Failed to establish a new connection: [Errno 111] Connection refused')': /session/d803562141e0fe33d1b8b54dd081e0b9/actions
[2025-04-01T06:50:34.021+0000] {connectionpool.py:823} WARNING - Retrying (Retry(total=0, connect=None, read=None, redirect=None, status=None)) after connection broken by 'NewConnectionError('<urllib3.connection.HTTPConnection object at 0x7fd4e3448670>: Failed to establish a new connection: [Errno 111] Connection refused')': /session/d803562141e0fe33d1b8b54dd081e0b9/actions
[2025-04-01T06:50:34.026+0000] {logging_mixin.py:151} INFO - Lỗi khi lấy dữ liệu: HTTPConnectionPool(host='localhost', port=49435): Max retries exceeded with url: /session/d803562141e0fe33d1b8b54dd081e0b9/actions (Caused by NewConnectionError('<urllib3.connection.HTTPConnection object at 0x7fd4e34487c0>: Failed to establish a new connection: [Errno 111] Connection refused'))
[2025-04-01T06:50:34.031+0000] {connectionpool.py:823} WARNING - Retrying (Retry(total=2, connect=None, read=None, redirect=None, status=None)) after connection broken by 'NewConnectionError('<urllib3.connection.HTTPConnection object at 0x7fd4e3448c10>: Failed to establish a new connection: [Errno 111] Connection refused')': /session/d803562141e0fe33d1b8b54dd081e0b9/actions
[2025-04-01T06:50:34.035+0000] {connectionpool.py:823} WARNING - Retrying (Retry(total=1, connect=None, read=None, redirect=None, status=None)) after connection broken by 'NewConnectionError('<urllib3.connection.HTTPConnection object at 0x7fd4e3448d00>: Failed to establish a new connection: [Errno 111] Connection refused')': /session/d803562141e0fe33d1b8b54dd081e0b9/actions
[2025-04-01T06:50:34.042+0000] {connectionpool.py:823} WARNING - Retrying (Retry(total=0, connect=None, read=None, redirect=None, status=None)) after connection broken by 'NewConnectionError('<urllib3.connection.HTTPConnection object at 0x7fd4e3448e80>: Failed to establish a new connection: [Errno 111] Connection refused')': /session/d803562141e0fe33d1b8b54dd081e0b9/actions
[2025-04-01T06:50:34.047+0000] {logging_mixin.py:151} INFO - Lỗi khi lấy dữ liệu: HTTPConnectionPool(host='localhost', port=49435): Max retries exceeded with url: /session/d803562141e0fe33d1b8b54dd081e0b9/actions (Caused by NewConnectionError('<urllib3.connection.HTTPConnection object at 0x7fd4e33e0040>: Failed to establish a new connection: [Errno 111] Connection refused'))
[2025-04-01T06:50:34.052+0000] {connectionpool.py:823} WARNING - Retrying (Retry(total=2, connect=None, read=None, redirect=None, status=None)) after connection broken by 'NewConnectionError('<urllib3.connection.HTTPConnection object at 0x7fd4e34485e0>: Failed to establish a new connection: [Errno 111] Connection refused')': /session/d803562141e0fe33d1b8b54dd081e0b9/actions
[2025-04-01T06:50:34.057+0000] {connectionpool.py:823} WARNING - Retrying (Retry(total=1, connect=None, read=None, redirect=None, status=None)) after connection broken by 'NewConnectionError('<urllib3.connection.HTTPConnection object at 0x7fd4e3448460>: Failed to establish a new connection: [Errno 111] Connection refused')': /session/d803562141e0fe33d1b8b54dd081e0b9/actions
[2025-04-01T06:50:34.060+0000] {connectionpool.py:823} WARNING - Retrying (Retry(total=0, connect=None, read=None, redirect=None, status=None)) after connection broken by 'NewConnectionError('<urllib3.connection.HTTPConnection object at 0x7fd4e3448340>: Failed to establish a new connection: [Errno 111] Connection refused')': /session/d803562141e0fe33d1b8b54dd081e0b9/actions
[2025-04-01T06:50:34.062+0000] {logging_mixin.py:151} INFO - Lỗi khi lấy dữ liệu: HTTPConnectionPool(host='localhost', port=49435): Max retries exceeded with url: /session/d803562141e0fe33d1b8b54dd081e0b9/actions (Caused by NewConnectionError('<urllib3.connection.HTTPConnection object at 0x7fd4e34482b0>: Failed to establish a new connection: [Errno 111] Connection refused'))
[2025-04-01T06:50:34.065+0000] {connectionpool.py:823} WARNING - Retrying (Retry(total=2, connect=None, read=None, redirect=None, status=None)) after connection broken by 'NewConnectionError('<urllib3.connection.HTTPConnection object at 0x7fd4e3430160>: Failed to establish a new connection: [Errno 111] Connection refused')': /session/d803562141e0fe33d1b8b54dd081e0b9/actions
[2025-04-01T06:50:34.067+0000] {process_utils.py:79} INFO - Process psutil.Process(pid=65, status='terminated', started='06:49:59') (65) terminated with exit code None
[2025-04-01T06:50:34.071+0000] {process_utils.py:79} INFO - Process psutil.Process(pid=60, status='terminated', started='06:49:59') (60) terminated with exit code None
[2025-04-01T06:50:34.077+0000] {process_utils.py:79} INFO - Process psutil.Process(pid=75, status='terminated', started='06:50:00') (75) terminated with exit code None
[2025-04-01T06:50:34.073+0000] {connectionpool.py:823} WARNING - Retrying (Retry(total=1, connect=None, read=None, redirect=None, status=None)) after connection broken by 'NewConnectionError('<urllib3.connection.HTTPConnection object at 0x7fd4e34300d0>: Failed to establish a new connection: [Errno 111] Connection refused')': /session/d803562141e0fe33d1b8b54dd081e0b9/actions
[2025-04-01T06:50:34.081+0000] {process_utils.py:79} INFO - Process psutil.Process(pid=194, status='terminated', started='06:50:04') (194) terminated with exit code None
[2025-04-01T06:50:34.084+0000] {connectionpool.py:823} WARNING - Retrying (Retry(total=0, connect=None, read=None, redirect=None, status=None)) after connection broken by 'NewConnectionError('<urllib3.connection.HTTPConnection object at 0x7fd4e3430850>: Failed to establish a new connection: [Errno 111] Connection refused')': /session/d803562141e0fe33d1b8b54dd081e0b9/actions
[2025-04-01T06:50:34.091+0000] {logging_mixin.py:151} INFO - Lỗi khi lấy dữ liệu: HTTPConnectionPool(host='localhost', port=49435): Max retries exceeded with url: /session/d803562141e0fe33d1b8b54dd081e0b9/actions (Caused by NewConnectionError('<urllib3.connection.HTTPConnection object at 0x7fd4e34306d0>: Failed to establish a new connection: [Errno 111] Connection refused'))
[2025-04-01T06:50:34.095+0000] {connectionpool.py:823} WARNING - Retrying (Retry(total=2, connect=None, read=None, redirect=None, status=None)) after connection broken by 'NewConnectionError('<urllib3.connection.HTTPConnection object at 0x7fd4e33e0250>: Failed to establish a new connection: [Errno 111] Connection refused')': /session/d803562141e0fe33d1b8b54dd081e0b9/actions
[2025-04-01T06:50:34.098+0000] {connectionpool.py:823} WARNING - Retrying (Retry(total=1, connect=None, read=None, redirect=None, status=None)) after connection broken by 'NewConnectionError('<urllib3.connection.HTTPConnection object at 0x7fd4e33e0310>: Failed to establish a new connection: [Errno 111] Connection refused')': /session/d803562141e0fe33d1b8b54dd081e0b9/actions
[2025-04-01T06:50:34.088+0000] {process_utils.py:79} INFO - Process psutil.Process(pid=147, status='terminated', started='06:50:00') (147) terminated with exit code None
[2025-04-01T06:50:34.103+0000] {process_utils.py:79} INFO - Process psutil.Process(pid=180, status='terminated', started='06:50:03') (180) terminated with exit code None
[2025-04-01T06:50:34.107+0000] {process_utils.py:79} INFO - Process psutil.Process(pid=219, status='terminated', started='06:50:04') (219) terminated with exit code None
[2025-04-01T06:50:34.105+0000] {connectionpool.py:823} WARNING - Retrying (Retry(total=0, connect=None, read=None, redirect=None, status=None)) after connection broken by 'NewConnectionError('<urllib3.connection.HTTPConnection object at 0x7fd4e33e0490>: Failed to establish a new connection: [Errno 111] Connection refused')': /session/d803562141e0fe33d1b8b54dd081e0b9/actions
[2025-04-01T06:50:34.109+0000] {process_utils.py:79} INFO - Process psutil.Process(pid=156, status='terminated', started='06:50:00') (156) terminated with exit code None
[2025-04-01T06:50:34.116+0000] {logging_mixin.py:151} INFO - Lỗi khi lấy dữ liệu: HTTPConnectionPool(host='localhost', port=49435): Max retries exceeded with url: /session/d803562141e0fe33d1b8b54dd081e0b9/actions (Caused by NewConnectionError('<urllib3.connection.HTTPConnection object at 0x7fd4e33e05e0>: Failed to establish a new connection: [Errno 111] Connection refused'))
[2025-04-01T06:50:34.121+0000] {connectionpool.py:823} WARNING - Retrying (Retry(total=2, connect=None, read=None, redirect=None, status=None)) after connection broken by 'NewConnectionError('<urllib3.connection.HTTPConnection object at 0x7fd4e33e0a30>: Failed to establish a new connection: [Errno 111] Connection refused')': /session/d803562141e0fe33d1b8b54dd081e0b9/actions
[2025-04-01T06:50:34.115+0000] {process_utils.py:79} INFO - Process psutil.Process(pid=171, status='terminated', started='06:50:03') (171) terminated with exit code None
[2025-04-01T06:50:34.130+0000] {process_utils.py:79} INFO - Process psutil.Process(pid=96, status='terminated', started='06:50:00') (96) terminated with exit code None
[2025-04-01T06:50:34.126+0000] {connectionpool.py:823} WARNING - Retrying (Retry(total=1, connect=None, read=None, redirect=None, status=None)) after connection broken by 'NewConnectionError('<urllib3.connection.HTTPConnection object at 0x7fd4e33e0b20>: Failed to establish a new connection: [Errno 111] Connection refused')': /session/d803562141e0fe33d1b8b54dd081e0b9/actions
[2025-04-01T06:50:34.136+0000] {connectionpool.py:823} WARNING - Retrying (Retry(total=0, connect=None, read=None, redirect=None, status=None)) after connection broken by 'NewConnectionError('<urllib3.connection.HTTPConnection object at 0x7fd4e33e0ca0>: Failed to establish a new connection: [Errno 111] Connection refused')': /session/d803562141e0fe33d1b8b54dd081e0b9/actions
[2025-04-01T06:50:34.142+0000] {logging_mixin.py:151} INFO - Lỗi khi lấy dữ liệu: HTTPConnectionPool(host='localhost', port=49435): Max retries exceeded with url: /session/d803562141e0fe33d1b8b54dd081e0b9/actions (Caused by NewConnectionError('<urllib3.connection.HTTPConnection object at 0x7fd4e34307f0>: Failed to establish a new connection: [Errno 111] Connection refused'))
[2025-04-01T06:50:34.147+0000] {connectionpool.py:823} WARNING - Retrying (Retry(total=2, connect=None, read=None, redirect=None, status=None)) after connection broken by 'NewConnectionError('<urllib3.connection.HTTPConnection object at 0x7fd4e3430850>: Failed to establish a new connection: [Errno 111] Connection refused')': /session/d803562141e0fe33d1b8b54dd081e0b9/actions
[2025-04-01T06:50:34.156+0000] {connectionpool.py:823} WARNING - Retrying (Retry(total=1, connect=None, read=None, redirect=None, status=None)) after connection broken by 'NewConnectionError('<urllib3.connection.HTTPConnection object at 0x7fd4e34300d0>: Failed to establish a new connection: [Errno 111] Connection refused')': /session/d803562141e0fe33d1b8b54dd081e0b9/actions
[2025-04-01T06:50:34.158+0000] {connectionpool.py:823} WARNING - Retrying (Retry(total=0, connect=None, read=None, redirect=None, status=None)) after connection broken by 'NewConnectionError('<urllib3.connection.HTTPConnection object at 0x7fd4e3430460>: Failed to establish a new connection: [Errno 111] Connection refused')': /session/d803562141e0fe33d1b8b54dd081e0b9/actions
[2025-04-01T06:50:34.160+0000] {logging_mixin.py:151} INFO - Lỗi khi lấy dữ liệu: HTTPConnectionPool(host='localhost', port=49435): Max retries exceeded with url: /session/d803562141e0fe33d1b8b54dd081e0b9/actions (Caused by NewConnectionError('<urllib3.connection.HTTPConnection object at 0x7fd4e3430f70>: Failed to establish a new connection: [Errno 111] Connection refused'))
[2025-04-01T06:50:34.162+0000] {connectionpool.py:823} WARNING - Retrying (Retry(total=2, connect=None, read=None, redirect=None, status=None)) after connection broken by 'NewConnectionError('<urllib3.connection.HTTPConnection object at 0x7fd4e34480d0>: Failed to establish a new connection: [Errno 111] Connection refused')': /session/d803562141e0fe33d1b8b54dd081e0b9/actions
[2025-04-01T06:50:34.164+0000] {connectionpool.py:823} WARNING - Retrying (Retry(total=1, connect=None, read=None, redirect=None, status=None)) after connection broken by 'NewConnectionError('<urllib3.connection.HTTPConnection object at 0x7fd4e34483a0>: Failed to establish a new connection: [Errno 111] Connection refused')': /session/d803562141e0fe33d1b8b54dd081e0b9/actions
[2025-04-01T06:50:34.167+0000] {connectionpool.py:823} WARNING - Retrying (Retry(total=0, connect=None, read=None, redirect=None, status=None)) after connection broken by 'NewConnectionError('<urllib3.connection.HTTPConnection object at 0x7fd4e34485b0>: Failed to establish a new connection: [Errno 111] Connection refused')': /session/d803562141e0fe33d1b8b54dd081e0b9/actions
[2025-04-01T06:50:34.172+0000] {logging_mixin.py:151} INFO - Lỗi khi lấy dữ liệu: HTTPConnectionPool(host='localhost', port=49435): Max retries exceeded with url: /session/d803562141e0fe33d1b8b54dd081e0b9/actions (Caused by NewConnectionError('<urllib3.connection.HTTPConnection object at 0x7fd4e3448790>: Failed to establish a new connection: [Errno 111] Connection refused'))
[2025-04-01T06:50:34.175+0000] {connectionpool.py:823} WARNING - Retrying (Retry(total=2, connect=None, read=None, redirect=None, status=None)) after connection broken by 'NewConnectionError('<urllib3.connection.HTTPConnection object at 0x7fd4e33e0490>: Failed to establish a new connection: [Errno 111] Connection refused')': /session/d803562141e0fe33d1b8b54dd081e0b9/actions
[2025-04-01T06:50:34.177+0000] {connectionpool.py:823} WARNING - Retrying (Retry(total=1, connect=None, read=None, redirect=None, status=None)) after connection broken by 'NewConnectionError('<urllib3.connection.HTTPConnection object at 0x7fd4e33e0310>: Failed to establish a new connection: [Errno 111] Connection refused')': /session/d803562141e0fe33d1b8b54dd081e0b9/actions
[2025-04-01T06:50:34.179+0000] {connectionpool.py:823} WARNING - Retrying (Retry(total=0, connect=None, read=None, redirect=None, status=None)) after connection broken by 'NewConnectionError('<urllib3.connection.HTTPConnection object at 0x7fd4e33e01f0>: Failed to establish a new connection: [Errno 111] Connection refused')': /session/d803562141e0fe33d1b8b54dd081e0b9/actions
[2025-04-01T06:50:34.181+0000] {logging_mixin.py:151} INFO - Lỗi khi lấy dữ liệu: HTTPConnectionPool(host='localhost', port=49435): Max retries exceeded with url: /session/d803562141e0fe33d1b8b54dd081e0b9/actions (Caused by NewConnectionError('<urllib3.connection.HTTPConnection object at 0x7fd4e33e0e50>: Failed to establish a new connection: [Errno 111] Connection refused'))
[2025-04-01T06:50:34.183+0000] {connectionpool.py:823} WARNING - Retrying (Retry(total=2, connect=None, read=None, redirect=None, status=None)) after connection broken by 'NewConnectionError('<urllib3.connection.HTTPConnection object at 0x7fd4e33f3280>: Failed to establish a new connection: [Errno 111] Connection refused')': /session/d803562141e0fe33d1b8b54dd081e0b9/actions
[2025-04-01T06:50:34.187+0000] {connectionpool.py:823} WARNING - Retrying (Retry(total=1, connect=None, read=None, redirect=None, status=None)) after connection broken by 'NewConnectionError('<urllib3.connection.HTTPConnection object at 0x7fd4e33f3370>: Failed to establish a new connection: [Errno 111] Connection refused')': /session/d803562141e0fe33d1b8b54dd081e0b9/actions
[2025-04-01T06:50:34.190+0000] {connectionpool.py:823} WARNING - Retrying (Retry(total=0, connect=None, read=None, redirect=None, status=None)) after connection broken by 'NewConnectionError('<urllib3.connection.HTTPConnection object at 0x7fd4e3448610>: Failed to establish a new connection: [Errno 111] Connection refused')': /session/d803562141e0fe33d1b8b54dd081e0b9/actions
[2025-04-01T06:50:34.192+0000] {logging_mixin.py:151} INFO - Lỗi khi lấy dữ liệu: HTTPConnectionPool(host='localhost', port=49435): Max retries exceeded with url: /session/d803562141e0fe33d1b8b54dd081e0b9/actions (Caused by NewConnectionError('<urllib3.connection.HTTPConnection object at 0x7fd4e34485e0>: Failed to establish a new connection: [Errno 111] Connection refused'))
[2025-04-01T06:50:34.194+0000] {connectionpool.py:823} WARNING - Retrying (Retry(total=2, connect=None, read=None, redirect=None, status=None)) after connection broken by 'NewConnectionError('<urllib3.connection.HTTPConnection object at 0x7fd4e3448040>: Failed to establish a new connection: [Errno 111] Connection refused')': /session/d803562141e0fe33d1b8b54dd081e0b9/actions
[2025-04-01T06:50:34.199+0000] {connectionpool.py:823} WARNING - Retrying (Retry(total=1, connect=None, read=None, redirect=None, status=None)) after connection broken by 'NewConnectionError('<urllib3.connection.HTTPConnection object at 0x7fd4e34481c0>: Failed to establish a new connection: [Errno 111] Connection refused')': /session/d803562141e0fe33d1b8b54dd081e0b9/actions
[2025-04-01T06:50:34.200+0000] {process_utils.py:79} INFO - Process psutil.Process(pid=76, status='terminated', started='06:50:00') (76) terminated with exit code None
[2025-04-01T06:50:34.201+0000] {process_utils.py:79} INFO - Process psutil.Process(pid=98, status='terminated', started='06:50:00') (98) terminated with exit code None
[2025-04-01T06:50:34.208+0000] {process_utils.py:79} INFO - Process psutil.Process(pid=66, status='terminated', started='06:49:59') (66) terminated with exit code None
[2025-04-01T06:50:34.207+0000] {connectionpool.py:823} WARNING - Retrying (Retry(total=0, connect=None, read=None, redirect=None, status=None)) after connection broken by 'NewConnectionError('<urllib3.connection.HTTPConnection object at 0x7fd4e3430400>: Failed to establish a new connection: [Errno 111] Connection refused')': /session/d803562141e0fe33d1b8b54dd081e0b9/actions
[2025-04-01T06:50:34.210+0000] {logging_mixin.py:151} INFO - Lỗi khi lấy dữ liệu: HTTPConnectionPool(host='localhost', port=49435): Max retries exceeded with url: /session/d803562141e0fe33d1b8b54dd081e0b9/actions (Caused by NewConnectionError('<urllib3.connection.HTTPConnection object at 0x7fd4e34305b0>: Failed to establish a new connection: [Errno 111] Connection refused'))
[2025-04-01T06:50:34.212+0000] {connectionpool.py:823} WARNING - Retrying (Retry(total=2, connect=None, read=None, redirect=None, status=None)) after connection broken by 'NewConnectionError('<urllib3.connection.HTTPConnection object at 0x7fd4e3430670>: Failed to establish a new connection: [Errno 111] Connection refused')': /session/d803562141e0fe33d1b8b54dd081e0b9/actions
[2025-04-01T06:50:34.213+0000] {connectionpool.py:823} WARNING - Retrying (Retry(total=1, connect=None, read=None, redirect=None, status=None)) after connection broken by 'NewConnectionError('<urllib3.connection.HTTPConnection object at 0x7fd4e34301f0>: Failed to establish a new connection: [Errno 111] Connection refused')': /session/d803562141e0fe33d1b8b54dd081e0b9/actions
[2025-04-01T06:50:34.215+0000] {connectionpool.py:823} WARNING - Retrying (Retry(total=0, connect=None, read=None, redirect=None, status=None)) after connection broken by 'NewConnectionError('<urllib3.connection.HTTPConnection object at 0x7fd4e34304c0>: Failed to establish a new connection: [Errno 111] Connection refused')': /session/d803562141e0fe33d1b8b54dd081e0b9/actions
[2025-04-01T06:50:34.217+0000] {logging_mixin.py:151} INFO - Lỗi khi lấy dữ liệu: HTTPConnectionPool(host='localhost', port=49435): Max retries exceeded with url: /session/d803562141e0fe33d1b8b54dd081e0b9/actions (Caused by NewConnectionError('<urllib3.connection.HTTPConnection object at 0x7fd4e33e0430>: Failed to establish a new connection: [Errno 111] Connection refused'))
[2025-04-01T06:50:34.223+0000] {connectionpool.py:823} WARNING - Retrying (Retry(total=2, connect=None, read=None, redirect=None, status=None)) after connection broken by 'NewConnectionError('<urllib3.connection.HTTPConnection object at 0x7fd4e33e03d0>: Failed to establish a new connection: [Errno 111] Connection refused')': /session/d803562141e0fe33d1b8b54dd081e0b9/actions
[2025-04-01T06:50:34.226+0000] {connectionpool.py:823} WARNING - Retrying (Retry(total=1, connect=None, read=None, redirect=None, status=None)) after connection broken by 'NewConnectionError('<urllib3.connection.HTTPConnection object at 0x7fd4e33e0580>: Failed to establish a new connection: [Errno 111] Connection refused')': /session/d803562141e0fe33d1b8b54dd081e0b9/actions
[2025-04-01T06:50:34.228+0000] {connectionpool.py:823} WARNING - Retrying (Retry(total=0, connect=None, read=None, redirect=None, status=None)) after connection broken by 'NewConnectionError('<urllib3.connection.HTTPConnection object at 0x7fd4e33e0a00>: Failed to establish a new connection: [Errno 111] Connection refused')': /session/d803562141e0fe33d1b8b54dd081e0b9/actions
[2025-04-01T06:50:34.230+0000] {logging_mixin.py:151} INFO - Lỗi khi lấy dữ liệu: HTTPConnectionPool(host='localhost', port=49435): Max retries exceeded with url: /session/d803562141e0fe33d1b8b54dd081e0b9/actions (Caused by NewConnectionError('<urllib3.connection.HTTPConnection object at 0x7fd4e33e0d90>: Failed to establish a new connection: [Errno 111] Connection refused'))
[2025-04-01T06:50:34.236+0000] {connectionpool.py:823} WARNING - Retrying (Retry(total=2, connect=None, read=None, redirect=None, status=None)) after connection broken by 'NewConnectionError('<urllib3.connection.HTTPConnection object at 0x7fd4e33f3850>: Failed to establish a new connection: [Errno 111] Connection refused')': /session/d803562141e0fe33d1b8b54dd081e0b9/actions
[2025-04-01T06:50:34.239+0000] {connectionpool.py:823} WARNING - Retrying (Retry(total=1, connect=None, read=None, redirect=None, status=None)) after connection broken by 'NewConnectionError('<urllib3.connection.HTTPConnection object at 0x7fd4e33f3940>: Failed to establish a new connection: [Errno 111] Connection refused')': /session/d803562141e0fe33d1b8b54dd081e0b9/actions
[2025-04-01T06:50:34.241+0000] {connectionpool.py:823} WARNING - Retrying (Retry(total=0, connect=None, read=None, redirect=None, status=None)) after connection broken by 'NewConnectionError('<urllib3.connection.HTTPConnection object at 0x7fd4e33e0520>: Failed to establish a new connection: [Errno 111] Connection refused')': /session/d803562141e0fe33d1b8b54dd081e0b9/actions
[2025-04-01T06:50:34.243+0000] {logging_mixin.py:151} INFO - Lỗi khi lấy dữ liệu: HTTPConnectionPool(host='localhost', port=49435): Max retries exceeded with url: /session/d803562141e0fe33d1b8b54dd081e0b9/actions (Caused by NewConnectionError('<urllib3.connection.HTTPConnection object at 0x7fd4e33e0d30>: Failed to establish a new connection: [Errno 111] Connection refused'))
[2025-04-01T06:50:34.245+0000] {connectionpool.py:823} WARNING - Retrying (Retry(total=2, connect=None, read=None, redirect=None, status=None)) after connection broken by 'NewConnectionError('<urllib3.connection.HTTPConnection object at 0x7fd4e33e02b0>: Failed to establish a new connection: [Errno 111] Connection refused')': /session/d803562141e0fe33d1b8b54dd081e0b9/actions
[2025-04-01T06:50:34.247+0000] {connectionpool.py:823} WARNING - Retrying (Retry(total=1, connect=None, read=None, redirect=None, status=None)) after connection broken by 'NewConnectionError('<urllib3.connection.HTTPConnection object at 0x7fd4e33e0e80>: Failed to establish a new connection: [Errno 111] Connection refused')': /session/d803562141e0fe33d1b8b54dd081e0b9/actions
[2025-04-01T06:50:34.249+0000] {connectionpool.py:823} WARNING - Retrying (Retry(total=0, connect=None, read=None, redirect=None, status=None)) after connection broken by 'NewConnectionError('<urllib3.connection.HTTPConnection object at 0x7fd4e3430310>: Failed to establish a new connection: [Errno 111] Connection refused')': /session/d803562141e0fe33d1b8b54dd081e0b9/actions
[2025-04-01T06:50:34.253+0000] {logging_mixin.py:151} INFO - Lỗi khi lấy dữ liệu: HTTPConnectionPool(host='localhost', port=49435): Max retries exceeded with url: /session/d803562141e0fe33d1b8b54dd081e0b9/actions (Caused by NewConnectionError('<urllib3.connection.HTTPConnection object at 0x7fd4e3430df0>: Failed to establish a new connection: [Errno 111] Connection refused'))
[2025-04-01T06:50:34.256+0000] {connectionpool.py:823} WARNING - Retrying (Retry(total=2, connect=None, read=None, redirect=None, status=None)) after connection broken by 'NewConnectionError('<urllib3.connection.HTTPConnection object at 0x7fd4e3430430>: Failed to establish a new connection: [Errno 111] Connection refused')': /session/d803562141e0fe33d1b8b54dd081e0b9/actions
[2025-04-01T06:50:34.257+0000] {connectionpool.py:823} WARNING - Retrying (Retry(total=1, connect=None, read=None, redirect=None, status=None)) after connection broken by 'NewConnectionError('<urllib3.connection.HTTPConnection object at 0x7fd4e34302b0>: Failed to establish a new connection: [Errno 111] Connection refused')': /session/d803562141e0fe33d1b8b54dd081e0b9/actions
[2025-04-01T06:50:34.259+0000] {connectionpool.py:823} WARNING - Retrying (Retry(total=0, connect=None, read=None, redirect=None, status=None)) after connection broken by 'NewConnectionError('<urllib3.connection.HTTPConnection object at 0x7fd4e34305b0>: Failed to establish a new connection: [Errno 111] Connection refused')': /session/d803562141e0fe33d1b8b54dd081e0b9/actions
[2025-04-01T06:50:34.260+0000] {logging_mixin.py:151} INFO - Lỗi khi lấy dữ liệu: HTTPConnectionPool(host='localhost', port=49435): Max retries exceeded with url: /session/d803562141e0fe33d1b8b54dd081e0b9/actions (Caused by NewConnectionError('<urllib3.connection.HTTPConnection object at 0x7fd4e3448850>: Failed to establish a new connection: [Errno 111] Connection refused'))
[2025-04-01T06:50:34.262+0000] {connectionpool.py:823} WARNING - Retrying (Retry(total=2, connect=None, read=None, redirect=None, status=None)) after connection broken by 'NewConnectionError('<urllib3.connection.HTTPConnection object at 0x7fd4e3448190>: Failed to establish a new connection: [Errno 111] Connection refused')': /session/d803562141e0fe33d1b8b54dd081e0b9/actions
[2025-04-01T06:50:34.264+0000] {connectionpool.py:823} WARNING - Retrying (Retry(total=1, connect=None, read=None, redirect=None, status=None)) after connection broken by 'NewConnectionError('<urllib3.connection.HTTPConnection object at 0x7fd4e34482e0>: Failed to establish a new connection: [Errno 111] Connection refused')': /session/d803562141e0fe33d1b8b54dd081e0b9/actions
[2025-04-01T06:50:34.266+0000] {connectionpool.py:823} WARNING - Retrying (Retry(total=0, connect=None, read=None, redirect=None, status=None)) after connection broken by 'NewConnectionError('<urllib3.connection.HTTPConnection object at 0x7fd4e34485e0>: Failed to establish a new connection: [Errno 111] Connection refused')': /session/d803562141e0fe33d1b8b54dd081e0b9/actions
[2025-04-01T06:50:34.269+0000] {logging_mixin.py:151} INFO - Lỗi khi lấy dữ liệu: HTTPConnectionPool(host='localhost', port=49435): Max retries exceeded with url: /session/d803562141e0fe33d1b8b54dd081e0b9/actions (Caused by NewConnectionError('<urllib3.connection.HTTPConnection object at 0x7fd4e33f34c0>: Failed to establish a new connection: [Errno 111] Connection refused'))
[2025-04-01T06:50:34.275+0000] {connectionpool.py:823} WARNING - Retrying (Retry(total=2, connect=None, read=None, redirect=None, status=None)) after connection broken by 'NewConnectionError('<urllib3.connection.HTTPConnection object at 0x7fd4e33f3e20>: Failed to establish a new connection: [Errno 111] Connection refused')': /session/d803562141e0fe33d1b8b54dd081e0b9/actions
[2025-04-01T06:50:34.278+0000] {connectionpool.py:823} WARNING - Retrying (Retry(total=1, connect=None, read=None, redirect=None, status=None)) after connection broken by 'NewConnectionError('<urllib3.connection.HTTPConnection object at 0x7fd4e33f3f70>: Failed to establish a new connection: [Errno 111] Connection refused')': /session/d803562141e0fe33d1b8b54dd081e0b9/actions
[2025-04-01T06:50:34.279+0000] {connectionpool.py:823} WARNING - Retrying (Retry(total=0, connect=None, read=None, redirect=None, status=None)) after connection broken by 'NewConnectionError('<urllib3.connection.HTTPConnection object at 0x7fd4e33f36a0>: Failed to establish a new connection: [Errno 111] Connection refused')': /session/d803562141e0fe33d1b8b54dd081e0b9/actions
[2025-04-01T06:50:34.281+0000] {logging_mixin.py:151} INFO - Lỗi khi lấy dữ liệu: HTTPConnectionPool(host='localhost', port=49435): Max retries exceeded with url: /session/d803562141e0fe33d1b8b54dd081e0b9/actions (Caused by NewConnectionError('<urllib3.connection.HTTPConnection object at 0x7fd4e33f3a30>: Failed to establish a new connection: [Errno 111] Connection refused'))
[2025-04-01T06:50:34.283+0000] {connectionpool.py:823} WARNING - Retrying (Retry(total=2, connect=None, read=None, redirect=None, status=None)) after connection broken by 'NewConnectionError('<urllib3.connection.HTTPConnection object at 0x7fd4e33f30d0>: Failed to establish a new connection: [Errno 111] Connection refused')': /session/d803562141e0fe33d1b8b54dd081e0b9/actions
[2025-04-01T06:50:34.285+0000] {connectionpool.py:823} WARNING - Retrying (Retry(total=1, connect=None, read=None, redirect=None, status=None)) after connection broken by 'NewConnectionError('<urllib3.connection.HTTPConnection object at 0x7fd4e33f3370>: Failed to establish a new connection: [Errno 111] Connection refused')': /session/d803562141e0fe33d1b8b54dd081e0b9/actions
[2025-04-01T06:50:34.291+0000] {connectionpool.py:823} WARNING - Retrying (Retry(total=0, connect=None, read=None, redirect=None, status=None)) after connection broken by 'NewConnectionError('<urllib3.connection.HTTPConnection object at 0x7fd4e33f3250>: Failed to establish a new connection: [Errno 111] Connection refused')': /session/d803562141e0fe33d1b8b54dd081e0b9/actions
[2025-04-01T06:50:34.295+0000] {logging_mixin.py:151} INFO - Lỗi khi lấy dữ liệu: HTTPConnectionPool(host='localhost', port=49435): Max retries exceeded with url: /session/d803562141e0fe33d1b8b54dd081e0b9/actions (Caused by NewConnectionError('<urllib3.connection.HTTPConnection object at 0x7fd4e33f3190>: Failed to establish a new connection: [Errno 111] Connection refused'))
[2025-04-01T06:50:34.297+0000] {connectionpool.py:823} WARNING - Retrying (Retry(total=2, connect=None, read=None, redirect=None, status=None)) after connection broken by 'NewConnectionError('<urllib3.connection.HTTPConnection object at 0x7fd4e34486d0>: Failed to establish a new connection: [Errno 111] Connection refused')': /session/d803562141e0fe33d1b8b54dd081e0b9/actions
[2025-04-01T06:50:34.298+0000] {connectionpool.py:823} WARNING - Retrying (Retry(total=1, connect=None, read=None, redirect=None, status=None)) after connection broken by 'NewConnectionError('<urllib3.connection.HTTPConnection object at 0x7fd4e3448460>: Failed to establish a new connection: [Errno 111] Connection refused')': /session/d803562141e0fe33d1b8b54dd081e0b9/actions
[2025-04-01T06:50:34.303+0000] {connectionpool.py:823} WARNING - Retrying (Retry(total=0, connect=None, read=None, redirect=None, status=None)) after connection broken by 'NewConnectionError('<urllib3.connection.HTTPConnection object at 0x7fd4e34481f0>: Failed to establish a new connection: [Errno 111] Connection refused')': /session/d803562141e0fe33d1b8b54dd081e0b9/actions
[2025-04-01T06:50:34.307+0000] {logging_mixin.py:151} INFO - Lỗi khi lấy dữ liệu: HTTPConnectionPool(host='localhost', port=49435): Max retries exceeded with url: /session/d803562141e0fe33d1b8b54dd081e0b9/actions (Caused by NewConnectionError('<urllib3.connection.HTTPConnection object at 0x7fd4e3448850>: Failed to establish a new connection: [Errno 111] Connection refused'))
[2025-04-01T06:50:34.312+0000] {connectionpool.py:823} WARNING - Retrying (Retry(total=2, connect=None, read=None, redirect=None, status=None)) after connection broken by 'NewConnectionError('<urllib3.connection.HTTPConnection object at 0x7fd4e3448c10>: Failed to establish a new connection: [Errno 111] Connection refused')': /session/d803562141e0fe33d1b8b54dd081e0b9/actions
[2025-04-01T06:50:34.313+0000] {connectionpool.py:823} WARNING - Retrying (Retry(total=1, connect=None, read=None, redirect=None, status=None)) after connection broken by 'NewConnectionError('<urllib3.connection.HTTPConnection object at 0x7fd4e3448d30>: Failed to establish a new connection: [Errno 111] Connection refused')': /session/d803562141e0fe33d1b8b54dd081e0b9/actions
[2025-04-01T06:50:34.315+0000] {connectionpool.py:823} WARNING - Retrying (Retry(total=0, connect=None, read=None, redirect=None, status=None)) after connection broken by 'NewConnectionError('<urllib3.connection.HTTPConnection object at 0x7fd4e3448b20>: Failed to establish a new connection: [Errno 111] Connection refused')': /session/d803562141e0fe33d1b8b54dd081e0b9/actions
[2025-04-01T06:50:34.320+0000] {logging_mixin.py:151} INFO - Lỗi khi lấy dữ liệu: HTTPConnectionPool(host='localhost', port=49435): Max retries exceeded with url: /session/d803562141e0fe33d1b8b54dd081e0b9/actions (Caused by NewConnectionError('<urllib3.connection.HTTPConnection object at 0x7fd4e347d760>: Failed to establish a new connection: [Errno 111] Connection refused'))
[2025-04-01T06:50:34.325+0000] {connectionpool.py:823} WARNING - Retrying (Retry(total=2, connect=None, read=None, redirect=None, status=None)) after connection broken by 'NewConnectionError('<urllib3.connection.HTTPConnection object at 0x7fd4e3430460>: Failed to establish a new connection: [Errno 111] Connection refused')': /session/d803562141e0fe33d1b8b54dd081e0b9/actions
[2025-04-01T06:50:34.327+0000] {connectionpool.py:823} WARNING - Retrying (Retry(total=1, connect=None, read=None, redirect=None, status=None)) after connection broken by 'NewConnectionError('<urllib3.connection.HTTPConnection object at 0x7fd4e34301c0>: Failed to establish a new connection: [Errno 111] Connection refused')': /session/d803562141e0fe33d1b8b54dd081e0b9/actions
[2025-04-01T06:50:34.331+0000] {connectionpool.py:823} WARNING - Retrying (Retry(total=0, connect=None, read=None, redirect=None, status=None)) after connection broken by 'NewConnectionError('<urllib3.connection.HTTPConnection object at 0x7fd4e34487c0>: Failed to establish a new connection: [Errno 111] Connection refused')': /session/d803562141e0fe33d1b8b54dd081e0b9/actions
[2025-04-01T06:50:34.334+0000] {logging_mixin.py:151} INFO - Lỗi khi lấy dữ liệu: HTTPConnectionPool(host='localhost', port=49435): Max retries exceeded with url: /session/d803562141e0fe33d1b8b54dd081e0b9/actions (Caused by NewConnectionError('<urllib3.connection.HTTPConnection object at 0x7fd4e3448940>: Failed to establish a new connection: [Errno 111] Connection refused'))
[2025-04-01T06:50:34.342+0000] {connectionpool.py:823} WARNING - Retrying (Retry(total=2, connect=None, read=None, redirect=None, status=None)) after connection broken by 'NewConnectionError('<urllib3.connection.HTTPConnection object at 0x7fd4e3448d00>: Failed to establish a new connection: [Errno 111] Connection refused')': /session/d803562141e0fe33d1b8b54dd081e0b9/actions
[2025-04-01T06:50:34.345+0000] {connectionpool.py:823} WARNING - Retrying (Retry(total=1, connect=None, read=None, redirect=None, status=None)) after connection broken by 'NewConnectionError('<urllib3.connection.HTTPConnection object at 0x7fd4e3448f70>: Failed to establish a new connection: [Errno 111] Connection refused')': /session/d803562141e0fe33d1b8b54dd081e0b9/actions
[2025-04-01T06:50:34.347+0000] {connectionpool.py:823} WARNING - Retrying (Retry(total=0, connect=None, read=None, redirect=None, status=None)) after connection broken by 'NewConnectionError('<urllib3.connection.HTTPConnection object at 0x7fd4e3448160>: Failed to establish a new connection: [Errno 111] Connection refused')': /session/d803562141e0fe33d1b8b54dd081e0b9/actions
[2025-04-01T06:50:34.351+0000] {logging_mixin.py:151} INFO - Lỗi khi lấy dữ liệu: HTTPConnectionPool(host='localhost', port=49435): Max retries exceeded with url: /session/d803562141e0fe33d1b8b54dd081e0b9/actions (Caused by NewConnectionError('<urllib3.connection.HTTPConnection object at 0x7fd4e3448850>: Failed to establish a new connection: [Errno 111] Connection refused'))
[2025-04-01T06:50:34.358+0000] {connectionpool.py:823} WARNING - Retrying (Retry(total=2, connect=None, read=None, redirect=None, status=None)) after connection broken by 'NewConnectionError('<urllib3.connection.HTTPConnection object at 0x7fd4e3448790>: Failed to establish a new connection: [Errno 111] Connection refused')': /session/d803562141e0fe33d1b8b54dd081e0b9/actions
[2025-04-01T06:50:34.360+0000] {connectionpool.py:823} WARNING - Retrying (Retry(total=1, connect=None, read=None, redirect=None, status=None)) after connection broken by 'NewConnectionError('<urllib3.connection.HTTPConnection object at 0x7fd4e3448760>: Failed to establish a new connection: [Errno 111] Connection refused')': /session/d803562141e0fe33d1b8b54dd081e0b9/actions
[2025-04-01T06:50:34.361+0000] {connectionpool.py:823} WARNING - Retrying (Retry(total=0, connect=None, read=None, redirect=None, status=None)) after connection broken by 'NewConnectionError('<urllib3.connection.HTTPConnection object at 0x7fd4e33f3730>: Failed to establish a new connection: [Errno 111] Connection refused')': /session/d803562141e0fe33d1b8b54dd081e0b9/actions
[2025-04-01T06:50:34.366+0000] {logging_mixin.py:151} INFO - Lỗi khi lấy dữ liệu: HTTPConnectionPool(host='localhost', port=49435): Max retries exceeded with url: /session/d803562141e0fe33d1b8b54dd081e0b9/actions (Caused by NewConnectionError('<urllib3.connection.HTTPConnection object at 0x7fd4e33f31c0>: Failed to establish a new connection: [Errno 111] Connection refused'))
[2025-04-01T06:50:34.368+0000] {connectionpool.py:823} WARNING - Retrying (Retry(total=2, connect=None, read=None, redirect=None, status=None)) after connection broken by 'NewConnectionError('<urllib3.connection.HTTPConnection object at 0x7fd4e33f3700>: Failed to establish a new connection: [Errno 111] Connection refused')': /session/d803562141e0fe33d1b8b54dd081e0b9/actions
[2025-04-01T06:50:34.371+0000] {connectionpool.py:823} WARNING - Retrying (Retry(total=1, connect=None, read=None, redirect=None, status=None)) after connection broken by 'NewConnectionError('<urllib3.connection.HTTPConnection object at 0x7fd4e33f39a0>: Failed to establish a new connection: [Errno 111] Connection refused')': /session/d803562141e0fe33d1b8b54dd081e0b9/actions
[2025-04-01T06:50:34.374+0000] {connectionpool.py:823} WARNING - Retrying (Retry(total=0, connect=None, read=None, redirect=None, status=None)) after connection broken by 'NewConnectionError('<urllib3.connection.HTTPConnection object at 0x7fd4e33f3910>: Failed to establish a new connection: [Errno 111] Connection refused')': /session/d803562141e0fe33d1b8b54dd081e0b9/actions
[2025-04-01T06:50:34.378+0000] {logging_mixin.py:151} INFO - Lỗi khi lấy dữ liệu: HTTPConnectionPool(host='localhost', port=49435): Max retries exceeded with url: /session/d803562141e0fe33d1b8b54dd081e0b9/actions (Caused by NewConnectionError('<urllib3.connection.HTTPConnection object at 0x7fd4e33f36a0>: Failed to establish a new connection: [Errno 111] Connection refused'))
[2025-04-01T06:50:34.381+0000] {connectionpool.py:823} WARNING - Retrying (Retry(total=2, connect=None, read=None, redirect=None, status=None)) after connection broken by 'NewConnectionError('<urllib3.connection.HTTPConnection object at 0x7fd4e34303d0>: Failed to establish a new connection: [Errno 111] Connection refused')': /session/d803562141e0fe33d1b8b54dd081e0b9/actions
[2025-04-01T06:50:34.384+0000] {connectionpool.py:823} WARNING - Retrying (Retry(total=1, connect=None, read=None, redirect=None, status=None)) after connection broken by 'NewConnectionError('<urllib3.connection.HTTPConnection object at 0x7fd4e3430580>: Failed to establish a new connection: [Errno 111] Connection refused')': /session/d803562141e0fe33d1b8b54dd081e0b9/actions
[2025-04-01T06:50:34.392+0000] {connectionpool.py:823} WARNING - Retrying (Retry(total=0, connect=None, read=None, redirect=None, status=None)) after connection broken by 'NewConnectionError('<urllib3.connection.HTTPConnection object at 0x7fd4e33f33a0>: Failed to establish a new connection: [Errno 111] Connection refused')': /session/d803562141e0fe33d1b8b54dd081e0b9/actions
[2025-04-01T06:50:34.395+0000] {logging_mixin.py:151} INFO - Lỗi khi lấy dữ liệu: HTTPConnectionPool(host='localhost', port=49435): Max retries exceeded with url: /session/d803562141e0fe33d1b8b54dd081e0b9/actions (Caused by NewConnectionError('<urllib3.connection.HTTPConnection object at 0x7fd4e33f38e0>: Failed to establish a new connection: [Errno 111] Connection refused'))
[2025-04-01T06:50:34.399+0000] {connectionpool.py:823} WARNING - Retrying (Retry(total=2, connect=None, read=None, redirect=None, status=None)) after connection broken by 'NewConnectionError('<urllib3.connection.HTTPConnection object at 0x7fd4e33f3550>: Failed to establish a new connection: [Errno 111] Connection refused')': /session/d803562141e0fe33d1b8b54dd081e0b9/actions
[2025-04-01T06:50:34.414+0000] {connectionpool.py:823} WARNING - Retrying (Retry(total=1, connect=None, read=None, redirect=None, status=None)) after connection broken by 'NewConnectionError('<urllib3.connection.HTTPConnection object at 0x7fd4e33f3370>: Failed to establish a new connection: [Errno 111] Connection refused')': /session/d803562141e0fe33d1b8b54dd081e0b9/actions
[2025-04-01T06:50:34.417+0000] {connectionpool.py:823} WARNING - Retrying (Retry(total=0, connect=None, read=None, redirect=None, status=None)) after connection broken by 'NewConnectionError('<urllib3.connection.HTTPConnection object at 0x7fd4e33f3970>: Failed to establish a new connection: [Errno 111] Connection refused')': /session/d803562141e0fe33d1b8b54dd081e0b9/actions
[2025-04-01T06:50:34.421+0000] {logging_mixin.py:151} INFO - Lỗi khi lấy dữ liệu: HTTPConnectionPool(host='localhost', port=49435): Max retries exceeded with url: /session/d803562141e0fe33d1b8b54dd081e0b9/actions (Caused by NewConnectionError('<urllib3.connection.HTTPConnection object at 0x7fd4e33f33d0>: Failed to establish a new connection: [Errno 111] Connection refused'))
[2025-04-01T06:50:34.425+0000] {connectionpool.py:823} WARNING - Retrying (Retry(total=2, connect=None, read=None, redirect=None, status=None)) after connection broken by 'NewConnectionError('<urllib3.connection.HTTPConnection object at 0x7fd4e3448430>: Failed to establish a new connection: [Errno 111] Connection refused')': /session/d803562141e0fe33d1b8b54dd081e0b9/actions
[2025-04-01T06:50:34.428+0000] {connectionpool.py:823} WARNING - Retrying (Retry(total=1, connect=None, read=None, redirect=None, status=None)) after connection broken by 'NewConnectionError('<urllib3.connection.HTTPConnection object at 0x7fd4e34483a0>: Failed to establish a new connection: [Errno 111] Connection refused')': /session/d803562141e0fe33d1b8b54dd081e0b9/actions
[2025-04-01T06:50:34.434+0000] {connectionpool.py:823} WARNING - Retrying (Retry(total=0, connect=None, read=None, redirect=None, status=None)) after connection broken by 'NewConnectionError('<urllib3.connection.HTTPConnection object at 0x7fd4e3448e50>: Failed to establish a new connection: [Errno 111] Connection refused')': /session/d803562141e0fe33d1b8b54dd081e0b9/actions
[2025-04-01T06:50:34.438+0000] {logging_mixin.py:151} INFO - Lỗi khi lấy dữ liệu: HTTPConnectionPool(host='localhost', port=49435): Max retries exceeded with url: /session/d803562141e0fe33d1b8b54dd081e0b9/actions (Caused by NewConnectionError('<urllib3.connection.HTTPConnection object at 0x7fd4e34487f0>: Failed to establish a new connection: [Errno 111] Connection refused'))
[2025-04-01T06:50:34.443+0000] {connectionpool.py:823} WARNING - Retrying (Retry(total=2, connect=None, read=None, redirect=None, status=None)) after connection broken by 'NewConnectionError('<urllib3.connection.HTTPConnection object at 0x7fd4e3448bb0>: Failed to establish a new connection: [Errno 111] Connection refused')': /session/d803562141e0fe33d1b8b54dd081e0b9/actions
[2025-04-01T06:50:34.444+0000] {connectionpool.py:823} WARNING - Retrying (Retry(total=1, connect=None, read=None, redirect=None, status=None)) after connection broken by 'NewConnectionError('<urllib3.connection.HTTPConnection object at 0x7fd4e3448a30>: Failed to establish a new connection: [Errno 111] Connection refused')': /session/d803562141e0fe33d1b8b54dd081e0b9/actions
[2025-04-01T06:50:34.447+0000] {connectionpool.py:823} WARNING - Retrying (Retry(total=0, connect=None, read=None, redirect=None, status=None)) after connection broken by 'NewConnectionError('<urllib3.connection.HTTPConnection object at 0x7fd4e3448b80>: Failed to establish a new connection: [Errno 111] Connection refused')': /session/d803562141e0fe33d1b8b54dd081e0b9/actions
[2025-04-01T06:50:34.449+0000] {logging_mixin.py:151} INFO - Lỗi khi lấy dữ liệu: HTTPConnectionPool(host='localhost', port=49435): Max retries exceeded with url: /session/d803562141e0fe33d1b8b54dd081e0b9/actions (Caused by NewConnectionError('<urllib3.connection.HTTPConnection object at 0x7fd4e347d550>: Failed to establish a new connection: [Errno 111] Connection refused'))
[2025-04-01T06:50:34.453+0000] {connectionpool.py:823} WARNING - Retrying (Retry(total=2, connect=None, read=None, redirect=None, status=None)) after connection broken by 'NewConnectionError('<urllib3.connection.HTTPConnection object at 0x7fd4e3430970>: Failed to establish a new connection: [Errno 111] Connection refused')': /session/d803562141e0fe33d1b8b54dd081e0b9/actions
[2025-04-01T06:50:34.461+0000] {connectionpool.py:823} WARNING - Retrying (Retry(total=1, connect=None, read=None, redirect=None, status=None)) after connection broken by 'NewConnectionError('<urllib3.connection.HTTPConnection object at 0x7fd4e33e5040>: Failed to establish a new connection: [Errno 111] Connection refused')': /session/d803562141e0fe33d1b8b54dd081e0b9/actions
[2025-04-01T06:50:34.463+0000] {connectionpool.py:823} WARNING - Retrying (Retry(total=0, connect=None, read=None, redirect=None, status=None)) after connection broken by 'NewConnectionError('<urllib3.connection.HTTPConnection object at 0x7fd4e3448820>: Failed to establish a new connection: [Errno 111] Connection refused')': /session/d803562141e0fe33d1b8b54dd081e0b9/actions
[2025-04-01T06:50:34.470+0000] {logging_mixin.py:151} INFO - Lỗi khi lấy dữ liệu: HTTPConnectionPool(host='localhost', port=49435): Max retries exceeded with url: /session/d803562141e0fe33d1b8b54dd081e0b9/actions (Caused by NewConnectionError('<urllib3.connection.HTTPConnection object at 0x7fd4e34483d0>: Failed to establish a new connection: [Errno 111] Connection refused'))
[2025-04-01T06:50:34.472+0000] {connectionpool.py:823} WARNING - Retrying (Retry(total=2, connect=None, read=None, redirect=None, status=None)) after connection broken by 'NewConnectionError('<urllib3.connection.HTTPConnection object at 0x7fd4e3448640>: Failed to establish a new connection: [Errno 111] Connection refused')': /session/d803562141e0fe33d1b8b54dd081e0b9/actions
[2025-04-01T06:50:34.476+0000] {connectionpool.py:823} WARNING - Retrying (Retry(total=1, connect=None, read=None, redirect=None, status=None)) after connection broken by 'NewConnectionError('<urllib3.connection.HTTPConnection object at 0x7fd4e34485e0>: Failed to establish a new connection: [Errno 111] Connection refused')': /session/d803562141e0fe33d1b8b54dd081e0b9/actions
[2025-04-01T06:50:34.480+0000] {connectionpool.py:823} WARNING - Retrying (Retry(total=0, connect=None, read=None, redirect=None, status=None)) after connection broken by 'NewConnectionError('<urllib3.connection.HTTPConnection object at 0x7fd4e3448130>: Failed to establish a new connection: [Errno 111] Connection refused')': /session/d803562141e0fe33d1b8b54dd081e0b9/actions
[2025-04-01T06:50:34.483+0000] {logging_mixin.py:151} INFO - Lỗi khi lấy dữ liệu: HTTPConnectionPool(host='localhost', port=49435): Max retries exceeded with url: /session/d803562141e0fe33d1b8b54dd081e0b9/actions (Caused by NewConnectionError('<urllib3.connection.HTTPConnection object at 0x7fd4e3448280>: Failed to establish a new connection: [Errno 111] Connection refused'))
[2025-04-01T06:50:34.491+0000] {connectionpool.py:823} WARNING - Retrying (Retry(total=2, connect=None, read=None, redirect=None, status=None)) after connection broken by 'NewConnectionError('<urllib3.connection.HTTPConnection object at 0x7fd4e34480d0>: Failed to establish a new connection: [Errno 111] Connection refused')': /session/d803562141e0fe33d1b8b54dd081e0b9/actions
[2025-04-01T06:50:34.494+0000] {connectionpool.py:823} WARNING - Retrying (Retry(total=1, connect=None, read=None, redirect=None, status=None)) after connection broken by 'NewConnectionError('<urllib3.connection.HTTPConnection object at 0x7fd4e3448370>: Failed to establish a new connection: [Errno 111] Connection refused')': /session/d803562141e0fe33d1b8b54dd081e0b9/actions
[2025-04-01T06:50:34.497+0000] {connectionpool.py:823} WARNING - Retrying (Retry(total=0, connect=None, read=None, redirect=None, status=None)) after connection broken by 'NewConnectionError('<urllib3.connection.HTTPConnection object at 0x7fd4e33f3580>: Failed to establish a new connection: [Errno 111] Connection refused')': /session/d803562141e0fe33d1b8b54dd081e0b9/actions
[2025-04-01T06:50:34.503+0000] {logging_mixin.py:151} INFO - Lỗi khi lấy dữ liệu: HTTPConnectionPool(host='localhost', port=49435): Max retries exceeded with url: /session/d803562141e0fe33d1b8b54dd081e0b9/actions (Caused by NewConnectionError('<urllib3.connection.HTTPConnection object at 0x7fd4e33f31c0>: Failed to establish a new connection: [Errno 111] Connection refused'))
[2025-04-01T06:50:34.506+0000] {connectionpool.py:823} WARNING - Retrying (Retry(total=2, connect=None, read=None, redirect=None, status=None)) after connection broken by 'NewConnectionError('<urllib3.connection.HTTPConnection object at 0x7fd4e33f3a00>: Failed to establish a new connection: [Errno 111] Connection refused')': /session/d803562141e0fe33d1b8b54dd081e0b9/actions
[2025-04-01T06:50:34.510+0000] {connectionpool.py:823} WARNING - Retrying (Retry(total=1, connect=None, read=None, redirect=None, status=None)) after connection broken by 'NewConnectionError('<urllib3.connection.HTTPConnection object at 0x7fd4e33f37f0>: Failed to establish a new connection: [Errno 111] Connection refused')': /session/d803562141e0fe33d1b8b54dd081e0b9/actions
[2025-04-01T06:50:34.513+0000] {connectionpool.py:823} WARNING - Retrying (Retry(total=0, connect=None, read=None, redirect=None, status=None)) after connection broken by 'NewConnectionError('<urllib3.connection.HTTPConnection object at 0x7fd4e33f3a90>: Failed to establish a new connection: [Errno 111] Connection refused')': /session/d803562141e0fe33d1b8b54dd081e0b9/actions
[2025-04-01T06:50:34.518+0000] {logging_mixin.py:151} INFO - Lỗi khi lấy dữ liệu: HTTPConnectionPool(host='localhost', port=49435): Max retries exceeded with url: /session/d803562141e0fe33d1b8b54dd081e0b9/actions (Caused by NewConnectionError('<urllib3.connection.HTTPConnection object at 0x7fd4e33f33a0>: Failed to establish a new connection: [Errno 111] Connection refused'))
[2025-04-01T06:50:34.526+0000] {connectionpool.py:823} WARNING - Retrying (Retry(total=2, connect=None, read=None, redirect=None, status=None)) after connection broken by 'NewConnectionError('<urllib3.connection.HTTPConnection object at 0x7fd4e33e54c0>: Failed to establish a new connection: [Errno 111] Connection refused')': /session/d803562141e0fe33d1b8b54dd081e0b9/actions
[2025-04-01T06:50:34.527+0000] {connectionpool.py:823} WARNING - Retrying (Retry(total=1, connect=None, read=None, redirect=None, status=None)) after connection broken by 'NewConnectionError('<urllib3.connection.HTTPConnection object at 0x7fd4e33e55b0>: Failed to establish a new connection: [Errno 111] Connection refused')': /session/d803562141e0fe33d1b8b54dd081e0b9/actions
[2025-04-01T06:50:34.535+0000] {connectionpool.py:823} WARNING - Retrying (Retry(total=0, connect=None, read=None, redirect=None, status=None)) after connection broken by 'NewConnectionError('<urllib3.connection.HTTPConnection object at 0x7fd4e33f3760>: Failed to establish a new connection: [Errno 111] Connection refused')': /session/d803562141e0fe33d1b8b54dd081e0b9/actions
[2025-04-01T06:50:34.539+0000] {logging_mixin.py:151} INFO - Lỗi khi lấy dữ liệu: HTTPConnectionPool(host='localhost', port=49435): Max retries exceeded with url: /session/d803562141e0fe33d1b8b54dd081e0b9/actions (Caused by NewConnectionError('<urllib3.connection.HTTPConnection object at 0x7fd4e33f3310>: Failed to establish a new connection: [Errno 111] Connection refused'))
[2025-04-01T06:50:34.542+0000] {connectionpool.py:823} WARNING - Retrying (Retry(total=2, connect=None, read=None, redirect=None, status=None)) after connection broken by 'NewConnectionError('<urllib3.connection.HTTPConnection object at 0x7fd4e33f3250>: Failed to establish a new connection: [Errno 111] Connection refused')': /session/d803562141e0fe33d1b8b54dd081e0b9/actions
[2025-04-01T06:50:34.548+0000] {connectionpool.py:823} WARNING - Retrying (Retry(total=1, connect=None, read=None, redirect=None, status=None)) after connection broken by 'NewConnectionError('<urllib3.connection.HTTPConnection object at 0x7fd4e33f3370>: Failed to establish a new connection: [Errno 111] Connection refused')': /session/d803562141e0fe33d1b8b54dd081e0b9/actions
[2025-04-01T06:50:34.556+0000] {connectionpool.py:823} WARNING - Retrying (Retry(total=0, connect=None, read=None, redirect=None, status=None)) after connection broken by 'NewConnectionError('<urllib3.connection.HTTPConnection object at 0x7fd4e33f31c0>: Failed to establish a new connection: [Errno 111] Connection refused')': /session/d803562141e0fe33d1b8b54dd081e0b9/actions
[2025-04-01T06:50:34.568+0000] {logging_mixin.py:151} INFO - Lỗi khi lấy dữ liệu: HTTPConnectionPool(host='localhost', port=49435): Max retries exceeded with url: /session/d803562141e0fe33d1b8b54dd081e0b9/actions (Caused by NewConnectionError('<urllib3.connection.HTTPConnection object at 0x7fd4e33f34c0>: Failed to establish a new connection: [Errno 111] Connection refused'))
[2025-04-01T06:50:34.572+0000] {connectionpool.py:823} WARNING - Retrying (Retry(total=2, connect=None, read=None, redirect=None, status=None)) after connection broken by 'NewConnectionError('<urllib3.connection.HTTPConnection object at 0x7fd4e34481f0>: Failed to establish a new connection: [Errno 111] Connection refused')': /session/d803562141e0fe33d1b8b54dd081e0b9/actions
[2025-04-01T06:50:34.575+0000] {connectionpool.py:823} WARNING - Retrying (Retry(total=1, connect=None, read=None, redirect=None, status=None)) after connection broken by 'NewConnectionError('<urllib3.connection.HTTPConnection object at 0x7fd4e3448e50>: Failed to establish a new connection: [Errno 111] Connection refused')': /session/d803562141e0fe33d1b8b54dd081e0b9/actions
[2025-04-01T06:50:34.583+0000] {connectionpool.py:823} WARNING - Retrying (Retry(total=0, connect=None, read=None, redirect=None, status=None)) after connection broken by 'NewConnectionError('<urllib3.connection.HTTPConnection object at 0x7fd4e3448e20>: Failed to establish a new connection: [Errno 111] Connection refused')': /session/d803562141e0fe33d1b8b54dd081e0b9/actions
[2025-04-01T06:50:34.589+0000] {logging_mixin.py:151} INFO - Lỗi khi lấy dữ liệu: HTTPConnectionPool(host='localhost', port=49435): Max retries exceeded with url: /session/d803562141e0fe33d1b8b54dd081e0b9/actions (Caused by NewConnectionError('<urllib3.connection.HTTPConnection object at 0x7fd4e3448250>: Failed to establish a new connection: [Errno 111] Connection refused'))
[2025-04-01T06:50:34.592+0000] {connectionpool.py:823} WARNING - Retrying (Retry(total=2, connect=None, read=None, redirect=None, status=None)) after connection broken by 'NewConnectionError('<urllib3.connection.HTTPConnection object at 0x7fd4e34486a0>: Failed to establish a new connection: [Errno 111] Connection refused')': /session/d803562141e0fe33d1b8b54dd081e0b9/actions
[2025-04-01T06:50:34.596+0000] {connectionpool.py:823} WARNING - Retrying (Retry(total=1, connect=None, read=None, redirect=None, status=None)) after connection broken by 'NewConnectionError('<urllib3.connection.HTTPConnection object at 0x7fd4e3448c10>: Failed to establish a new connection: [Errno 111] Connection refused')': /session/d803562141e0fe33d1b8b54dd081e0b9/actions
[2025-04-01T06:50:34.599+0000] {connectionpool.py:823} WARNING - Retrying (Retry(total=0, connect=None, read=None, redirect=None, status=None)) after connection broken by 'NewConnectionError('<urllib3.connection.HTTPConnection object at 0x7fd4e34483d0>: Failed to establish a new connection: [Errno 111] Connection refused')': /session/d803562141e0fe33d1b8b54dd081e0b9/actions
[2025-04-01T06:50:34.602+0000] {logging_mixin.py:151} INFO - Lỗi khi lấy dữ liệu: HTTPConnectionPool(host='localhost', port=49435): Max retries exceeded with url: /session/d803562141e0fe33d1b8b54dd081e0b9/actions (Caused by NewConnectionError('<urllib3.connection.HTTPConnection object at 0x7fd4e33e5790>: Failed to establish a new connection: [Errno 111] Connection refused'))
[2025-04-01T06:50:34.604+0000] {connectionpool.py:823} WARNING - Retrying (Retry(total=2, connect=None, read=None, redirect=None, status=None)) after connection broken by 'NewConnectionError('<urllib3.connection.HTTPConnection object at 0x7fd4e33e5a90>: Failed to establish a new connection: [Errno 111] Connection refused')': /session/d803562141e0fe33d1b8b54dd081e0b9/actions
[2025-04-01T06:50:34.610+0000] {connectionpool.py:823} WARNING - Retrying (Retry(total=1, connect=None, read=None, redirect=None, status=None)) after connection broken by 'NewConnectionError('<urllib3.connection.HTTPConnection object at 0x7fd4e33e5b80>: Failed to establish a new connection: [Errno 111] Connection refused')': /session/d803562141e0fe33d1b8b54dd081e0b9/actions
[2025-04-01T06:50:34.613+0000] {connectionpool.py:823} WARNING - Retrying (Retry(total=0, connect=None, read=None, redirect=None, status=None)) after connection broken by 'NewConnectionError('<urllib3.connection.HTTPConnection object at 0x7fd4e3448670>: Failed to establish a new connection: [Errno 111] Connection refused')': /session/d803562141e0fe33d1b8b54dd081e0b9/actions
[2025-04-01T06:50:34.615+0000] {logging_mixin.py:151} INFO - Lỗi khi lấy dữ liệu: HTTPConnectionPool(host='localhost', port=49435): Max retries exceeded with url: /session/d803562141e0fe33d1b8b54dd081e0b9/actions (Caused by NewConnectionError('<urllib3.connection.HTTPConnection object at 0x7fd4e3448cd0>: Failed to establish a new connection: [Errno 111] Connection refused'))
[2025-04-01T06:50:34.619+0000] {connectionpool.py:823} WARNING - Retrying (Retry(total=2, connect=None, read=None, redirect=None, status=None)) after connection broken by 'NewConnectionError('<urllib3.connection.HTTPConnection object at 0x7fd4e34487f0>: Failed to establish a new connection: [Errno 111] Connection refused')': /session/d803562141e0fe33d1b8b54dd081e0b9/actions
[2025-04-01T06:50:34.623+0000] {connectionpool.py:823} WARNING - Retrying (Retry(total=1, connect=None, read=None, redirect=None, status=None)) after connection broken by 'NewConnectionError('<urllib3.connection.HTTPConnection object at 0x7fd4e3448190>: Failed to establish a new connection: [Errno 111] Connection refused')': /session/d803562141e0fe33d1b8b54dd081e0b9/actions
[2025-04-01T06:50:34.627+0000] {connectionpool.py:823} WARNING - Retrying (Retry(total=0, connect=None, read=None, redirect=None, status=None)) after connection broken by 'NewConnectionError('<urllib3.connection.HTTPConnection object at 0x7fd4e34485b0>: Failed to establish a new connection: [Errno 111] Connection refused')': /session/d803562141e0fe33d1b8b54dd081e0b9/actions
[2025-04-01T06:50:34.629+0000] {logging_mixin.py:151} INFO - Lỗi khi lấy dữ liệu: HTTPConnectionPool(host='localhost', port=49435): Max retries exceeded with url: /session/d803562141e0fe33d1b8b54dd081e0b9/actions (Caused by NewConnectionError('<urllib3.connection.HTTPConnection object at 0x7fd4e3448e20>: Failed to establish a new connection: [Errno 111] Connection refused'))
[2025-04-01T06:50:34.631+0000] {connectionpool.py:823} WARNING - Retrying (Retry(total=2, connect=None, read=None, redirect=None, status=None)) after connection broken by 'NewConnectionError('<urllib3.connection.HTTPConnection object at 0x7fd4e3448790>: Failed to establish a new connection: [Errno 111] Connection refused')': /session/d803562141e0fe33d1b8b54dd081e0b9/actions
[2025-04-01T06:50:34.634+0000] {connectionpool.py:823} WARNING - Retrying (Retry(total=1, connect=None, read=None, redirect=None, status=None)) after connection broken by 'NewConnectionError('<urllib3.connection.HTTPConnection object at 0x7fd4e33f3550>: Failed to establish a new connection: [Errno 111] Connection refused')': /session/d803562141e0fe33d1b8b54dd081e0b9/actions
[2025-04-01T06:50:34.638+0000] {connectionpool.py:823} WARNING - Retrying (Retry(total=0, connect=None, read=None, redirect=None, status=None)) after connection broken by 'NewConnectionError('<urllib3.connection.HTTPConnection object at 0x7fd4e33f30a0>: Failed to establish a new connection: [Errno 111] Connection refused')': /session/d803562141e0fe33d1b8b54dd081e0b9/actions
[2025-04-01T06:50:34.640+0000] {logging_mixin.py:151} INFO - Lỗi khi lấy dữ liệu: HTTPConnectionPool(host='localhost', port=49435): Max retries exceeded with url: /session/d803562141e0fe33d1b8b54dd081e0b9/actions (Caused by NewConnectionError('<urllib3.connection.HTTPConnection object at 0x7fd4e33f32b0>: Failed to establish a new connection: [Errno 111] Connection refused'))
[2025-04-01T06:50:34.653+0000] {connectionpool.py:823} WARNING - Retrying (Retry(total=2, connect=None, read=None, redirect=None, status=None)) after connection broken by 'NewConnectionError('<urllib3.connection.HTTPConnection object at 0x7fd4e33f3820>: Failed to establish a new connection: [Errno 111] Connection refused')': /session/d803562141e0fe33d1b8b54dd081e0b9/actions
[2025-04-01T06:50:34.654+0000] {connectionpool.py:823} WARNING - Retrying (Retry(total=1, connect=None, read=None, redirect=None, status=None)) after connection broken by 'NewConnectionError('<urllib3.connection.HTTPConnection object at 0x7fd4e33f37f0>: Failed to establish a new connection: [Errno 111] Connection refused')': /session/d803562141e0fe33d1b8b54dd081e0b9/actions
[2025-04-01T06:50:34.657+0000] {connectionpool.py:823} WARNING - Retrying (Retry(total=0, connect=None, read=None, redirect=None, status=None)) after connection broken by 'NewConnectionError('<urllib3.connection.HTTPConnection object at 0x7fd4e33f3f70>: Failed to establish a new connection: [Errno 111] Connection refused')': /session/d803562141e0fe33d1b8b54dd081e0b9/actions
[2025-04-01T06:50:34.666+0000] {logging_mixin.py:151} INFO - Lỗi khi lấy dữ liệu: HTTPConnectionPool(host='localhost', port=49435): Max retries exceeded with url: /session/d803562141e0fe33d1b8b54dd081e0b9/actions (Caused by NewConnectionError('<urllib3.connection.HTTPConnection object at 0x7fd4e33e5a60>: Failed to establish a new connection: [Errno 111] Connection refused'))
[2025-04-01T06:50:34.706+0000] {connectionpool.py:823} WARNING - Retrying (Retry(total=2, connect=None, read=None, redirect=None, status=None)) after connection broken by 'NewConnectionError('<urllib3.connection.HTTPConnection object at 0x7fd4e33e5f10>: Failed to establish a new connection: [Errno 111] Connection refused')': /session/d803562141e0fe33d1b8b54dd081e0b9/actions
[2025-04-01T06:50:34.710+0000] {connectionpool.py:823} WARNING - Retrying (Retry(total=1, connect=None, read=None, redirect=None, status=None)) after connection broken by 'NewConnectionError('<urllib3.connection.HTTPConnection object at 0x7fd4e33eb070>: Failed to establish a new connection: [Errno 111] Connection refused')': /session/d803562141e0fe33d1b8b54dd081e0b9/actions
[2025-04-01T06:50:34.713+0000] {connectionpool.py:823} WARNING - Retrying (Retry(total=0, connect=None, read=None, redirect=None, status=None)) after connection broken by 'NewConnectionError('<urllib3.connection.HTTPConnection object at 0x7fd4e33f3460>: Failed to establish a new connection: [Errno 111] Connection refused')': /session/d803562141e0fe33d1b8b54dd081e0b9/actions
[2025-04-01T06:50:34.718+0000] {logging_mixin.py:151} INFO - Lỗi khi lấy dữ liệu: HTTPConnectionPool(host='localhost', port=49435): Max retries exceeded with url: /session/d803562141e0fe33d1b8b54dd081e0b9/actions (Caused by NewConnectionError('<urllib3.connection.HTTPConnection object at 0x7fd4e33f3070>: Failed to establish a new connection: [Errno 111] Connection refused'))
[2025-04-01T06:50:34.726+0000] {connectionpool.py:823} WARNING - Retrying (Retry(total=2, connect=None, read=None, redirect=None, status=None)) after connection broken by 'NewConnectionError('<urllib3.connection.HTTPConnection object at 0x7fd4e33f3370>: Failed to establish a new connection: [Errno 111] Connection refused')': /session/d803562141e0fe33d1b8b54dd081e0b9/actions
[2025-04-01T06:50:34.728+0000] {connectionpool.py:823} WARNING - Retrying (Retry(total=1, connect=None, read=None, redirect=None, status=None)) after connection broken by 'NewConnectionError('<urllib3.connection.HTTPConnection object at 0x7fd4e33f3220>: Failed to establish a new connection: [Errno 111] Connection refused')': /session/d803562141e0fe33d1b8b54dd081e0b9/actions
[2025-04-01T06:50:34.729+0000] {connectionpool.py:823} WARNING - Retrying (Retry(total=0, connect=None, read=None, redirect=None, status=None)) after connection broken by 'NewConnectionError('<urllib3.connection.HTTPConnection object at 0x7fd4e33f3400>: Failed to establish a new connection: [Errno 111] Connection refused')': /session/d803562141e0fe33d1b8b54dd081e0b9/actions
[2025-04-01T06:50:34.731+0000] {logging_mixin.py:151} INFO - Lỗi khi lấy dữ liệu: HTTPConnectionPool(host='localhost', port=49435): Max retries exceeded with url: /session/d803562141e0fe33d1b8b54dd081e0b9/actions (Caused by NewConnectionError('<urllib3.connection.HTTPConnection object at 0x7fd4e33f3550>: Failed to establish a new connection: [Errno 111] Connection refused'))
[2025-04-01T06:50:34.737+0000] {connectionpool.py:823} WARNING - Retrying (Retry(total=2, connect=None, read=None, redirect=None, status=None)) after connection broken by 'NewConnectionError('<urllib3.connection.HTTPConnection object at 0x7fd4e34480a0>: Failed to establish a new connection: [Errno 111] Connection refused')': /session/d803562141e0fe33d1b8b54dd081e0b9/actions
[2025-04-01T06:50:34.739+0000] {connectionpool.py:823} WARNING - Retrying (Retry(total=1, connect=None, read=None, redirect=None, status=None)) after connection broken by 'NewConnectionError('<urllib3.connection.HTTPConnection object at 0x7fd4e3448160>: Failed to establish a new connection: [Errno 111] Connection refused')': /session/d803562141e0fe33d1b8b54dd081e0b9/actions
[2025-04-01T06:50:34.740+0000] {connectionpool.py:823} WARNING - Retrying (Retry(total=0, connect=None, read=None, redirect=None, status=None)) after connection broken by 'NewConnectionError('<urllib3.connection.HTTPConnection object at 0x7fd4e3448d90>: Failed to establish a new connection: [Errno 111] Connection refused')': /session/d803562141e0fe33d1b8b54dd081e0b9/actions
[2025-04-01T06:50:34.742+0000] {logging_mixin.py:151} INFO - Lỗi khi lấy dữ liệu: HTTPConnectionPool(host='localhost', port=49435): Max retries exceeded with url: /session/d803562141e0fe33d1b8b54dd081e0b9/actions (Caused by NewConnectionError('<urllib3.connection.HTTPConnection object at 0x7fd4e34485b0>: Failed to establish a new connection: [Errno 111] Connection refused'))
[2025-04-01T06:50:34.747+0000] {connectionpool.py:823} WARNING - Retrying (Retry(total=2, connect=None, read=None, redirect=None, status=None)) after connection broken by 'NewConnectionError('<urllib3.connection.HTTPConnection object at 0x7fd4e3448940>: Failed to establish a new connection: [Errno 111] Connection refused')': /session/d803562141e0fe33d1b8b54dd081e0b9/actions
[2025-04-01T06:50:34.754+0000] {connectionpool.py:823} WARNING - Retrying (Retry(total=1, connect=None, read=None, redirect=None, status=None)) after connection broken by 'NewConnectionError('<urllib3.connection.HTTPConnection object at 0x7fd4e3448b20>: Failed to establish a new connection: [Errno 111] Connection refused')': /session/d803562141e0fe33d1b8b54dd081e0b9/actions
[2025-04-01T06:50:34.758+0000] {connectionpool.py:823} WARNING - Retrying (Retry(total=0, connect=None, read=None, redirect=None, status=None)) after connection broken by 'NewConnectionError('<urllib3.connection.HTTPConnection object at 0x7fd4e3448fd0>: Failed to establish a new connection: [Errno 111] Connection refused')': /session/d803562141e0fe33d1b8b54dd081e0b9/actions
[2025-04-01T06:50:34.763+0000] {logging_mixin.py:151} INFO - Lỗi khi lấy dữ liệu: HTTPConnectionPool(host='localhost', port=49435): Max retries exceeded with url: /session/d803562141e0fe33d1b8b54dd081e0b9/actions (Caused by NewConnectionError('<urllib3.connection.HTTPConnection object at 0x7fd4e33e5d60>: Failed to establish a new connection: [Errno 111] Connection refused'))
[2025-04-01T06:50:34.766+0000] {connectionpool.py:823} WARNING - Retrying (Retry(total=2, connect=None, read=None, redirect=None, status=None)) after connection broken by 'NewConnectionError('<urllib3.connection.HTTPConnection object at 0x7fd4e33eb3d0>: Failed to establish a new connection: [Errno 111] Connection refused')': /session/d803562141e0fe33d1b8b54dd081e0b9/actions
[2025-04-01T06:50:34.772+0000] {connectionpool.py:823} WARNING - Retrying (Retry(total=1, connect=None, read=None, redirect=None, status=None)) after connection broken by 'NewConnectionError('<urllib3.connection.HTTPConnection object at 0x7fd4e33eb4c0>: Failed to establish a new connection: [Errno 111] Connection refused')': /session/d803562141e0fe33d1b8b54dd081e0b9/actions
[2025-04-01T06:50:34.776+0000] {connectionpool.py:823} WARNING - Retrying (Retry(total=0, connect=None, read=None, redirect=None, status=None)) after connection broken by 'NewConnectionError('<urllib3.connection.HTTPConnection object at 0x7fd4e33e5d60>: Failed to establish a new connection: [Errno 111] Connection refused')': /session/d803562141e0fe33d1b8b54dd081e0b9/actions
[2025-04-01T06:50:34.780+0000] {logging_mixin.py:151} INFO - Lỗi khi lấy dữ liệu: HTTPConnectionPool(host='localhost', port=49435): Max retries exceeded with url: /session/d803562141e0fe33d1b8b54dd081e0b9/actions (Caused by NewConnectionError('<urllib3.connection.HTTPConnection object at 0x7fd4e34483a0>: Failed to establish a new connection: [Errno 111] Connection refused'))
[2025-04-01T06:50:34.783+0000] {connectionpool.py:823} WARNING - Retrying (Retry(total=2, connect=None, read=None, redirect=None, status=None)) after connection broken by 'NewConnectionError('<urllib3.connection.HTTPConnection object at 0x7fd4e3448eb0>: Failed to establish a new connection: [Errno 111] Connection refused')': /session/d803562141e0fe33d1b8b54dd081e0b9/actions
[2025-04-01T06:50:34.787+0000] {connectionpool.py:823} WARNING - Retrying (Retry(total=1, connect=None, read=None, redirect=None, status=None)) after connection broken by 'NewConnectionError('<urllib3.connection.HTTPConnection object at 0x7fd4e3448130>: Failed to establish a new connection: [Errno 111] Connection refused')': /session/d803562141e0fe33d1b8b54dd081e0b9/actions
[2025-04-01T06:50:34.790+0000] {connectionpool.py:823} WARNING - Retrying (Retry(total=0, connect=None, read=None, redirect=None, status=None)) after connection broken by 'NewConnectionError('<urllib3.connection.HTTPConnection object at 0x7fd4e3448370>: Failed to establish a new connection: [Errno 111] Connection refused')': /session/d803562141e0fe33d1b8b54dd081e0b9/actions
[2025-04-01T06:50:34.793+0000] {logging_mixin.py:151} INFO - Lỗi khi lấy dữ liệu: HTTPConnectionPool(host='localhost', port=49435): Max retries exceeded with url: /session/d803562141e0fe33d1b8b54dd081e0b9/actions (Caused by NewConnectionError('<urllib3.connection.HTTPConnection object at 0x7fd4e3448190>: Failed to establish a new connection: [Errno 111] Connection refused'))
[2025-04-01T06:50:34.795+0000] {connectionpool.py:823} WARNING - Retrying (Retry(total=2, connect=None, read=None, redirect=None, status=None)) after connection broken by 'NewConnectionError('<urllib3.connection.HTTPConnection object at 0x7fd4e34486d0>: Failed to establish a new connection: [Errno 111] Connection refused')': /session/d803562141e0fe33d1b8b54dd081e0b9/actions
[2025-04-01T06:50:34.797+0000] {connectionpool.py:823} WARNING - Retrying (Retry(total=1, connect=None, read=None, redirect=None, status=None)) after connection broken by 'NewConnectionError('<urllib3.connection.HTTPConnection object at 0x7fd4e3448430>: Failed to establish a new connection: [Errno 111] Connection refused')': /session/d803562141e0fe33d1b8b54dd081e0b9/actions
[2025-04-01T06:50:34.804+0000] {connectionpool.py:823} WARNING - Retrying (Retry(total=0, connect=None, read=None, redirect=None, status=None)) after connection broken by 'NewConnectionError('<urllib3.connection.HTTPConnection object at 0x7fd4e33f3280>: Failed to establish a new connection: [Errno 111] Connection refused')': /session/d803562141e0fe33d1b8b54dd081e0b9/actions
[2025-04-01T06:50:34.813+0000] {logging_mixin.py:151} INFO - Lỗi khi lấy dữ liệu: HTTPConnectionPool(host='localhost', port=49435): Max retries exceeded with url: /session/d803562141e0fe33d1b8b54dd081e0b9/actions (Caused by NewConnectionError('<urllib3.connection.HTTPConnection object at 0x7fd4e33f3580>: Failed to establish a new connection: [Errno 111] Connection refused'))
[2025-04-01T06:50:34.820+0000] {connectionpool.py:823} WARNING - Retrying (Retry(total=2, connect=None, read=None, redirect=None, status=None)) after connection broken by 'NewConnectionError('<urllib3.connection.HTTPConnection object at 0x7fd4e33f3520>: Failed to establish a new connection: [Errno 111] Connection refused')': /session/d803562141e0fe33d1b8b54dd081e0b9/actions
[2025-04-01T06:50:34.822+0000] {connectionpool.py:823} WARNING - Retrying (Retry(total=1, connect=None, read=None, redirect=None, status=None)) after connection broken by 'NewConnectionError('<urllib3.connection.HTTPConnection object at 0x7fd4e33f3760>: Failed to establish a new connection: [Errno 111] Connection refused')': /session/d803562141e0fe33d1b8b54dd081e0b9/actions
[2025-04-01T06:50:34.825+0000] {connectionpool.py:823} WARNING - Retrying (Retry(total=0, connect=None, read=None, redirect=None, status=None)) after connection broken by 'NewConnectionError('<urllib3.connection.HTTPConnection object at 0x7fd4e33f36d0>: Failed to establish a new connection: [Errno 111] Connection refused')': /session/d803562141e0fe33d1b8b54dd081e0b9/actions
[2025-04-01T06:50:34.827+0000] {logging_mixin.py:151} INFO - Lỗi khi lấy dữ liệu: HTTPConnectionPool(host='localhost', port=49435): Max retries exceeded with url: /session/d803562141e0fe33d1b8b54dd081e0b9/actions (Caused by NewConnectionError('<urllib3.connection.HTTPConnection object at 0x7fd4e33f3f70>: Failed to establish a new connection: [Errno 111] Connection refused'))
[2025-04-01T06:50:34.830+0000] {connectionpool.py:823} WARNING - Retrying (Retry(total=2, connect=None, read=None, redirect=None, status=None)) after connection broken by 'NewConnectionError('<urllib3.connection.HTTPConnection object at 0x7fd4e33eb880>: Failed to establish a new connection: [Errno 111] Connection refused')': /session/d803562141e0fe33d1b8b54dd081e0b9/actions
[2025-04-01T06:50:34.835+0000] {connectionpool.py:823} WARNING - Retrying (Retry(total=1, connect=None, read=None, redirect=None, status=None)) after connection broken by 'NewConnectionError('<urllib3.connection.HTTPConnection object at 0x7fd4e33eb970>: Failed to establish a new connection: [Errno 111] Connection refused')': /session/d803562141e0fe33d1b8b54dd081e0b9/actions
[2025-04-01T06:50:34.843+0000] {connectionpool.py:823} WARNING - Retrying (Retry(total=0, connect=None, read=None, redirect=None, status=None)) after connection broken by 'NewConnectionError('<urllib3.connection.HTTPConnection object at 0x7fd4e33f3160>: Failed to establish a new connection: [Errno 111] Connection refused')': /session/d803562141e0fe33d1b8b54dd081e0b9/actions
[2025-04-01T06:50:34.845+0000] {logging_mixin.py:151} INFO - Lỗi khi lấy dữ liệu: HTTPConnectionPool(host='localhost', port=49435): Max retries exceeded with url: /session/d803562141e0fe33d1b8b54dd081e0b9/actions (Caused by NewConnectionError('<urllib3.connection.HTTPConnection object at 0x7fd4e33f38b0>: Failed to establish a new connection: [Errno 111] Connection refused'))
[2025-04-01T06:50:34.848+0000] {connectionpool.py:823} WARNING - Retrying (Retry(total=2, connect=None, read=None, redirect=None, status=None)) after connection broken by 'NewConnectionError('<urllib3.connection.HTTPConnection object at 0x7fd4e33f3430>: Failed to establish a new connection: [Errno 111] Connection refused')': /session/d803562141e0fe33d1b8b54dd081e0b9/actions
[2025-04-01T06:50:34.852+0000] {connectionpool.py:823} WARNING - Retrying (Retry(total=1, connect=None, read=None, redirect=None, status=None)) after connection broken by 'NewConnectionError('<urllib3.connection.HTTPConnection object at 0x7fd4e33f3370>: Failed to establish a new connection: [Errno 111] Connection refused')': /session/d803562141e0fe33d1b8b54dd081e0b9/actions
[2025-04-01T06:50:34.855+0000] {connectionpool.py:823} WARNING - Retrying (Retry(total=0, connect=None, read=None, redirect=None, status=None)) after connection broken by 'NewConnectionError('<urllib3.connection.HTTPConnection object at 0x7fd4e33f35b0>: Failed to establish a new connection: [Errno 111] Connection refused')': /session/d803562141e0fe33d1b8b54dd081e0b9/actions
[2025-04-01T06:50:34.858+0000] {logging_mixin.py:151} INFO - Lỗi khi lấy dữ liệu: HTTPConnectionPool(host='localhost', port=49435): Max retries exceeded with url: /session/d803562141e0fe33d1b8b54dd081e0b9/actions (Caused by NewConnectionError('<urllib3.connection.HTTPConnection object at 0x7fd4e33f3190>: Failed to establish a new connection: [Errno 111] Connection refused'))
[2025-04-01T06:50:34.863+0000] {connectionpool.py:823} WARNING - Retrying (Retry(total=2, connect=None, read=None, redirect=None, status=None)) after connection broken by 'NewConnectionError('<urllib3.connection.HTTPConnection object at 0x7fd4e34480d0>: Failed to establish a new connection: [Errno 111] Connection refused')': /session/d803562141e0fe33d1b8b54dd081e0b9/actions
[2025-04-01T06:50:34.865+0000] {connectionpool.py:823} WARNING - Retrying (Retry(total=1, connect=None, read=None, redirect=None, status=None)) after connection broken by 'NewConnectionError('<urllib3.connection.HTTPConnection object at 0x7fd4e34480a0>: Failed to establish a new connection: [Errno 111] Connection refused')': /session/d803562141e0fe33d1b8b54dd081e0b9/actions
[2025-04-01T06:50:34.873+0000] {connectionpool.py:823} WARNING - Retrying (Retry(total=0, connect=None, read=None, redirect=None, status=None)) after connection broken by 'NewConnectionError('<urllib3.connection.HTTPConnection object at 0x7fd4e3448610>: Failed to establish a new connection: [Errno 111] Connection refused')': /session/d803562141e0fe33d1b8b54dd081e0b9/actions
[2025-04-01T06:50:34.876+0000] {logging_mixin.py:151} INFO - Lỗi khi lấy dữ liệu: HTTPConnectionPool(host='localhost', port=49435): Max retries exceeded with url: /session/d803562141e0fe33d1b8b54dd081e0b9/actions (Caused by NewConnectionError('<urllib3.connection.HTTPConnection object at 0x7fd4e3448190>: Failed to establish a new connection: [Errno 111] Connection refused'))
[2025-04-01T06:50:34.879+0000] {connectionpool.py:823} WARNING - Retrying (Retry(total=2, connect=None, read=None, redirect=None, status=None)) after connection broken by 'NewConnectionError('<urllib3.connection.HTTPConnection object at 0x7fd4e3448220>: Failed to establish a new connection: [Errno 111] Connection refused')': /session/d803562141e0fe33d1b8b54dd081e0b9/url
[2025-04-01T06:50:34.882+0000] {connectionpool.py:823} WARNING - Retrying (Retry(total=1, connect=None, read=None, redirect=None, status=None)) after connection broken by 'NewConnectionError('<urllib3.connection.HTTPConnection object at 0x7fd4e3448eb0>: Failed to establish a new connection: [Errno 111] Connection refused')': /session/d803562141e0fe33d1b8b54dd081e0b9/url
[2025-04-01T06:50:34.890+0000] {connectionpool.py:823} WARNING - Retrying (Retry(total=0, connect=None, read=None, redirect=None, status=None)) after connection broken by 'NewConnectionError('<urllib3.connection.HTTPConnection object at 0x7fd4e3448910>: Failed to establish a new connection: [Errno 111] Connection refused')': /session/d803562141e0fe33d1b8b54dd081e0b9/url
[2025-04-01T06:50:34.895+0000] {data_stream.py:39} ERROR - An error occurred: HTTPConnectionPool(host='localhost', port=49435): Max retries exceeded with url: /session/d803562141e0fe33d1b8b54dd081e0b9/url (Caused by NewConnectionError('<urllib3.connection.HTTPConnection object at 0x7fd4e3448970>: Failed to establish a new connection: [Errno 111] Connection refused'))
[2025-04-01T06:50:34.898+0000] {python.py:194} INFO - Done. Returned value was: None
[2025-04-01T06:50:34.936+0000] {taskinstance.py:1400} INFO - Marking task as SUCCESS. dag_id=job_data_stream, task_id=job_data_stream, execution_date=20250401T064958, start_date=20250401T064959, end_date=20250401T065034
[2025-04-01T06:50:34.976+0000] {process_utils.py:79} INFO - Process psutil.Process(pid=52, status='terminated', exitcode=0, started='06:49:59') (52) terminated with exit code 0
[2025-04-01T06:50:34.977+0000] {process_utils.py:79} INFO - Process psutil.Process(pid=54, status='terminated', started='06:49:59') (54) terminated with exit code None
[2025-04-01T06:50:34.978+0000] {local_task_job_runner.py:228} INFO - Task exited with return code 143
[2025-04-01T06:50:35.008+0000] {taskinstance.py:2784} INFO - 0 downstream tasks scheduled from follow-on schedule check
