[2025-03-25T02:38:37.909+0000] {taskinstance.py:1159} INFO - Dependencies all met for dep_context=non-requeueable deps ti=<TaskInstance: job_data_stream.job_data_stream manual__2025-03-25T02:38:36.831366+00:00 [queued]>
[2025-03-25T02:38:37.921+0000] {taskinstance.py:1159} INFO - Dependencies all met for dep_context=requeueable deps ti=<TaskInstance: job_data_stream.job_data_stream manual__2025-03-25T02:38:36.831366+00:00 [queued]>
[2025-03-25T02:38:37.921+0000] {taskinstance.py:1361} INFO - Starting attempt 1 of 1
[2025-03-25T02:38:37.938+0000] {taskinstance.py:1382} INFO - Executing <Task(PythonOperator): job_data_stream> on 2025-03-25 02:38:36.831366+00:00
[2025-03-25T02:38:37.943+0000] {standard_task_runner.py:57} INFO - Started process 3212 to run task
[2025-03-25T02:38:37.947+0000] {standard_task_runner.py:84} INFO - Running: ['***', 'tasks', 'run', 'job_data_stream', 'job_data_stream', 'manual__2025-03-25T02:38:36.831366+00:00', '--job-id', '48', '--raw', '--subdir', 'DAGS_FOLDER/data_stream.py', '--cfg-path', '/tmp/tmpjhb9s1cc']
[2025-03-25T02:38:37.949+0000] {standard_task_runner.py:85} INFO - Job 48: Subtask job_data_stream
[2025-03-25T02:38:38.018+0000] {task_command.py:415} INFO - Running <TaskInstance: job_data_stream.job_data_stream manual__2025-03-25T02:38:36.831366+00:00 [running]> on host 844ea759a987
[2025-03-25T02:38:38.120+0000] {taskinstance.py:1660} INFO - Exporting env vars: AIRFLOW_CTX_DAG_OWNER='dii' AIRFLOW_CTX_DAG_ID='job_data_stream' AIRFLOW_CTX_TASK_ID='job_data_stream' AIRFLOW_CTX_EXECUTION_DATE='2025-03-25T02:38:36.831366+00:00' AIRFLOW_CTX_TRY_NUMBER='1' AIRFLOW_CTX_DAG_RUN_ID='manual__2025-03-25T02:38:36.831366+00:00'
[2025-03-25T02:38:38.123+0000] {conn.py:384} INFO - <BrokerConnection client_id=kafka-python-producer-1, node_id=bootstrap-0 host=broker:29092 <connecting> [IPv4 ('172.18.0.2', 29092)]>: connecting to broker:29092 [('172.18.0.2', 29092) IPv4]
[2025-03-25T02:38:38.124+0000] {conn.py:1219} INFO - Probing node bootstrap-0 broker version
[2025-03-25T02:38:38.124+0000] {conn.py:414} INFO - <BrokerConnection client_id=kafka-python-producer-1, node_id=bootstrap-0 host=broker:29092 <connecting> [IPv4 ('172.18.0.2', 29092)]>: Connection complete.
[2025-03-25T02:38:38.239+0000] {conn.py:1282} INFO - Broker version identified as 2.6.0
[2025-03-25T02:38:38.240+0000] {conn.py:1283} INFO - Set configuration api_version=(2, 6, 0) to skip auto check_version requests on startup
[2025-03-25T02:38:50.737+0000] {logging_mixin.py:151} INFO - Số công việc tìm thấy trên trang 301:70
[2025-03-25T02:40:41.977+0000] {logging_mixin.py:151} INFO - Số công việc tìm thấy trên trang 302:70
[2025-03-25T02:42:32.621+0000] {logging_mixin.py:151} INFO - Số công việc tìm thấy trên trang 303:70
[2025-03-25T02:43:38.352+0000] {conn.py:384} INFO - <BrokerConnection client_id=kafka-python-producer-1, node_id=1 host=broker:29092 <connecting> [IPv4 ('172.18.0.2', 29092)]>: connecting to broker:29092 [('172.18.0.2', 29092) IPv4]
[2025-03-25T02:43:38.354+0000] {conn.py:414} INFO - <BrokerConnection client_id=kafka-python-producer-1, node_id=1 host=broker:29092 <connecting> [IPv4 ('172.18.0.2', 29092)]>: Connection complete.
[2025-03-25T02:43:38.356+0000] {conn.py:928} INFO - <BrokerConnection client_id=kafka-python-producer-1, node_id=bootstrap-0 host=broker:29092 <connected> [IPv4 ('172.18.0.2', 29092)]>: Closing connection. 
[2025-03-25T02:44:23.396+0000] {logging_mixin.py:151} INFO - Số công việc tìm thấy trên trang 304:70
[2025-03-25T02:46:14.959+0000] {logging_mixin.py:151} INFO - Số công việc tìm thấy trên trang 305:70
[2025-03-25T02:48:05.385+0000] {logging_mixin.py:151} INFO - Số công việc tìm thấy trên trang 306:70
[2025-03-25T02:49:56.527+0000] {logging_mixin.py:151} INFO - Số công việc tìm thấy trên trang 307:70
[2025-03-25T02:51:47.944+0000] {logging_mixin.py:151} INFO - Số công việc tìm thấy trên trang 308:70
[2025-03-25T02:53:39.573+0000] {logging_mixin.py:151} INFO - Số công việc tìm thấy trên trang 309:70
[2025-03-25T02:55:30.462+0000] {logging_mixin.py:151} INFO - Số công việc tìm thấy trên trang 310:70
[2025-03-25T02:57:22.037+0000] {logging_mixin.py:151} INFO - Số công việc tìm thấy trên trang 311:70
[2025-03-25T02:59:12.802+0000] {logging_mixin.py:151} INFO - Số công việc tìm thấy trên trang 312:70
[2025-03-25T03:01:03.820+0000] {logging_mixin.py:151} INFO - Số công việc tìm thấy trên trang 313:70
[2025-03-25T03:02:55.233+0000] {logging_mixin.py:151} INFO - Số công việc tìm thấy trên trang 314:70
[2025-03-25T03:04:46.511+0000] {logging_mixin.py:151} INFO - Số công việc tìm thấy trên trang 315:70
[2025-03-25T03:06:37.269+0000] {logging_mixin.py:151} INFO - Số công việc tìm thấy trên trang 316:70
[2025-03-25T03:08:27.365+0000] {logging_mixin.py:151} INFO - Số công việc tìm thấy trên trang 317:70
[2025-03-25T03:10:18.610+0000] {logging_mixin.py:151} INFO - Số công việc tìm thấy trên trang 318:70
[2025-03-25T03:12:09.332+0000] {logging_mixin.py:151} INFO - Số công việc tìm thấy trên trang 319:70
[2025-03-25T03:13:59.821+0000] {logging_mixin.py:151} INFO - Số công việc tìm thấy trên trang 320:70
[2025-03-25T03:15:51.598+0000] {logging_mixin.py:151} INFO - Số công việc tìm thấy trên trang 321:70
[2025-03-25T03:17:42.767+0000] {logging_mixin.py:151} INFO - Số công việc tìm thấy trên trang 322:70
[2025-03-25T03:19:34.428+0000] {logging_mixin.py:151} INFO - Số công việc tìm thấy trên trang 323:70
[2025-03-25T03:21:25.944+0000] {logging_mixin.py:151} INFO - Số công việc tìm thấy trên trang 324:70
[2025-03-25T03:23:17.264+0000] {logging_mixin.py:151} INFO - Số công việc tìm thấy trên trang 325:70
[2025-03-25T03:25:08.830+0000] {logging_mixin.py:151} INFO - Số công việc tìm thấy trên trang 326:70
[2025-03-25T03:26:59.919+0000] {logging_mixin.py:151} INFO - Số công việc tìm thấy trên trang 327:70
[2025-03-25T03:28:50.762+0000] {logging_mixin.py:151} INFO - Số công việc tìm thấy trên trang 328:70
[2025-03-25T03:30:40.969+0000] {logging_mixin.py:151} INFO - Số công việc tìm thấy trên trang 329:70
[2025-03-25T03:32:31.318+0000] {logging_mixin.py:151} INFO - Số công việc tìm thấy trên trang 330:70
[2025-03-25T03:34:21.490+0000] {logging_mixin.py:151} INFO - Số công việc tìm thấy trên trang 331:70
[2025-03-25T03:36:11.902+0000] {logging_mixin.py:151} INFO - Số công việc tìm thấy trên trang 332:70
[2025-03-25T03:38:02.020+0000] {logging_mixin.py:151} INFO - Số công việc tìm thấy trên trang 333:70
[2025-03-25T03:39:52.378+0000] {logging_mixin.py:151} INFO - Số công việc tìm thấy trên trang 334:70
[2025-03-25T03:41:44.130+0000] {logging_mixin.py:151} INFO - Số công việc tìm thấy trên trang 335:70
[2025-03-25T03:43:34.829+0000] {logging_mixin.py:151} INFO - Số công việc tìm thấy trên trang 336:70
[2025-03-25T03:45:25.629+0000] {logging_mixin.py:151} INFO - Số công việc tìm thấy trên trang 337:70
[2025-03-25T03:47:16.428+0000] {logging_mixin.py:151} INFO - Số công việc tìm thấy trên trang 338:70
[2025-03-25T03:49:06.466+0000] {logging_mixin.py:151} INFO - Số công việc tìm thấy trên trang 339:70
[2025-03-25T03:50:57.583+0000] {logging_mixin.py:151} INFO - Số công việc tìm thấy trên trang 340:70
[2025-03-25T03:52:48.053+0000] {logging_mixin.py:151} INFO - Số công việc tìm thấy trên trang 341:70
[2025-03-25T03:54:38.398+0000] {logging_mixin.py:151} INFO - Số công việc tìm thấy trên trang 342:70
[2025-03-25T03:56:28.779+0000] {logging_mixin.py:151} INFO - Số công việc tìm thấy trên trang 343:70
[2025-03-25T03:58:19.320+0000] {logging_mixin.py:151} INFO - Số công việc tìm thấy trên trang 344:70
[2025-03-25T04:00:09.363+0000] {logging_mixin.py:151} INFO - Số công việc tìm thấy trên trang 345:70
[2025-03-25T04:01:59.699+0000] {logging_mixin.py:151} INFO - Số công việc tìm thấy trên trang 346:70
[2025-03-25T04:03:51.201+0000] {logging_mixin.py:151} INFO - Số công việc tìm thấy trên trang 347:70
[2025-03-25T04:05:41.516+0000] {logging_mixin.py:151} INFO - Số công việc tìm thấy trên trang 348:70
[2025-03-25T04:07:32.976+0000] {logging_mixin.py:151} INFO - Số công việc tìm thấy trên trang 349:70
[2025-03-25T04:09:23.607+0000] {logging_mixin.py:151} INFO - Số công việc tìm thấy trên trang 350:70
[2025-03-25T04:11:13.938+0000] {logging_mixin.py:151} INFO - Số công việc tìm thấy trên trang 351:70
[2025-03-25T04:13:04.716+0000] {logging_mixin.py:151} INFO - Số công việc tìm thấy trên trang 352:70
[2025-03-25T04:14:55.918+0000] {logging_mixin.py:151} INFO - Số công việc tìm thấy trên trang 353:70
[2025-03-25T04:16:47.290+0000] {logging_mixin.py:151} INFO - Số công việc tìm thấy trên trang 354:70
[2025-03-25T04:18:38.463+0000] {logging_mixin.py:151} INFO - Số công việc tìm thấy trên trang 355:70
[2025-03-25T04:20:29.765+0000] {logging_mixin.py:151} INFO - Số công việc tìm thấy trên trang 356:70
[2025-03-25T04:22:21.646+0000] {logging_mixin.py:151} INFO - Số công việc tìm thấy trên trang 357:70
[2025-03-25T04:24:13.288+0000] {logging_mixin.py:151} INFO - Số công việc tìm thấy trên trang 358:70
[2025-03-25T04:26:04.893+0000] {logging_mixin.py:151} INFO - Số công việc tìm thấy trên trang 359:70
[2025-03-25T04:27:56.159+0000] {logging_mixin.py:151} INFO - Số công việc tìm thấy trên trang 360:70
[2025-03-25T04:29:47.291+0000] {logging_mixin.py:151} INFO - Số công việc tìm thấy trên trang 361:70
[2025-03-25T04:31:37.532+0000] {logging_mixin.py:151} INFO - Số công việc tìm thấy trên trang 362:70
[2025-03-25T04:33:27.854+0000] {logging_mixin.py:151} INFO - Số công việc tìm thấy trên trang 363:70
[2025-03-25T04:35:18.081+0000] {logging_mixin.py:151} INFO - Số công việc tìm thấy trên trang 364:70
[2025-03-25T04:37:09.105+0000] {logging_mixin.py:151} INFO - Số công việc tìm thấy trên trang 365:70
[2025-03-25T04:38:58.806+0000] {logging_mixin.py:151} INFO - Số công việc tìm thấy trên trang 366:70
[2025-03-25T04:40:50.710+0000] {logging_mixin.py:151} INFO - Số công việc tìm thấy trên trang 367:70
[2025-03-25T04:42:42.279+0000] {logging_mixin.py:151} INFO - Số công việc tìm thấy trên trang 368:70
[2025-03-25T04:44:34.034+0000] {logging_mixin.py:151} INFO - Số công việc tìm thấy trên trang 369:70
[2025-03-25T04:46:23.724+0000] {logging_mixin.py:151} INFO - Số công việc tìm thấy trên trang 370:70
[2025-03-25T04:48:13.740+0000] {logging_mixin.py:151} INFO - Số công việc tìm thấy trên trang 371:70
[2025-03-25T04:50:04.752+0000] {logging_mixin.py:151} INFO - Số công việc tìm thấy trên trang 372:70
[2025-03-25T04:51:55.975+0000] {logging_mixin.py:151} INFO - Số công việc tìm thấy trên trang 373:70
[2025-03-25T04:53:46.385+0000] {logging_mixin.py:151} INFO - Số công việc tìm thấy trên trang 374:70
[2025-03-25T04:55:37.667+0000] {logging_mixin.py:151} INFO - Số công việc tìm thấy trên trang 375:70
[2025-03-25T04:57:28.058+0000] {logging_mixin.py:151} INFO - Số công việc tìm thấy trên trang 376:70
[2025-03-25T04:59:18.612+0000] {logging_mixin.py:151} INFO - Số công việc tìm thấy trên trang 377:70
[2025-03-25T05:01:08.550+0000] {logging_mixin.py:151} INFO - Số công việc tìm thấy trên trang 378:70
[2025-03-25T05:02:57.762+0000] {logging_mixin.py:151} INFO - Số công việc tìm thấy trên trang 379:70
[2025-03-25T05:04:58.112+0000] {logging_mixin.py:151} INFO - Số công việc tìm thấy trên trang 380:70
[2025-03-25T05:07:08.124+0000] {logging_mixin.py:151} INFO - Lỗi khi lấy dữ liệu: HTTPConnectionPool(host='localhost', port=39053): Read timed out. (read timeout=120)
[2025-03-25T05:10:20.719+0000] {logging_mixin.py:151} INFO - Lỗi khi lấy dữ liệu: HTTPConnectionPool(host='localhost', port=39053): Read timed out. (read timeout=120)
[2025-03-25T05:12:10.743+0000] {local_task_job_runner.py:294} WARNING - State of this instance has been externally set to failed. Terminating instance.
[2025-03-25T05:12:10.807+0000] {process_utils.py:131} INFO - Sending 15 to group 3212. PIDs of all processes in the group: [3214, 3220, 3224, 3225, 3231, 3234, 3257, 3339, 3273, 3313, 3388, 7808, 7846, 7856, 7857, 3256, 3212]
[2025-03-25T05:12:10.808+0000] {process_utils.py:86} INFO - Sending the signal 15 to group 3212
[2025-03-25T05:12:10.809+0000] {taskinstance.py:1632} ERROR - Received SIGTERM. Terminating subprocesses.
[2025-03-25T05:12:10.810+0000] {logging_mixin.py:151} INFO - Lỗi khi lấy dữ liệu: Task received SIGTERM signal
[2025-03-25T05:12:10.827+0000] {logging_mixin.py:151} INFO - Lỗi khi lấy dữ liệu: ('Connection aborted.', ConnectionResetError(104, 'Connection reset by peer'))
[2025-03-25T05:12:10.836+0000] {connectionpool.py:823} WARNING - Retrying (Retry(total=2, connect=None, read=None, redirect=None, status=None)) after connection broken by 'NewConnectionError('<urllib3.connection.HTTPConnection object at 0x7fcce6388070>: Failed to establish a new connection: [Errno 111] Connection refused')': /session/265bb54c5fc7e20e81d365ae57947314/actions
[2025-03-25T05:12:10.855+0000] {connectionpool.py:823} WARNING - Retrying (Retry(total=1, connect=None, read=None, redirect=None, status=None)) after connection broken by 'NewConnectionError('<urllib3.connection.HTTPConnection object at 0x7fcce6388250>: Failed to establish a new connection: [Errno 111] Connection refused')': /session/265bb54c5fc7e20e81d365ae57947314/actions
[2025-03-25T05:12:10.858+0000] {connectionpool.py:823} WARNING - Retrying (Retry(total=0, connect=None, read=None, redirect=None, status=None)) after connection broken by 'NewConnectionError('<urllib3.connection.HTTPConnection object at 0x7fcce6388730>: Failed to establish a new connection: [Errno 111] Connection refused')': /session/265bb54c5fc7e20e81d365ae57947314/actions
[2025-03-25T05:12:10.864+0000] {logging_mixin.py:151} INFO - Lỗi khi lấy dữ liệu: HTTPConnectionPool(host='localhost', port=39053): Max retries exceeded with url: /session/265bb54c5fc7e20e81d365ae57947314/actions (Caused by NewConnectionError('<urllib3.connection.HTTPConnection object at 0x7fcce6388910>: Failed to establish a new connection: [Errno 111] Connection refused'))
[2025-03-25T05:12:10.868+0000] {connectionpool.py:823} WARNING - Retrying (Retry(total=2, connect=None, read=None, redirect=None, status=None)) after connection broken by 'NewConnectionError('<urllib3.connection.HTTPConnection object at 0x7fcce63a5e50>: Failed to establish a new connection: [Errno 111] Connection refused')': /session/265bb54c5fc7e20e81d365ae57947314/actions
[2025-03-25T05:12:10.871+0000] {connectionpool.py:823} WARNING - Retrying (Retry(total=1, connect=None, read=None, redirect=None, status=None)) after connection broken by 'NewConnectionError('<urllib3.connection.HTTPConnection object at 0x7fcce63a5910>: Failed to establish a new connection: [Errno 111] Connection refused')': /session/265bb54c5fc7e20e81d365ae57947314/actions
[2025-03-25T05:12:10.873+0000] {connectionpool.py:823} WARNING - Retrying (Retry(total=0, connect=None, read=None, redirect=None, status=None)) after connection broken by 'NewConnectionError('<urllib3.connection.HTTPConnection object at 0x7fcce63a5be0>: Failed to establish a new connection: [Errno 111] Connection refused')': /session/265bb54c5fc7e20e81d365ae57947314/actions
[2025-03-25T05:12:10.875+0000] {logging_mixin.py:151} INFO - Lỗi khi lấy dữ liệu: HTTPConnectionPool(host='localhost', port=39053): Max retries exceeded with url: /session/265bb54c5fc7e20e81d365ae57947314/actions (Caused by NewConnectionError('<urllib3.connection.HTTPConnection object at 0x7fcce63a5550>: Failed to establish a new connection: [Errno 111] Connection refused'))
[2025-03-25T05:12:10.878+0000] {connectionpool.py:823} WARNING - Retrying (Retry(total=2, connect=None, read=None, redirect=None, status=None)) after connection broken by 'NewConnectionError('<urllib3.connection.HTTPConnection object at 0x7fcce5f93bb0>: Failed to establish a new connection: [Errno 111] Connection refused')': /session/265bb54c5fc7e20e81d365ae57947314/actions
[2025-03-25T05:12:10.880+0000] {connectionpool.py:823} WARNING - Retrying (Retry(total=1, connect=None, read=None, redirect=None, status=None)) after connection broken by 'NewConnectionError('<urllib3.connection.HTTPConnection object at 0x7fcce5f93ca0>: Failed to establish a new connection: [Errno 111] Connection refused')': /session/265bb54c5fc7e20e81d365ae57947314/actions
[2025-03-25T05:12:10.881+0000] {connectionpool.py:823} WARNING - Retrying (Retry(total=0, connect=None, read=None, redirect=None, status=None)) after connection broken by 'NewConnectionError('<urllib3.connection.HTTPConnection object at 0x7fcce63a51c0>: Failed to establish a new connection: [Errno 111] Connection refused')': /session/265bb54c5fc7e20e81d365ae57947314/actions
[2025-03-25T05:12:10.883+0000] {logging_mixin.py:151} INFO - Lỗi khi lấy dữ liệu: HTTPConnectionPool(host='localhost', port=39053): Max retries exceeded with url: /session/265bb54c5fc7e20e81d365ae57947314/actions (Caused by NewConnectionError('<urllib3.connection.HTTPConnection object at 0x7fcce63a58e0>: Failed to establish a new connection: [Errno 111] Connection refused'))
[2025-03-25T05:12:10.885+0000] {connectionpool.py:823} WARNING - Retrying (Retry(total=2, connect=None, read=None, redirect=None, status=None)) after connection broken by 'NewConnectionError('<urllib3.connection.HTTPConnection object at 0x7fcce63f43a0>: Failed to establish a new connection: [Errno 111] Connection refused')': /session/265bb54c5fc7e20e81d365ae57947314/actions
[2025-03-25T05:12:10.886+0000] {connectionpool.py:823} WARNING - Retrying (Retry(total=1, connect=None, read=None, redirect=None, status=None)) after connection broken by 'NewConnectionError('<urllib3.connection.HTTPConnection object at 0x7fcce63c2af0>: Failed to establish a new connection: [Errno 111] Connection refused')': /session/265bb54c5fc7e20e81d365ae57947314/actions
[2025-03-25T05:12:10.887+0000] {connectionpool.py:823} WARNING - Retrying (Retry(total=0, connect=None, read=None, redirect=None, status=None)) after connection broken by 'NewConnectionError('<urllib3.connection.HTTPConnection object at 0x7fcce63c2f40>: Failed to establish a new connection: [Errno 111] Connection refused')': /session/265bb54c5fc7e20e81d365ae57947314/actions
[2025-03-25T05:12:10.889+0000] {logging_mixin.py:151} INFO - Lỗi khi lấy dữ liệu: HTTPConnectionPool(host='localhost', port=39053): Max retries exceeded with url: /session/265bb54c5fc7e20e81d365ae57947314/actions (Caused by NewConnectionError('<urllib3.connection.HTTPConnection object at 0x7fcce63c21c0>: Failed to establish a new connection: [Errno 111] Connection refused'))
[2025-03-25T05:12:10.891+0000] {connectionpool.py:823} WARNING - Retrying (Retry(total=2, connect=None, read=None, redirect=None, status=None)) after connection broken by 'NewConnectionError('<urllib3.connection.HTTPConnection object at 0x7fcce63886d0>: Failed to establish a new connection: [Errno 111] Connection refused')': /session/265bb54c5fc7e20e81d365ae57947314/actions
[2025-03-25T05:12:10.892+0000] {connectionpool.py:823} WARNING - Retrying (Retry(total=1, connect=None, read=None, redirect=None, status=None)) after connection broken by 'NewConnectionError('<urllib3.connection.HTTPConnection object at 0x7fcce6388910>: Failed to establish a new connection: [Errno 111] Connection refused')': /session/265bb54c5fc7e20e81d365ae57947314/actions
[2025-03-25T05:12:10.894+0000] {connectionpool.py:823} WARNING - Retrying (Retry(total=0, connect=None, read=None, redirect=None, status=None)) after connection broken by 'NewConnectionError('<urllib3.connection.HTTPConnection object at 0x7fcce63886a0>: Failed to establish a new connection: [Errno 111] Connection refused')': /session/265bb54c5fc7e20e81d365ae57947314/actions
[2025-03-25T05:12:10.895+0000] {logging_mixin.py:151} INFO - Lỗi khi lấy dữ liệu: HTTPConnectionPool(host='localhost', port=39053): Max retries exceeded with url: /session/265bb54c5fc7e20e81d365ae57947314/actions (Caused by NewConnectionError('<urllib3.connection.HTTPConnection object at 0x7fcce63888e0>: Failed to establish a new connection: [Errno 111] Connection refused'))
[2025-03-25T05:12:10.898+0000] {connectionpool.py:823} WARNING - Retrying (Retry(total=2, connect=None, read=None, redirect=None, status=None)) after connection broken by 'NewConnectionError('<urllib3.connection.HTTPConnection object at 0x7fcce6388e50>: Failed to establish a new connection: [Errno 111] Connection refused')': /session/265bb54c5fc7e20e81d365ae57947314/actions
[2025-03-25T05:12:10.900+0000] {connectionpool.py:823} WARNING - Retrying (Retry(total=1, connect=None, read=None, redirect=None, status=None)) after connection broken by 'NewConnectionError('<urllib3.connection.HTTPConnection object at 0x7fcce6388970>: Failed to establish a new connection: [Errno 111] Connection refused')': /session/265bb54c5fc7e20e81d365ae57947314/actions
[2025-03-25T05:12:10.902+0000] {connectionpool.py:823} WARNING - Retrying (Retry(total=0, connect=None, read=None, redirect=None, status=None)) after connection broken by 'NewConnectionError('<urllib3.connection.HTTPConnection object at 0x7fcce6388d60>: Failed to establish a new connection: [Errno 111] Connection refused')': /session/265bb54c5fc7e20e81d365ae57947314/actions
[2025-03-25T05:12:10.907+0000] {logging_mixin.py:151} INFO - Lỗi khi lấy dữ liệu: HTTPConnectionPool(host='localhost', port=39053): Max retries exceeded with url: /session/265bb54c5fc7e20e81d365ae57947314/actions (Caused by NewConnectionError('<urllib3.connection.HTTPConnection object at 0x7fcce5f93e20>: Failed to establish a new connection: [Errno 111] Connection refused'))
[2025-03-25T05:12:10.917+0000] {connectionpool.py:823} WARNING - Retrying (Retry(total=2, connect=None, read=None, redirect=None, status=None)) after connection broken by 'NewConnectionError('<urllib3.connection.HTTPConnection object at 0x7fcce5f3c2e0>: Failed to establish a new connection: [Errno 111] Connection refused')': /session/265bb54c5fc7e20e81d365ae57947314/actions
[2025-03-25T05:12:10.929+0000] {connectionpool.py:823} WARNING - Retrying (Retry(total=1, connect=None, read=None, redirect=None, status=None)) after connection broken by 'NewConnectionError('<urllib3.connection.HTTPConnection object at 0x7fcce5f93df0>: Failed to establish a new connection: [Errno 111] Connection refused')': /session/265bb54c5fc7e20e81d365ae57947314/actions
[2025-03-25T05:12:10.932+0000] {connectionpool.py:823} WARNING - Retrying (Retry(total=0, connect=None, read=None, redirect=None, status=None)) after connection broken by 'NewConnectionError('<urllib3.connection.HTTPConnection object at 0x7fcce6388a60>: Failed to establish a new connection: [Errno 111] Connection refused')': /session/265bb54c5fc7e20e81d365ae57947314/actions
[2025-03-25T05:12:10.937+0000] {logging_mixin.py:151} INFO - Lỗi khi lấy dữ liệu: HTTPConnectionPool(host='localhost', port=39053): Max retries exceeded with url: /session/265bb54c5fc7e20e81d365ae57947314/actions (Caused by NewConnectionError('<urllib3.connection.HTTPConnection object at 0x7fcce6388c40>: Failed to establish a new connection: [Errno 111] Connection refused'))
[2025-03-25T05:12:10.941+0000] {connectionpool.py:823} WARNING - Retrying (Retry(total=2, connect=None, read=None, redirect=None, status=None)) after connection broken by 'NewConnectionError('<urllib3.connection.HTTPConnection object at 0x7fcce6388e80>: Failed to establish a new connection: [Errno 111] Connection refused')': /session/265bb54c5fc7e20e81d365ae57947314/actions
[2025-03-25T05:12:10.943+0000] {connectionpool.py:823} WARNING - Retrying (Retry(total=1, connect=None, read=None, redirect=None, status=None)) after connection broken by 'NewConnectionError('<urllib3.connection.HTTPConnection object at 0x7fcce63882b0>: Failed to establish a new connection: [Errno 111] Connection refused')': /session/265bb54c5fc7e20e81d365ae57947314/actions
[2025-03-25T05:12:10.944+0000] {connectionpool.py:823} WARNING - Retrying (Retry(total=0, connect=None, read=None, redirect=None, status=None)) after connection broken by 'NewConnectionError('<urllib3.connection.HTTPConnection object at 0x7fcce6388610>: Failed to establish a new connection: [Errno 111] Connection refused')': /session/265bb54c5fc7e20e81d365ae57947314/actions
[2025-03-25T05:12:10.946+0000] {logging_mixin.py:151} INFO - Lỗi khi lấy dữ liệu: HTTPConnectionPool(host='localhost', port=39053): Max retries exceeded with url: /session/265bb54c5fc7e20e81d365ae57947314/actions (Caused by NewConnectionError('<urllib3.connection.HTTPConnection object at 0x7fcce63886a0>: Failed to establish a new connection: [Errno 111] Connection refused'))
[2025-03-25T05:12:10.948+0000] {connectionpool.py:823} WARNING - Retrying (Retry(total=2, connect=None, read=None, redirect=None, status=None)) after connection broken by 'NewConnectionError('<urllib3.connection.HTTPConnection object at 0x7fcce63884f0>: Failed to establish a new connection: [Errno 111] Connection refused')': /session/265bb54c5fc7e20e81d365ae57947314/actions
[2025-03-25T05:12:10.949+0000] {connectionpool.py:823} WARNING - Retrying (Retry(total=1, connect=None, read=None, redirect=None, status=None)) after connection broken by 'NewConnectionError('<urllib3.connection.HTTPConnection object at 0x7fcce63c2a90>: Failed to establish a new connection: [Errno 111] Connection refused')': /session/265bb54c5fc7e20e81d365ae57947314/actions
[2025-03-25T05:12:10.951+0000] {connectionpool.py:823} WARNING - Retrying (Retry(total=0, connect=None, read=None, redirect=None, status=None)) after connection broken by 'NewConnectionError('<urllib3.connection.HTTPConnection object at 0x7fcce63c2fd0>: Failed to establish a new connection: [Errno 111] Connection refused')': /session/265bb54c5fc7e20e81d365ae57947314/actions
[2025-03-25T05:12:10.952+0000] {logging_mixin.py:151} INFO - Lỗi khi lấy dữ liệu: HTTPConnectionPool(host='localhost', port=39053): Max retries exceeded with url: /session/265bb54c5fc7e20e81d365ae57947314/actions (Caused by NewConnectionError('<urllib3.connection.HTTPConnection object at 0x7fcce63c2eb0>: Failed to establish a new connection: [Errno 111] Connection refused'))
[2025-03-25T05:12:10.954+0000] {connectionpool.py:823} WARNING - Retrying (Retry(total=2, connect=None, read=None, redirect=None, status=None)) after connection broken by 'NewConnectionError('<urllib3.connection.HTTPConnection object at 0x7fcce63a5250>: Failed to establish a new connection: [Errno 111] Connection refused')': /session/265bb54c5fc7e20e81d365ae57947314/actions
[2025-03-25T05:12:10.955+0000] {connectionpool.py:823} WARNING - Retrying (Retry(total=1, connect=None, read=None, redirect=None, status=None)) after connection broken by 'NewConnectionError('<urllib3.connection.HTTPConnection object at 0x7fcce63a5220>: Failed to establish a new connection: [Errno 111] Connection refused')': /session/265bb54c5fc7e20e81d365ae57947314/actions
[2025-03-25T05:12:10.956+0000] {connectionpool.py:823} WARNING - Retrying (Retry(total=0, connect=None, read=None, redirect=None, status=None)) after connection broken by 'NewConnectionError('<urllib3.connection.HTTPConnection object at 0x7fcce63a5d00>: Failed to establish a new connection: [Errno 111] Connection refused')': /session/265bb54c5fc7e20e81d365ae57947314/actions
[2025-03-25T05:12:10.957+0000] {logging_mixin.py:151} INFO - Lỗi khi lấy dữ liệu: HTTPConnectionPool(host='localhost', port=39053): Max retries exceeded with url: /session/265bb54c5fc7e20e81d365ae57947314/actions (Caused by NewConnectionError('<urllib3.connection.HTTPConnection object at 0x7fcce5f3c460>: Failed to establish a new connection: [Errno 111] Connection refused'))
[2025-03-25T05:12:10.959+0000] {connectionpool.py:823} WARNING - Retrying (Retry(total=2, connect=None, read=None, redirect=None, status=None)) after connection broken by 'NewConnectionError('<urllib3.connection.HTTPConnection object at 0x7fcce5f3c8b0>: Failed to establish a new connection: [Errno 111] Connection refused')': /session/265bb54c5fc7e20e81d365ae57947314/actions
[2025-03-25T05:12:10.960+0000] {connectionpool.py:823} WARNING - Retrying (Retry(total=1, connect=None, read=None, redirect=None, status=None)) after connection broken by 'NewConnectionError('<urllib3.connection.HTTPConnection object at 0x7fcce63a5e50>: Failed to establish a new connection: [Errno 111] Connection refused')': /session/265bb54c5fc7e20e81d365ae57947314/actions
[2025-03-25T05:12:10.961+0000] {connectionpool.py:823} WARNING - Retrying (Retry(total=0, connect=None, read=None, redirect=None, status=None)) after connection broken by 'NewConnectionError('<urllib3.connection.HTTPConnection object at 0x7fcce63a5730>: Failed to establish a new connection: [Errno 111] Connection refused')': /session/265bb54c5fc7e20e81d365ae57947314/actions
[2025-03-25T05:12:10.962+0000] {logging_mixin.py:151} INFO - Lỗi khi lấy dữ liệu: HTTPConnectionPool(host='localhost', port=39053): Max retries exceeded with url: /session/265bb54c5fc7e20e81d365ae57947314/actions (Caused by NewConnectionError('<urllib3.connection.HTTPConnection object at 0x7fcce63a5e20>: Failed to establish a new connection: [Errno 111] Connection refused'))
[2025-03-25T05:12:10.964+0000] {connectionpool.py:823} WARNING - Retrying (Retry(total=2, connect=None, read=None, redirect=None, status=None)) after connection broken by 'NewConnectionError('<urllib3.connection.HTTPConnection object at 0x7fcce63c2e80>: Failed to establish a new connection: [Errno 111] Connection refused')': /session/265bb54c5fc7e20e81d365ae57947314/actions
[2025-03-25T05:12:10.965+0000] {connectionpool.py:823} WARNING - Retrying (Retry(total=1, connect=None, read=None, redirect=None, status=None)) after connection broken by 'NewConnectionError('<urllib3.connection.HTTPConnection object at 0x7fcce63c2fa0>: Failed to establish a new connection: [Errno 111] Connection refused')': /session/265bb54c5fc7e20e81d365ae57947314/actions
[2025-03-25T05:12:10.966+0000] {connectionpool.py:823} WARNING - Retrying (Retry(total=0, connect=None, read=None, redirect=None, status=None)) after connection broken by 'NewConnectionError('<urllib3.connection.HTTPConnection object at 0x7fcce63c2c70>: Failed to establish a new connection: [Errno 111] Connection refused')': /session/265bb54c5fc7e20e81d365ae57947314/actions
[2025-03-25T05:12:10.967+0000] {logging_mixin.py:151} INFO - Lỗi khi lấy dữ liệu: HTTPConnectionPool(host='localhost', port=39053): Max retries exceeded with url: /session/265bb54c5fc7e20e81d365ae57947314/actions (Caused by NewConnectionError('<urllib3.connection.HTTPConnection object at 0x7fcce6388460>: Failed to establish a new connection: [Errno 111] Connection refused'))
[2025-03-25T05:12:10.968+0000] {connectionpool.py:823} WARNING - Retrying (Retry(total=2, connect=None, read=None, redirect=None, status=None)) after connection broken by 'NewConnectionError('<urllib3.connection.HTTPConnection object at 0x7fcce6388370>: Failed to establish a new connection: [Errno 111] Connection refused')': /session/265bb54c5fc7e20e81d365ae57947314/actions
[2025-03-25T05:12:10.969+0000] {connectionpool.py:823} WARNING - Retrying (Retry(total=1, connect=None, read=None, redirect=None, status=None)) after connection broken by 'NewConnectionError('<urllib3.connection.HTTPConnection object at 0x7fcce63889d0>: Failed to establish a new connection: [Errno 111] Connection refused')': /session/265bb54c5fc7e20e81d365ae57947314/actions
[2025-03-25T05:12:10.970+0000] {connectionpool.py:823} WARNING - Retrying (Retry(total=0, connect=None, read=None, redirect=None, status=None)) after connection broken by 'NewConnectionError('<urllib3.connection.HTTPConnection object at 0x7fcce63888e0>: Failed to establish a new connection: [Errno 111] Connection refused')': /session/265bb54c5fc7e20e81d365ae57947314/actions
[2025-03-25T05:12:10.971+0000] {logging_mixin.py:151} INFO - Lỗi khi lấy dữ liệu: HTTPConnectionPool(host='localhost', port=39053): Max retries exceeded with url: /session/265bb54c5fc7e20e81d365ae57947314/actions (Caused by NewConnectionError('<urllib3.connection.HTTPConnection object at 0x7fcce6388a30>: Failed to establish a new connection: [Errno 111] Connection refused'))
[2025-03-25T05:12:10.972+0000] {connectionpool.py:823} WARNING - Retrying (Retry(total=2, connect=None, read=None, redirect=None, status=None)) after connection broken by 'NewConnectionError('<urllib3.connection.HTTPConnection object at 0x7fcce63883d0>: Failed to establish a new connection: [Errno 111] Connection refused')': /session/265bb54c5fc7e20e81d365ae57947314/actions
[2025-03-25T05:12:10.973+0000] {connectionpool.py:823} WARNING - Retrying (Retry(total=1, connect=None, read=None, redirect=None, status=None)) after connection broken by 'NewConnectionError('<urllib3.connection.HTTPConnection object at 0x7fcce6388a60>: Failed to establish a new connection: [Errno 111] Connection refused')': /session/265bb54c5fc7e20e81d365ae57947314/actions
[2025-03-25T05:12:10.974+0000] {connectionpool.py:823} WARNING - Retrying (Retry(total=0, connect=None, read=None, redirect=None, status=None)) after connection broken by 'NewConnectionError('<urllib3.connection.HTTPConnection object at 0x7fcce5f93eb0>: Failed to establish a new connection: [Errno 111] Connection refused')': /session/265bb54c5fc7e20e81d365ae57947314/actions
[2025-03-25T05:12:10.975+0000] {logging_mixin.py:151} INFO - Lỗi khi lấy dữ liệu: HTTPConnectionPool(host='localhost', port=39053): Max retries exceeded with url: /session/265bb54c5fc7e20e81d365ae57947314/actions (Caused by NewConnectionError('<urllib3.connection.HTTPConnection object at 0x7fcce5f3c460>: Failed to establish a new connection: [Errno 111] Connection refused'))
[2025-03-25T05:12:10.977+0000] {connectionpool.py:823} WARNING - Retrying (Retry(total=2, connect=None, read=None, redirect=None, status=None)) after connection broken by 'NewConnectionError('<urllib3.connection.HTTPConnection object at 0x7fcce5f3cd30>: Failed to establish a new connection: [Errno 111] Connection refused')': /session/265bb54c5fc7e20e81d365ae57947314/actions
[2025-03-25T05:12:10.978+0000] {connectionpool.py:823} WARNING - Retrying (Retry(total=1, connect=None, read=None, redirect=None, status=None)) after connection broken by 'NewConnectionError('<urllib3.connection.HTTPConnection object at 0x7fcce5f93f10>: Failed to establish a new connection: [Errno 111] Connection refused')': /session/265bb54c5fc7e20e81d365ae57947314/actions
[2025-03-25T05:12:10.979+0000] {connectionpool.py:823} WARNING - Retrying (Retry(total=0, connect=None, read=None, redirect=None, status=None)) after connection broken by 'NewConnectionError('<urllib3.connection.HTTPConnection object at 0x7fcce6388b80>: Failed to establish a new connection: [Errno 111] Connection refused')': /session/265bb54c5fc7e20e81d365ae57947314/actions
[2025-03-25T05:12:10.979+0000] {logging_mixin.py:151} INFO - Lỗi khi lấy dữ liệu: HTTPConnectionPool(host='localhost', port=39053): Max retries exceeded with url: /session/265bb54c5fc7e20e81d365ae57947314/actions (Caused by NewConnectionError('<urllib3.connection.HTTPConnection object at 0x7fcce6388a60>: Failed to establish a new connection: [Errno 111] Connection refused'))
[2025-03-25T05:12:10.981+0000] {connectionpool.py:823} WARNING - Retrying (Retry(total=2, connect=None, read=None, redirect=None, status=None)) after connection broken by 'NewConnectionError('<urllib3.connection.HTTPConnection object at 0x7fcce6388b50>: Failed to establish a new connection: [Errno 111] Connection refused')': /session/265bb54c5fc7e20e81d365ae57947314/actions
[2025-03-25T05:12:10.982+0000] {connectionpool.py:823} WARNING - Retrying (Retry(total=1, connect=None, read=None, redirect=None, status=None)) after connection broken by 'NewConnectionError('<urllib3.connection.HTTPConnection object at 0x7fcce6388e80>: Failed to establish a new connection: [Errno 111] Connection refused')': /session/265bb54c5fc7e20e81d365ae57947314/actions
[2025-03-25T05:12:10.983+0000] {connectionpool.py:823} WARNING - Retrying (Retry(total=0, connect=None, read=None, redirect=None, status=None)) after connection broken by 'NewConnectionError('<urllib3.connection.HTTPConnection object at 0x7fcce63882b0>: Failed to establish a new connection: [Errno 111] Connection refused')': /session/265bb54c5fc7e20e81d365ae57947314/actions
[2025-03-25T05:12:10.983+0000] {logging_mixin.py:151} INFO - Lỗi khi lấy dữ liệu: HTTPConnectionPool(host='localhost', port=39053): Max retries exceeded with url: /session/265bb54c5fc7e20e81d365ae57947314/actions (Caused by NewConnectionError('<urllib3.connection.HTTPConnection object at 0x7fcce63887c0>: Failed to establish a new connection: [Errno 111] Connection refused'))
[2025-03-25T05:12:10.985+0000] {connectionpool.py:823} WARNING - Retrying (Retry(total=2, connect=None, read=None, redirect=None, status=None)) after connection broken by 'NewConnectionError('<urllib3.connection.HTTPConnection object at 0x7fcce63884f0>: Failed to establish a new connection: [Errno 111] Connection refused')': /session/265bb54c5fc7e20e81d365ae57947314/actions
[2025-03-25T05:12:10.985+0000] {connectionpool.py:823} WARNING - Retrying (Retry(total=1, connect=None, read=None, redirect=None, status=None)) after connection broken by 'NewConnectionError('<urllib3.connection.HTTPConnection object at 0x7fcce63c2ca0>: Failed to establish a new connection: [Errno 111] Connection refused')': /session/265bb54c5fc7e20e81d365ae57947314/actions
[2025-03-25T05:12:10.986+0000] {connectionpool.py:823} WARNING - Retrying (Retry(total=0, connect=None, read=None, redirect=None, status=None)) after connection broken by 'NewConnectionError('<urllib3.connection.HTTPConnection object at 0x7fcce63c2f40>: Failed to establish a new connection: [Errno 111] Connection refused')': /session/265bb54c5fc7e20e81d365ae57947314/actions
[2025-03-25T05:12:10.987+0000] {logging_mixin.py:151} INFO - Lỗi khi lấy dữ liệu: HTTPConnectionPool(host='localhost', port=39053): Max retries exceeded with url: /session/265bb54c5fc7e20e81d365ae57947314/actions (Caused by NewConnectionError('<urllib3.connection.HTTPConnection object at 0x7fcce63c2af0>: Failed to establish a new connection: [Errno 111] Connection refused'))
[2025-03-25T05:12:10.988+0000] {connectionpool.py:823} WARNING - Retrying (Retry(total=2, connect=None, read=None, redirect=None, status=None)) after connection broken by 'NewConnectionError('<urllib3.connection.HTTPConnection object at 0x7fcce63a5250>: Failed to establish a new connection: [Errno 111] Connection refused')': /session/265bb54c5fc7e20e81d365ae57947314/actions
[2025-03-25T05:12:10.989+0000] {connectionpool.py:823} WARNING - Retrying (Retry(total=1, connect=None, read=None, redirect=None, status=None)) after connection broken by 'NewConnectionError('<urllib3.connection.HTTPConnection object at 0x7fcce63a5be0>: Failed to establish a new connection: [Errno 111] Connection refused')': /session/265bb54c5fc7e20e81d365ae57947314/actions
[2025-03-25T05:12:10.990+0000] {connectionpool.py:823} WARNING - Retrying (Retry(total=0, connect=None, read=None, redirect=None, status=None)) after connection broken by 'NewConnectionError('<urllib3.connection.HTTPConnection object at 0x7fcce5f3cd00>: Failed to establish a new connection: [Errno 111] Connection refused')': /session/265bb54c5fc7e20e81d365ae57947314/actions
[2025-03-25T05:12:10.991+0000] {logging_mixin.py:151} INFO - Lỗi khi lấy dữ liệu: HTTPConnectionPool(host='localhost', port=39053): Max retries exceeded with url: /session/265bb54c5fc7e20e81d365ae57947314/actions (Caused by NewConnectionError('<urllib3.connection.HTTPConnection object at 0x7fcce5f3c4c0>: Failed to establish a new connection: [Errno 111] Connection refused'))
[2025-03-25T05:12:10.992+0000] {connectionpool.py:823} WARNING - Retrying (Retry(total=2, connect=None, read=None, redirect=None, status=None)) after connection broken by 'NewConnectionError('<urllib3.connection.HTTPConnection object at 0x7fcce5f4a1f0>: Failed to establish a new connection: [Errno 111] Connection refused')': /session/265bb54c5fc7e20e81d365ae57947314/actions
[2025-03-25T05:12:10.993+0000] {connectionpool.py:823} WARNING - Retrying (Retry(total=1, connect=None, read=None, redirect=None, status=None)) after connection broken by 'NewConnectionError('<urllib3.connection.HTTPConnection object at 0x7fcce5f3c550>: Failed to establish a new connection: [Errno 111] Connection refused')': /session/265bb54c5fc7e20e81d365ae57947314/actions
[2025-03-25T05:12:10.994+0000] {connectionpool.py:823} WARNING - Retrying (Retry(total=0, connect=None, read=None, redirect=None, status=None)) after connection broken by 'NewConnectionError('<urllib3.connection.HTTPConnection object at 0x7fcce5f3cd00>: Failed to establish a new connection: [Errno 111] Connection refused')': /session/265bb54c5fc7e20e81d365ae57947314/actions
[2025-03-25T05:12:10.995+0000] {logging_mixin.py:151} INFO - Lỗi khi lấy dữ liệu: HTTPConnectionPool(host='localhost', port=39053): Max retries exceeded with url: /session/265bb54c5fc7e20e81d365ae57947314/actions (Caused by NewConnectionError('<urllib3.connection.HTTPConnection object at 0x7fcce63a5e50>: Failed to establish a new connection: [Errno 111] Connection refused'))
[2025-03-25T05:12:10.996+0000] {connectionpool.py:823} WARNING - Retrying (Retry(total=2, connect=None, read=None, redirect=None, status=None)) after connection broken by 'NewConnectionError('<urllib3.connection.HTTPConnection object at 0x7fcce63a5ca0>: Failed to establish a new connection: [Errno 111] Connection refused')': /session/265bb54c5fc7e20e81d365ae57947314/actions
[2025-03-25T05:12:10.997+0000] {connectionpool.py:823} WARNING - Retrying (Retry(total=1, connect=None, read=None, redirect=None, status=None)) after connection broken by 'NewConnectionError('<urllib3.connection.HTTPConnection object at 0x7fcce63c2d60>: Failed to establish a new connection: [Errno 111] Connection refused')': /session/265bb54c5fc7e20e81d365ae57947314/actions
[2025-03-25T05:12:10.998+0000] {connectionpool.py:823} WARNING - Retrying (Retry(total=0, connect=None, read=None, redirect=None, status=None)) after connection broken by 'NewConnectionError('<urllib3.connection.HTTPConnection object at 0x7fcce63c2af0>: Failed to establish a new connection: [Errno 111] Connection refused')': /session/265bb54c5fc7e20e81d365ae57947314/actions
[2025-03-25T05:12:10.999+0000] {logging_mixin.py:151} INFO - Lỗi khi lấy dữ liệu: HTTPConnectionPool(host='localhost', port=39053): Max retries exceeded with url: /session/265bb54c5fc7e20e81d365ae57947314/actions (Caused by NewConnectionError('<urllib3.connection.HTTPConnection object at 0x7fcce63c28b0>: Failed to establish a new connection: [Errno 111] Connection refused'))
[2025-03-25T05:12:11.000+0000] {connectionpool.py:823} WARNING - Retrying (Retry(total=2, connect=None, read=None, redirect=None, status=None)) after connection broken by 'NewConnectionError('<urllib3.connection.HTTPConnection object at 0x7fcce6388fd0>: Failed to establish a new connection: [Errno 111] Connection refused')': /session/265bb54c5fc7e20e81d365ae57947314/actions
[2025-03-25T05:12:11.001+0000] {connectionpool.py:823} WARNING - Retrying (Retry(total=1, connect=None, read=None, redirect=None, status=None)) after connection broken by 'NewConnectionError('<urllib3.connection.HTTPConnection object at 0x7fcce6388640>: Failed to establish a new connection: [Errno 111] Connection refused')': /session/265bb54c5fc7e20e81d365ae57947314/actions
[2025-03-25T05:12:11.002+0000] {connectionpool.py:823} WARNING - Retrying (Retry(total=0, connect=None, read=None, redirect=None, status=None)) after connection broken by 'NewConnectionError('<urllib3.connection.HTTPConnection object at 0x7fcce6388670>: Failed to establish a new connection: [Errno 111] Connection refused')': /session/265bb54c5fc7e20e81d365ae57947314/actions
[2025-03-25T05:12:11.002+0000] {logging_mixin.py:151} INFO - Lỗi khi lấy dữ liệu: HTTPConnectionPool(host='localhost', port=39053): Max retries exceeded with url: /session/265bb54c5fc7e20e81d365ae57947314/actions (Caused by NewConnectionError('<urllib3.connection.HTTPConnection object at 0x7fcce63885b0>: Failed to establish a new connection: [Errno 111] Connection refused'))
[2025-03-25T05:12:11.004+0000] {connectionpool.py:823} WARNING - Retrying (Retry(total=2, connect=None, read=None, redirect=None, status=None)) after connection broken by 'NewConnectionError('<urllib3.connection.HTTPConnection object at 0x7fcce6388f40>: Failed to establish a new connection: [Errno 111] Connection refused')': /session/265bb54c5fc7e20e81d365ae57947314/actions
[2025-03-25T05:12:11.004+0000] {connectionpool.py:823} WARNING - Retrying (Retry(total=1, connect=None, read=None, redirect=None, status=None)) after connection broken by 'NewConnectionError('<urllib3.connection.HTTPConnection object at 0x7fcce6388970>: Failed to establish a new connection: [Errno 111] Connection refused')': /session/265bb54c5fc7e20e81d365ae57947314/actions
[2025-03-25T05:12:11.005+0000] {connectionpool.py:823} WARNING - Retrying (Retry(total=0, connect=None, read=None, redirect=None, status=None)) after connection broken by 'NewConnectionError('<urllib3.connection.HTTPConnection object at 0x7fcce6388400>: Failed to establish a new connection: [Errno 111] Connection refused')': /session/265bb54c5fc7e20e81d365ae57947314/actions
[2025-03-25T05:12:11.006+0000] {logging_mixin.py:151} INFO - Lỗi khi lấy dữ liệu: HTTPConnectionPool(host='localhost', port=39053): Max retries exceeded with url: /session/265bb54c5fc7e20e81d365ae57947314/actions (Caused by NewConnectionError('<urllib3.connection.HTTPConnection object at 0x7fcce5f93e50>: Failed to establish a new connection: [Errno 111] Connection refused'))
[2025-03-25T05:12:11.008+0000] {connectionpool.py:823} WARNING - Retrying (Retry(total=2, connect=None, read=None, redirect=None, status=None)) after connection broken by 'NewConnectionError('<urllib3.connection.HTTPConnection object at 0x7fcce5f4a670>: Failed to establish a new connection: [Errno 111] Connection refused')': /session/265bb54c5fc7e20e81d365ae57947314/actions
[2025-03-25T05:12:11.008+0000] {connectionpool.py:823} WARNING - Retrying (Retry(total=1, connect=None, read=None, redirect=None, status=None)) after connection broken by 'NewConnectionError('<urllib3.connection.HTTPConnection object at 0x7fcce5f93eb0>: Failed to establish a new connection: [Errno 111] Connection refused')': /session/265bb54c5fc7e20e81d365ae57947314/actions
[2025-03-25T05:12:11.009+0000] {connectionpool.py:823} WARNING - Retrying (Retry(total=0, connect=None, read=None, redirect=None, status=None)) after connection broken by 'NewConnectionError('<urllib3.connection.HTTPConnection object at 0x7fcce6388b20>: Failed to establish a new connection: [Errno 111] Connection refused')': /session/265bb54c5fc7e20e81d365ae57947314/actions
[2025-03-25T05:12:11.010+0000] {logging_mixin.py:151} INFO - Lỗi khi lấy dữ liệu: HTTPConnectionPool(host='localhost', port=39053): Max retries exceeded with url: /session/265bb54c5fc7e20e81d365ae57947314/actions (Caused by NewConnectionError('<urllib3.connection.HTTPConnection object at 0x7fcce6388280>: Failed to establish a new connection: [Errno 111] Connection refused'))
[2025-03-25T05:12:11.012+0000] {connectionpool.py:823} WARNING - Retrying (Retry(total=2, connect=None, read=None, redirect=None, status=None)) after connection broken by 'NewConnectionError('<urllib3.connection.HTTPConnection object at 0x7fcce6388d30>: Failed to establish a new connection: [Errno 111] Connection refused')': /session/265bb54c5fc7e20e81d365ae57947314/actions
[2025-03-25T05:12:11.014+0000] {connectionpool.py:823} WARNING - Retrying (Retry(total=1, connect=None, read=None, redirect=None, status=None)) after connection broken by 'NewConnectionError('<urllib3.connection.HTTPConnection object at 0x7fcce6388760>: Failed to establish a new connection: [Errno 111] Connection refused')': /session/265bb54c5fc7e20e81d365ae57947314/actions
[2025-03-25T05:12:11.015+0000] {connectionpool.py:823} WARNING - Retrying (Retry(total=0, connect=None, read=None, redirect=None, status=None)) after connection broken by 'NewConnectionError('<urllib3.connection.HTTPConnection object at 0x7fcce63882b0>: Failed to establish a new connection: [Errno 111] Connection refused')': /session/265bb54c5fc7e20e81d365ae57947314/actions
[2025-03-25T05:12:11.016+0000] {logging_mixin.py:151} INFO - Lỗi khi lấy dữ liệu: HTTPConnectionPool(host='localhost', port=39053): Max retries exceeded with url: /session/265bb54c5fc7e20e81d365ae57947314/actions (Caused by NewConnectionError('<urllib3.connection.HTTPConnection object at 0x7fcce6388910>: Failed to establish a new connection: [Errno 111] Connection refused'))
[2025-03-25T05:12:11.018+0000] {connectionpool.py:823} WARNING - Retrying (Retry(total=2, connect=None, read=None, redirect=None, status=None)) after connection broken by 'NewConnectionError('<urllib3.connection.HTTPConnection object at 0x7fcce63887f0>: Failed to establish a new connection: [Errno 111] Connection refused')': /session/265bb54c5fc7e20e81d365ae57947314/actions
[2025-03-25T05:12:11.019+0000] {connectionpool.py:823} WARNING - Retrying (Retry(total=1, connect=None, read=None, redirect=None, status=None)) after connection broken by 'NewConnectionError('<urllib3.connection.HTTPConnection object at 0x7fcce63c2d00>: Failed to establish a new connection: [Errno 111] Connection refused')': /session/265bb54c5fc7e20e81d365ae57947314/actions
[2025-03-25T05:12:11.020+0000] {connectionpool.py:823} WARNING - Retrying (Retry(total=0, connect=None, read=None, redirect=None, status=None)) after connection broken by 'NewConnectionError('<urllib3.connection.HTTPConnection object at 0x7fcce63c2ca0>: Failed to establish a new connection: [Errno 111] Connection refused')': /session/265bb54c5fc7e20e81d365ae57947314/actions
[2025-03-25T05:12:11.022+0000] {logging_mixin.py:151} INFO - Lỗi khi lấy dữ liệu: HTTPConnectionPool(host='localhost', port=39053): Max retries exceeded with url: /session/265bb54c5fc7e20e81d365ae57947314/actions (Caused by NewConnectionError('<urllib3.connection.HTTPConnection object at 0x7fcce63c2eb0>: Failed to establish a new connection: [Errno 111] Connection refused'))
[2025-03-25T05:12:11.024+0000] {connectionpool.py:823} WARNING - Retrying (Retry(total=2, connect=None, read=None, redirect=None, status=None)) after connection broken by 'NewConnectionError('<urllib3.connection.HTTPConnection object at 0x7fcce63a5550>: Failed to establish a new connection: [Errno 111] Connection refused')': /session/265bb54c5fc7e20e81d365ae57947314/actions
[2025-03-25T05:12:11.026+0000] {connectionpool.py:823} WARNING - Retrying (Retry(total=1, connect=None, read=None, redirect=None, status=None)) after connection broken by 'NewConnectionError('<urllib3.connection.HTTPConnection object at 0x7fcce63a5910>: Failed to establish a new connection: [Errno 111] Connection refused')': /session/265bb54c5fc7e20e81d365ae57947314/actions
[2025-03-25T05:12:11.027+0000] {connectionpool.py:823} WARNING - Retrying (Retry(total=0, connect=None, read=None, redirect=None, status=None)) after connection broken by 'NewConnectionError('<urllib3.connection.HTTPConnection object at 0x7fcce5f3ceb0>: Failed to establish a new connection: [Errno 111] Connection refused')': /session/265bb54c5fc7e20e81d365ae57947314/actions
[2025-03-25T05:12:11.030+0000] {logging_mixin.py:151} INFO - Lỗi khi lấy dữ liệu: HTTPConnectionPool(host='localhost', port=39053): Max retries exceeded with url: /session/265bb54c5fc7e20e81d365ae57947314/actions (Caused by NewConnectionError('<urllib3.connection.HTTPConnection object at 0x7fcce5f3c550>: Failed to establish a new connection: [Errno 111] Connection refused'))
[2025-03-25T05:12:11.033+0000] {connectionpool.py:823} WARNING - Retrying (Retry(total=2, connect=None, read=None, redirect=None, status=None)) after connection broken by 'NewConnectionError('<urllib3.connection.HTTPConnection object at 0x7fcce5f4aaf0>: Failed to establish a new connection: [Errno 111] Connection refused')': /session/265bb54c5fc7e20e81d365ae57947314/actions
[2025-03-25T05:12:11.035+0000] {connectionpool.py:823} WARNING - Retrying (Retry(total=1, connect=None, read=None, redirect=None, status=None)) after connection broken by 'NewConnectionError('<urllib3.connection.HTTPConnection object at 0x7fcce5f3cd00>: Failed to establish a new connection: [Errno 111] Connection refused')': /session/265bb54c5fc7e20e81d365ae57947314/actions
[2025-03-25T05:12:11.037+0000] {connectionpool.py:823} WARNING - Retrying (Retry(total=0, connect=None, read=None, redirect=None, status=None)) after connection broken by 'NewConnectionError('<urllib3.connection.HTTPConnection object at 0x7fcce5f3ceb0>: Failed to establish a new connection: [Errno 111] Connection refused')': /session/265bb54c5fc7e20e81d365ae57947314/actions
[2025-03-25T05:12:11.039+0000] {logging_mixin.py:151} INFO - Lỗi khi lấy dữ liệu: HTTPConnectionPool(host='localhost', port=39053): Max retries exceeded with url: /session/265bb54c5fc7e20e81d365ae57947314/actions (Caused by NewConnectionError('<urllib3.connection.HTTPConnection object at 0x7fcce63a5f10>: Failed to establish a new connection: [Errno 111] Connection refused'))
[2025-03-25T05:12:11.043+0000] {connectionpool.py:823} WARNING - Retrying (Retry(total=2, connect=None, read=None, redirect=None, status=None)) after connection broken by 'NewConnectionError('<urllib3.connection.HTTPConnection object at 0x7fcce63a5d90>: Failed to establish a new connection: [Errno 111] Connection refused')': /session/265bb54c5fc7e20e81d365ae57947314/actions
[2025-03-25T05:12:11.044+0000] {connectionpool.py:823} WARNING - Retrying (Retry(total=1, connect=None, read=None, redirect=None, status=None)) after connection broken by 'NewConnectionError('<urllib3.connection.HTTPConnection object at 0x7fcce63c2bb0>: Failed to establish a new connection: [Errno 111] Connection refused')': /session/265bb54c5fc7e20e81d365ae57947314/actions
[2025-03-25T05:12:11.046+0000] {connectionpool.py:823} WARNING - Retrying (Retry(total=0, connect=None, read=None, redirect=None, status=None)) after connection broken by 'NewConnectionError('<urllib3.connection.HTTPConnection object at 0x7fcce63c2a90>: Failed to establish a new connection: [Errno 111] Connection refused')': /session/265bb54c5fc7e20e81d365ae57947314/actions
[2025-03-25T05:12:11.048+0000] {logging_mixin.py:151} INFO - Lỗi khi lấy dữ liệu: HTTPConnectionPool(host='localhost', port=39053): Max retries exceeded with url: /session/265bb54c5fc7e20e81d365ae57947314/actions (Caused by NewConnectionError('<urllib3.connection.HTTPConnection object at 0x7fcce63c2d00>: Failed to establish a new connection: [Errno 111] Connection refused'))
[2025-03-25T05:12:11.051+0000] {connectionpool.py:823} WARNING - Retrying (Retry(total=2, connect=None, read=None, redirect=None, status=None)) after connection broken by 'NewConnectionError('<urllib3.connection.HTTPConnection object at 0x7fcce6388df0>: Failed to establish a new connection: [Errno 111] Connection refused')': /session/265bb54c5fc7e20e81d365ae57947314/actions
[2025-03-25T05:12:11.053+0000] {connectionpool.py:823} WARNING - Retrying (Retry(total=1, connect=None, read=None, redirect=None, status=None)) after connection broken by 'NewConnectionError('<urllib3.connection.HTTPConnection object at 0x7fcce6388b80>: Failed to establish a new connection: [Errno 111] Connection refused')': /session/265bb54c5fc7e20e81d365ae57947314/actions
[2025-03-25T05:12:11.056+0000] {connectionpool.py:823} WARNING - Retrying (Retry(total=0, connect=None, read=None, redirect=None, status=None)) after connection broken by 'NewConnectionError('<urllib3.connection.HTTPConnection object at 0x7fcce63886a0>: Failed to establish a new connection: [Errno 111] Connection refused')': /session/265bb54c5fc7e20e81d365ae57947314/actions
[2025-03-25T05:12:11.057+0000] {logging_mixin.py:151} INFO - Lỗi khi lấy dữ liệu: HTTPConnectionPool(host='localhost', port=39053): Max retries exceeded with url: /session/265bb54c5fc7e20e81d365ae57947314/actions (Caused by NewConnectionError('<urllib3.connection.HTTPConnection object at 0x7fcce63882b0>: Failed to establish a new connection: [Errno 111] Connection refused'))
[2025-03-25T05:12:11.060+0000] {connectionpool.py:823} WARNING - Retrying (Retry(total=2, connect=None, read=None, redirect=None, status=None)) after connection broken by 'NewConnectionError('<urllib3.connection.HTTPConnection object at 0x7fcce6388be0>: Failed to establish a new connection: [Errno 111] Connection refused')': /session/265bb54c5fc7e20e81d365ae57947314/actions
[2025-03-25T05:12:11.062+0000] {connectionpool.py:823} WARNING - Retrying (Retry(total=1, connect=None, read=None, redirect=None, status=None)) after connection broken by 'NewConnectionError('<urllib3.connection.HTTPConnection object at 0x7fcce63880d0>: Failed to establish a new connection: [Errno 111] Connection refused')': /session/265bb54c5fc7e20e81d365ae57947314/actions
[2025-03-25T05:12:11.064+0000] {connectionpool.py:823} WARNING - Retrying (Retry(total=0, connect=None, read=None, redirect=None, status=None)) after connection broken by 'NewConnectionError('<urllib3.connection.HTTPConnection object at 0x7fcce6388400>: Failed to establish a new connection: [Errno 111] Connection refused')': /session/265bb54c5fc7e20e81d365ae57947314/actions
[2025-03-25T05:12:11.066+0000] {logging_mixin.py:151} INFO - Lỗi khi lấy dữ liệu: HTTPConnectionPool(host='localhost', port=39053): Max retries exceeded with url: /session/265bb54c5fc7e20e81d365ae57947314/actions (Caused by NewConnectionError('<urllib3.connection.HTTPConnection object at 0x7fcce5f93f10>: Failed to establish a new connection: [Errno 111] Connection refused'))
[2025-03-25T05:12:11.069+0000] {connectionpool.py:823} WARNING - Retrying (Retry(total=2, connect=None, read=None, redirect=None, status=None)) after connection broken by 'NewConnectionError('<urllib3.connection.HTTPConnection object at 0x7fcce5f4af70>: Failed to establish a new connection: [Errno 111] Connection refused')': /session/265bb54c5fc7e20e81d365ae57947314/actions
[2025-03-25T05:12:11.070+0000] {connectionpool.py:823} WARNING - Retrying (Retry(total=1, connect=None, read=None, redirect=None, status=None)) after connection broken by 'NewConnectionError('<urllib3.connection.HTTPConnection object at 0x7fcce5f4abe0>: Failed to establish a new connection: [Errno 111] Connection refused')': /session/265bb54c5fc7e20e81d365ae57947314/actions
[2025-03-25T05:12:11.072+0000] {connectionpool.py:823} WARNING - Retrying (Retry(total=0, connect=None, read=None, redirect=None, status=None)) after connection broken by 'NewConnectionError('<urllib3.connection.HTTPConnection object at 0x7fcce5f93f40>: Failed to establish a new connection: [Errno 111] Connection refused')': /session/265bb54c5fc7e20e81d365ae57947314/actions
[2025-03-25T05:12:11.073+0000] {logging_mixin.py:151} INFO - Lỗi khi lấy dữ liệu: HTTPConnectionPool(host='localhost', port=39053): Max retries exceeded with url: /session/265bb54c5fc7e20e81d365ae57947314/actions (Caused by NewConnectionError('<urllib3.connection.HTTPConnection object at 0x7fcce6388d90>: Failed to establish a new connection: [Errno 111] Connection refused'))
[2025-03-25T05:12:11.073+0000] {process_utils.py:79} INFO - Process psutil.Process(pid=3220, status='terminated', started='02:38:37') (3220) terminated with exit code None
[2025-03-25T05:12:11.074+0000] {process_utils.py:79} INFO - Process psutil.Process(pid=3231, status='terminated', started='02:38:37') (3231) terminated with exit code None
[2025-03-25T05:12:11.075+0000] {process_utils.py:79} INFO - Process psutil.Process(pid=3313, status='terminated', started='02:38:37') (3313) terminated with exit code None
[2025-03-25T05:12:11.075+0000] {connectionpool.py:823} WARNING - Retrying (Retry(total=2, connect=None, read=None, redirect=None, status=None)) after connection broken by 'NewConnectionError('<urllib3.connection.HTTPConnection object at 0x7fcce6388850>: Failed to establish a new connection: [Errno 111] Connection refused')': /session/265bb54c5fc7e20e81d365ae57947314/actions
[2025-03-25T05:12:11.076+0000] {process_utils.py:79} INFO - Process psutil.Process(pid=7808, status='terminated', started='05:02:47') (7808) terminated with exit code None
[2025-03-25T05:12:11.077+0000] {process_utils.py:79} INFO - Process psutil.Process(pid=3234, status='terminated', started='02:38:37') (3234) terminated with exit code None
[2025-03-25T05:12:11.077+0000] {connectionpool.py:823} WARNING - Retrying (Retry(total=1, connect=None, read=None, redirect=None, status=None)) after connection broken by 'NewConnectionError('<urllib3.connection.HTTPConnection object at 0x7fcce6388d30>: Failed to establish a new connection: [Errno 111] Connection refused')': /session/265bb54c5fc7e20e81d365ae57947314/actions
[2025-03-25T05:12:11.077+0000] {process_utils.py:79} INFO - Process psutil.Process(pid=3339, status='terminated', started='02:38:39') (3339) terminated with exit code None
[2025-03-25T05:12:11.078+0000] {process_utils.py:79} INFO - Process psutil.Process(pid=3273, status='terminated', started='02:38:37') (3273) terminated with exit code None
[2025-03-25T05:12:11.079+0000] {connectionpool.py:823} WARNING - Retrying (Retry(total=0, connect=None, read=None, redirect=None, status=None)) after connection broken by 'NewConnectionError('<urllib3.connection.HTTPConnection object at 0x7fcce6388af0>: Failed to establish a new connection: [Errno 111] Connection refused')': /session/265bb54c5fc7e20e81d365ae57947314/actions
[2025-03-25T05:12:11.079+0000] {process_utils.py:79} INFO - Process psutil.Process(pid=3388, status='terminated', started='02:38:40') (3388) terminated with exit code None
[2025-03-25T05:12:11.080+0000] {process_utils.py:79} INFO - Process psutil.Process(pid=7846, status='terminated', started='05:04:51') (7846) terminated with exit code None
[2025-03-25T05:12:11.081+0000] {process_utils.py:79} INFO - Process psutil.Process(pid=7856, status='terminated', started='05:04:51') (7856) terminated with exit code None
[2025-03-25T05:12:11.081+0000] {logging_mixin.py:151} INFO - Lỗi khi lấy dữ liệu: HTTPConnectionPool(host='localhost', port=39053): Max retries exceeded with url: /session/265bb54c5fc7e20e81d365ae57947314/actions (Caused by NewConnectionError('<urllib3.connection.HTTPConnection object at 0x7fcce6388670>: Failed to establish a new connection: [Errno 111] Connection refused'))
[2025-03-25T05:12:11.082+0000] {process_utils.py:79} INFO - Process psutil.Process(pid=7857, status='terminated', started='05:04:51') (7857) terminated with exit code None
[2025-03-25T05:12:11.083+0000] {connectionpool.py:823} WARNING - Retrying (Retry(total=2, connect=None, read=None, redirect=None, status=None)) after connection broken by 'NewConnectionError('<urllib3.connection.HTTPConnection object at 0x7fcce63882e0>: Failed to establish a new connection: [Errno 111] Connection refused')': /session/265bb54c5fc7e20e81d365ae57947314/actions
[2025-03-25T05:12:11.084+0000] {connectionpool.py:823} WARNING - Retrying (Retry(total=1, connect=None, read=None, redirect=None, status=None)) after connection broken by 'NewConnectionError('<urllib3.connection.HTTPConnection object at 0x7fcce63c2a00>: Failed to establish a new connection: [Errno 111] Connection refused')': /session/265bb54c5fc7e20e81d365ae57947314/actions
[2025-03-25T05:12:11.085+0000] {connectionpool.py:823} WARNING - Retrying (Retry(total=0, connect=None, read=None, redirect=None, status=None)) after connection broken by 'NewConnectionError('<urllib3.connection.HTTPConnection object at 0x7fcce63c2d00>: Failed to establish a new connection: [Errno 111] Connection refused')': /session/265bb54c5fc7e20e81d365ae57947314/actions
[2025-03-25T05:12:11.086+0000] {logging_mixin.py:151} INFO - Lỗi khi lấy dữ liệu: HTTPConnectionPool(host='localhost', port=39053): Max retries exceeded with url: /session/265bb54c5fc7e20e81d365ae57947314/actions (Caused by NewConnectionError('<urllib3.connection.HTTPConnection object at 0x7fcce63c2fd0>: Failed to establish a new connection: [Errno 111] Connection refused'))
[2025-03-25T05:12:11.088+0000] {connectionpool.py:823} WARNING - Retrying (Retry(total=2, connect=None, read=None, redirect=None, status=None)) after connection broken by 'NewConnectionError('<urllib3.connection.HTTPConnection object at 0x7fcce63a5730>: Failed to establish a new connection: [Errno 111] Connection refused')': /session/265bb54c5fc7e20e81d365ae57947314/actions
[2025-03-25T05:12:11.089+0000] {connectionpool.py:823} WARNING - Retrying (Retry(total=1, connect=None, read=None, redirect=None, status=None)) after connection broken by 'NewConnectionError('<urllib3.connection.HTTPConnection object at 0x7fcce63a5550>: Failed to establish a new connection: [Errno 111] Connection refused')': /session/265bb54c5fc7e20e81d365ae57947314/actions
[2025-03-25T05:12:11.090+0000] {connectionpool.py:823} WARNING - Retrying (Retry(total=0, connect=None, read=None, redirect=None, status=None)) after connection broken by 'NewConnectionError('<urllib3.connection.HTTPConnection object at 0x7fcce5f3c430>: Failed to establish a new connection: [Errno 111] Connection refused')': /session/265bb54c5fc7e20e81d365ae57947314/actions
[2025-03-25T05:12:11.091+0000] {logging_mixin.py:151} INFO - Lỗi khi lấy dữ liệu: HTTPConnectionPool(host='localhost', port=39053): Max retries exceeded with url: /session/265bb54c5fc7e20e81d365ae57947314/actions (Caused by NewConnectionError('<urllib3.connection.HTTPConnection object at 0x7fcce5f3c550>: Failed to establish a new connection: [Errno 111] Connection refused'))
[2025-03-25T05:12:11.093+0000] {connectionpool.py:823} WARNING - Retrying (Retry(total=2, connect=None, read=None, redirect=None, status=None)) after connection broken by 'NewConnectionError('<urllib3.connection.HTTPConnection object at 0x7fcce5edb430>: Failed to establish a new connection: [Errno 111] Connection refused')': /session/265bb54c5fc7e20e81d365ae57947314/actions
[2025-03-25T05:12:11.094+0000] {connectionpool.py:823} WARNING - Retrying (Retry(total=1, connect=None, read=None, redirect=None, status=None)) after connection broken by 'NewConnectionError('<urllib3.connection.HTTPConnection object at 0x7fcce5f3c460>: Failed to establish a new connection: [Errno 111] Connection refused')': /session/265bb54c5fc7e20e81d365ae57947314/actions
[2025-03-25T05:12:11.095+0000] {connectionpool.py:823} WARNING - Retrying (Retry(total=0, connect=None, read=None, redirect=None, status=None)) after connection broken by 'NewConnectionError('<urllib3.connection.HTTPConnection object at 0x7fcce5f3c430>: Failed to establish a new connection: [Errno 111] Connection refused')': /session/265bb54c5fc7e20e81d365ae57947314/actions
[2025-03-25T05:12:11.095+0000] {logging_mixin.py:151} INFO - Lỗi khi lấy dữ liệu: HTTPConnectionPool(host='localhost', port=39053): Max retries exceeded with url: /session/265bb54c5fc7e20e81d365ae57947314/actions (Caused by NewConnectionError('<urllib3.connection.HTTPConnection object at 0x7fcce63a58e0>: Failed to establish a new connection: [Errno 111] Connection refused'))
[2025-03-25T05:12:11.097+0000] {connectionpool.py:823} WARNING - Retrying (Retry(total=2, connect=None, read=None, redirect=None, status=None)) after connection broken by 'NewConnectionError('<urllib3.connection.HTTPConnection object at 0x7fcce63a5340>: Failed to establish a new connection: [Errno 111] Connection refused')': /session/265bb54c5fc7e20e81d365ae57947314/actions
[2025-03-25T05:12:11.098+0000] {connectionpool.py:823} WARNING - Retrying (Retry(total=1, connect=None, read=None, redirect=None, status=None)) after connection broken by 'NewConnectionError('<urllib3.connection.HTTPConnection object at 0x7fcce63c2f70>: Failed to establish a new connection: [Errno 111] Connection refused')': /session/265bb54c5fc7e20e81d365ae57947314/actions
[2025-03-25T05:12:11.098+0000] {connectionpool.py:823} WARNING - Retrying (Retry(total=0, connect=None, read=None, redirect=None, status=None)) after connection broken by 'NewConnectionError('<urllib3.connection.HTTPConnection object at 0x7fcce63c2f40>: Failed to establish a new connection: [Errno 111] Connection refused')': /session/265bb54c5fc7e20e81d365ae57947314/actions
[2025-03-25T05:12:11.099+0000] {logging_mixin.py:151} INFO - Lỗi khi lấy dữ liệu: HTTPConnectionPool(host='localhost', port=39053): Max retries exceeded with url: /session/265bb54c5fc7e20e81d365ae57947314/actions (Caused by NewConnectionError('<urllib3.connection.HTTPConnection object at 0x7fcce63c2ca0>: Failed to establish a new connection: [Errno 111] Connection refused'))
[2025-03-25T05:12:11.101+0000] {connectionpool.py:823} WARNING - Retrying (Retry(total=2, connect=None, read=None, redirect=None, status=None)) after connection broken by 'NewConnectionError('<urllib3.connection.HTTPConnection object at 0x7fcce6388b80>: Failed to establish a new connection: [Errno 111] Connection refused')': /session/265bb54c5fc7e20e81d365ae57947314/actions
[2025-03-25T05:12:11.102+0000] {connectionpool.py:823} WARNING - Retrying (Retry(total=1, connect=None, read=None, redirect=None, status=None)) after connection broken by 'NewConnectionError('<urllib3.connection.HTTPConnection object at 0x7fcce6388dc0>: Failed to establish a new connection: [Errno 111] Connection refused')': /session/265bb54c5fc7e20e81d365ae57947314/actions
[2025-03-25T05:12:11.102+0000] {connectionpool.py:823} WARNING - Retrying (Retry(total=0, connect=None, read=None, redirect=None, status=None)) after connection broken by 'NewConnectionError('<urllib3.connection.HTTPConnection object at 0x7fcce63882b0>: Failed to establish a new connection: [Errno 111] Connection refused')': /session/265bb54c5fc7e20e81d365ae57947314/actions
[2025-03-25T05:12:11.103+0000] {logging_mixin.py:151} INFO - Lỗi khi lấy dữ liệu: HTTPConnectionPool(host='localhost', port=39053): Max retries exceeded with url: /session/265bb54c5fc7e20e81d365ae57947314/actions (Caused by NewConnectionError('<urllib3.connection.HTTPConnection object at 0x7fcce6388af0>: Failed to establish a new connection: [Errno 111] Connection refused'))
[2025-03-25T05:12:11.105+0000] {connectionpool.py:823} WARNING - Retrying (Retry(total=2, connect=None, read=None, redirect=None, status=None)) after connection broken by 'NewConnectionError('<urllib3.connection.HTTPConnection object at 0x7fcce6388700>: Failed to establish a new connection: [Errno 111] Connection refused')': /session/265bb54c5fc7e20e81d365ae57947314/actions
[2025-03-25T05:12:11.105+0000] {connectionpool.py:823} WARNING - Retrying (Retry(total=1, connect=None, read=None, redirect=None, status=None)) after connection broken by 'NewConnectionError('<urllib3.connection.HTTPConnection object at 0x7fcce6388b50>: Failed to establish a new connection: [Errno 111] Connection refused')': /session/265bb54c5fc7e20e81d365ae57947314/actions
[2025-03-25T05:12:11.106+0000] {connectionpool.py:823} WARNING - Retrying (Retry(total=0, connect=None, read=None, redirect=None, status=None)) after connection broken by 'NewConnectionError('<urllib3.connection.HTTPConnection object at 0x7fcce5f93df0>: Failed to establish a new connection: [Errno 111] Connection refused')': /session/265bb54c5fc7e20e81d365ae57947314/actions
[2025-03-25T05:12:11.107+0000] {logging_mixin.py:151} INFO - Lỗi khi lấy dữ liệu: HTTPConnectionPool(host='localhost', port=39053): Max retries exceeded with url: /session/265bb54c5fc7e20e81d365ae57947314/actions (Caused by NewConnectionError('<urllib3.connection.HTTPConnection object at 0x7fcce5f4abe0>: Failed to establish a new connection: [Errno 111] Connection refused'))
[2025-03-25T05:12:11.109+0000] {connectionpool.py:823} WARNING - Retrying (Retry(total=2, connect=None, read=None, redirect=None, status=None)) after connection broken by 'NewConnectionError('<urllib3.connection.HTTPConnection object at 0x7fcce5edb8b0>: Failed to establish a new connection: [Errno 111] Connection refused')': /session/265bb54c5fc7e20e81d365ae57947314/actions
[2025-03-25T05:12:11.110+0000] {connectionpool.py:823} WARNING - Retrying (Retry(total=1, connect=None, read=None, redirect=None, status=None)) after connection broken by 'NewConnectionError('<urllib3.connection.HTTPConnection object at 0x7fcce5f4aac0>: Failed to establish a new connection: [Errno 111] Connection refused')': /session/265bb54c5fc7e20e81d365ae57947314/actions
[2025-03-25T05:12:11.110+0000] {connectionpool.py:823} WARNING - Retrying (Retry(total=0, connect=None, read=None, redirect=None, status=None)) after connection broken by 'NewConnectionError('<urllib3.connection.HTTPConnection object at 0x7fcce5f93fd0>: Failed to establish a new connection: [Errno 111] Connection refused')': /session/265bb54c5fc7e20e81d365ae57947314/actions
[2025-03-25T05:12:11.111+0000] {logging_mixin.py:151} INFO - Lỗi khi lấy dữ liệu: HTTPConnectionPool(host='localhost', port=39053): Max retries exceeded with url: /session/265bb54c5fc7e20e81d365ae57947314/actions (Caused by NewConnectionError('<urllib3.connection.HTTPConnection object at 0x7fcce63883a0>: Failed to establish a new connection: [Errno 111] Connection refused'))
[2025-03-25T05:12:11.112+0000] {connectionpool.py:823} WARNING - Retrying (Retry(total=2, connect=None, read=None, redirect=None, status=None)) after connection broken by 'NewConnectionError('<urllib3.connection.HTTPConnection object at 0x7fcce6388b50>: Failed to establish a new connection: [Errno 111] Connection refused')': /session/265bb54c5fc7e20e81d365ae57947314/url
[2025-03-25T05:12:11.113+0000] {connectionpool.py:823} WARNING - Retrying (Retry(total=1, connect=None, read=None, redirect=None, status=None)) after connection broken by 'NewConnectionError('<urllib3.connection.HTTPConnection object at 0x7fcce6388df0>: Failed to establish a new connection: [Errno 111] Connection refused')': /session/265bb54c5fc7e20e81d365ae57947314/url
[2025-03-25T05:12:11.114+0000] {connectionpool.py:823} WARNING - Retrying (Retry(total=0, connect=None, read=None, redirect=None, status=None)) after connection broken by 'NewConnectionError('<urllib3.connection.HTTPConnection object at 0x7fcce6388e50>: Failed to establish a new connection: [Errno 111] Connection refused')': /session/265bb54c5fc7e20e81d365ae57947314/url
[2025-03-25T05:12:11.115+0000] {data_stream.py:39} ERROR - An error occurred: HTTPConnectionPool(host='localhost', port=39053): Max retries exceeded with url: /session/265bb54c5fc7e20e81d365ae57947314/url (Caused by NewConnectionError('<urllib3.connection.HTTPConnection object at 0x7fcce6388d00>: Failed to establish a new connection: [Errno 111] Connection refused'))
[2025-03-25T05:12:11.115+0000] {python.py:194} INFO - Done. Returned value was: None
[2025-03-25T05:12:11.133+0000] {taskinstance.py:1400} INFO - Marking task as SUCCESS. dag_id=job_data_stream, task_id=job_data_stream, execution_date=20250325T023836, start_date=20250325T023837, end_date=20250325T051211
[2025-03-25T05:12:11.179+0000] {process_utils.py:79} INFO - Process psutil.Process(pid=3212, status='terminated', exitcode=0, started='02:38:37') (3212) terminated with exit code 0
[2025-03-25T05:12:11.180+0000] {process_utils.py:79} INFO - Process psutil.Process(pid=3256, status='terminated', started='02:38:37') (3256) terminated with exit code None
[2025-03-25T05:12:11.182+0000] {process_utils.py:79} INFO - Process psutil.Process(pid=3224, status='terminated', started='02:38:37') (3224) terminated with exit code None
[2025-03-25T05:12:11.183+0000] {process_utils.py:79} INFO - Process psutil.Process(pid=3257, status='terminated', started='02:38:37') (3257) terminated with exit code None
[2025-03-25T05:12:11.185+0000] {process_utils.py:79} INFO - Process psutil.Process(pid=3225, status='terminated', started='02:38:37') (3225) terminated with exit code None
[2025-03-25T05:12:11.186+0000] {process_utils.py:79} INFO - Process psutil.Process(pid=3214, status='terminated', started='02:38:37') (3214) terminated with exit code None
